Workbook

Sheet Resumen
A1: Indicador | B1: F Calculado | C1: F Critico Critico | D1: P Valor
A2: Participación activa | B2: =ROUND('Participación-activa'!G74, 4) -> 20.0487 | C2: =ROUND('Participación-activa'!G82, 4) -> 2.6281 | D2: ='Participación-activa'!G83 -> 4.3098479e-12
A3: Comunicación equipo | B3: =ROUND('Comunicación-equipo'!G74, 4) -> 21.1506 | C3: =ROUND('Comunicación-equipo'!G82, 4) -> 2.6281 | D3: ='Comunicación-equipo'!G83 -> 1.0611795e-12
A4: Cumplimiento tareas | B4: =ROUND('Cumplimiento-tareas'!G74, 4) -> 16.293 | C4: =ROUND('Cumplimiento-tareas'!G82, 4) -> 2.6281 | D4: ='Cumplimiento-tareas'!G83 -> 5.484433e-10
A5: Contribución grupo | B5: =ROUND('Contribución-grupo'!G74, 4) -> 28.7624 | C5: =ROUND('Contribución-grupo'!G82, 4) -> 2.6281 | D5: ='Contribución-grupo'!G83 -> 8.5019536e-17
A6: Resolución problemas | B6: =ROUND('Resolución-problemas'!G74, 4) -> 15.3586 | C6: =ROUND('Resolución-problemas'!G82, 4) -> 2.6281 | D6: ='Resolución-problemas'!G83 -> 1.8619809e-09
A7: Conocimientos adquiridos | B7: =ROUND('Conocimientos-adquiridos'!G74, 4) -> 22.5594 | C7: =ROUND('Conocimientos-adquiridos'!G82, 4) -> 2.6281 | D7: ='Conocimientos-adquiridos'!G83 -> 1.7923878e-13
A8: Nota final | B8: =ROUND('Nota-final'!G74, 4) -> 36.1723 | C8: =ROUND('Nota-final'!G82, 4) -> 2.6281 | D8: ='Nota-final'!G83 -> 1.3096309e-20
A9: Comprensión | B9: =ROUND(Comprensión!G74, 4) -> 19.7433 | C9: =ROUND(Comprensión!G82, 4) -> 2.6281 | D9: =Comprensión!G83 -> 6.3658765e-12
A10: Habilidades | B10: =ROUND(Habilidades!G74, 4) -> 19.7569 | C10: =ROUND(Habilidades!G82, 4) -> 2.6281 | D10: =Habilidades!G83 -> 6.2559827e-12
A11: Resolución autónoma | B11: =ROUND('Resolución-autónoma'!G74, 4) -> 34.642 | C11: =ROUND('Resolución-autónoma'!G82, 4) -> 2.6281 | D11: ='Resolución-autónoma'!G83 -> 7.7780568e-20
A12: Motivación | B12: =ROUND(Motivación!G74, 4) -> 19.3722 | C12: =ROUND(Motivación!G82, 4) -> 2.6281 | D12: =Motivación!G83 -> 1.0236147e-11

Sheet Participación-activa
A1: Grupo Control Pre Test Sin intervención | B1: Grupo Control Post Test Sin intervención | C1: Grupo Experimental Pre Test Sin intervención | D1: Grupo Experimental Post Test Con intervención
A2: 2 | B2: 2 | C2: 4 | D2: 4 | F2: Datos Generales
A3: 4 | B3: 2 | C3: 1 | D3: 5 | F3: Tamano Grupos | G3: =COUNT(A:A) -> 97
A4: 2 | B4: 2 | C4: 3 | D4: 2 | F4: Promedio Grupo A | G4: =AVERAGE(A:A) -> 3.185567
A5: 3 | B5: 3 | C5: 2 | D5: 3 | F5: Promedio Grupo B | G5: =AVERAGE(B:B) -> 3
A6: 2 | B6: 4 | C6: 3 | D6: 4 | F6: Promedio Grupo C | G6: =AVERAGE(C:C) -> 3.1134021
A7: 1 | B7: 5 | C7: 5 | D7: 4 | F7: Promedio Grupo D | G7: =AVERAGE(D:D) -> 4.1134021
A8: 5 | B8: 1 | C8: 3 | D8: 5 | F8: Promedio Total total | G8: =AVERAGE(G4:G7) -> 3.3530928
A9: 3 | B9: 2 | C9: 5 | D9: 4
A10: 3 | B10: 3 | C10: 3 | D10: 5
A11: 5 | B11: 3 | C11: 2 | D11: 4 | F11: Calculo Suma de Cuadrados Entre Grupos
A12: 2 | B12: 3 | C12: 4 | D12: 5 | F12: Mide qué tan diferentes son los grupos entre sí
A13: 4 | B13: 5 | C13: 2 | D13: 5 | F13: Compara las medias de cada grupo con la media general
A14: 5 | B14: 4 | C14: 3 | D14: 5
A15: 5 | B15: 5 | C15: 3 | D15: 5
A16: 1 | B16: 2 | C16: 4 | D16: 4
A17: 3 | B17: 4 | C17: 2 | D17: 5 | F17: SC Entre Grupos | G17: =G3*((G4-G8)^2+(G5-G8)^2+(G6-G8)^2+(G7-G8)^2) -> 76.46134
A18: 5 | B18: 3 | C18: 2 | D18: 5
A19: 4 | B19: 5 | C19: 1 | D19: 4
A20: 2 | B20: 4 | C20: 5 | D20: 3 | F20: Calculo gl ENTRE (Grados de libertad entre grupos)
A21: 4 | B21: 3 | C21: 4 | D21: 5 | F21: Cantidad de grupos independientes que puedes comparar
A22: 2 | B22: 2 | C22: 3 | D22: 5 | F22: k (Numero de grupos) | G22: 4
A23: 3 | B23: 2 | C23: 2 | D23: 1
A24: 2 | B24: 1 | C24: 1 | D24: 4
A25: 1 | B25: 2 | C25: 4 | D25: 5 | F25: gl entre | G25: =G22-1 -> 3
A26: 5 | B26: 2 | C26: 3 | D26: 4
A27: 5 | B27: 2 | C27: 4 | D27: 4
A28: 3 | B28: 5 | C28: 5 | D28: 5 | F28: Calculo MC ENTRE (Media Cuadrática Entre)
A29: 3 | B29: 4 | C29: 2 | D29: 4 | F29: Es el promedio de la variación entre grupos
A30: 4 | B30: 4 | C30: 5 | D30: 2
A31: 5 | B31: 3 | C31: 3 | D31: 5
A32: 4 | B32: 3 | C32: 5 | D32: 5
A33: 5 | B33: 4 | C33: 3 | D33: 5
A34: 2 | B34: 4 | C34: 4 | D34: 3 | F34: MC entre | G34: =G17/G25 -> 25.487113
A35: 3 | B35: 5 | C35: 2 | D35: 3
A36: 3 | B36: 2 | C36: 2 | D36: 5
A37: 3 | B37: 4 | C37: 2 | D37: 5 | F37: Calculo SC DENTRO DE GRUPOS (Suma de Cuadrados Dentro)
A38: 3 | B38: 2 | C38: 3 | D38: 5 | F38: Mide la variabilidad interna de cada grupo
A39: 5 | B39: 1 | C39: 3 | D39: 4 | F39: Qué tanto varían los datos dentro del mismo grupo
A40: 5 | B40: 3 | C40: 1 | D40: 5
...

Sheet Comunicación-equipo
A1: Grupo Control Pre Test Sin intervención | B1: Grupo Control Post Test Sin intervención | C1: Grupo Experimental Pre Test Sin intervención | D1: Grupo Experimental Post Test Con intervención
A2: 3 | B2: 3 | C2: 2 | D2: 5 | F2: Datos Generales
A3: 4 | B3: 3 | C3: 5 | D3: 5 | F3: Tamano Grupos | G3: =COUNT(A:A) -> 97
A4: 2 | B4: 3 | C4: 1 | D4: 5 | F4: Promedio Grupo A | G4: =AVERAGE(A:A) -> 2.9278351
A5: 5 | B5: 2 | C5: 4 | D5: 4 | F5: Promedio Grupo B | G5: =AVERAGE(B:B) -> 3.1237113
A6: 3 | B6: 1 | C6: 2 | D6: 2 | F6: Promedio Grupo C | G6: =AVERAGE(C:C) -> 3.0412371
A7: 2 | B7: 3 | C7: 2 | D7: 5 | F7: Promedio Grupo D | G7: =AVERAGE(D:D) -> 4.0824742
A8: 3 | B8: 3 | C8: 3 | D8: 3 | F8: Promedio Total total | G8: =AVERAGE(G4:G7) -> 3.2938144
A9: 3 | B9: 4 | C9: 3 | D9: 3
A10: 5 | B10: 1 | C10: 4 | D10: 5
A11: 1 | B11: 4 | C11: 4 | D11: 1 | F11: Calculo Suma de Cuadrados Entre Grupos
A12: 3 | B12: 2 | C12: 3 | D12: 3 | F12: Mide qué tan diferentes son los grupos entre sí
A13: 2 | B13: 3 | C13: 2 | D13: 5 | F13: Compara las medias de cada grupo con la media general
A14: 3 | B14: 2 | C14: 3 | D14: 3
A15: 4 | B15: 2 | C15: 3 | D15: 4
A16: 3 | B16: 5 | C16: 3 | D16: 4
A17: 4 | B17: 1 | C17: 1 | D17: 4 | F17: SC Entre Grupos | G17: =G3*((G4-G8)^2+(G5-G8)^2+(G6-G8)^2+(G7-G8)^2) -> 82.319588
A18: 1 | B18: 5 | C18: 3 | D18: 5
A19: 3 | B19: 4 | C19: 5 | D19: 3
A20: 3 | B20: 3 | C20: 3 | D20: 5 | F20: Calculo gl ENTRE (Grados de libertad entre grupos)
A21: 2 | B21: 3 | C21: 3 | D21: 4 | F21: Cantidad de grupos independientes que puedes comparar
A22: 3 | B22: 3 | C22: 4 | D22: 5 | F22: k (Numero de grupos) | G22: 4
A23: 2 | B23: 4 | C23: 2 | D23: 5
A24: 4 | B24: 1 | C24: 2 | D24: 2
A25: 1 | B25: 4 | C25: 3 | D25: 5 | F25: gl entre | G25: =G22-1 -> 3
A26: 3 | B26: 4 | C26: 2 | D26: 5
A27: 3 | B27: 4 | C27: 1 | D27: 4
A28: 5 | B28: 5 | C28: 3 | D28: 4 | F28: Calculo MC ENTRE (Media Cuadrática Entre)
A29: 4 | B29: 3 | C29: 2 | D29: 4 | F29: Es el promedio de la variación entre grupos
A30: 5 | B30: 1 | C30: 5 | D30: 5
A31: 3 | B31: 5 | C31: 3 | D31: 3
A32: 1 | B32: 1 | C32: 5 | D32: 5
A33: 2 | B33: 4 | C33: 5 | D33: 5
A34: 3 | B34: 1 | C34: 2 | D34: 5 | F34: MC entre | G34: =G17/G25 -> 27.439863
A35: 4 | B35: 2 | C35: 5 | D35: 5
A36: 5 | B36: 5 | C36: 2 | D36: 3
A37: 4 | B37: 3 | C37: 4 | D37: 5 | F37: Calculo SC DENTRO DE GRUPOS (Suma de Cuadrados Dentro)
A38: 3 | B38: 4 | C38: 2 | D38: 3 | F38: Mide la variabilidad interna de cada grupo
A39: 3 | B39: 4 | C39: 3 | D39: 4 | F39: Qué tanto varían los datos dentro del mismo grupo
A40: 3 | B40: 5 | C40: 3 | D40: 3
...

Sheet Cumplimiento-tareas
A1: Grupo Control Pre Test Sin intervención | B1: Grupo Control Post Test Sin intervención | C1: Grupo Experimental Pre Test Sin intervención | D1: Grupo Experimental Post Test Con intervención
A2: 3 | B2: 4 | C2: 5 | D2: 4 | F2: Datos Generales
A3: 3 | B3: 3 | C3: 3 | D3: 4 | F3: Tamano Grupos | G3: =COUNT(A:A) -> 97
A4: 5 | B4: 4 | C4: 5 | D4: 2 | F4: Promedio Grupo A | G4: =AVERAGE(A:A) -> 3.2886598
A5: 4 | B5: 3 | C5: 3 | D5: 5 | F5: Promedio Grupo B | G5: =AVERAGE(B:B) -> 3.1237113
A6: 4 | B6: 3 | C6: 2 | D6: 4 | F6: Promedio Grupo C | G6: =AVERAGE(C:C) -> 3.1752577
A7: 2 | B7: 4 | C7: 4 | D7: 5 | F7: Promedio Grupo D | G7: =AVERAGE(D:D) -> 4.0927835
A8: 3 | B8: 3 | C8: 5 | D8: 5 | F8: Promedio Total total | G8: =AVERAGE(G4:G7) -> 3.4201031
A9: 5 | B9: 3 | C9: 3 | D9: 5
A10: 2 | B10: 5 | C10: 3 | D10: 5
A11: 4 | B11: 3 | C11: 4 | D11: 4 | F11: Calculo Suma de Cuadrados Entre Grupos
A12: 1 | B12: 4 | C12: 4 | D12: 5 | F12: Mide qué tan diferentes son los grupos entre sí
A13: 3 | B13: 5 | C13: 2 | D13: 3 | F13: Compara las medias de cada grupo con la media general
A14: 4 | B14: 2 | C14: 2 | D14: 4
A15: 5 | B15: 3 | C15: 4 | D15: 3
A16: 3 | B16: 4 | C16: 3 | D16: 4
A17: 2 | B17: 4 | C17: 3 | D17: 5 | F17: SC Entre Grupos | G17: =G3*((G4-G8)^2+(G5-G8)^2+(G6-G8)^2+(G7-G8)^2) -> 59.904639
A18: 3 | B18: 4 | C18: 3 | D18: 3
A19: 5 | B19: 5 | C19: 5 | D19: 4
A20: 4 | B20: 3 | C20: 4 | D20: 4 | F20: Calculo gl ENTRE (Grados de libertad entre grupos)
A21: 5 | B21: 3 | C21: 4 | D21: 4 | F21: Cantidad de grupos independientes que puedes comparar
A22: 3 | B22: 4 | C22: 2 | D22: 4 | F22: k (Numero de grupos) | G22: 4
A23: 2 | B23: 2 | C23: 4 | D23: 3
A24: 2 | B24: 4 | C24: 4 | D24: 5
A25: 2 | B25: 2 | C25: 3 | D25: 5 | F25: gl entre | G25: =G22-1 -> 3
A26: 2 | B26: 5 | C26: 3 | D26: 2
A27: 4 | B27: 3 | C27: 2 | D27: 3
A28: 3 | B28: 1 | C28: 4 | D28: 3 | F28: Calculo MC ENTRE (Media Cuadrática Entre)
A29: 1 | B29: 3 | C29: 4 | D29: 4 | F29: Es el promedio de la variación entre grupos
A30: 4 | B30: 3 | C30: 3 | D30: 5
A31: 4 | B31: 1 | C31: 5 | D31: 2
A32: 5 | B32: 5 | C32: 4 | D32: 5
A33: 4 | B33: 4 | C33: 2 | D33: 5
A34: 2 | B34: 5 | C34: 4 | D34: 5 | F34: MC entre | G34: =G17/G25 -> 19.968213
A35: 2 | B35: 3 | C35: 3 | D35: 2
A36: 3 | B36: 1 | C36: 1 | D36: 4
A37: 2 | B37: 2 | C37: 3 | D37: 5 | F37: Calculo SC DENTRO DE GRUPOS (Suma de Cuadrados Dentro)
A38: 4 | B38: 4 | C38: 1 | D38: 5 | F38: Mide la variabilidad interna de cada grupo
A39: 5 | B39: 4 | C39: 3 | D39: 5 | F39: Qué tanto varían los datos dentro del mismo grupo
A40: 5 | B40: 4 | C40: 2 | D40: 4
...

Sheet Contribución-grupo
A1: Grupo Control Pre Test Sin intervención | B1: Grupo Control Post Test Sin intervención | C1: Grupo Experimental Pre Test Sin intervención | D1: Grupo Experimental Post Test Con intervención
A2: 4 | B2: 3 | C2: 3 | D2: 5 | F2: Datos Generales
A3: 2 | B3: 3 | C3: 3 | D3: 5 | F3: Tamano Grupos | G3: =COUNT(A:A) -> 97
A4: 5 | B4: 4 | C4: 3 | D4: 5 | F4: Promedio Grupo A | G4: =AVERAGE(A:A) -> 3.1030928
A5: 3 | B5: 3 | C5: 3 | D5: 4 | F5: Promedio Grupo B | G5: =AVERAGE(B:B) -> 3.1958763
A6: 3 | B6: 4 | C6: 4 | D6: 5 | F6: Promedio Grupo C | G6: =AVERAGE(C:C) -> 3.0103093
A7: 1 | B7: 3 | C7: 3 | D7: 4 | F7: Promedio Grupo D | G7: =AVERAGE(D:D) -> 4.2268041
A8: 3 | B8: 4 | C8: 3 | D8: 5 | F8: Promedio Total total | G8: =AVERAGE(G4:G7) -> 3.3840206
A9: 3 | B9: 2 | C9: 4 | D9: 5
A10: 3 | B10: 3 | C10: 1 | D10: 5
A11: 4 | B11: 3 | C11: 3 | D11: 5 | F11: Calculo Suma de Cuadrados Entre Grupos
A12: 4 | B12: 5 | C12: 3 | D12: 3 | F12: Mide qué tan diferentes son los grupos entre sí
A13: 4 | B13: 4 | C13: 2 | D13: 5 | F13: Compara las medias de cada grupo con la media general
A14: 2 | B14: 5 | C14: 4 | D14: 3
A15: 3 | B15: 5 | C15: 4 | D15: 2
A16: 4 | B16: 4 | C16: 2 | D16: 4
A17: 3 | B17: 5 | C17: 1 | D17: 5 | F17: SC Entre Grupos | G17: =G3*((G4-G8)^2+(G5-G8)^2+(G6-G8)^2+(G7-G8)^2) -> 93.533505
A18: 4 | B18: 3 | C18: 3 | D18: 5
A19: 2 | B19: 2 | C19: 2 | D19: 5
A20: 3 | B20: 3 | C20: 2 | D20: 5 | F20: Calculo gl ENTRE (Grados de libertad entre grupos)
A21: 5 | B21: 1 | C21: 4 | D21: 5 | F21: Cantidad de grupos independientes que puedes comparar
A22: 3 | B22: 4 | C22: 3 | D22: 3 | F22: k (Numero de grupos) | G22: 4
A23: 5 | B23: 3 | C23: 3 | D23: 5
A24: 3 | B24: 4 | C24: 3 | D24: 5
A25: 4 | B25: 1 | C25: 4 | D25: 5 | F25: gl entre | G25: =G22-1 -> 3
A26: 3 | B26: 3 | C26: 2 | D26: 5
A27: 3 | B27: 2 | C27: 3 | D27: 4
A28: 3 | B28: 3 | C28: 5 | D28: 3 | F28: Calculo MC ENTRE (Media Cuadrática Entre)
A29: 3 | B29: 5 | C29: 3 | D29: 4 | F29: Es el promedio de la variación entre grupos
A30: 3 | B30: 4 | C30: 3 | D30: 5
A31: 3 | B31: 3 | C31: 3 | D31: 5
A32: 3 | B32: 2 | C32: 4 | D32: 5
A33: 3 | B33: 3 | C33: 3 | D33: 5
A34: 5 | B34: 2 | C34: 3 | D34: 4 | F34: MC entre | G34: =G17/G25 -> 31.177835
A35: 4 | B35: 5 | C35: 1 | D35: 5
A36: 3 | B36: 3 | C36: 3 | D36: 3
A37: 2 | B37: 3 | C37: 2 | D37: 4 | F37: Calculo SC DENTRO DE GRUPOS (Suma de Cuadrados Dentro)
A38: 5 | B38: 3 | C38: 1 | D38: 5 | F38: Mide la variabilidad interna de cada grupo
A39: 3 | B39: 2 | C39: 1 | D39: 5 | F39: Qué tanto varían los datos dentro del mismo grupo
A40: 4 | B40: 4 | C40: 5 | D40: 5
...

Sheet Resolución-problemas
A1: Grupo Control Pre Test Sin intervención | B1: Grupo Control Post Test Sin intervención | C1: Grupo Experimental Pre Test Sin intervención | D1: Grupo Experimental Post Test Con intervención
A2: 2 | B2: 4 | C2: 5 | D2: 2 | F2: Datos Generales
A3: 3 | B3: 3 | C3: 4 | D3: 3 | F3: Tamano Grupos | G3: =COUNT(A:A) -> 97
A4: 4 | B4: 1 | C4: 3 | D4: 4 | F4: Promedio Grupo A | G4: =AVERAGE(A:A) -> 2.9793814
A5: 1 | B5: 3 | C5: 2 | D5: 1 | F5: Promedio Grupo B | G5: =AVERAGE(B:B) -> 3.2886598
A6: 3 | B6: 3 | C6: 2 | D6: 4 | F6: Promedio Grupo C | G6: =AVERAGE(C:C) -> 3.0824742
A7: 4 | B7: 5 | C7: 2 | D7: 4 | F7: Promedio Grupo D | G7: =AVERAGE(D:D) -> 3.9793814
A8: 5 | B8: 3 | C8: 5 | D8: 4 | F8: Promedio Total total | G8: =AVERAGE(G4:G7) -> 3.3324742
A9: 2 | B9: 3 | C9: 2 | D9: 4
A10: 3 | B10: 4 | C10: 3 | D10: 5
A11: 3 | B11: 4 | C11: 2 | D11: 4 | F11: Calculo Suma de Cuadrados Entre Grupos
A12: 3 | B12: 3 | C12: 1 | D12: 5 | F12: Mide qué tan diferentes son los grupos entre sí
A13: 5 | B13: 3 | C13: 2 | D13: 3 | F13: Compara las medias de cada grupo con la media general
A14: 2 | B14: 4 | C14: 2 | D14: 5
A15: 3 | B15: 4 | C15: 4 | D15: 3
A16: 1 | B16: 3 | C16: 2 | D16: 4
A17: 3 | B17: 2 | C17: 5 | D17: 1 | F17: SC Entre Grupos | G17: =G3*((G4-G8)^2+(G5-G8)^2+(G6-G8)^2+(G7-G8)^2) -> 58.935567
A18: 3 | B18: 5 | C18: 3 | D18: 4
A19: 4 | B19: 2 | C19: 3 | D19: 3
A20: 3 | B20: 4 | C20: 3 | D20: 4 | F20: Calculo gl ENTRE (Grados de libertad entre grupos)
A21: 3 | B21: 3 | C21: 2 | D21: 5 | F21: Cantidad de grupos independientes que puedes comparar
A22: 2 | B22: 4 | C22: 2 | D22: 5 | F22: k (Numero de grupos) | G22: 4
A23: 2 | B23: 3 | C23: 3 | D23: 5
A24: 2 | B24: 3 | C24: 4 | D24: 4
A25: 3 | B25: 4 | C25: 2 | D25: 4 | F25: gl entre | G25: =G22-1 -> 3
A26: 5 | B26: 2 | C26: 3 | D26: 3
A27: 1 | B27: 5 | C27: 1 | D27: 4
A28: 3 | B28: 2 | C28: 3 | D28: 3 | F28: Calculo MC ENTRE (Media Cuadrática Entre)
A29: 3 | B29: 1 | C29: 4 | D29: 4 | F29: Es el promedio de la variación entre grupos
A30: 2 | B30: 4 | C30: 5 | D30: 5
A31: 4 | B31: 3 | C31: 3 | D31: 4
A32: 5 | B32: 3 | C32: 3 | D32: 4
A33: 2 | B33: 1 | C33: 2 | D33: 3
A34: 5 | B34: 3 | C34: 4 | D34: 4 | F34: MC entre | G34: =G17/G25 -> 19.645189
A35: 5 | B35: 3 | C35: 2 | D35: 5
A36: 2 | B36: 5 | C36: 4 | D36: 4
A37: 3 | B37: 1 | C37: 5 | D37: 3 | F37: Calculo SC DENTRO DE GRUPOS (Suma de Cuadrados Dentro)
A38: 5 | B38: 4 | C38: 4 | D38: 5 | F38: Mide la variabilidad interna de cada grupo
A39: 1 | B39: 4 | C39: 1 | D39: 5 | F39: Qué tanto varían los datos dentro del mismo grupo
A40: 3 | B40: 3 | C40: 5 | D40: 5
...

Sheet Conocimientos-adquiridos
A1: Grupo Control Pre Test Sin intervención | B1: Grupo Control Post Test Sin intervención | C1: Grupo Experimental Pre Test Sin intervención | D1: Grupo Experimental Post Test Con intervención
A2: 2 | B2: 3 | C2: 3 | D2: 4 | F2: Datos Generales
A3: 2 | B3: 4 | C3: 3 | D3: 5 | F3: Tamano Grupos | G3: =COUNT(A:A) -> 97
A4: 5 | B4: 2 | C4: 3 | D4: 5 | F4: Promedio Grupo A | G4: =AVERAGE(A:A) -> 3.2268041
A5: 4 | B5: 2 | C5: 5 | D5: 5 | F5: Promedio Grupo B | G5: =AVERAGE(B:B) -> 3.1340206
A6: 5 | B6: 2 | C6: 4 | D6: 3 | F6: Promedio Grupo C | G6: =AVERAGE(C:C) -> 3.0412371
A7: 5 | B7: 3 | C7: 3 | D7: 3 | F7: Promedio Grupo D | G7: =AVERAGE(D:D) -> 4.2061856
A8: 5 | B8: 3 | C8: 4 | D8: 4 | F8: Promedio Total total | G8: =AVERAGE(G4:G7) -> 3.4020619
A9: 2 | B9: 4 | C9: 3 | D9: 5
A10: 4 | B10: 2 | C10: 4 | D10: 5
A11: 3 | B11: 2 | C11: 2 | D11: 4 | F11: Calculo Suma de Cuadrados Entre Grupos
A12: 3 | B12: 5 | C12: 1 | D12: 5 | F12: Mide qué tan diferentes son los grupos entre sí
A13: 4 | B13: 5 | C13: 3 | D13: 5 | F13: Compara las medias de cada grupo con la media general
A14: 3 | B14: 1 | C14: 5 | D14: 4
A15: 4 | B15: 5 | C15: 5 | D15: 5
A16: 3 | B16: 3 | C16: 2 | D16: 5
A17: 3 | B17: 5 | C17: 3 | D17: 4 | F17: SC Entre Grupos | G17: =G3*((G4-G8)^2+(G5-G8)^2+(G6-G8)^2+(G7-G8)^2) -> 85.298969
A18: 4 | B18: 1 | C18: 3 | D18: 5
A19: 3 | B19: 2 | C19: 4 | D19: 4
A20: 3 | B20: 3 | C20: 2 | D20: 3 | F20: Calculo gl ENTRE (Grados de libertad entre grupos)
A21: 3 | B21: 3 | C21: 5 | D21: 4 | F21: Cantidad de grupos independientes que puedes comparar
A22: 4 | B22: 4 | C22: 1 | D22: 4 | F22: k (Numero de grupos) | G22: 4
A23: 4 | B23: 4 | C23: 4 | D23: 3
A24: 1 | B24: 4 | C24: 5 | D24: 4
A25: 5 | B25: 2 | C25: 3 | D25: 5 | F25: gl entre | G25: =G22-1 -> 3
A26: 5 | B26: 3 | C26: 3 | D26: 4
A27: 4 | B27: 3 | C27: 3 | D27: 4
A28: 4 | B28: 1 | C28: 3 | D28: 5 | F28: Calculo MC ENTRE (Media Cuadrática Entre)
A29: 3 | B29: 3 | C29: 5 | D29: 5 | F29: Es el promedio de la variación entre grupos
A30: 2 | B30: 5 | C30: 5 | D30: 4
A31: 5 | B31: 1 | C31: 2 | D31: 5
A32: 4 | B32: 5 | C32: 1 | D32: 4
A33: 3 | B33: 3 | C33: 3 | D33: 4
A34: 4 | B34: 4 | C34: 3 | D34: 3 | F34: MC entre | G34: =G17/G25 -> 28.43299
A35: 1 | B35: 5 | C35: 2 | D35: 5
A36: 3 | B36: 4 | C36: 3 | D36: 5
A37: 3 | B37: 2 | C37: 2 | D37: 4 | F37: Calculo SC DENTRO DE GRUPOS (Suma de Cuadrados Dentro)
A38: 5 | B38: 3 | C38: 3 | D38: 4 | F38: Mide la variabilidad interna de cada grupo
A39: 3 | B39: 2 | C39: 3 | D39: 2 | F39: Qué tanto varían los datos dentro del mismo grupo
A40: 3 | B40: 4 | C40: 3 | D40: 4
...

Sheet Nota-final
A1: Grupo Control Pre Test Sin intervención | B1: Grupo Control Post Test Sin intervención | C1: Grupo Experimental Pre Test Sin intervención | D1: Grupo Experimental Post Test Con intervención
A2: 3 | B2: 3 | C2: 3 | D2: 4 | F2: Datos Generales
A3: 4 | B3: 2 | C3: 3 | D3: 3 | F3: Tamano Grupos | G3: =COUNT(A:A) -> 97
A4: 3 | B4: 1 | C4: 3 | D4: 5 | F4: Promedio Grupo A | G4: =AVERAGE(A:A) -> 2.9381443
A5: 3 | B5: 2 | C5: 2 | D5: 3 | F5: Promedio Grupo B | G5: =AVERAGE(B:B) -> 2.7731959
A6: 2 | B6: 5 | C6: 3 | D6: 5 | F6: Promedio Grupo C | G6: =AVERAGE(C:C) -> 2.8969072
A7: 2 | B7: 2 | C7: 3 | D7: 4 | F7: Promedio Grupo D | G7: =AVERAGE(D:D) -> 4.1546392
A8: 3 | B8: 4 | C8: 3 | D8: 2 | F8: Promedio Total total | G8: =AVERAGE(G4:G7) -> 3.1907216
A9: 1 | B9: 4 | C9: 3 | D9: 4
A10: 4 | B10: 2 | C10: 1 | D10: 5
A11: 5 | B11: 2 | C11: 4 | D11: 3 | F11: Calculo Suma de Cuadrados Entre Grupos
A12: 1 | B12: 3 | C12: 1 | D12: 4 | F12: Mide qué tan diferentes son los grupos entre sí
A13: 3 | B13: 5 | C13: 4 | D13: 5 | F13: Compara las medias de cada grupo con la media general
A14: 5 | B14: 3 | C14: 2 | D14: 5
A15: 3 | B15: 1 | C15: 1 | D15: 5
A16: 3 | B16: 1 | C16: 3 | D16: 2
A17: 3 | B17: 3 | C17: 2 | D17: 5 | F17: SC Entre Grupos | G17: =G3*((G4-G8)^2+(G5-G8)^2+(G6-G8)^2+(G7-G8)^2) -> 121.59794
A18: 2 | B18: 3 | C18: 4 | D18: 4
A19: 3 | B19: 2 | C19: 3 | D19: 5
A20: 3 | B20: 4 | C20: 3 | D20: 5 | F20: Calculo gl ENTRE (Grados de libertad entre grupos)
A21: 4 | B21: 2 | C21: 4 | D21: 4 | F21: Cantidad de grupos independientes que puedes comparar
A22: 3 | B22: 3 | C22: 3 | D22: 4 | F22: k (Numero de grupos) | G22: 4
A23: 4 | B23: 1 | C23: 2 | D23: 5
A24: 3 | B24: 4 | C24: 5 | D24: 5
A25: 3 | B25: 3 | C25: 1 | D25: 5 | F25: gl entre | G25: =G22-1 -> 3
A26: 4 | B26: 3 | C26: 5 | D26: 4
A27: 2 | B27: 3 | C27: 2 | D27: 5
A28: 2 | B28: 1 | C28: 5 | D28: 4 | F28: Calculo MC ENTRE (Media Cuadrática Entre)
A29: 2 | B29: 2 | C29: 1 | D29: 3 | F29: Es el promedio de la variación entre grupos
A30: 1 | B30: 3 | C30: 4 | D30: 5
A31: 3 | B31: 1 | C31: 2 | D31: 4
A32: 4 | B32: 1 | C32: 5 | D32: 4
A33: 3 | B33: 3 | C33: 2 | D33: 3
A34: 4 | B34: 5 | C34: 4 | D34: 5 | F34: MC entre | G34: =G17/G25 -> 40.532646
A35: 2 | B35: 5 | C35: 3 | D35: 5
A36: 1 | B36: 1 | C36: 3 | D36: 5
A37: 5 | B37: 3 | C37: 2 | D37: 4 | F37: Calculo SC DENTRO DE GRUPOS (Suma de Cuadrados Dentro)
A38: 2 | B38: 2 | C38: 4 | D38: 4 | F38: Mide la variabilidad interna de cada grupo
A39: 3 | B39: 2 | C39: 1 | D39: 5 | F39: Qué tanto varían los datos dentro del mismo grupo
A40: 3 | B40: 1 | C40: 2 | D40: 4
...

Sheet Comprensión
A1: Grupo Control Pre Test Sin intervención | B1: Grupo Control Post Test Sin intervención | C1: Grupo Experimental Pre Test Sin intervención | D1: Grupo Experimental Post Test Con intervención
A2: 3 | B2: 3 | C2: 5 | D2: 4 | F2: Datos Generales
A3: 3 | B3: 5 | C3: 3 | D3: 5 | F3: Tamano Grupos | G3: =COUNT(A:A) -> 97
A4: 1 | B4: 2 | C4: 4 | D4: 4 | F4: Promedio Grupo A | G4: =AVERAGE(A:A) -> 3.1340206
A5: 3 | B5: 3 | C5: 3 | D5: 5 | F5: Promedio Grupo B | G5: =AVERAGE(B:B) -> 3.0618557
A6: 3 | B6: 3 | C6: 4 | D6: 4 | F6: Promedio Grupo C | G6: =AVERAGE(C:C) -> 3.1237113
A7: 3 | B7: 3 | C7: 2 | D7: 5 | F7: Promedio Grupo D | G7: =AVERAGE(D:D) -> 4.1237113
A8: 3 | B8: 2 | C8: 3 | D8: 3 | F8: Promedio Total total | G8: =AVERAGE(G4:G7) -> 3.3608247
A9: 4 | B9: 1 | C9: 4 | D9: 5
A10: 3 | B10: 3 | C10: 4 | D10: 3
A11: 5 | B11: 3 | C11: 4 | D11: 5 | F11: Calculo Suma de Cuadrados Entre Grupos
A12: 1 | B12: 3 | C12: 3 | D12: 5 | F12: Mide qué tan diferentes son los grupos entre sí
A13: 2 | B13: 2 | C13: 2 | D13: 4 | F13: Compara las medias de cada grupo con la media general
A14: 5 | B14: 2 | C14: 3 | D14: 4
A15: 2 | B15: 5 | C15: 3 | D15: 4
A16: 3 | B16: 4 | C16: 1 | D16: 5
A17: 4 | B17: 3 | C17: 3 | D17: 4 | F17: SC Entre Grupos | G17: =G3*((G4-G8)^2+(G5-G8)^2+(G6-G8)^2+(G7-G8)^2) -> 75.56701
A18: 4 | B18: 3 | C18: 5 | D18: 2
A19: 3 | B19: 5 | C19: 4 | D19: 5
A20: 2 | B20: 4 | C20: 2 | D20: 3 | F20: Calculo gl ENTRE (Grados de libertad entre grupos)
A21: 4 | B21: 3 | C21: 2 | D21: 4 | F21: Cantidad de grupos independientes que puedes comparar
A22: 3 | B22: 1 | C22: 4 | D22: 4 | F22: k (Numero de grupos) | G22: 4
A23: 4 | B23: 2 | C23: 4 | D23: 3
A24: 5 | B24: 5 | C24: 4 | D24: 5
A25: 4 | B25: 3 | C25: 5 | D25: 5 | F25: gl entre | G25: =G22-1 -> 3
A26: 4 | B26: 3 | C26: 3 | D26: 5
A27: 5 | B27: 3 | C27: 5 | D27: 5
A28: 3 | B28: 1 | C28: 2 | D28: 5 | F28: Calculo MC ENTRE (Media Cuadrática Entre)
A29: 3 | B29: 3 | C29: 4 | D29: 3 | F29: Es el promedio de la variación entre grupos
A30: 2 | B30: 2 | C30: 2 | D30: 4
A31: 2 | B31: 2 | C31: 3 | D31: 5
A32: 5 | B32: 5 | C32: 3 | D32: 4
A33: 3 | B33: 4 | C33: 3 | D33: 4
A34: 4 | B34: 4 | C34: 4 | D34: 5 | F34: MC entre | G34: =G17/G25 -> 25.189003
A35: 4 | B35: 5 | C35: 5 | D35: 5
A36: 4 | B36: 3 | C36: 3 | D36: 5
A37: 2 | B37: 5 | C37: 2 | D37: 4 | F37: Calculo SC DENTRO DE GRUPOS (Suma de Cuadrados Dentro)
A38: 3 | B38: 1 | C38: 5 | D38: 5 | F38: Mide la variabilidad interna de cada grupo
A39: 2 | B39: 4 | C39: 5 | D39: 1 | F39: Qué tanto varían los datos dentro del mismo grupo
A40: 3 | B40: 1 | C40: 2 | D40: 5
...

Sheet Habilidades
A1: Grupo Control Pre Test Sin intervención | B1: Grupo Control Post Test Sin intervención | C1: Grupo Experimental Pre Test Sin intervención | D1: Grupo Experimental Post Test Con intervención
A2: 4 | B2: 4 | C2: 3 | D2: 4 | F2: Datos Generales
A3: 4 | B3: 4 | C3: 3 | D3: 3 | F3: Tamano Grupos | G3: =COUNT(A:A) -> 97
A4: 3 | B4: 4 | C4: 5 | D4: 3 | F4: Promedio Grupo A | G4: =AVERAGE(A:A) -> 3.1546392
A5: 3 | B5: 2 | C5: 3 | D5: 5 | F5: Promedio Grupo B | G5: =AVERAGE(B:B) -> 3.0927835
A6: 5 | B6: 1 | C6: 4 | D6: 3 | F6: Promedio Grupo C | G6: =AVERAGE(C:C) -> 2.9587629
A7: 3 | B7: 5 | C7: 2 | D7: 5 | F7: Promedio Grupo D | G7: =AVERAGE(D:D) -> 4.0721649
A8: 4 | B8: 4 | C8: 4 | D8: 3 | F8: Promedio Total total | G8: =AVERAGE(G4:G7) -> 3.3195876
A9: 3 | B9: 2 | C9: 3 | D9: 4
A10: 5 | B10: 1 | C10: 2 | D10: 5
A11: 4 | B11: 4 | C11: 4 | D11: 1 | F11: Calculo Suma de Cuadrados Entre Grupos
A12: 3 | B12: 2 | C12: 2 | D12: 4 | F12: Mide qué tan diferentes son los grupos entre sí
A13: 3 | B13: 3 | C13: 2 | D13: 4 | F13: Compara las medias de cada grupo con la media general
A14: 3 | B14: 5 | C14: 5 | D14: 5
A15: 1 | B15: 2 | C15: 5 | D15: 5
A16: 3 | B16: 3 | C16: 5 | D16: 3
A17: 1 | B17: 4 | C17: 5 | D17: 4 | F17: SC Entre Grupos | G17: =G3*((G4-G8)^2+(G5-G8)^2+(G6-G8)^2+(G7-G8)^2) -> 75.195876
A18: 5 | B18: 4 | C18: 3 | D18: 5
A19: 1 | B19: 3 | C19: 1 | D19: 5
A20: 4 | B20: 3 | C20: 3 | D20: 2 | F20: Calculo gl ENTRE (Grados de libertad entre grupos)
A21: 4 | B21: 3 | C21: 1 | D21: 4 | F21: Cantidad de grupos independientes que puedes comparar
A22: 2 | B22: 2 | C22: 5 | D22: 5 | F22: k (Numero de grupos) | G22: 4
A23: 2 | B23: 5 | C23: 4 | D23: 3
A24: 4 | B24: 3 | C24: 3 | D24: 4
A25: 3 | B25: 3 | C25: 2 | D25: 5 | F25: gl entre | G25: =G22-1 -> 3
A26: 4 | B26: 4 | C26: 1 | D26: 5
A27: 4 | B27: 1 | C27: 3 | D27: 4
A28: 2 | B28: 5 | C28: 3 | D28: 2 | F28: Calculo MC ENTRE (Media Cuadrática Entre)
A29: 2 | B29: 5 | C29: 2 | D29: 4 | F29: Es el promedio de la variación entre grupos
A30: 3 | B30: 1 | C30: 5 | D30: 4
A31: 3 | B31: 2 | C31: 1 | D31: 5
A32: 5 | B32: 3 | C32: 3 | D32: 5
A33: 3 | B33: 3 | C33: 3 | D33: 4
A34: 4 | B34: 2 | C34: 5 | D34: 5 | F34: MC entre | G34: =G17/G25 -> 25.065292
A35: 3 | B35: 4 | C35: 3 | D35: 5
A36: 3 | B36: 4 | C36: 4 | D36: 5
A37: 4 | B37: 4 | C37: 3 | D37: 4 | F37: Calculo SC DENTRO DE GRUPOS (Suma de Cuadrados Dentro)
A38: 2 | B38: 4 | C38: 4 | D38: 4 | F38: Mide la variabilidad interna de cada grupo
A39: 2 | B39: 2 | C39: 2 | D39: 5 | F39: Qué tanto varían los datos dentro del mismo grupo
A40: 5 | B40: 5 | C40: 4 | D40: 5
...

Sheet Resolución-autónoma
A1: Grupo Control Pre Test Sin intervención | B1: Grupo Control Post Test Sin intervención | C1: Grupo Experimental Pre Test Sin intervención | D1: Grupo Experimental Post Test Con intervención
A2: 3 | B2: 3 | C2: 1 | D2: 5 | F2: Datos Generales
A3: 4 | B3: 2 | C3: 1 | D3: 5 | F3: Tamano Grupos | G3: =COUNT(A:A) -> 97
A4: 3 | B4: 5 | C4: 3 | D4: 4 | F4: Promedio Grupo A | G4: =AVERAGE(A:A) -> 2.9793814
A5: 3 | B5: 5 | C5: 3 | D5: 2 | F5: Promedio Grupo B | G5: =AVERAGE(B:B) -> 2.9587629
A6: 3 | B6: 4 | C6: 1 | D6: 3 | F6: Promedio Grupo C | G6: =AVERAGE(C:C) -> 3.0206186
A7: 3 | B7: 2 | C7: 3 | D7: 5 | F7: Promedio Grupo D | G7: =AVERAGE(D:D) -> 4.2371134
A8: 3 | B8: 4 | C8: 4 | D8: 4 | F8: Promedio Total total | G8: =AVERAGE(G4:G7) -> 3.2989691
A9: 3 | B9: 3 | C9: 1 | D9: 5
A10: 4 | B10: 3 | C10: 4 | D10: 4
A11: 3 | B11: 3 | C11: 4 | D11: 5 | F11: Calculo Suma de Cuadrados Entre Grupos
A12: 5 | B12: 5 | C12: 3 | D12: 5 | F12: Mide qué tan diferentes son los grupos entre sí
A13: 3 | B13: 5 | C13: 2 | D13: 5 | F13: Compara las medias de cada grupo con la media general
A14: 1 | B14: 4 | C14: 3 | D14: 1
A15: 2 | B15: 3 | C15: 1 | D15: 4
A16: 2 | B16: 3 | C16: 3 | D16: 4
A17: 3 | B17: 3 | C17: 5 | D17: 4 | F17: SC Entre Grupos | G17: =G3*((G4-G8)^2+(G5-G8)^2+(G6-G8)^2+(G7-G8)^2) -> 114.02062
A18: 2 | B18: 3 | C18: 3 | D18: 4
A19: 3 | B19: 4 | C19: 3 | D19: 5
A20: 4 | B20: 3 | C20: 3 | D20: 5 | F20: Calculo gl ENTRE (Grados de libertad entre grupos)
A21: 5 | B21: 4 | C21: 5 | D21: 3 | F21: Cantidad de grupos independientes que puedes comparar
A22: 2 | B22: 2 | C22: 3 | D22: 4 | F22: k (Numero de grupos) | G22: 4
A23: 3 | B23: 5 | C23: 5 | D23: 5
A24: 3 | B24: 4 | C24: 3 | D24: 5
A25: 4 | B25: 2 | C25: 4 | D25: 5 | F25: gl entre | G25: =G22-1 -> 3
A26: 5 | B26: 4 | C26: 3 | D26: 5
A27: 2 | B27: 3 | C27: 3 | D27: 5
A28: 2 | B28: 3 | C28: 3 | D28: 4 | F28: Calculo MC ENTRE (Media Cuadrática Entre)
A29: 2 | B29: 3 | C29: 4 | D29: 3 | F29: Es el promedio de la variación entre grupos
A30: 2 | B30: 1 | C30: 3 | D30: 5
A31: 4 | B31: 3 | C31: 3 | D31: 5
A32: 3 | B32: 1 | C32: 4 | D32: 5
A33: 4 | B33: 3 | C33: 3 | D33: 5
A34: 3 | B34: 3 | C34: 2 | D34: 4 | F34: MC entre | G34: =G17/G25 -> 38.006873
A35: 3 | B35: 3 | C35: 3 | D35: 5
A36: 2 | B36: 3 | C36: 3 | D36: 5
A37: 1 | B37: 4 | C37: 2 | D37: 3 | F37: Calculo SC DENTRO DE GRUPOS (Suma de Cuadrados Dentro)
A38: 3 | B38: 3 | C38: 5 | D38: 3 | F38: Mide la variabilidad interna de cada grupo
A39: 3 | B39: 2 | C39: 3 | D39: 3 | F39: Qué tanto varían los datos dentro del mismo grupo
A40: 2 | B40: 2 | C40: 2 | D40: 3
...

Sheet Motivación
A1: Grupo Control Pre Test Sin intervención | B1: Grupo Control Post Test Sin intervención | C1: Grupo Experimental Pre Test Sin intervención | D1: Grupo Experimental Post Test Con intervención
A2: 4 | B2: 3 | C2: 3 | D2: 5 | F2: Datos Generales
A3: 4 | B3: 3 | C3: 4 | D3: 4 | F3: Tamano Grupos | G3: =COUNT(A:A) -> 97
A4: 2 | B4: 5 | C4: 2 | D4: 4 | F4: Promedio Grupo A | G4: =AVERAGE(A:A) -> 3.0309278
A5: 3 | B5: 5 | C5: 1 | D5: 1 | F5: Promedio Grupo B | G5: =AVERAGE(B:B) -> 2.9278351
A6: 3 | B6: 2 | C6: 3 | D6: 5 | F6: Promedio Grupo C | G6: =AVERAGE(C:C) -> 2.9484536
A7: 2 | B7: 3 | C7: 3 | D7: 4 | F7: Promedio Grupo D | G7: =AVERAGE(D:D) -> 3.9484536
A8: 4 | B8: 3 | C8: 3 | D8: 3 | F8: Promedio Total total | G8: =AVERAGE(G4:G7) -> 3.2139175
A9: 3 | B9: 1 | C9: 2 | D9: 2
A10: 3 | B10: 2 | C10: 3 | D10: 5
A11: 1 | B11: 3 | C11: 3 | D11: 5 | F11: Calculo Suma de Cuadrados Entre Grupos
A12: 1 | B12: 3 | C12: 2 | D12: 3 | F12: Mide qué tan diferentes son los grupos entre sí
A13: 4 | B13: 5 | C13: 4 | D13: 4 | F13: Compara las medias de cada grupo con la media general
A14: 4 | B14: 4 | C14: 3 | D14: 5
A15: 5 | B15: 3 | C15: 5 | D15: 2
A16: 5 | B16: 4 | C16: 3 | D16: 5
A17: 2 | B17: 4 | C17: 3 | D17: 4 | F17: SC Entre Grupos | G17: =G3*((G4-G8)^2+(G5-G8)^2+(G6-G8)^2+(G7-G8)^2) -> 70.358247
A18: 3 | B18: 2 | C18: 3 | D18: 5
A19: 3 | B19: 2 | C19: 3 | D19: 5
A20: 4 | B20: 3 | C20: 4 | D20: 4 | F20: Calculo gl ENTRE (Grados de libertad entre grupos)
A21: 3 | B21: 5 | C21: 2 | D21: 1 | F21: Cantidad de grupos independientes que puedes comparar
A22: 2 | B22: 1 | C22: 2 | D22: 4 | F22: k (Numero de grupos) | G22: 4
A23: 3 | B23: 2 | C23: 3 | D23: 3
A24: 1 | B24: 3 | C24: 4 | D24: 5
A25: 3 | B25: 3 | C25: 2 | D25: 4 | F25: gl entre | G25: =G22-1 -> 3
A26: 3 | B26: 4 | C26: 4 | D26: 3
A27: 4 | B27: 1 | C27: 4 | D27: 4
A28: 3 | B28: 1 | C28: 1 | D28: 5 | F28: Calculo MC ENTRE (Media Cuadrática Entre)
A29: 3 | B29: 4 | C29: 3 | D29: 2 | F29: Es el promedio de la variación entre grupos
A30: 3 | B30: 1 | C30: 1 | D30: 3
A31: 3 | B31: 1 | C31: 3 | D31: 4
A32: 5 | B32: 4 | C32: 3 | D32: 5
A33: 3 | B33: 2 | C33: 5 | D33: 3
A34: 1 | B34: 3 | C34: 3 | D34: 5 | F34: MC entre | G34: =G17/G25 -> 23.452749
A35: 5 | B35: 3 | C35: 1 | D35: 4
A36: 1 | B36: 5 | C36: 5 | D36: 5
A37: 3 | B37: 2 | C37: 3 | D37: 5 | F37: Calculo SC DENTRO DE GRUPOS (Suma de Cuadrados Dentro)
A38: 2 | B38: 5 | C38: 3 | D38: 5 | F38: Mide la variabilidad interna de cada grupo
A39: 2 | B39: 2 | C39: 4 | D39: 4 | F39: Qué tanto varían los datos dentro del mismo grupo
A40: 3 | B40: 5 | C40: 4 | D40: 4
...
