Workbook

Sheet Resumen
A1: Indicador | B1: F Calculado | C1: F Critico Critico | D1: P Valor
A2: Participación activa | B2: =ROUND('Participación-activa'!F73, 4) -> 0.6167 | C2: =ROUND('Participación-activa'!F81, 4) -> 3.0271 | D2: =ROUND('Participación-activa'!F82, 4) -> 0.5405
A3: Comunicación equipo | B3: =ROUND('Comunicación-equipo'!F73, 4) -> 0.6674 | C3: =ROUND('Comunicación-equipo'!F81, 4) -> 3.0271 | D3: =ROUND('Comunicación-equipo'!F82, 4) -> 0.5138
A4: Cumplimiento tareas | B4: =ROUND('Cumplimiento-tareas'!F73, 4) -> 0.5201 | C4: =ROUND('Cumplimiento-tareas'!F81, 4) -> 3.0271 | D4: =ROUND('Cumplimiento-tareas'!F82, 4) -> 0.595
A5: Contribución grupo | B5: =ROUND('Contribución-grupo'!F73, 4) -> 0.7174 | C5: =ROUND('Contribución-grupo'!F81, 4) -> 3.0271 | D5: =ROUND('Contribución-grupo'!F82, 4) -> 0.4889
A6: Resolución problemas | B6: =ROUND('Resolución-problemas'!F73, 4) -> 1.7529 | C6: =ROUND('Resolución-problemas'!F81, 4) -> 3.0271 | D6: =ROUND('Resolución-problemas'!F82, 4) -> 0.1751
A7: Conocimientos adquiridos | B7: =ROUND('Conocimientos-adquiridos'!F73, 4) -> 0.5922 | C7: =ROUND('Conocimientos-adquiridos'!F81, 4) -> 3.0271 | D7: =ROUND('Conocimientos-adquiridos'!F82, 4) -> 0.5538
A8: Nota final | B8: =ROUND('Nota-final'!F73, 4) -> 0.5888 | C8: =ROUND('Nota-final'!F81, 4) -> 3.0271 | D8: =ROUND('Nota-final'!F82, 4) -> 0.5556
A9: Comprensión | B9: =ROUND(Comprensión!F73, 4) -> 0.105 | C9: =ROUND(Comprensión!F81, 4) -> 3.0271 | D9: =ROUND(Comprensión!F82, 4) -> 0.9004
A10: Habilidades | B10: =ROUND(Habilidades!F73, 4) -> 0.7515 | C10: =ROUND(Habilidades!F81, 4) -> 3.0271 | D10: =ROUND(Habilidades!F82, 4) -> 0.4726
A11: Resolución autónoma | B11: =ROUND('Resolución-autónoma'!F73, 4) -> 0.0835 | C11: =ROUND('Resolución-autónoma'!F81, 4) -> 3.0271 | D11: =ROUND('Resolución-autónoma'!F82, 4) -> 0.9199
A12: Motivación | B12: =ROUND(Motivación!F73, 4) -> 0.2416 | C12: =ROUND(Motivación!F81, 4) -> 3.0271 | D12: =ROUND(Motivación!F82, 4) -> 0.7856

Sheet Participación-activa
A1: Grupo Control Pre Test Sin intervención | B1: Grupo Control Post Test Sin intervención | C1: Grupo Experimental Pre Test Sin intervención
A2: 2 | B2: 2 | C2: 4 | E2: Datos Generales
A3: 4 | B3: 2 | C3: 1 | E3: Tamano Grupos | F3: =COUNT(A:A) -> 97
A4: 2 | B4: 2 | C4: 3 | E4: Promedio Grupo A | F4: =AVERAGE(A:A) -> 3.185567
A5: 3 | B5: 3 | C5: 2 | E5: Promedio Grupo B | F5: =AVERAGE(B:B) -> 3
A6: 2 | B6: 4 | C6: 3 | E6: Promedio Grupo C | F6: =AVERAGE(C:C) -> 3.1134021
A7: 1 | B7: 5 | C7: 5 | E7: Promedio Total total | F7: =AVERAGE(F4:F6) -> 3.0996564
A8: 5 | B8: 1 | C8: 3
A9: 3 | B9: 2 | C9: 5
A10: 3 | B10: 3 | C10: 3 | E10: Calculo Suma de Cuadrados Entre Grupos
A11: 5 | B11: 3 | C11: 2 | E11: Mide qué tan diferentes son los grupos entre sí
A12: 2 | B12: 3 | C12: 4 | E12: Compara las medias de cada grupo con la media general
A13: 4 | B13: 5 | C13: 2
A14: 5 | B14: 4 | C14: 3
A15: 5 | B15: 5 | C15: 3
A16: 1 | B16: 2 | C16: 4 | E16: SC Entre Grupos | F16: =F3*((F4-F7)^2+(F5-F7)^2+(F6-F7)^2) -> 1.6975945
A17: 3 | B17: 4 | C17: 2
A18: 5 | B18: 3 | C18: 2
A19: 4 | B19: 5 | C19: 1 | E19: Calculo gl ENTRE (Grados de libertad entre grupos)
A20: 2 | B20: 4 | C20: 5 | E20: Cantidad de grupos independientes que puedes comparar
A21: 4 | B21: 3 | C21: 4 | E21: k (Numero de grupos) | F21: 3
A22: 2 | B22: 2 | C22: 3
A23: 3 | B23: 2 | C23: 2
A24: 2 | B24: 1 | C24: 1 | E24: gl entre | F24: =F21-1 -> 2
A25: 1 | B25: 2 | C25: 4
A26: 5 | B26: 2 | C26: 3
A27: 5 | B27: 2 | C27: 4 | E27: Calculo MC ENTRE (Media Cuadrática Entre)
A28: 3 | B28: 5 | C28: 5 | E28: Es el promedio de la variación entre grupos
A29: 3 | B29: 4 | C29: 2
A30: 4 | B30: 4 | C30: 5
A31: 5 | B31: 3 | C31: 3
A32: 4 | B32: 3 | C32: 5
A33: 5 | B33: 4 | C33: 3 | E33: MC entre | F33: =F16/F24 -> 0.84879725
A34: 2 | B34: 4 | C34: 4
A35: 3 | B35: 5 | C35: 2
A36: 3 | B36: 2 | C36: 2 | E36: Calculo SC DENTRO DE GRUPOS (Suma de Cuadrados Dentro)
A37: 3 | B37: 4 | C37: 2 | E37: Mide la variabilidad interna de cada grupo
A38: 3 | B38: 2 | C38: 3 | E38: Qué tanto varían los datos dentro del mismo grupo
A39: 5 | B39: 1 | C39: 3
A40: 5 | B40: 3 | C40: 1
...

Sheet Comunicación-equipo
A1: Grupo Control Pre Test Sin intervención | B1: Grupo Control Post Test Sin intervención | C1: Grupo Experimental Pre Test Sin intervención
A2: 3 | B2: 3 | C2: 2 | E2: Datos Generales
A3: 4 | B3: 3 | C3: 5 | E3: Tamano Grupos | F3: =COUNT(A:A) -> 97
A4: 2 | B4: 3 | C4: 1 | E4: Promedio Grupo A | F4: =AVERAGE(A:A) -> 2.9278351
A5: 5 | B5: 2 | C5: 4 | E5: Promedio Grupo B | F5: =AVERAGE(B:B) -> 3.1237113
A6: 3 | B6: 1 | C6: 2 | E6: Promedio Grupo C | F6: =AVERAGE(C:C) -> 3.0412371
A7: 2 | B7: 3 | C7: 2 | E7: Promedio Total total | F7: =AVERAGE(F4:F6) -> 3.0309278
A8: 3 | B8: 3 | C8: 3
A9: 3 | B9: 4 | C9: 3
A10: 5 | B10: 1 | C10: 4 | E10: Calculo Suma de Cuadrados Entre Grupos
A11: 1 | B11: 4 | C11: 4 | E11: Mide qué tan diferentes son los grupos entre sí
A12: 3 | B12: 2 | C12: 3 | E12: Compara las medias de cada grupo con la media general
A13: 2 | B13: 3 | C13: 2
A14: 3 | B14: 2 | C14: 3
A15: 4 | B15: 2 | C15: 3
A16: 3 | B16: 5 | C16: 3 | E16: SC Entre Grupos | F16: =F3*((F4-F7)^2+(F5-F7)^2+(F6-F7)^2) -> 1.8762887
A17: 4 | B17: 1 | C17: 1
A18: 1 | B18: 5 | C18: 3
A19: 3 | B19: 4 | C19: 5 | E19: Calculo gl ENTRE (Grados de libertad entre grupos)
A20: 3 | B20: 3 | C20: 3 | E20: Cantidad de grupos independientes que puedes comparar
A21: 2 | B21: 3 | C21: 3 | E21: k (Numero de grupos) | F21: 3
A22: 3 | B22: 3 | C22: 4
A23: 2 | B23: 4 | C23: 2
A24: 4 | B24: 1 | C24: 2 | E24: gl entre | F24: =F21-1 -> 2
A25: 1 | B25: 4 | C25: 3
A26: 3 | B26: 4 | C26: 2
A27: 3 | B27: 4 | C27: 1 | E27: Calculo MC ENTRE (Media Cuadrática Entre)
A28: 5 | B28: 5 | C28: 3 | E28: Es el promedio de la variación entre grupos
A29: 4 | B29: 3 | C29: 2
A30: 5 | B30: 1 | C30: 5
A31: 3 | B31: 5 | C31: 3
A32: 1 | B32: 1 | C32: 5
A33: 2 | B33: 4 | C33: 5 | E33: MC entre | F33: =F16/F24 -> 0.93814433
A34: 3 | B34: 1 | C34: 2
A35: 4 | B35: 2 | C35: 5
A36: 5 | B36: 5 | C36: 2 | E36: Calculo SC DENTRO DE GRUPOS (Suma de Cuadrados Dentro)
A37: 4 | B37: 3 | C37: 4 | E37: Mide la variabilidad interna de cada grupo
A38: 3 | B38: 4 | C38: 2 | E38: Qué tanto varían los datos dentro del mismo grupo
A39: 3 | B39: 4 | C39: 3
A40: 3 | B40: 5 | C40: 3
...

Sheet Cumplimiento-tareas
A1: Grupo Control Pre Test Sin intervención | B1: Grupo Control Post Test Sin intervención | C1: Grupo Experimental Pre Test Sin intervención
A2: 3 | B2: 4 | C2: 5 | E2: Datos Generales
A3: 3 | B3: 3 | C3: 3 | E3: Tamano Grupos | F3: =COUNT(A:A) -> 97
A4: 5 | B4: 4 | C4: 5 | E4: Promedio Grupo A | F4: =AVERAGE(A:A) -> 3.2886598
A5: 4 | B5: 3 | C5: 3 | E5: Promedio Grupo B | F5: =AVERAGE(B:B) -> 3.1237113
A6: 4 | B6: 3 | C6: 2 | E6: Promedio Grupo C | F6: =AVERAGE(C:C) -> 3.1752577
A7: 2 | B7: 4 | C7: 4 | E7: Promedio Total total | F7: =AVERAGE(F4:F6) -> 3.1958763
A8: 3 | B8: 3 | C8: 5
A9: 5 | B9: 3 | C9: 3
A10: 2 | B10: 5 | C10: 3 | E10: Calculo Suma de Cuadrados Entre Grupos
A11: 4 | B11: 3 | C11: 4 | E11: Mide qué tan diferentes son los grupos entre sí
A12: 1 | B12: 4 | C12: 4 | E12: Compara las medias de cada grupo con la media general
A13: 3 | B13: 5 | C13: 2
A14: 4 | B14: 2 | C14: 2
A15: 5 | B15: 3 | C15: 4
A16: 3 | B16: 4 | C16: 3 | E16: SC Entre Grupos | F16: =F3*((F4-F7)^2+(F5-F7)^2+(F6-F7)^2) -> 1.3814433
A17: 2 | B17: 4 | C17: 3
A18: 3 | B18: 4 | C18: 3
A19: 5 | B19: 5 | C19: 5 | E19: Calculo gl ENTRE (Grados de libertad entre grupos)
A20: 4 | B20: 3 | C20: 4 | E20: Cantidad de grupos independientes que puedes comparar
A21: 5 | B21: 3 | C21: 4 | E21: k (Numero de grupos) | F21: 3
A22: 3 | B22: 4 | C22: 2
A23: 2 | B23: 2 | C23: 4
A24: 2 | B24: 4 | C24: 4 | E24: gl entre | F24: =F21-1 -> 2
A25: 2 | B25: 2 | C25: 3
A26: 2 | B26: 5 | C26: 3
A27: 4 | B27: 3 | C27: 2 | E27: Calculo MC ENTRE (Media Cuadrática Entre)
A28: 3 | B28: 1 | C28: 4 | E28: Es el promedio de la variación entre grupos
A29: 1 | B29: 3 | C29: 4
A30: 4 | B30: 3 | C30: 3
A31: 4 | B31: 1 | C31: 5
A32: 5 | B32: 5 | C32: 4
A33: 4 | B33: 4 | C33: 2 | E33: MC entre | F33: =F16/F24 -> 0.69072165
A34: 2 | B34: 5 | C34: 4
A35: 2 | B35: 3 | C35: 3
A36: 3 | B36: 1 | C36: 1 | E36: Calculo SC DENTRO DE GRUPOS (Suma de Cuadrados Dentro)
A37: 2 | B37: 2 | C37: 3 | E37: Mide la variabilidad interna de cada grupo
A38: 4 | B38: 4 | C38: 1 | E38: Qué tanto varían los datos dentro del mismo grupo
A39: 5 | B39: 4 | C39: 3
A40: 5 | B40: 4 | C40: 2
...

Sheet Contribución-grupo
A1: Grupo Control Pre Test Sin intervención | B1: Grupo Control Post Test Sin intervención | C1: Grupo Experimental Pre Test Sin intervención
A2: 4 | B2: 3 | C2: 3 | E2: Datos Generales
A3: 2 | B3: 3 | C3: 3 | E3: Tamano Grupos | F3: =COUNT(A:A) -> 97
A4: 5 | B4: 4 | C4: 3 | E4: Promedio Grupo A | F4: =AVERAGE(A:A) -> 3.1030928
A5: 3 | B5: 3 | C5: 3 | E5: Promedio Grupo B | F5: =AVERAGE(B:B) -> 3.1958763
A6: 3 | B6: 4 | C6: 4 | E6: Promedio Grupo C | F6: =AVERAGE(C:C) -> 3.0103093
A7: 1 | B7: 3 | C7: 3 | E7: Promedio Total total | F7: =AVERAGE(F4:F6) -> 3.1030928
A8: 3 | B8: 4 | C8: 3
A9: 3 | B9: 2 | C9: 4
A10: 3 | B10: 3 | C10: 1 | E10: Calculo Suma de Cuadrados Entre Grupos
A11: 4 | B11: 3 | C11: 3 | E11: Mide qué tan diferentes son los grupos entre sí
A12: 4 | B12: 5 | C12: 3 | E12: Compara las medias de cada grupo con la media general
A13: 4 | B13: 4 | C13: 2
A14: 2 | B14: 5 | C14: 4
A15: 3 | B15: 5 | C15: 4
A16: 4 | B16: 4 | C16: 2 | E16: SC Entre Grupos | F16: =F3*((F4-F7)^2+(F5-F7)^2+(F6-F7)^2) -> 1.6701031
A17: 3 | B17: 5 | C17: 1
A18: 4 | B18: 3 | C18: 3
A19: 2 | B19: 2 | C19: 2 | E19: Calculo gl ENTRE (Grados de libertad entre grupos)
A20: 3 | B20: 3 | C20: 2 | E20: Cantidad de grupos independientes que puedes comparar
A21: 5 | B21: 1 | C21: 4 | E21: k (Numero de grupos) | F21: 3
A22: 3 | B22: 4 | C22: 3
A23: 5 | B23: 3 | C23: 3
A24: 3 | B24: 4 | C24: 3 | E24: gl entre | F24: =F21-1 -> 2
A25: 4 | B25: 1 | C25: 4
A26: 3 | B26: 3 | C26: 2
A27: 3 | B27: 2 | C27: 3 | E27: Calculo MC ENTRE (Media Cuadrática Entre)
A28: 3 | B28: 3 | C28: 5 | E28: Es el promedio de la variación entre grupos
A29: 3 | B29: 5 | C29: 3
A30: 3 | B30: 4 | C30: 3
A31: 3 | B31: 3 | C31: 3
A32: 3 | B32: 2 | C32: 4
A33: 3 | B33: 3 | C33: 3 | E33: MC entre | F33: =F16/F24 -> 0.83505155
A34: 5 | B34: 2 | C34: 3
A35: 4 | B35: 5 | C35: 1
A36: 3 | B36: 3 | C36: 3 | E36: Calculo SC DENTRO DE GRUPOS (Suma de Cuadrados Dentro)
A37: 2 | B37: 3 | C37: 2 | E37: Mide la variabilidad interna de cada grupo
A38: 5 | B38: 3 | C38: 1 | E38: Qué tanto varían los datos dentro del mismo grupo
A39: 3 | B39: 2 | C39: 1
A40: 4 | B40: 4 | C40: 5
...

Sheet Resolución-problemas
A1: Grupo Control Pre Test Sin intervención | B1: Grupo Control Post Test Sin intervención | C1: Grupo Experimental Pre Test Sin intervención
A2: 2 | B2: 4 | C2: 5 | E2: Datos Generales
A3: 3 | B3: 3 | C3: 4 | E3: Tamano Grupos | F3: =COUNT(A:A) -> 97
A4: 4 | B4: 1 | C4: 3 | E4: Promedio Grupo A | F4: =AVERAGE(A:A) -> 2.9793814
A5: 1 | B5: 3 | C5: 2 | E5: Promedio Grupo B | F5: =AVERAGE(B:B) -> 3.2886598
A6: 3 | B6: 3 | C6: 2 | E6: Promedio Grupo C | F6: =AVERAGE(C:C) -> 3.0824742
A7: 4 | B7: 5 | C7: 2 | E7: Promedio Total total | F7: =AVERAGE(F4:F6) -> 3.1168385
A8: 5 | B8: 3 | C8: 5
A9: 2 | B9: 3 | C9: 2
A10: 3 | B10: 4 | C10: 3 | E10: Calculo Suma de Cuadrados Entre Grupos
A11: 3 | B11: 4 | C11: 2 | E11: Mide qué tan diferentes son los grupos entre sí
A12: 3 | B12: 3 | C12: 1 | E12: Compara las medias de cada grupo con la media general
A13: 5 | B13: 3 | C13: 2
A14: 2 | B14: 4 | C14: 2
A15: 3 | B15: 4 | C15: 4
A16: 1 | B16: 3 | C16: 2 | E16: SC Entre Grupos | F16: =F3*((F4-F7)^2+(F5-F7)^2+(F6-F7)^2) -> 4.8109966
A17: 3 | B17: 2 | C17: 5
A18: 3 | B18: 5 | C18: 3
A19: 4 | B19: 2 | C19: 3 | E19: Calculo gl ENTRE (Grados de libertad entre grupos)
A20: 3 | B20: 4 | C20: 3 | E20: Cantidad de grupos independientes que puedes comparar
A21: 3 | B21: 3 | C21: 2 | E21: k (Numero de grupos) | F21: 3
A22: 2 | B22: 4 | C22: 2
A23: 2 | B23: 3 | C23: 3
A24: 2 | B24: 3 | C24: 4 | E24: gl entre | F24: =F21-1 -> 2
A25: 3 | B25: 4 | C25: 2
A26: 5 | B26: 2 | C26: 3
A27: 1 | B27: 5 | C27: 1 | E27: Calculo MC ENTRE (Media Cuadrática Entre)
A28: 3 | B28: 2 | C28: 3 | E28: Es el promedio de la variación entre grupos
A29: 3 | B29: 1 | C29: 4
A30: 2 | B30: 4 | C30: 5
A31: 4 | B31: 3 | C31: 3
A32: 5 | B32: 3 | C32: 3
A33: 2 | B33: 1 | C33: 2 | E33: MC entre | F33: =F16/F24 -> 2.4054983
A34: 5 | B34: 3 | C34: 4
A35: 5 | B35: 3 | C35: 2
A36: 2 | B36: 5 | C36: 4 | E36: Calculo SC DENTRO DE GRUPOS (Suma de Cuadrados Dentro)
A37: 3 | B37: 1 | C37: 5 | E37: Mide la variabilidad interna de cada grupo
A38: 5 | B38: 4 | C38: 4 | E38: Qué tanto varían los datos dentro del mismo grupo
A39: 1 | B39: 4 | C39: 1
A40: 3 | B40: 3 | C40: 5
...

Sheet Conocimientos-adquiridos
A1: Grupo Control Pre Test Sin intervención | B1: Grupo Control Post Test Sin intervención | C1: Grupo Experimental Pre Test Sin intervención
A2: 2 | B2: 3 | C2: 3 | E2: Datos Generales
A3: 2 | B3: 4 | C3: 3 | E3: Tamano Grupos | F3: =COUNT(A:A) -> 97
A4: 5 | B4: 2 | C4: 3 | E4: Promedio Grupo A | F4: =AVERAGE(A:A) -> 3.2268041
A5: 4 | B5: 2 | C5: 5 | E5: Promedio Grupo B | F5: =AVERAGE(B:B) -> 3.1340206
A6: 5 | B6: 2 | C6: 4 | E6: Promedio Grupo C | F6: =AVERAGE(C:C) -> 3.0412371
A7: 5 | B7: 3 | C7: 3 | E7: Promedio Total total | F7: =AVERAGE(F4:F6) -> 3.1340206
A8: 5 | B8: 3 | C8: 4
A9: 2 | B9: 4 | C9: 3
A10: 4 | B10: 2 | C10: 4 | E10: Calculo Suma de Cuadrados Entre Grupos
A11: 3 | B11: 2 | C11: 2 | E11: Mide qué tan diferentes son los grupos entre sí
A12: 3 | B12: 5 | C12: 1 | E12: Compara las medias de cada grupo con la media general
A13: 4 | B13: 5 | C13: 3
A14: 3 | B14: 1 | C14: 5
A15: 4 | B15: 5 | C15: 5
A16: 3 | B16: 3 | C16: 2 | E16: SC Entre Grupos | F16: =F3*((F4-F7)^2+(F5-F7)^2+(F6-F7)^2) -> 1.6701031
A17: 3 | B17: 5 | C17: 3
A18: 4 | B18: 1 | C18: 3
A19: 3 | B19: 2 | C19: 4 | E19: Calculo gl ENTRE (Grados de libertad entre grupos)
A20: 3 | B20: 3 | C20: 2 | E20: Cantidad de grupos independientes que puedes comparar
A21: 3 | B21: 3 | C21: 5 | E21: k (Numero de grupos) | F21: 3
A22: 4 | B22: 4 | C22: 1
A23: 4 | B23: 4 | C23: 4
A24: 1 | B24: 4 | C24: 5 | E24: gl entre | F24: =F21-1 -> 2
A25: 5 | B25: 2 | C25: 3
A26: 5 | B26: 3 | C26: 3
A27: 4 | B27: 3 | C27: 3 | E27: Calculo MC ENTRE (Media Cuadrática Entre)
A28: 4 | B28: 1 | C28: 3 | E28: Es el promedio de la variación entre grupos
A29: 3 | B29: 3 | C29: 5
A30: 2 | B30: 5 | C30: 5
A31: 5 | B31: 1 | C31: 2
A32: 4 | B32: 5 | C32: 1
A33: 3 | B33: 3 | C33: 3 | E33: MC entre | F33: =F16/F24 -> 0.83505155
A34: 4 | B34: 4 | C34: 3
A35: 1 | B35: 5 | C35: 2
A36: 3 | B36: 4 | C36: 3 | E36: Calculo SC DENTRO DE GRUPOS (Suma de Cuadrados Dentro)
A37: 3 | B37: 2 | C37: 2 | E37: Mide la variabilidad interna de cada grupo
A38: 5 | B38: 3 | C38: 3 | E38: Qué tanto varían los datos dentro del mismo grupo
A39: 3 | B39: 2 | C39: 3
A40: 3 | B40: 4 | C40: 3
...

Sheet Nota-final
A1: Grupo Control Pre Test Sin intervención | B1: Grupo Control Post Test Sin intervención | C1: Grupo Experimental Pre Test Sin intervención
A2: 3 | B2: 3 | C2: 3 | E2: Datos Generales
A3: 4 | B3: 2 | C3: 3 | E3: Tamano Grupos | F3: =COUNT(A:A) -> 97
A4: 3 | B4: 1 | C4: 3 | E4: Promedio Grupo A | F4: =AVERAGE(A:A) -> 2.9381443
A5: 3 | B5: 2 | C5: 2 | E5: Promedio Grupo B | F5: =AVERAGE(B:B) -> 2.7731959
A6: 2 | B6: 5 | C6: 3 | E6: Promedio Grupo C | F6: =AVERAGE(C:C) -> 2.8969072
A7: 2 | B7: 2 | C7: 3 | E7: Promedio Total total | F7: =AVERAGE(F4:F6) -> 2.8694158
A8: 3 | B8: 4 | C8: 3
A9: 1 | B9: 4 | C9: 3
A10: 4 | B10: 2 | C10: 1 | E10: Calculo Suma de Cuadrados Entre Grupos
A11: 5 | B11: 2 | C11: 4 | E11: Mide qué tan diferentes son los grupos entre sí
A12: 1 | B12: 3 | C12: 1 | E12: Compara las medias de cada grupo con la media general
A13: 3 | B13: 5 | C13: 4
A14: 5 | B14: 3 | C14: 2
A15: 3 | B15: 1 | C15: 1
A16: 3 | B16: 1 | C16: 3 | E16: SC Entre Grupos | F16: =F3*((F4-F7)^2+(F5-F7)^2+(F6-F7)^2) -> 1.4295533
A17: 3 | B17: 3 | C17: 2
A18: 2 | B18: 3 | C18: 4
A19: 3 | B19: 2 | C19: 3 | E19: Calculo gl ENTRE (Grados de libertad entre grupos)
A20: 3 | B20: 4 | C20: 3 | E20: Cantidad de grupos independientes que puedes comparar
A21: 4 | B21: 2 | C21: 4 | E21: k (Numero de grupos) | F21: 3
A22: 3 | B22: 3 | C22: 3
A23: 4 | B23: 1 | C23: 2
A24: 3 | B24: 4 | C24: 5 | E24: gl entre | F24: =F21-1 -> 2
A25: 3 | B25: 3 | C25: 1
A26: 4 | B26: 3 | C26: 5
A27: 2 | B27: 3 | C27: 2 | E27: Calculo MC ENTRE (Media Cuadrática Entre)
A28: 2 | B28: 1 | C28: 5 | E28: Es el promedio de la variación entre grupos
A29: 2 | B29: 2 | C29: 1
A30: 1 | B30: 3 | C30: 4
A31: 3 | B31: 1 | C31: 2
A32: 4 | B32: 1 | C32: 5
A33: 3 | B33: 3 | C33: 2 | E33: MC entre | F33: =F16/F24 -> 0.71477663
A34: 4 | B34: 5 | C34: 4
A35: 2 | B35: 5 | C35: 3
A36: 1 | B36: 1 | C36: 3 | E36: Calculo SC DENTRO DE GRUPOS (Suma de Cuadrados Dentro)
A37: 5 | B37: 3 | C37: 2 | E37: Mide la variabilidad interna de cada grupo
A38: 2 | B38: 2 | C38: 4 | E38: Qué tanto varían los datos dentro del mismo grupo
A39: 3 | B39: 2 | C39: 1
A40: 3 | B40: 1 | C40: 2
...

Sheet Comprensión
A1: Grupo Control Pre Test Sin intervención | B1: Grupo Control Post Test Sin intervención | C1: Grupo Experimental Pre Test Sin intervención
A2: 3 | B2: 3 | C2: 5 | E2: Datos Generales
A3: 3 | B3: 5 | C3: 3 | E3: Tamano Grupos | F3: =COUNT(A:A) -> 97
A4: 1 | B4: 2 | C4: 4 | E4: Promedio Grupo A | F4: =AVERAGE(A:A) -> 3.1340206
A5: 3 | B5: 3 | C5: 3 | E5: Promedio Grupo B | F5: =AVERAGE(B:B) -> 3.0618557
A6: 3 | B6: 3 | C6: 4 | E6: Promedio Grupo C | F6: =AVERAGE(C:C) -> 3.1237113
A7: 3 | B7: 3 | C7: 2 | E7: Promedio Total total | F7: =AVERAGE(F4:F6) -> 3.1065292
A8: 3 | B8: 2 | C8: 3
A9: 4 | B9: 1 | C9: 4
A10: 3 | B10: 3 | C10: 4 | E10: Calculo Suma de Cuadrados Entre Grupos
A11: 5 | B11: 3 | C11: 4 | E11: Mide qué tan diferentes son los grupos entre sí
A12: 1 | B12: 3 | C12: 3 | E12: Compara las medias de cada grupo con la media general
A13: 2 | B13: 2 | C13: 2
A14: 5 | B14: 2 | C14: 3
A15: 2 | B15: 5 | C15: 3
A16: 3 | B16: 4 | C16: 1 | E16: SC Entre Grupos | F16: =F3*((F4-F7)^2+(F5-F7)^2+(F6-F7)^2) -> 0.29553265
A17: 4 | B17: 3 | C17: 3
A18: 4 | B18: 3 | C18: 5
A19: 3 | B19: 5 | C19: 4 | E19: Calculo gl ENTRE (Grados de libertad entre grupos)
A20: 2 | B20: 4 | C20: 2 | E20: Cantidad de grupos independientes que puedes comparar
A21: 4 | B21: 3 | C21: 2 | E21: k (Numero de grupos) | F21: 3
A22: 3 | B22: 1 | C22: 4
A23: 4 | B23: 2 | C23: 4
A24: 5 | B24: 5 | C24: 4 | E24: gl entre | F24: =F21-1 -> 2
A25: 4 | B25: 3 | C25: 5
A26: 4 | B26: 3 | C26: 3
A27: 5 | B27: 3 | C27: 5 | E27: Calculo MC ENTRE (Media Cuadrática Entre)
A28: 3 | B28: 1 | C28: 2 | E28: Es el promedio de la variación entre grupos
A29: 3 | B29: 3 | C29: 4
A30: 2 | B30: 2 | C30: 2
A31: 2 | B31: 2 | C31: 3
A32: 5 | B32: 5 | C32: 3
A33: 3 | B33: 4 | C33: 3 | E33: MC entre | F33: =F16/F24 -> 0.14776632
A34: 4 | B34: 4 | C34: 4
A35: 4 | B35: 5 | C35: 5
A36: 4 | B36: 3 | C36: 3 | E36: Calculo SC DENTRO DE GRUPOS (Suma de Cuadrados Dentro)
A37: 2 | B37: 5 | C37: 2 | E37: Mide la variabilidad interna de cada grupo
A38: 3 | B38: 1 | C38: 5 | E38: Qué tanto varían los datos dentro del mismo grupo
A39: 2 | B39: 4 | C39: 5
A40: 3 | B40: 1 | C40: 2
...

Sheet Habilidades
A1: Grupo Control Pre Test Sin intervención | B1: Grupo Control Post Test Sin intervención | C1: Grupo Experimental Pre Test Sin intervención
A2: 4 | B2: 4 | C2: 3 | E2: Datos Generales
A3: 4 | B3: 4 | C3: 3 | E3: Tamano Grupos | F3: =COUNT(A:A) -> 97
A4: 3 | B4: 4 | C4: 5 | E4: Promedio Grupo A | F4: =AVERAGE(A:A) -> 3.1546392
A5: 3 | B5: 2 | C5: 3 | E5: Promedio Grupo B | F5: =AVERAGE(B:B) -> 3.0927835
A6: 5 | B6: 1 | C6: 4 | E6: Promedio Grupo C | F6: =AVERAGE(C:C) -> 2.9587629
A7: 3 | B7: 5 | C7: 2 | E7: Promedio Total total | F7: =AVERAGE(F4:F6) -> 3.0687285
A8: 4 | B8: 4 | C8: 4
A9: 3 | B9: 2 | C9: 3
A10: 5 | B10: 1 | C10: 2 | E10: Calculo Suma de Cuadrados Entre Grupos
A11: 4 | B11: 4 | C11: 4 | E11: Mide qué tan diferentes son los grupos entre sí
A12: 3 | B12: 2 | C12: 2 | E12: Compara las medias de cada grupo con la media general
A13: 3 | B13: 3 | C13: 2
A14: 3 | B14: 5 | C14: 5
A15: 1 | B15: 2 | C15: 5
A16: 3 | B16: 3 | C16: 5 | E16: SC Entre Grupos | F16: =F3*((F4-F7)^2+(F5-F7)^2+(F6-F7)^2) -> 1.9450172
A17: 1 | B17: 4 | C17: 5
A18: 5 | B18: 4 | C18: 3
A19: 1 | B19: 3 | C19: 1 | E19: Calculo gl ENTRE (Grados de libertad entre grupos)
A20: 4 | B20: 3 | C20: 3 | E20: Cantidad de grupos independientes que puedes comparar
A21: 4 | B21: 3 | C21: 1 | E21: k (Numero de grupos) | F21: 3
A22: 2 | B22: 2 | C22: 5
A23: 2 | B23: 5 | C23: 4
A24: 4 | B24: 3 | C24: 3 | E24: gl entre | F24: =F21-1 -> 2
A25: 3 | B25: 3 | C25: 2
A26: 4 | B26: 4 | C26: 1
A27: 4 | B27: 1 | C27: 3 | E27: Calculo MC ENTRE (Media Cuadrática Entre)
A28: 2 | B28: 5 | C28: 3 | E28: Es el promedio de la variación entre grupos
A29: 2 | B29: 5 | C29: 2
A30: 3 | B30: 1 | C30: 5
A31: 3 | B31: 2 | C31: 1
A32: 5 | B32: 3 | C32: 3
A33: 3 | B33: 3 | C33: 3 | E33: MC entre | F33: =F16/F24 -> 0.97250859
A34: 4 | B34: 2 | C34: 5
A35: 3 | B35: 4 | C35: 3
A36: 3 | B36: 4 | C36: 4 | E36: Calculo SC DENTRO DE GRUPOS (Suma de Cuadrados Dentro)
A37: 4 | B37: 4 | C37: 3 | E37: Mide la variabilidad interna de cada grupo
A38: 2 | B38: 4 | C38: 4 | E38: Qué tanto varían los datos dentro del mismo grupo
A39: 2 | B39: 2 | C39: 2
A40: 5 | B40: 5 | C40: 4
...

Sheet Resolución-autónoma
A1: Grupo Control Pre Test Sin intervención | B1: Grupo Control Post Test Sin intervención | C1: Grupo Experimental Pre Test Sin intervención
A2: 3 | B2: 3 | C2: 1 | E2: Datos Generales
A3: 4 | B3: 2 | C3: 1 | E3: Tamano Grupos | F3: =COUNT(A:A) -> 97
A4: 3 | B4: 5 | C4: 3 | E4: Promedio Grupo A | F4: =AVERAGE(A:A) -> 2.9793814
A5: 3 | B5: 5 | C5: 3 | E5: Promedio Grupo B | F5: =AVERAGE(B:B) -> 2.9587629
A6: 3 | B6: 4 | C6: 1 | E6: Promedio Grupo C | F6: =AVERAGE(C:C) -> 3.0206186
A7: 3 | B7: 2 | C7: 3 | E7: Promedio Total total | F7: =AVERAGE(F4:F6) -> 2.9862543
A8: 3 | B8: 4 | C8: 4
A9: 3 | B9: 3 | C9: 1
A10: 4 | B10: 3 | C10: 4 | E10: Calculo Suma de Cuadrados Entre Grupos
A11: 3 | B11: 3 | C11: 4 | E11: Mide qué tan diferentes son los grupos entre sí
A12: 5 | B12: 5 | C12: 3 | E12: Compara las medias de cada grupo con la media general
A13: 3 | B13: 5 | C13: 2
A14: 1 | B14: 4 | C14: 3
A15: 2 | B15: 3 | C15: 1
A16: 2 | B16: 3 | C16: 3 | E16: SC Entre Grupos | F16: =F3*((F4-F7)^2+(F5-F7)^2+(F6-F7)^2) -> 0.19243986
A17: 3 | B17: 3 | C17: 5
A18: 2 | B18: 3 | C18: 3
A19: 3 | B19: 4 | C19: 3 | E19: Calculo gl ENTRE (Grados de libertad entre grupos)
A20: 4 | B20: 3 | C20: 3 | E20: Cantidad de grupos independientes que puedes comparar
A21: 5 | B21: 4 | C21: 5 | E21: k (Numero de grupos) | F21: 3
A22: 2 | B22: 2 | C22: 3
A23: 3 | B23: 5 | C23: 5
A24: 3 | B24: 4 | C24: 3 | E24: gl entre | F24: =F21-1 -> 2
A25: 4 | B25: 2 | C25: 4
A26: 5 | B26: 4 | C26: 3
A27: 2 | B27: 3 | C27: 3 | E27: Calculo MC ENTRE (Media Cuadrática Entre)
A28: 2 | B28: 3 | C28: 3 | E28: Es el promedio de la variación entre grupos
A29: 2 | B29: 3 | C29: 4
A30: 2 | B30: 1 | C30: 3
A31: 4 | B31: 3 | C31: 3
A32: 3 | B32: 1 | C32: 4
A33: 4 | B33: 3 | C33: 3 | E33: MC entre | F33: =F16/F24 -> 0.096219931
A34: 3 | B34: 3 | C34: 2
A35: 3 | B35: 3 | C35: 3
A36: 2 | B36: 3 | C36: 3 | E36: Calculo SC DENTRO DE GRUPOS (Suma de Cuadrados Dentro)
A37: 1 | B37: 4 | C37: 2 | E37: Mide la variabilidad interna de cada grupo
A38: 3 | B38: 3 | C38: 5 | E38: Qué tanto varían los datos dentro del mismo grupo
A39: 3 | B39: 2 | C39: 3
A40: 2 | B40: 2 | C40: 2
...

Sheet Motivación
A1: Grupo Control Pre Test Sin intervención | B1: Grupo Control Post Test Sin intervención | C1: Grupo Experimental Pre Test Sin intervención
A2: 4 | B2: 3 | C2: 3 | E2: Datos Generales
A3: 4 | B3: 3 | C3: 4 | E3: Tamano Grupos | F3: =COUNT(A:A) -> 97
A4: 2 | B4: 5 | C4: 2 | E4: Promedio Grupo A | F4: =AVERAGE(A:A) -> 3.0309278
A5: 3 | B5: 5 | C5: 1 | E5: Promedio Grupo B | F5: =AVERAGE(B:B) -> 2.9278351
A6: 3 | B6: 2 | C6: 3 | E6: Promedio Grupo C | F6: =AVERAGE(C:C) -> 2.9484536
A7: 2 | B7: 3 | C7: 3 | E7: Promedio Total total | F7: =AVERAGE(F4:F6) -> 2.9690722
A8: 4 | B8: 3 | C8: 3
A9: 3 | B9: 1 | C9: 2
A10: 3 | B10: 2 | C10: 3 | E10: Calculo Suma de Cuadrados Entre Grupos
A11: 1 | B11: 3 | C11: 3 | E11: Mide qué tan diferentes son los grupos entre sí
A12: 1 | B12: 3 | C12: 2 | E12: Compara las medias de cada grupo con la media general
A13: 4 | B13: 5 | C13: 4
A14: 4 | B14: 4 | C14: 3
A15: 5 | B15: 3 | C15: 5
A16: 5 | B16: 4 | C16: 3 | E16: SC Entre Grupos | F16: =F3*((F4-F7)^2+(F5-F7)^2+(F6-F7)^2) -> 0.57731959
A17: 2 | B17: 4 | C17: 3
A18: 3 | B18: 2 | C18: 3
A19: 3 | B19: 2 | C19: 3 | E19: Calculo gl ENTRE (Grados de libertad entre grupos)
A20: 4 | B20: 3 | C20: 4 | E20: Cantidad de grupos independientes que puedes comparar
A21: 3 | B21: 5 | C21: 2 | E21: k (Numero de grupos) | F21: 3
A22: 2 | B22: 1 | C22: 2
A23: 3 | B23: 2 | C23: 3
A24: 1 | B24: 3 | C24: 4 | E24: gl entre | F24: =F21-1 -> 2
A25: 3 | B25: 3 | C25: 2
A26: 3 | B26: 4 | C26: 4
A27: 4 | B27: 1 | C27: 4 | E27: Calculo MC ENTRE (Media Cuadrática Entre)
A28: 3 | B28: 1 | C28: 1 | E28: Es el promedio de la variación entre grupos
A29: 3 | B29: 4 | C29: 3
A30: 3 | B30: 1 | C30: 1
A31: 3 | B31: 1 | C31: 3
A32: 5 | B32: 4 | C32: 3
A33: 3 | B33: 2 | C33: 5 | E33: MC entre | F33: =F16/F24 -> 0.28865979
A34: 1 | B34: 3 | C34: 3
A35: 5 | B35: 3 | C35: 1
A36: 1 | B36: 5 | C36: 5 | E36: Calculo SC DENTRO DE GRUPOS (Suma de Cuadrados Dentro)
A37: 3 | B37: 2 | C37: 3 | E37: Mide la variabilidad interna de cada grupo
A38: 2 | B38: 5 | C38: 3 | E38: Qué tanto varían los datos dentro del mismo grupo
A39: 2 | B39: 2 | C39: 4
A40: 3 | B40: 5 | C40: 4
...
