Workbook

Sheet Resumen
A1: Indicador | B1: T Calculado | C1: T Critico 2 Colas | D1: T Critico 1 Cola | E1: P valor 2 Colas | F1: P valor 1 Cola
A2: Participo actividades | B2: =ROUND('Participas-actividades'!E29, 4) -> 1.4992 | C2: =ROUND('Participas-actividades'!E52, 4) -> 1.973 | D2: =ROUND('Participas-actividades'!E53, 4) -> -1.6532 | E2: =ROUND('Participas-actividades'!E55, 4) -> 0.1355 | F2: =ROUND('Participas-actividades'!E56, 4) -> 0.0678
A3: Comprensión contenidos | B3: =ROUND('Comprensión-contenidos'!E29, 4) -> -1.2798 | C3: =ROUND('Comprensión-contenidos'!E52, 4) -> 1.973 | D3: =ROUND('Comprensión-contenidos'!E53, 4) -> -1.6532 | E3: =ROUND('Comprensión-contenidos'!E55, 4) -> 0.2022 | F3: =ROUND('Comprensión-contenidos'!E56, 4) -> 0.1011
A4: Herramientas tecnológicas | B4: =ROUND('Herramientas-tecnológicas'!E29, 4) -> -1.7053 | C4: =ROUND('Herramientas-tecnológicas'!E52, 4) -> 1.973 | D4: =ROUND('Herramientas-tecnológicas'!E53, 4) -> -1.6532 | E4: =ROUND('Herramientas-tecnológicas'!E55, 4) -> 0.0898 | F4: =ROUND('Herramientas-tecnológicas'!E56, 4) -> 0.0449
A5: Recursos tecnológicos | B5: =ROUND('Recursos-tecnológicos'!E29, 4) -> 1.5647 | C5: =ROUND('Recursos-tecnológicos'!E52, 4) -> 1.973 | D5: =ROUND('Recursos-tecnológicos'!E53, 4) -> -1.6532 | E5: =ROUND('Recursos-tecnológicos'!E55, 4) -> 0.1194 | F5: =ROUND('Recursos-tecnológicos'!E56, 4) -> 0.0597
A6: Percepción evaluaciones | B6: =ROUND('Percepción-evaluaciones'!E29, 4) -> -0.9804 | C6: =ROUND('Percepción-evaluaciones'!E52, 4) -> 1.9732 | D6: =ROUND('Percepción-evaluaciones'!E53, 4) -> -1.6533 | E6: =ROUND('Percepción-evaluaciones'!E55, 4) -> 0.3282 | F6: =ROUND('Percepción-evaluaciones'!E56, 4) -> 0.1641
A7: Retroalimentación oportuna | B7: =ROUND('Retroalimentación-oportuna'!E29, 4) -> -2.2782 | C7: =ROUND('Retroalimentación-oportuna'!E52, 4) -> 1.9731 | D7: =ROUND('Retroalimentación-oportuna'!E53, 4) -> -1.6533 | E7: =ROUND('Retroalimentación-oportuna'!E55, 4) -> 0.0239 | F7: =ROUND('Retroalimentación-oportuna'!E56, 4) -> 0.0119
A8: Calificación | B8: =ROUND(Calificación!E29, 4) -> 1.6248 | C8: =ROUND(Calificación!E52, 4) -> 1.9735 | D8: =ROUND(Calificación!E53, 4) -> -1.6536 | E8: =ROUND(Calificación!E55, 4) -> 0.1059 | F8: =ROUND(Calificación!E56, 4) -> 0.053
A9: Nivel comprensión | B9: =ROUND('Nivel-comprensión'!E29, 4) -> 0.1954 | C9: =ROUND('Nivel-comprensión'!E52, 4) -> 1.9731 | D9: =ROUND('Nivel-comprensión'!E53, 4) -> -1.6533 | E9: =ROUND('Nivel-comprensión'!E55, 4) -> 0.8453 | F9: =ROUND('Nivel-comprensión'!E56, 4) -> 0.4226
A10: Habilidades tareas | B10: =ROUND('Habilidades-tareas'!E29, 4) -> 1.2274 | C10: =ROUND('Habilidades-tareas'!E52, 4) -> 1.973 | D10: =ROUND('Habilidades-tareas'!E53, 4) -> -1.6532 | E10: =ROUND('Habilidades-tareas'!E55, 4) -> 0.2212 | F10: =ROUND('Habilidades-tareas'!E56, 4) -> 0.1106
A11: Resolución problemas | B11: =ROUND('Resolución-problemas'!E29, 4) -> 0.3437 | C11: =ROUND('Resolución-problemas'!E52, 4) -> 1.973 | D11: =ROUND('Resolución-problemas'!E53, 4) -> -1.6532 | E11: =ROUND('Resolución-problemas'!E55, 4) -> 0.7314 | F11: =ROUND('Resolución-problemas'!E56, 4) -> 0.3657
A12: Motivación | B12: =ROUND(Motivación!E29, 4) -> -2.3205 | C12: =ROUND(Motivación!E52, 4) -> 1.9733 | D12: =ROUND(Motivación!E53, 4) -> -1.6534 | E12: =ROUND(Motivación!E55, 4) -> 0.0214 | F12: =ROUND(Motivación!E56, 4) -> 0.0107

Sheet Participas-actividades
A1: (Sin Innovacion Didactica) Grupo Control - Pre-test Participó_activamente a) Siempre = 5 b) Frecuente = 4 c) A veces = 3 d) Raro = 2 e) Nunca = 1 | B1: (Sin Innovacion Didactica) Grupo Experimental - Pre-test Participó_activamente a) Siempre = 5 b) Frecuente = 4 c) A veces = 3 d) Raro = 2 e) Nunca = 1
A2: 5 | B2: 3 | D2: Media (X1) Grupo Control | E2: =AVERAGE(A:A) -> 3.4623656
A3: 5 | B3: 4 | D3: Mediana (Me1) | E3: =MEDIAN(A:A) -> 3
A4: 2 | B4: 2 | D4: Moda (Mo1) | E4: =MODE(A:A) -> 3
A5: 3 | B5: 3 | D5: Desviacion Tipica o Estandar (S1) | E5: =STDEV(A:A) -> 1.0890676
A6: 3 | B6: 1 | D6: n1 | E6: =COUNT(A:A) -> 93
A7: 5 | B7: 3
A8: 1 | B8: 5 | D8: Media (X2) Grupo Experimental | E8: =AVERAGE(B:B) -> 3.2150538
A9: 2 | B9: 3 | D9: Mediana (Me2) | E9: =MEDIAN(B:B) -> 3
A10: 4 | B10: 4 | D10: Moda (Mo2) | E10: =MODE(B:B) -> 3
A11: 4 | B11: 3 | D11: Desviacion Tipica o Estandar (S2) | E11: =STDEV(B:B) -> 1.1595488
A12: 4 | B12: 5 | D12: n2 | E12: =COUNT(B:B) -> 93
A13: 4 | B13: 4
A14: 3 | B14: 2
A15: 4 | B15: 4
A16: 4 | B16: 2
A17: 3 | B17: 4 | D17: t de student
A18: 5 | B18: 3
A19: 4 | B19: 3
A20: 4 | B20: 3
A21: 4 | B21: 4
A22: 3 | B22: 4
A23: 4 | B23: 5
A24: 3 | B24: 4
A25: 3 | B25: 3
A26: 5 | B26: 1
A27: 3 | B27: 2
A28: 4 | B28: 2
A29: 5 | B29: 2 | D29: Valor de t | E29: =(E2-E8)/SQRT(((E5^2)/E6)+((E11^2)/E12)) -> 1.4992455
A30: 2 | B30: 3
A31: 1 | B31: 4 | D31: df grados de libertad
A32: 2 | B32: 2
A33: 4 | B33: 3
A34: 5 | B34: 3
A35: 3 | B35: 5
A36: 4 | B36: 3
A37: 5 | B37: 3
A38: 3 | B38: 2
A39: 5 | B39: 3
A40: 2 | B40: 4
...

Sheet Comprensión-contenidos
A1: (Sin Innovacion Didactica) Grupo Control - Pre-test Comprensión-contenidos a) Siempre = 5 b) Muchas veces = 4 c) A veces = 3 d) Pocas veces = 2 e) Nunca = 1 | B1: (Sin Innovacion Didactica) Grupo Experimental - Pre-test Comprensión-contenidos a) Siempre = 5 b) Muchas veces = 4 c) A veces = 3 d) Pocas veces = 2 e) Nunca = 1
A2: 3 | B2: 4 | D2: Media (X1) Grupo Control | E2: =AVERAGE(A:A) -> 3.344086
A3: 2 | B3: 3 | D3: Mediana (Me1) | E3: =MEDIAN(A:A) -> 3
A4: 4 | B4: 3 | D4: Moda (Mo1) | E4: =MODE(A:A) -> 4
A5: 4 | B5: 2 | D5: Desviacion Tipica o Estandar (S1) | E5: =STDEV(A:A) -> 1.1082166
A6: 3 | B6: 4 | D6: n1 | E6: =COUNT(A:A) -> 93
A7: 4 | B7: 3
A8: 5 | B8: 3 | D8: Media (X2) Grupo Experimental | E8: =AVERAGE(B:B) -> 3.5483871
A9: 4 | B9: 3 | D9: Mediana (Me2) | E9: =MEDIAN(B:B) -> 4
A10: 5 | B10: 3 | D10: Moda (Mo2) | E10: =MODE(B:B) -> 3
A11: 2 | B11: 4 | D11: Desviacion Tipica o Estandar (S2) | E11: =STDEV(B:B) -> 1.0684826
A12: 2 | B12: 3 | D12: n2 | E12: =COUNT(B:B) -> 93
A13: 3 | B13: 5
A14: 2 | B14: 4
A15: 2 | B15: 3
A16: 4 | B16: 3
A17: 2 | B17: 1 | D17: t de student
A18: 3 | B18: 3
A19: 2 | B19: 3
A20: 2 | B20: 3
A21: 4 | B21: 3
A22: 5 | B22: 5
A23: 4 | B23: 4
A24: 4 | B24: 4
A25: 2 | B25: 4
A26: 2 | B26: 5
A27: 5 | B27: 5
A28: 3 | B28: 4
A29: 4 | B29: 1 | D29: Valor de t | E29: =(E2-E8)/SQRT(((E5^2)/E6)+((E11^2)/E12)) -> -1.279842
A30: 4 | B30: 4
A31: 5 | B31: 3 | D31: df grados de libertad
A32: 4 | B32: 5
A33: 1 | B33: 3
A34: 4 | B34: 4
A35: 3 | B35: 4
A36: 3 | B36: 3
A37: 4 | B37: 5
A38: 1 | B38: 5
A39: 1 | B39: 4
A40: 4 | B40: 5
...

Sheet Herramientas-tecnológicas
A1: (Sin Innovacion Didactica) Grupo Control - Pre-test Herramientas-tecnológicas a) Siempre = 5 b) Frecuente = 4 c) A veces = 3 d) Raro = 2 e) Nunca = 1 | B1: (Sin Innovacion Didactica) Grupo Experimental - Pre-test Herramientas-tecnológicas a) Siempre = 5 b) Frecuente = 4 c) A veces = 3 d) Raro = 2 e) Nunca = 1
A2: 5 | B2: 5 | D2: Media (X1) Grupo Control | E2: =AVERAGE(A:A) -> 3.2365591
A3: 5 | B3: 3 | D3: Mediana (Me1) | E3: =MEDIAN(A:A) -> 3
A4: 2 | B4: 5 | D4: Moda (Mo1) | E4: =MODE(A:A) -> 3
A5: 3 | B5: 5 | D5: Desviacion Tipica o Estandar (S1) | E5: =STDEV(A:A) -> 1.1923474
A6: 5 | B6: 4 | D6: n1 | E6: =COUNT(A:A) -> 93
A7: 5 | B7: 4
A8: 3 | B8: 3 | D8: Media (X2) Grupo Experimental | E8: =AVERAGE(B:B) -> 3.5268817
A9: 5 | B9: 3 | D9: Mediana (Me2) | E9: =MEDIAN(B:B) -> 4
A10: 5 | B10: 5 | D10: Moda (Mo2) | E10: =MODE(B:B) -> 4
A11: 3 | B11: 5 | D11: Desviacion Tipica o Estandar (S2) | E11: =STDEV(B:B) -> 1.1285947
A12: 3 | B12: 3 | D12: n2 | E12: =COUNT(B:B) -> 93
A13: 3 | B13: 4
A14: 4 | B14: 3
A15: 3 | B15: 3
A16: 4 | B16: 2
A17: 4 | B17: 3 | D17: t de student
A18: 3 | B18: 4
A19: 3 | B19: 3
A20: 2 | B20: 4
A21: 3 | B21: 4
A22: 3 | B22: 2
A23: 5 | B23: 4
A24: 4 | B24: 2
A25: 4 | B25: 2
A26: 4 | B26: 2
A27: 1 | B27: 1
A28: 4 | B28: 4
A29: 2 | B29: 4 | D29: Valor de t | E29: =(E2-E8)/SQRT(((E5^2)/E6)+((E11^2)/E12)) -> -1.705333
A30: 3 | B30: 3
A31: 2 | B31: 4 | D31: df grados de libertad
A32: 3 | B32: 3
A33: 3 | B33: 3
A34: 3 | B34: 3
A35: 4 | B35: 4
A36: 3 | B36: 5
A37: 4 | B37: 4
A38: 5 | B38: 5
A39: 3 | B39: 2
A40: 5 | B40: 4
...

Sheet Recursos-tecnológicos
A1: (Sin Innovacion Didactica) Grupo control - Pre-test Recursos-tecnológicos a) Siempre = 5 b) Muchas veces = 4 c) A veces = 3 d) Pocas veces = 2 e) Nunca = 1 | B1: (Sin Innovacion Didactica) Grupo Experimental - Pre-test Recursos-tecnológicos a) Siempre = 5 b) Muchas veces = 4 c) A veces = 3 d) Pocas veces = 2 e) Nunca = 1
A2: 5 | B2: 5 | D2: Media (X1) Grupo Control | E2: =AVERAGE(A:A) -> 3.4193548
A3: 5 | B3: 4 | D3: Mediana (Me1) | E3: =MEDIAN(A:A) -> 3
A4: 3 | B4: 3 | D4: Moda (Mo1) | E4: =MODE(A:A) -> 3
A5: 3 | B5: 3 | D5: Desviacion Tipica o Estandar (S1) | E5: =STDEV(A:A) -> 1.1639754
A6: 3 | B6: 4 | D6: n1 | E6: =COUNT(A:A) -> 93
A7: 3 | B7: 1
A8: 1 | B8: 2 | D8: Media (X2) Grupo Experimental | E8: =AVERAGE(B:B) -> 3.1505376
A9: 3 | B9: 3 | D9: Mediana (Me2) | E9: =MEDIAN(B:B) -> 3
A10: 4 | B10: 3 | D10: Moda (Mo2) | E10: =MODE(B:B) -> 3
A11: 2 | B11: 3 | D11: Desviacion Tipica o Estandar (S2) | E11: =STDEV(B:B) -> 1.1790401
A12: 4 | B12: 4 | D12: n2 | E12: =COUNT(B:B) -> 93
A13: 4 | B13: 4
A14: 5 | B14: 5
A15: 5 | B15: 3
A16: 1 | B16: 3
A17: 2 | B17: 4 | D17: t de student
A18: 3 | B18: 1
A19: 4 | B19: 2
A20: 4 | B20: 3
A21: 5 | B21: 3
A22: 4 | B22: 2
A23: 3 | B23: 5
A24: 3 | B24: 2
A25: 3 | B25: 5
A26: 4 | B26: 2
A27: 1 | B27: 4
A28: 3 | B28: 2
A29: 3 | B29: 1 | D29: Valor de t | E29: =(E2-E8)/SQRT(((E5^2)/E6)+((E11^2)/E12)) -> 1.5646939
A30: 3 | B30: 5
A31: 4 | B31: 4 | D31: df grados de libertad
A32: 4 | B32: 1
A33: 4 | B33: 3
A34: 3 | B34: 2
A35: 5 | B35: 3
A36: 5 | B36: 4
A37: 5 | B37: 4
A38: 5 | B38: 4
A39: 2 | B39: 3
A40: 3 | B40: 4
...

Sheet Percepción-evaluaciones
A1: (Sin Innovacion Didactica) Grupo Control - Pre-test Percepción-evaluaciones a) Siempre = 5 b) Frecuente = 4 c) A veces = 3 d) Raro = 2 e) Nunca = 1 | B1: (Sin Innovacion Didactica) Grupo Experimental - Pre-test Percepción-evaluaciones a) Siempre = 5 b) Frecuente = 4 c) A veces = 3 d) Raro = 2 e) Nunca = 1
A2: 4 | B2: 1 | D2: Media (X1) Grupo Control | E2: =AVERAGE(A:A) -> 3.1827957
A3: 2 | B3: 5 | D3: Mediana (Me1) | E3: =MEDIAN(A:A) -> 3
A4: 2 | B4: 1 | D4: Moda (Mo1) | E4: =MODE(A:A) -> 3
A5: 5 | B5: 3 | D5: Desviacion Tipica o Estandar (S1) | E5: =STDEV(A:A) -> 1.342825
A6: 2 | B6: 4 | D6: n1 | E6: =COUNT(A:A) -> 93
A7: 3 | B7: 5
A8: 2 | B8: 3 | D8: Media (X2) Grupo Experimental | E8: =AVERAGE(B:B) -> 3.3655914
A9: 4 | B9: 2 | D9: Mediana (Me2) | E9: =MEDIAN(B:B) -> 3
A10: 2 | B10: 3 | D10: Moda (Mo2) | E10: =MODE(B:B) -> 3
A11: 4 | B11: 5 | D11: Desviacion Tipica o Estandar (S2) | E11: =STDEV(B:B) -> 1.195871
A12: 5 | B12: 5 | D12: n2 | E12: =COUNT(B:B) -> 93
A13: 2 | B13: 4
A14: 5 | B14: 4
A15: 4 | B15: 4
A16: 1 | B16: 4
A17: 1 | B17: 2 | D17: t de student
A18: 3 | B18: 1
A19: 3 | B19: 4
A20: 3 | B20: 2
A21: 4 | B21: 4
A22: 4 | B22: 3
A23: 3 | B23: 4
A24: 2 | B24: 3
A25: 2 | B25: 1
A26: 2 | B26: 3
A27: 5 | B27: 4
A28: 3 | B28: 3
A29: 5 | B29: 5 | D29: Valor de t | E29: =(E2-E8)/SQRT(((E5^2)/E6)+((E11^2)/E12)) -> -0.98035947
A30: 3 | B30: 2
A31: 4 | B31: 3 | D31: df grados de libertad
A32: 2 | B32: 3
A33: 4 | B33: 3
A34: 5 | B34: 3
A35: 5 | B35: 5
A36: 2 | B36: 3
A37: 3 | B37: 4
A38: 5 | B38: 3
A39: 5 | B39: 2
A40: 3 | B40: 2
...

Sheet Retroalimentación-oportuna
A1: (Sin Innovacion Didactica) Grupo Control - Pre-test Retroalimentación-oportuna a) Siempre = 5 b) Muchas veces = 4 c) A veces = 3 d) Pocas veces = 2 e) Nunca = 1 | B1: (Sin Innovacion Didactica) Grupo Experimental - Pre-test Retroalimentación-oportuna a) Siempre = 5 b) Muchas veces = 4 c) A veces = 3 d) Pocas veces = 2 e) Nunca = 1
A2: 4 | B2: 4 | D2: Media (X1) Grupo Control | E2: =AVERAGE(A:A) -> 3.1505376
A3: 3 | B3: 4 | D3: Mediana (Me1) | E3: =MEDIAN(A:A) -> 3
A4: 5 | B4: 5 | D4: Moda (Mo1) | E4: =MODE(A:A) -> 3
A5: 1 | B5: 3 | D5: Desviacion Tipica o Estandar (S1) | E5: =STDEV(A:A) -> 1.2506193
A6: 1 | B6: 4 | D6: n1 | E6: =COUNT(A:A) -> 93
A7: 3 | B7: 2
A8: 3 | B8: 2 | D8: Media (X2) Grupo Experimental | E8: =AVERAGE(B:B) -> 3.5483871
A9: 4 | B9: 4 | D9: Mediana (Me2) | E9: =MEDIAN(B:B) -> 4
A10: 2 | B10: 3 | D10: Moda (Mo2) | E10: =MODE(B:B) -> 4
A11: 3 | B11: 4 | D11: Desviacion Tipica o Estandar (S2) | E11: =STDEV(B:B) -> 1.1278696
A12: 5 | B12: 2 | D12: n2 | E12: =COUNT(B:B) -> 93
A13: 2 | B13: 4
A14: 2 | B14: 3
A15: 1 | B15: 3
A16: 3 | B16: 4
A17: 3 | B17: 5 | D17: t de student
A18: 4 | B18: 3
A19: 1 | B19: 3
A20: 2 | B20: 4
A21: 5 | B21: 3
A22: 5 | B22: 4
A23: 4 | B23: 3
A24: 2 | B24: 5
A25: 1 | B25: 2
A26: 5 | B26: 4
A27: 3 | B27: 4
A28: 4 | B28: 5
A29: 1 | B29: 5 | D29: Valor de t | E29: =(E2-E8)/SQRT(((E5^2)/E6)+((E11^2)/E12)) -> -2.2782246
A30: 2 | B30: 3
A31: 2 | B31: 4 | D31: df grados de libertad
A32: 4 | B32: 2
A33: 4 | B33: 5
A34: 4 | B34: 4
A35: 5 | B35: 4
A36: 2 | B36: 5
A37: 2 | B37: 5
A38: 1 | B38: 4
A39: 1 | B39: 3
A40: 3 | B40: 4
...

Sheet Calificación
A1: (Sin Innovacion Didactica) Grupo Control - Pre-test Calificación a) 81 - 100 = 5 b) 61 - 80 = 4 c) 41 - 60 = 3 d) 21 - 40 = 2 e) 0 - 20 = 1 | B1: (Sin Innovacion Didactica) Grupo Experimental - Pre-test Calificación a) 81 - 100 = 5 b) 61 - 80 = 4 c) 41 - 60 = 3 d) 21 - 40 = 2 e) 0 - 20 = 1
A2: 4 | B2: 3 | D2: Media (X1) Grupo Control | E2: =AVERAGE(A:A) -> 3.5483871
A3: 2 | B3: 4 | D3: Mediana (Me1) | E3: =MEDIAN(A:A) -> 4
A4: 3 | B4: 3 | D4: Moda (Mo1) | E4: =MODE(A:A) -> 4
A5: 3 | B5: 4 | D5: Desviacion Tipica o Estandar (S1) | E5: =STDEV(A:A) -> 1.0479393
A6: 4 | B6: 4 | D6: n1 | E6: =COUNT(A:A) -> 93
A7: 4 | B7: 1
A8: 5 | B8: 4 | D8: Media (X2) Grupo Experimental | E8: =AVERAGE(B:B) -> 3.2688172
A9: 5 | B9: 4 | D9: Mediana (Me2) | E9: =MEDIAN(B:B) -> 3
A10: 4 | B10: 2 | D10: Moda (Mo2) | E10: =MODE(B:B) -> 3
A11: 4 | B11: 3 | D11: Desviacion Tipica o Estandar (S2) | E11: =STDEV(B:B) -> 1.2865507
A12: 5 | B12: 5 | D12: n2 | E12: =COUNT(B:B) -> 93
A13: 5 | B13: 5
A14: 3 | B14: 5
A15: 4 | B15: 3
A16: 4 | B16: 4
A17: 3 | B17: 5 | D17: t de student
A18: 3 | B18: 1
A19: 5 | B19: 3
A20: 2 | B20: 4
A21: 3 | B21: 3
A22: 5 | B22: 3
A23: 2 | B23: 5
A24: 2 | B24: 4
A25: 5 | B25: 2
A26: 4 | B26: 4
A27: 2 | B27: 3
A28: 3 | B28: 4
A29: 4 | B29: 5 | D29: Valor de t | E29: =(E2-E8)/SQRT(((E5^2)/E6)+((E11^2)/E12)) -> 1.6247931
A30: 4 | B30: 5
A31: 4 | B31: 4 | D31: df grados de libertad
A32: 3 | B32: 4
A33: 3 | B33: 5
A34: 4 | B34: 2
A35: 3 | B35: 1
A36: 3 | B36: 2
A37: 5 | B37: 2
A38: 4 | B38: 4
A39: 3 | B39: 1
A40: 2 | B40: 4
...

Sheet Nivel-comprensión
A1: (Sin Innovacion Didactica) Grupo Control - Pre-test Nivel-comprensión a) Muy Bueno = 5 b) bueno = 4 c) Regular = 3 d) Malo = 2 e) Muy malo = 1 | B1: (Sin Innovacion Didactica) Grupo Experimental - Pre-test Nivel-comprensión a) Muy Bueno = 5 b) bueno = 4 c) Regular = 3 d) Malo = 2 e) Muy malo = 1
A2: 4 | B2: 4 | D2: Media (X1) Grupo Control | E2: =AVERAGE(A:A) -> 3.4301075
A3: 3 | B3: 3 | D3: Mediana (Me1) | E3: =MEDIAN(A:A) -> 3
A4: 4 | B4: 4 | D4: Moda (Mo1) | E4: =MODE(A:A) -> 3
A5: 5 | B5: 3 | D5: Desviacion Tipica o Estandar (S1) | E5: =STDEV(A:A) -> 1.0672786
A6: 3 | B6: 4 | D6: n1 | E6: =COUNT(A:A) -> 93
A7: 4 | B7: 5
A8: 3 | B8: 1 | D8: Media (X2) Grupo Experimental | E8: =AVERAGE(B:B) -> 3.3978495
A9: 5 | B9: 5 | D9: Mediana (Me2) | E9: =MEDIAN(B:B) -> 3
A10: 3 | B10: 3 | D10: Moda (Mo2) | E10: =MODE(B:B) -> 4
A11: 3 | B11: 4 | D11: Desviacion Tipica o Estandar (S2) | E11: =STDEV(B:B) -> 1.1808231
A12: 5 | B12: 5 | D12: n2 | E12: =COUNT(B:B) -> 93
A13: 4 | B13: 5
A14: 5 | B14: 5
A15: 5 | B15: 2
A16: 1 | B16: 4
A17: 4 | B17: 1 | D17: t de student
A18: 2 | B18: 3
A19: 4 | B19: 4
A20: 3 | B20: 3
A21: 3 | B21: 3
A22: 3 | B22: 3
A23: 3 | B23: 4
A24: 4 | B24: 4
A25: 4 | B25: 2
A26: 2 | B26: 1
A27: 2 | B27: 2
A28: 1 | B28: 4
A29: 5 | B29: 3 | D29: Valor de t | E29: =(E2-E8)/SQRT(((E5^2)/E6)+((E11^2)/E12)) -> 0.19544546
A30: 3 | B30: 4
A31: 2 | B31: 3 | D31: df grados de libertad
A32: 5 | B32: 4
A33: 5 | B33: 3
A34: 3 | B34: 5
A35: 3 | B35: 4
A36: 2 | B36: 2
A37: 5 | B37: 4
A38: 3 | B38: 5
A39: 4 | B39: 5
A40: 5 | B40: 1
...

Sheet Habilidades-tareas
A1: (Sin Innovacion Didactica) Grupo Control - Pre-test Habilidades-tareas a) Siempre = 5 b) Muchas veces = 4 c) A veces = 3 d) Pocas veces = 2 e) Nunca = 1 | B1: (Sin Innovacion Didactica) Grupo Experimental - Pre-test Habilidades-tareas a) Siempre = 5 b) Muchas veces = 4 c) A veces = 3 d) Pocas veces = 2 e) Nunca = 1
A2: 1 | B2: 5 | D2: Media (X1) Grupo Control | E2: =AVERAGE(A:A) -> 3.4301075
A3: 5 | B3: 3 | D3: Mediana (Me1) | E3: =MEDIAN(A:A) -> 3
A4: 3 | B4: 3 | D4: Moda (Mo1) | E4: =MODE(A:A) -> 3
A5: 3 | B5: 4 | D5: Desviacion Tipica o Estandar (S1) | E5: =STDEV(A:A) -> 1.1363352
A6: 3 | B6: 1 | D6: n1 | E6: =COUNT(A:A) -> 93
A7: 5 | B7: 2
A8: 2 | B8: 3 | D8: Media (X2) Grupo Experimental | E8: =AVERAGE(B:B) -> 3.2258065
A9: 2 | B9: 3 | D9: Mediana (Me2) | E9: =MEDIAN(B:B) -> 3
A10: 3 | B10: 3 | D10: Moda (Mo2) | E10: =MODE(B:B) -> 3
A11: 3 | B11: 1 | D11: Desviacion Tipica o Estandar (S2) | E11: =STDEV(B:B) -> 1.1337609
A12: 2 | B12: 3 | D12: n2 | E12: =COUNT(B:B) -> 93
A13: 3 | B13: 3
A14: 5 | B14: 2
A15: 3 | B15: 4
A16: 3 | B16: 2
A17: 4 | B17: 4 | D17: t de student
A18: 3 | B18: 4
A19: 1 | B19: 4
A20: 2 | B20: 1
A21: 4 | B21: 2
A22: 5 | B22: 3
A23: 1 | B23: 3
A24: 2 | B24: 3
A25: 5 | B25: 1
A26: 2 | B26: 3
A27: 2 | B27: 4
A28: 3 | B28: 5
A29: 3 | B29: 2 | D29: Valor de t | E29: =(E2-E8)/SQRT(((E5^2)/E6)+((E11^2)/E12)) -> 1.2273901
A30: 4 | B30: 3
A31: 5 | B31: 4 | D31: df grados de libertad
A32: 4 | B32: 5
A33: 2 | B33: 2
A34: 5 | B34: 5
A35: 4 | B35: 3
A36: 4 | B36: 1
A37: 3 | B37: 4
A38: 2 | B38: 4
A39: 4 | B39: 3
A40: 4 | B40: 2
...

Sheet Resolución-problemas
A1: (Sin Innovacion Didactica) Grupo Control - Pre-test Resolución-problemas a) Siempre = 5 b) Frecuente = 4 c) A veces = 3 d) Raro = 2 e) Nunca = 1 | B1: (Sin Innovacion Didactica) Grupo Experimental - Pre-test Resolución-problemas a) Siempre = 5 b) Frecuente = 4 c) A veces = 3 d) Raro = 2 e) Nunca = 1
A2: 4 | B2: 4 | D2: Media (X1) Grupo Control | E2: =AVERAGE(A:A) -> 3.4516129
A3: 5 | B3: 3 | D3: Mediana (Me1) | E3: =MEDIAN(A:A) -> 4
A4: 4 | B4: 3 | D4: Moda (Mo1) | E4: =MODE(A:A) -> 4
A5: 3 | B5: 4 | D5: Desviacion Tipica o Estandar (S1) | E5: =STDEV(A:A) -> 1.0375151
A6: 2 | B6: 4 | D6: n1 | E6: =COUNT(A:A) -> 93
A7: 2 | B7: 4
A8: 4 | B8: 4 | D8: Media (X2) Grupo Experimental | E8: =AVERAGE(B:B) -> 3.3978495
A9: 3 | B9: 4 | D9: Mediana (Me2) | E9: =MEDIAN(B:B) -> 3
A10: 4 | B10: 3 | D10: Moda (Mo2) | E10: =MODE(B:B) -> 3
A11: 4 | B11: 4 | D11: Desviacion Tipica o Estandar (S2) | E11: =STDEV(B:B) -> 1.0948475
A12: 2 | B12: 4 | D12: n2 | E12: =COUNT(B:B) -> 93
A13: 5 | B13: 3
A14: 5 | B14: 1
A15: 4 | B15: 3
A16: 5 | B16: 5
A17: 4 | B17: 5 | D17: t de student
A18: 3 | B18: 1
A19: 4 | B19: 4
A20: 2 | B20: 5
A21: 2 | B21: 3
A22: 4 | B22: 3
A23: 4 | B23: 3
A24: 4 | B24: 4
A25: 3 | B25: 5
A26: 4 | B26: 1
A27: 3 | B27: 4
A28: 4 | B28: 3
A29: 3 | B29: 3 | D29: Valor de t | E29: =(E2-E8)/SQRT(((E5^2)/E6)+((E11^2)/E12)) -> 0.34373643
A30: 3 | B30: 3
A31: 4 | B31: 4 | D31: df grados de libertad
A32: 1 | B32: 4
A33: 3 | B33: 3
A34: 5 | B34: 2
A35: 2 | B35: 2
A36: 3 | B36: 5
A37: 2 | B37: 5
A38: 2 | B38: 2
A39: 4 | B39: 3
A40: 5 | B40: 2
...

Sheet Motivación
A1: (Sin Innovacion Didactica) Grupo Control - Pre-test Motivación a) Muy Alta = 5 b) Alta = 4 c) Regular = 3 d) Baja = 2 e) Muy Baja = 1 | B1: (Sin Innovacion Didactica) Grupo Experimental - Pre-test Motivación a) Muy Alta = 5 b) Alta = 4 c) Regular = 3 d) Baja = 2 e) Muy Baja = 1
A2: 3 | B2: 2 | D2: Media (X1) Grupo Control | E2: =AVERAGE(A:A) -> 3.1612903
A3: 3 | B3: 3 | D3: Mediana (Me1) | E3: =MEDIAN(A:A) -> 3
A4: 4 | B4: 3 | D4: Moda (Mo1) | E4: =MODE(A:A) -> 4
A5: 4 | B5: 4 | D5: Desviacion Tipica o Estandar (S1) | E5: =STDEV(A:A) -> 1.2536063
A6: 2 | B6: 4 | D6: n1 | E6: =COUNT(A:A) -> 93
A7: 2 | B7: 2
A8: 3 | B8: 3 | D8: Media (X2) Grupo Experimental | E8: =AVERAGE(B:B) -> 3.5591398
A9: 4 | B9: 3 | D9: Mediana (Me2) | E9: =MEDIAN(B:B) -> 4
A10: 3 | B10: 4 | D10: Moda (Mo2) | E10: =MODE(B:B) -> 3
A11: 4 | B11: 3 | D11: Desviacion Tipica o Estandar (S2) | E11: =STDEV(B:B) -> 1.0780656
A12: 5 | B12: 4 | D12: n2 | E12: =COUNT(B:B) -> 93
A13: 1 | B13: 3
A14: 5 | B14: 4
A15: 1 | B15: 4
A16: 4 | B16: 3
A17: 4 | B17: 2 | D17: t de student
A18: 3 | B18: 5
A19: 2 | B19: 2
A20: 3 | B20: 4
A21: 2 | B21: 4
A22: 3 | B22: 5
A23: 3 | B23: 4
A24: 2 | B24: 3
A25: 4 | B25: 5
A26: 3 | B26: 3
A27: 4 | B27: 2
A28: 1 | B28: 5
A29: 1 | B29: 3 | D29: Valor de t | E29: =(E2-E8)/SQRT(((E5^2)/E6)+((E11^2)/E12)) -> -2.3204944
A30: 5 | B30: 4
A31: 3 | B31: 3 | D31: df grados de libertad
A32: 1 | B32: 4
A33: 4 | B33: 5
A34: 3 | B34: 5
A35: 1 | B35: 5
A36: 5 | B36: 5
A37: 3 | B37: 3
A38: 4 | B38: 2
A39: 1 | B39: 2
A40: 1 | B40: 3
...
