Workbook

Sheet Resumen
A1: Indicador | B1: T Calculado | C1: T Critico 2 Colas | D1: T Critico 1 Cola | E1: P valor 2 Colas | F1: P valor 1 Cola
A2: Participo actividades | B2: =ROUND('Participas-actividades'!G12, 4) -> -1.9492 | C2: =ROUND('Participas-actividades'!G23, 4) -> 1.9861 | D2: =ROUND('Participas-actividades'!G24, 4) -> -1.6616 | E2: =ROUND('Participas-actividades'!G29, 4) -> 0.0543 | F2: =ROUND('Participas-actividades'!G30, 4) -> 0.0272
A3: Comprensión contenidos | B3: =ROUND('Comprensión-contenidos'!G12, 4) -> -0.2478 | C3: =ROUND('Comprensión-contenidos'!G23, 4) -> 1.9861 | D3: =ROUND('Comprensión-contenidos'!G24, 4) -> -1.6616 | E3: =ROUND('Comprensión-contenidos'!G29, 4) -> 0.8049 | F3: =ROUND('Comprensión-contenidos'!G30, 4) -> 0.4024
A4: Herramientas tecnológicas | B4: =ROUND('Herramientas-tecnológicas'!G12, 4) -> 0.7665 | C4: =ROUND('Herramientas-tecnológicas'!G23, 4) -> 1.9861 | D4: =ROUND('Herramientas-tecnológicas'!G24, 4) -> -1.6616 | E4: =ROUND('Herramientas-tecnológicas'!G29, 4) -> 0.4453 | F4: =ROUND('Herramientas-tecnológicas'!G30, 4) -> 0.2227
A5: Recursos tecnológicos | B5: =ROUND('Recursos-tecnológicos'!G12, 4) -> -0.5999 | C5: =ROUND('Recursos-tecnológicos'!G23, 4) -> 1.9861 | D5: =ROUND('Recursos-tecnológicos'!G24, 4) -> -1.6616 | E5: =ROUND('Recursos-tecnológicos'!G29, 4) -> 0.5501 | F5: =ROUND('Recursos-tecnológicos'!G30, 4) -> 0.275
A6: Percepción evaluaciones | B6: =ROUND('Percepción-evaluaciones'!G12, 4) -> 1.2068 | C6: =ROUND('Percepción-evaluaciones'!G23, 4) -> 1.9861 | D6: =ROUND('Percepción-evaluaciones'!G24, 4) -> -1.6616 | E6: =ROUND('Percepción-evaluaciones'!G29, 4) -> 0.2306 | F6: =ROUND('Percepción-evaluaciones'!G30, 4) -> 0.1153
A7: Retroalimentación oportuna | B7: =ROUND('Retroalimentación-oportuna'!G12, 4) -> 0.9523 | C7: =ROUND('Retroalimentación-oportuna'!G23, 4) -> 1.9861 | D7: =ROUND('Retroalimentación-oportuna'!G24, 4) -> -1.6616 | E7: =ROUND('Retroalimentación-oportuna'!G29, 4) -> 0.3434 | F7: =ROUND('Retroalimentación-oportuna'!G30, 4) -> 0.1717
A8: Calificación | B8: =ROUND(Calificación!G12, 4) -> -0.7077 | C8: =ROUND(Calificación!G23, 4) -> 1.9861 | D8: =ROUND(Calificación!G24, 4) -> -1.6616 | E8: =ROUND(Calificación!G29, 4) -> 0.4809 | F8: =ROUND(Calificación!G30, 4) -> 0.2405
A9: Nivel comprensión | B9: =ROUND('Nivel-comprensión'!G12, 4) -> -0.8476 | C9: =ROUND('Nivel-comprensión'!G23, 4) -> 1.9861 | D9: =ROUND('Nivel-comprensión'!G24, 4) -> -1.6616 | E9: =ROUND('Nivel-comprensión'!G29, 4) -> 0.3989 | F9: =ROUND('Nivel-comprensión'!G30, 4) -> 0.1994
A10: Habilidades tareas | B10: =ROUND('Habilidades-tareas'!G12, 4) -> -0.8616 | C10: =ROUND('Habilidades-tareas'!G23, 4) -> 1.9861 | D10: =ROUND('Habilidades-tareas'!G24, 4) -> -1.6616 | E10: =ROUND('Habilidades-tareas'!G29, 4) -> 0.3911 | F10: =ROUND('Habilidades-tareas'!G30, 4) -> 0.1956
A11: Resolución problemas | B11: =ROUND('Resolución-problemas'!G12, 4) -> -0.3332 | C11: =ROUND('Resolución-problemas'!G23, 4) -> 1.9861 | D11: =ROUND('Resolución-problemas'!G24, 4) -> -1.6616 | E11: =ROUND('Resolución-problemas'!G29, 4) -> 0.7397 | F11: =ROUND('Resolución-problemas'!G30, 4) -> 0.3699
A12: Motivación | B12: =ROUND(Motivación!G12, 4) -> 0.4233 | C12: =ROUND(Motivación!G23, 4) -> 1.9861 | D12: =ROUND(Motivación!G24, 4) -> -1.6616 | E12: =ROUND(Motivación!G29, 4) -> 0.673 | F12: =ROUND(Motivación!G30, 4) -> 0.3365

Sheet Participas-actividades
A1: (Sin Innovacion Didactica) Pre-test Participó_activamente a) Siempre = 5 b) Frecuente = 4 c) A veces = 3 d) Raro = 2 e) Nunca = 1 | B1: (Sin Innovacion Didactica) Post-test Participó_activamente a) Siempre = 5 b) Frecuente = 4 c) A veces = 3 d) Raro = 2 e) Nunca = 1 | C1: Diferencia
A2: 5 | B2: 2 | C2: =B2-A2 -> -3 | D2: =(C2-$G$6)^2 -> 7.1685744
A3: 5 | B3: 1 | C3: =B3-A3 -> -4 | D3: =(C3-$G$6)^2 -> 13.523413 | F3: Datos
A4: 2 | B4: 4 | C4: =B4-A4 -> 2 | D4: =(C4-$G$6)^2 -> 5.3943809 | F4: numero de datos | G4: =COUNT(A:A) -> 93
A5: 3 | B5: 3 | C5: =B5-A5 -> 0 | D5: =(C5-$G$6)^2 -> 0.10405827 | F5: Sumatoria Diferencias | G5: =SUM(C:C) -> -30
A6: 3 | B6: 4 | C6: =B6-A6 -> 1 | D6: =(C6-$G$6)^2 -> 1.7492196 | F6: Media de las diferencias | G6: =G5/G4 -> -0.32258065
A7: 5 | B7: 1 | C7: =B7-A7 -> -4 | D7: =(C7-$G$6)^2 -> 13.523413 | F7: Sumatoria de diferencias | G7: =SUM(D:D) -> 234.32258
A8: 1 | B8: 4 | C8: =B8-A8 -> 3 | D8: =(C8-$G$6)^2 -> 11.039542 | F8: desviación estándar de las diferencias | G8: =SQRT(G7/(G4-1)) -> 1.5959275
A9: 2 | B9: 1 | C9: =B9-A9 -> -1 | D9: =(C9-$G$6)^2 -> 0.45889698
A10: 4 | B10: 3 | C10: =B10-A10 -> -1 | D10: =(C10-$G$6)^2 -> 0.45889698
A11: 4 | B11: 3 | C11: =B11-A11 -> -1 | D11: =(C11-$G$6)^2 -> 0.45889698
A12: 4 | B12: 3 | C12: =B12-A12 -> -1 | D12: =(C12-$G$6)^2 -> 0.45889698 | F12: t calculado (estadistico t): | G12: =G6/(G8/SQRT(G4)) -> -1.9492459
A13: 4 | B13: 4 | C13: =B13-A13 -> 0 | D13: =(C13-$G$6)^2 -> 0.10405827
A14: 3 | B14: 4 | C14: =B14-A14 -> 1 | D14: =(C14-$G$6)^2 -> 1.7492196
A15: 4 | B15: 4 | C15: =B15-A15 -> 0 | D15: =(C15-$G$6)^2 -> 0.10405827
A16: 4 | B16: 4 | C16: =B16-A16 -> 0 | D16: =(C16-$G$6)^2 -> 0.10405827
A17: 3 | B17: 3 | C17: =B17-A17 -> 0 | D17: =(C17-$G$6)^2 -> 0.10405827 | F17: nivel de significancia (α) | G17: 0.05
A18: 5 | B18: 4 | C18: =B18-A18 -> -1 | D18: =(C18-$G$6)^2 -> 0.45889698 | F18: grados de libertad (DF) | G18: =G4-1 -> 92
A19: 4 | B19: 5 | C19: =B19-A19 -> 1 | D19: =(C19-$G$6)^2 -> 1.7492196
A20: 4 | B20: 1 | C20: =B20-A20 -> -3 | D20: =(C20-$G$6)^2 -> 7.1685744
A21: 4 | B21: 2 | C21: =B21-A21 -> -2 | D21: =(C21-$G$6)^2 -> 2.8137357
A22: 3 | B22: 2 | C22: =B22-A22 -> -1 | D22: =(C22-$G$6)^2 -> 0.45889698 | F22: Valor critico t
A23: 4 | B23: 1 | C23: =B23-A23 -> -3 | D23: =(C23-$G$6)^2 -> 7.1685744 | F23: valor crítico t (Excel) - 2 colas | G23: =_xlfn.T.INV.2T(G17,G18) -> 1.9860863
A24: 3 | B24: 4 | C24: =B24-A24 -> 1 | D24: =(C24-$G$6)^2 -> 1.7492196 | F24: valor crítico t (Excel) - 1 colas | G24: =_xlfn.T.INV(G17,G18) -> -1.6615854
A25: 3 | B25: 4 | C25: =B25-A25 -> 1 | D25: =(C25-$G$6)^2 -> 1.7492196
A26: 5 | B26: 3 | C26: =B26-A26 -> -2 | D26: =(C26-$G$6)^2 -> 2.8137357
A27: 3 | B27: 3 | C27: =B27-A27 -> 0 | D27: =(C27-$G$6)^2 -> 0.10405827 | F27: p valor
A28: 4 | B28: 5 | C28: =B28-A28 -> 1 | D28: =(C28-$G$6)^2 -> 1.7492196 | F28: p valor
A29: 5 | B29: 2 | C29: =B29-A29 -> -3 | D29: =(C29-$G$6)^2 -> 7.1685744 | F29: p valor con (Excel) dos colas | G29: =TTEST(A:A,B:B,2,1) -> 0.054312006
A30: 2 | B30: 4 | C30: =B30-A30 -> 2 | D30: =(C30-$G$6)^2 -> 5.3943809 | F30: p valor con (Excel) una colas | G30: =TTEST(A:A,B:B,1,1) -> 0.027156003
A31: 1 | B31: 4 | C31: =B31-A31 -> 3 | D31: =(C31-$G$6)^2 -> 11.039542
A32: 2 | B32: 3 | C32: =B32-A32 -> 1 | D32: =(C32-$G$6)^2 -> 1.7492196
A33: 4 | B33: 3 | C33: =B33-A33 -> -1 | D33: =(C33-$G$6)^2 -> 0.45889698 | F33: Hipotesis
A34: 5 | B34: 3 | C34: =B34-A34 -> -2 | D34: =(C34-$G$6)^2 -> 2.8137357
A35: 3 | B35: 5 | C35: =B35-A35 -> 2 | D35: =(C35-$G$6)^2 -> 5.3943809 | F35: hipotesis nula Ho = No hay diferencias significativa
A36: 4 | B36: 2 | C36: =B36-A36 -> -2 | D36: =(C36-$G$6)^2 -> 2.8137357 | F36: hipotesis alternativa H1 = Si hay diferencia significativa
A37: 5 | B37: 4 | C37: =B37-A37 -> -1 | D37: =(C37-$G$6)^2 -> 0.45889698
A38: 3 | B38: 5 | C38: =B38-A38 -> 2 | D38: =(C38-$G$6)^2 -> 5.3943809
A39: 5 | B39: 2 | C39: =B39-A39 -> -3 | D39: =(C39-$G$6)^2 -> 7.1685744
A40: 2 | B40: 1 | C40: =B40-A40 -> -1 | D40: =(C40-$G$6)^2 -> 0.45889698 | F40: Si t calculado > t critico (Tabla)
...

Sheet Comprensión-contenidos
A1: (Sin Innovacion Didactica) Pre-test Comprensión-contenidos a) Siempre = 5 b) Muchas veces = 4 c) A veces = 3 d) Pocas veces = 2 e) Nunca = 1 | B1: (Sin Innovacion Didactica) Post-test Comprensión-contenidos a) Siempre = 5 b) Muchas veces = 4 c) A veces = 3 d) Pocas veces = 2 e) Nunca = 1 | C1: Diferencia
A2: 3 | B2: 4 | C2: =B2-A2 -> 1 | D2: =(C2-$G$6)^2 -> 1.0878714
A3: 2 | B3: 3 | C3: =B3-A3 -> 1 | D3: =(C3-$G$6)^2 -> 1.0878714 | F3: Datos
A4: 4 | B4: 1 | C4: =B4-A4 -> -3 | D4: =(C4-$G$6)^2 -> 8.7437854 | F4: numero de datos | G4: =COUNT(A:A) -> 93
A5: 4 | B5: 5 | C5: =B5-A5 -> 1 | D5: =(C5-$G$6)^2 -> 1.0878714 | F5: Sumatoria Diferencias | G5: =SUM(C:C) -> -4
A6: 3 | B6: 1 | C6: =B6-A6 -> -2 | D6: =(C6-$G$6)^2 -> 3.8298069 | F6: Media de las diferencias | G6: =G5/G4 -> -0.043010753
A7: 4 | B7: 3 | C7: =B7-A7 -> -1 | D7: =(C7-$G$6)^2 -> 0.91582842 | F7: Sumatoria de diferencias | G7: =SUM(D:D) -> 257.82796
A8: 5 | B8: 5 | C8: =B8-A8 -> 0 | D8: =(C8-$G$6)^2 -> 0.0018499248 | F8: desviación estándar de las diferencias | G8: =SQRT(G7/(G4-1)) -> 1.6740603
A9: 4 | B9: 4 | C9: =B9-A9 -> 0 | D9: =(C9-$G$6)^2 -> 0.0018499248
A10: 5 | B10: 3 | C10: =B10-A10 -> -2 | D10: =(C10-$G$6)^2 -> 3.8298069
A11: 2 | B11: 5 | C11: =B11-A11 -> 3 | D11: =(C11-$G$6)^2 -> 9.2599144
A12: 2 | B12: 3 | C12: =B12-A12 -> 1 | D12: =(C12-$G$6)^2 -> 1.0878714 | F12: t calculado (estadistico t): | G12: =G6/(G8/SQRT(G4)) -> -0.24776926
A13: 3 | B13: 4 | C13: =B13-A13 -> 1 | D13: =(C13-$G$6)^2 -> 1.0878714
A14: 2 | B14: 3 | C14: =B14-A14 -> 1 | D14: =(C14-$G$6)^2 -> 1.0878714
A15: 2 | B15: 5 | C15: =B15-A15 -> 3 | D15: =(C15-$G$6)^2 -> 9.2599144
A16: 4 | B16: 2 | C16: =B16-A16 -> -2 | D16: =(C16-$G$6)^2 -> 3.8298069
A17: 2 | B17: 1 | C17: =B17-A17 -> -1 | D17: =(C17-$G$6)^2 -> 0.91582842 | F17: nivel de significancia (α) | G17: 0.05
A18: 3 | B18: 1 | C18: =B18-A18 -> -2 | D18: =(C18-$G$6)^2 -> 3.8298069 | F18: grados de libertad (DF) | G18: =G4-1 -> 92
A19: 2 | B19: 3 | C19: =B19-A19 -> 1 | D19: =(C19-$G$6)^2 -> 1.0878714
A20: 2 | B20: 5 | C20: =B20-A20 -> 3 | D20: =(C20-$G$6)^2 -> 9.2599144
A21: 4 | B21: 3 | C21: =B21-A21 -> -1 | D21: =(C21-$G$6)^2 -> 0.91582842
A22: 5 | B22: 5 | C22: =B22-A22 -> 0 | D22: =(C22-$G$6)^2 -> 0.0018499248 | F22: Valor critico t
A23: 4 | B23: 5 | C23: =B23-A23 -> 1 | D23: =(C23-$G$6)^2 -> 1.0878714 | F23: valor crítico t (Excel) - 2 colas | G23: =_xlfn.T.INV.2T(G17,G18) -> 1.9860863
A24: 4 | B24: 4 | C24: =B24-A24 -> 0 | D24: =(C24-$G$6)^2 -> 0.0018499248 | F24: valor crítico t (Excel) - 1 colas | G24: =_xlfn.T.INV(G17,G18) -> -1.6615854
A25: 2 | B25: 3 | C25: =B25-A25 -> 1 | D25: =(C25-$G$6)^2 -> 1.0878714
A26: 2 | B26: 2 | C26: =B26-A26 -> 0 | D26: =(C26-$G$6)^2 -> 0.0018499248
A27: 5 | B27: 3 | C27: =B27-A27 -> -2 | D27: =(C27-$G$6)^2 -> 3.8298069 | F27: p valor
A28: 3 | B28: 3 | C28: =B28-A28 -> 0 | D28: =(C28-$G$6)^2 -> 0.0018499248 | F28: p valor
A29: 4 | B29: 4 | C29: =B29-A29 -> 0 | D29: =(C29-$G$6)^2 -> 0.0018499248 | F29: p valor con (Excel) dos colas | G29: =TTEST(A:A,B:B,2,1) -> 0.80486509
A30: 4 | B30: 1 | C30: =B30-A30 -> -3 | D30: =(C30-$G$6)^2 -> 8.7437854 | F30: p valor con (Excel) una colas | G30: =TTEST(A:A,B:B,1,1) -> 0.40243255
A31: 5 | B31: 4 | C31: =B31-A31 -> -1 | D31: =(C31-$G$6)^2 -> 0.91582842
A32: 4 | B32: 3 | C32: =B32-A32 -> -1 | D32: =(C32-$G$6)^2 -> 0.91582842
A33: 1 | B33: 5 | C33: =B33-A33 -> 4 | D33: =(C33-$G$6)^2 -> 16.345936 | F33: Hipotesis
A34: 4 | B34: 2 | C34: =B34-A34 -> -2 | D34: =(C34-$G$6)^2 -> 3.8298069
A35: 3 | B35: 3 | C35: =B35-A35 -> 0 | D35: =(C35-$G$6)^2 -> 0.0018499248 | F35: hipotesis nula Ho = No hay diferencias significativa
A36: 3 | B36: 4 | C36: =B36-A36 -> 1 | D36: =(C36-$G$6)^2 -> 1.0878714 | F36: hipotesis alternativa H1 = Si hay diferencia significativa
A37: 4 | B37: 5 | C37: =B37-A37 -> 1 | D37: =(C37-$G$6)^2 -> 1.0878714
A38: 1 | B38: 3 | C38: =B38-A38 -> 2 | D38: =(C38-$G$6)^2 -> 4.1738929
A39: 1 | B39: 3 | C39: =B39-A39 -> 2 | D39: =(C39-$G$6)^2 -> 4.1738929
A40: 4 | B40: 4 | C40: =B40-A40 -> 0 | D40: =(C40-$G$6)^2 -> 0.0018499248 | F40: Si t calculado > t critico (Tabla)
...

Sheet Herramientas-tecnológicas
A1: (Sin Innovacion Didactica) Pre-test Herramientas-tecnológicas a) Siempre = 5 b) Frecuente = 4 c) A veces = 3 d) Raro = 2 e) Nunca = 1 | B1: (Sin Innovacion Didactica) Post-test Herramientas-tecnológicas a) Siempre = 5 b) Frecuente = 4 c) A veces = 3 d) Raro = 2 e) Nunca = 1 | C1: Diferencia
A2: 5 | B2: 3 | C2: =B2-A2 -> -2 | D2: =(C2-$G$6)^2 -> 4.5327784
A3: 5 | B3: 3 | C3: =B3-A3 -> -2 | D3: =(C3-$G$6)^2 -> 4.5327784 | F3: Datos
A4: 2 | B4: 3 | C4: =B4-A4 -> 1 | D4: =(C4-$G$6)^2 -> 0.75858481 | F4: numero de datos | G4: =COUNT(A:A) -> 93
A5: 3 | B5: 3 | C5: =B5-A5 -> 0 | D5: =(C5-$G$6)^2 -> 0.016649324 | F5: Sumatoria Diferencias | G5: =SUM(C:C) -> 12
A6: 5 | B6: 5 | C6: =B6-A6 -> 0 | D6: =(C6-$G$6)^2 -> 0.016649324 | F6: Media de las diferencias | G6: =G5/G4 -> 0.12903226
A7: 5 | B7: 4 | C7: =B7-A7 -> -1 | D7: =(C7-$G$6)^2 -> 1.2747138 | F7: Sumatoria de diferencias | G7: =SUM(D:D) -> 242.45161
A8: 3 | B8: 3 | C8: =B8-A8 -> 0 | D8: =(C8-$G$6)^2 -> 0.016649324 | F8: desviación estándar de las diferencias | G8: =SQRT(G7/(G4-1)) -> 1.6233741
A9: 5 | B9: 5 | C9: =B9-A9 -> 0 | D9: =(C9-$G$6)^2 -> 0.016649324
A10: 5 | B10: 4 | C10: =B10-A10 -> -1 | D10: =(C10-$G$6)^2 -> 1.2747138
A11: 3 | B11: 5 | C11: =B11-A11 -> 2 | D11: =(C11-$G$6)^2 -> 3.5005203
A12: 3 | B12: 5 | C12: =B12-A12 -> 2 | D12: =(C12-$G$6)^2 -> 3.5005203 | F12: t calculado (estadistico t): | G12: =G6/(G8/SQRT(G4)) -> 0.76651586
A13: 3 | B13: 4 | C13: =B13-A13 -> 1 | D13: =(C13-$G$6)^2 -> 0.75858481
A14: 4 | B14: 5 | C14: =B14-A14 -> 1 | D14: =(C14-$G$6)^2 -> 0.75858481
A15: 3 | B15: 3 | C15: =B15-A15 -> 0 | D15: =(C15-$G$6)^2 -> 0.016649324
A16: 4 | B16: 3 | C16: =B16-A16 -> -1 | D16: =(C16-$G$6)^2 -> 1.2747138
A17: 4 | B17: 2 | C17: =B17-A17 -> -2 | D17: =(C17-$G$6)^2 -> 4.5327784 | F17: nivel de significancia (α) | G17: 0.05
A18: 3 | B18: 4 | C18: =B18-A18 -> 1 | D18: =(C18-$G$6)^2 -> 0.75858481 | F18: grados de libertad (DF) | G18: =G4-1 -> 92
A19: 3 | B19: 5 | C19: =B19-A19 -> 2 | D19: =(C19-$G$6)^2 -> 3.5005203
A20: 2 | B20: 5 | C20: =B20-A20 -> 3 | D20: =(C20-$G$6)^2 -> 8.2424558
A21: 3 | B21: 3 | C21: =B21-A21 -> 0 | D21: =(C21-$G$6)^2 -> 0.016649324
A22: 3 | B22: 3 | C22: =B22-A22 -> 0 | D22: =(C22-$G$6)^2 -> 0.016649324 | F22: Valor critico t
A23: 5 | B23: 5 | C23: =B23-A23 -> 0 | D23: =(C23-$G$6)^2 -> 0.016649324 | F23: valor crítico t (Excel) - 2 colas | G23: =_xlfn.T.INV.2T(G17,G18) -> 1.9860863
A24: 4 | B24: 2 | C24: =B24-A24 -> -2 | D24: =(C24-$G$6)^2 -> 4.5327784 | F24: valor crítico t (Excel) - 1 colas | G24: =_xlfn.T.INV(G17,G18) -> -1.6615854
A25: 4 | B25: 5 | C25: =B25-A25 -> 1 | D25: =(C25-$G$6)^2 -> 0.75858481
A26: 4 | B26: 3 | C26: =B26-A26 -> -1 | D26: =(C26-$G$6)^2 -> 1.2747138
A27: 1 | B27: 3 | C27: =B27-A27 -> 2 | D27: =(C27-$G$6)^2 -> 3.5005203 | F27: p valor
A28: 4 | B28: 2 | C28: =B28-A28 -> -2 | D28: =(C28-$G$6)^2 -> 4.5327784 | F28: p valor
A29: 2 | B29: 3 | C29: =B29-A29 -> 1 | D29: =(C29-$G$6)^2 -> 0.75858481 | F29: p valor con (Excel) dos colas | G29: =TTEST(A:A,B:B,2,1) -> 0.44533183
A30: 3 | B30: 2 | C30: =B30-A30 -> -1 | D30: =(C30-$G$6)^2 -> 1.2747138 | F30: p valor con (Excel) una colas | G30: =TTEST(A:A,B:B,1,1) -> 0.22266592
A31: 2 | B31: 4 | C31: =B31-A31 -> 2 | D31: =(C31-$G$6)^2 -> 3.5005203
A32: 3 | B32: 2 | C32: =B32-A32 -> -1 | D32: =(C32-$G$6)^2 -> 1.2747138
A33: 3 | B33: 5 | C33: =B33-A33 -> 2 | D33: =(C33-$G$6)^2 -> 3.5005203 | F33: Hipotesis
A34: 3 | B34: 2 | C34: =B34-A34 -> -1 | D34: =(C34-$G$6)^2 -> 1.2747138
A35: 4 | B35: 3 | C35: =B35-A35 -> -1 | D35: =(C35-$G$6)^2 -> 1.2747138 | F35: hipotesis nula Ho = No hay diferencias significativa
A36: 3 | B36: 2 | C36: =B36-A36 -> -1 | D36: =(C36-$G$6)^2 -> 1.2747138 | F36: hipotesis alternativa H1 = Si hay diferencia significativa
A37: 4 | B37: 3 | C37: =B37-A37 -> -1 | D37: =(C37-$G$6)^2 -> 1.2747138
A38: 5 | B38: 3 | C38: =B38-A38 -> -2 | D38: =(C38-$G$6)^2 -> 4.5327784
A39: 3 | B39: 3 | C39: =B39-A39 -> 0 | D39: =(C39-$G$6)^2 -> 0.016649324
A40: 5 | B40: 3 | C40: =B40-A40 -> -2 | D40: =(C40-$G$6)^2 -> 4.5327784 | F40: Si t calculado > t critico (Tabla)
...

Sheet Recursos-tecnológicos
A1: (Sin Innovacion Didactica) Pre-test Recursos-tecnológicos a) Siempre = 5 b) Muchas veces = 4 c) A veces = 3 d) Pocas veces = 2 e) Nunca = 1 | B1: (Sin Innovacion Didactica) Post-test Recursos-tecnológicos a) Siempre = 5 b) Muchas veces = 4 c) A veces = 3 d) Pocas veces = 2 e) Nunca = 1 | C1: Diferencia
A2: 5 | B2: 3 | C2: =B2-A2 -> -2 | D2: =(C2-$G$6)^2 -> 3.5814545
A3: 5 | B3: 4 | C3: =B3-A3 -> -1 | D3: =(C3-$G$6)^2 -> 0.79650827 | F3: Datos
A4: 3 | B4: 3 | C4: =B4-A4 -> 0 | D4: =(C4-$G$6)^2 -> 0.01156203 | F4: numero de datos | G4: =COUNT(A:A) -> 93
A5: 3 | B5: 5 | C5: =B5-A5 -> 2 | D5: =(C5-$G$6)^2 -> 4.4416696 | F5: Sumatoria Diferencias | G5: =SUM(C:C) -> -10
A6: 3 | B6: 4 | C6: =B6-A6 -> 1 | D6: =(C6-$G$6)^2 -> 1.2266158 | F6: Media de las diferencias | G6: =G5/G4 -> -0.10752688
A7: 3 | B7: 1 | C7: =B7-A7 -> -2 | D7: =(C7-$G$6)^2 -> 3.5814545 | F7: Sumatoria de diferencias | G7: =SUM(D:D) -> 274.92473
A8: 1 | B8: 4 | C8: =B8-A8 -> 3 | D8: =(C8-$G$6)^2 -> 9.6567233 | F8: desviación estándar de las diferencias | G8: =SQRT(G7/(G4-1)) -> 1.7286736
A9: 3 | B9: 3 | C9: =B9-A9 -> 0 | D9: =(C9-$G$6)^2 -> 0.01156203
A10: 4 | B10: 4 | C10: =B10-A10 -> 0 | D10: =(C10-$G$6)^2 -> 0.01156203
A11: 2 | B11: 2 | C11: =B11-A11 -> 0 | D11: =(C11-$G$6)^2 -> 0.01156203
A12: 4 | B12: 5 | C12: =B12-A12 -> 1 | D12: =(C12-$G$6)^2 -> 1.2266158 | F12: t calculado (estadistico t): | G12: =G6/(G8/SQRT(G4)) -> -0.59985397
A13: 4 | B13: 1 | C13: =B13-A13 -> -3 | D13: =(C13-$G$6)^2 -> 8.3664007
A14: 5 | B14: 4 | C14: =B14-A14 -> -1 | D14: =(C14-$G$6)^2 -> 0.79650827
A15: 5 | B15: 4 | C15: =B15-A15 -> -1 | D15: =(C15-$G$6)^2 -> 0.79650827
A16: 1 | B16: 5 | C16: =B16-A16 -> 4 | D16: =(C16-$G$6)^2 -> 16.871777
A17: 2 | B17: 5 | C17: =B17-A17 -> 3 | D17: =(C17-$G$6)^2 -> 9.6567233 | F17: nivel de significancia (α) | G17: 0.05
A18: 3 | B18: 3 | C18: =B18-A18 -> 0 | D18: =(C18-$G$6)^2 -> 0.01156203 | F18: grados de libertad (DF) | G18: =G4-1 -> 92
A19: 4 | B19: 4 | C19: =B19-A19 -> 0 | D19: =(C19-$G$6)^2 -> 0.01156203
A20: 4 | B20: 2 | C20: =B20-A20 -> -2 | D20: =(C20-$G$6)^2 -> 3.5814545
A21: 5 | B21: 4 | C21: =B21-A21 -> -1 | D21: =(C21-$G$6)^2 -> 0.79650827
A22: 4 | B22: 4 | C22: =B22-A22 -> 0 | D22: =(C22-$G$6)^2 -> 0.01156203 | F22: Valor critico t
A23: 3 | B23: 3 | C23: =B23-A23 -> 0 | D23: =(C23-$G$6)^2 -> 0.01156203 | F23: valor crítico t (Excel) - 2 colas | G23: =_xlfn.T.INV.2T(G17,G18) -> 1.9860863
A24: 3 | B24: 3 | C24: =B24-A24 -> 0 | D24: =(C24-$G$6)^2 -> 0.01156203 | F24: valor crítico t (Excel) - 1 colas | G24: =_xlfn.T.INV(G17,G18) -> -1.6615854
A25: 3 | B25: 5 | C25: =B25-A25 -> 2 | D25: =(C25-$G$6)^2 -> 4.4416696
A26: 4 | B26: 5 | C26: =B26-A26 -> 1 | D26: =(C26-$G$6)^2 -> 1.2266158
A27: 1 | B27: 5 | C27: =B27-A27 -> 4 | D27: =(C27-$G$6)^2 -> 16.871777 | F27: p valor
A28: 3 | B28: 3 | C28: =B28-A28 -> 0 | D28: =(C28-$G$6)^2 -> 0.01156203 | F28: p valor
A29: 3 | B29: 3 | C29: =B29-A29 -> 0 | D29: =(C29-$G$6)^2 -> 0.01156203 | F29: p valor con (Excel) dos colas | G29: =TTEST(A:A,B:B,2,1) -> 0.55007816
A30: 3 | B30: 3 | C30: =B30-A30 -> 0 | D30: =(C30-$G$6)^2 -> 0.01156203 | F30: p valor con (Excel) una colas | G30: =TTEST(A:A,B:B,1,1) -> 0.27503908
A31: 4 | B31: 2 | C31: =B31-A31 -> -2 | D31: =(C31-$G$6)^2 -> 3.5814545
A32: 4 | B32: 2 | C32: =B32-A32 -> -2 | D32: =(C32-$G$6)^2 -> 3.5814545
A33: 4 | B33: 3 | C33: =B33-A33 -> -1 | D33: =(C33-$G$6)^2 -> 0.79650827 | F33: Hipotesis
A34: 3 | B34: 2 | C34: =B34-A34 -> -1 | D34: =(C34-$G$6)^2 -> 0.79650827
A35: 5 | B35: 4 | C35: =B35-A35 -> -1 | D35: =(C35-$G$6)^2 -> 0.79650827 | F35: hipotesis nula Ho = No hay diferencias significativa
A36: 5 | B36: 5 | C36: =B36-A36 -> 0 | D36: =(C36-$G$6)^2 -> 0.01156203 | F36: hipotesis alternativa H1 = Si hay diferencia significativa
A37: 5 | B37: 4 | C37: =B37-A37 -> -1 | D37: =(C37-$G$6)^2 -> 0.79650827
A38: 5 | B38: 5 | C38: =B38-A38 -> 0 | D38: =(C38-$G$6)^2 -> 0.01156203
A39: 2 | B39: 3 | C39: =B39-A39 -> 1 | D39: =(C39-$G$6)^2 -> 1.2266158
A40: 3 | B40: 1 | C40: =B40-A40 -> -2 | D40: =(C40-$G$6)^2 -> 3.5814545 | F40: Si t calculado > t critico (Tabla)
...

Sheet Percepción-evaluaciones
A1: (Sin Innovacion Didactica) Pre-test Percepción-evaluaciones a) Siempre = 5 b) Frecuente = 4 c) A veces = 3 d) Raro = 2 e) Nunca = 1 | B1: (Sin Innovacion Didactica) Post-test Percepción-evaluaciones a) Siempre = 5 b) Frecuente = 4 c) A veces = 3 d) Raro = 2 e) Nunca = 1 | C1: Diferencia
A2: 4 | B2: 3 | C2: =B2-A2 -> -1 | D2: =(C2-$G$6)^2 -> 1.4763556
A3: 2 | B3: 2 | C3: =B3-A3 -> 0 | D3: =(C3-$G$6)^2 -> 0.046248121 | F3: Datos
A4: 2 | B4: 3 | C4: =B4-A4 -> 1 | D4: =(C4-$G$6)^2 -> 0.61614059 | F4: numero de datos | G4: =COUNT(A:A) -> 93
A5: 5 | B5: 3 | C5: =B5-A5 -> -2 | D5: =(C5-$G$6)^2 -> 4.9064632 | F5: Sumatoria Diferencias | G5: =SUM(C:C) -> 20
A6: 2 | B6: 4 | C6: =B6-A6 -> 2 | D6: =(C6-$G$6)^2 -> 3.1860331 | F6: Media de las diferencias | G6: =G5/G4 -> 0.21505376
A7: 3 | B7: 2 | C7: =B7-A7 -> -1 | D7: =(C7-$G$6)^2 -> 1.4763556 | F7: Sumatoria de diferencias | G7: =SUM(D:D) -> 271.69892
A8: 2 | B8: 5 | C8: =B8-A8 -> 3 | D8: =(C8-$G$6)^2 -> 7.7559255 | F8: desviación estándar de las diferencias | G8: =SQRT(G7/(G4-1)) -> 1.718502
A9: 4 | B9: 3 | C9: =B9-A9 -> -1 | D9: =(C9-$G$6)^2 -> 1.4763556
A10: 2 | B10: 5 | C10: =B10-A10 -> 3 | D10: =(C10-$G$6)^2 -> 7.7559255
A11: 4 | B11: 4 | C11: =B11-A11 -> 0 | D11: =(C11-$G$6)^2 -> 0.046248121
A12: 5 | B12: 4 | C12: =B12-A12 -> -1 | D12: =(C12-$G$6)^2 -> 1.4763556 | F12: t calculado (estadistico t): | G12: =G6/(G8/SQRT(G4)) -> 1.2068088
A13: 2 | B13: 4 | C13: =B13-A13 -> 2 | D13: =(C13-$G$6)^2 -> 3.1860331
A14: 5 | B14: 3 | C14: =B14-A14 -> -2 | D14: =(C14-$G$6)^2 -> 4.9064632
A15: 4 | B15: 4 | C15: =B15-A15 -> 0 | D15: =(C15-$G$6)^2 -> 0.046248121
A16: 1 | B16: 4 | C16: =B16-A16 -> 3 | D16: =(C16-$G$6)^2 -> 7.7559255
A17: 1 | B17: 4 | C17: =B17-A17 -> 3 | D17: =(C17-$G$6)^2 -> 7.7559255 | F17: nivel de significancia (α) | G17: 0.05
A18: 3 | B18: 4 | C18: =B18-A18 -> 1 | D18: =(C18-$G$6)^2 -> 0.61614059 | F18: grados de libertad (DF) | G18: =G4-1 -> 92
A19: 3 | B19: 4 | C19: =B19-A19 -> 1 | D19: =(C19-$G$6)^2 -> 0.61614059
A20: 3 | B20: 5 | C20: =B20-A20 -> 2 | D20: =(C20-$G$6)^2 -> 3.1860331
A21: 4 | B21: 3 | C21: =B21-A21 -> -1 | D21: =(C21-$G$6)^2 -> 1.4763556
A22: 4 | B22: 3 | C22: =B22-A22 -> -1 | D22: =(C22-$G$6)^2 -> 1.4763556 | F22: Valor critico t
A23: 3 | B23: 3 | C23: =B23-A23 -> 0 | D23: =(C23-$G$6)^2 -> 0.046248121 | F23: valor crítico t (Excel) - 2 colas | G23: =_xlfn.T.INV.2T(G17,G18) -> 1.9860863
A24: 2 | B24: 4 | C24: =B24-A24 -> 2 | D24: =(C24-$G$6)^2 -> 3.1860331 | F24: valor crítico t (Excel) - 1 colas | G24: =_xlfn.T.INV(G17,G18) -> -1.6615854
A25: 2 | B25: 4 | C25: =B25-A25 -> 2 | D25: =(C25-$G$6)^2 -> 3.1860331
A26: 2 | B26: 2 | C26: =B26-A26 -> 0 | D26: =(C26-$G$6)^2 -> 0.046248121
A27: 5 | B27: 3 | C27: =B27-A27 -> -2 | D27: =(C27-$G$6)^2 -> 4.9064632 | F27: p valor
A28: 3 | B28: 3 | C28: =B28-A28 -> 0 | D28: =(C28-$G$6)^2 -> 0.046248121 | F28: p valor
A29: 5 | B29: 5 | C29: =B29-A29 -> 0 | D29: =(C29-$G$6)^2 -> 0.046248121 | F29: p valor con (Excel) dos colas | G29: =TTEST(A:A,B:B,2,1) -> 0.23059966
A30: 3 | B30: 4 | C30: =B30-A30 -> 1 | D30: =(C30-$G$6)^2 -> 0.61614059 | F30: p valor con (Excel) una colas | G30: =TTEST(A:A,B:B,1,1) -> 0.11529983
A31: 4 | B31: 4 | C31: =B31-A31 -> 0 | D31: =(C31-$G$6)^2 -> 0.046248121
A32: 2 | B32: 4 | C32: =B32-A32 -> 2 | D32: =(C32-$G$6)^2 -> 3.1860331
A33: 4 | B33: 3 | C33: =B33-A33 -> -1 | D33: =(C33-$G$6)^2 -> 1.4763556 | F33: Hipotesis
A34: 5 | B34: 3 | C34: =B34-A34 -> -2 | D34: =(C34-$G$6)^2 -> 4.9064632
A35: 5 | B35: 3 | C35: =B35-A35 -> -2 | D35: =(C35-$G$6)^2 -> 4.9064632 | F35: hipotesis nula Ho = No hay diferencias significativa
A36: 2 | B36: 3 | C36: =B36-A36 -> 1 | D36: =(C36-$G$6)^2 -> 0.61614059 | F36: hipotesis alternativa H1 = Si hay diferencia significativa
A37: 3 | B37: 2 | C37: =B37-A37 -> -1 | D37: =(C37-$G$6)^2 -> 1.4763556
A38: 5 | B38: 3 | C38: =B38-A38 -> -2 | D38: =(C38-$G$6)^2 -> 4.9064632
A39: 5 | B39: 1 | C39: =B39-A39 -> -4 | D39: =(C39-$G$6)^2 -> 17.766678
A40: 3 | B40: 5 | C40: =B40-A40 -> 2 | D40: =(C40-$G$6)^2 -> 3.1860331 | F40: Si t calculado > t critico (Tabla)
...

Sheet Retroalimentación-oportuna
A1: (Sin Innovacion Didactica) Pre-test Retroalimentación-oportuna a) Siempre = 5 b) Muchas veces = 4 c) A veces = 3 d) Pocas veces = 2 e) Nunca = 1 | B1: (Sin Innovacion Didactica) Post-test Retroalimentación-oportuna a) Siempre = 5 b) Muchas veces = 4 c) A veces = 3 d) Pocas veces = 2 e) Nunca = 1 | C1: Diferencia
A2: 4 | B2: 2 | C2: =B2-A2 -> -2 | D2: =(C2-$G$6)^2 -> 4.7177708
A3: 3 | B3: 4 | C3: =B3-A3 -> 1 | D3: =(C3-$G$6)^2 -> 0.68551278 | F3: Datos
A4: 5 | B4: 5 | C4: =B4-A4 -> 0 | D4: =(C4-$G$6)^2 -> 0.029598798 | F4: numero de datos | G4: =COUNT(A:A) -> 93
A5: 1 | B5: 5 | C5: =B5-A5 -> 4 | D5: =(C5-$G$6)^2 -> 14.653255 | F5: Sumatoria Diferencias | G5: =SUM(C:C) -> 16
A6: 1 | B6: 3 | C6: =B6-A6 -> 2 | D6: =(C6-$G$6)^2 -> 3.3414268 | F6: Media de las diferencias | G6: =G5/G4 -> 0.17204301
A7: 3 | B7: 3 | C7: =B7-A7 -> 0 | D7: =(C7-$G$6)^2 -> 0.029598798 | F7: Sumatoria de diferencias | G7: =SUM(D:D) -> 279.24731
A8: 3 | B8: 3 | C8: =B8-A8 -> 0 | D8: =(C8-$G$6)^2 -> 0.029598798 | F8: desviación estándar de las diferencias | G8: =SQRT(G7/(G4-1)) -> 1.7422103
A9: 4 | B9: 4 | C9: =B9-A9 -> 0 | D9: =(C9-$G$6)^2 -> 0.029598798
A10: 2 | B10: 4 | C10: =B10-A10 -> 2 | D10: =(C10-$G$6)^2 -> 3.3414268
A11: 3 | B11: 3 | C11: =B11-A11 -> 0 | D11: =(C11-$G$6)^2 -> 0.029598798
A12: 5 | B12: 3 | C12: =B12-A12 -> -2 | D12: =(C12-$G$6)^2 -> 4.7177708 | F12: t calculado (estadistico t): | G12: =G6/(G8/SQRT(G4)) -> 0.95230907
A13: 2 | B13: 1 | C13: =B13-A13 -> -1 | D13: =(C13-$G$6)^2 -> 1.3736848
A14: 2 | B14: 5 | C14: =B14-A14 -> 3 | D14: =(C14-$G$6)^2 -> 7.9973407
A15: 1 | B15: 3 | C15: =B15-A15 -> 2 | D15: =(C15-$G$6)^2 -> 3.3414268
A16: 3 | B16: 4 | C16: =B16-A16 -> 1 | D16: =(C16-$G$6)^2 -> 0.68551278
A17: 3 | B17: 4 | C17: =B17-A17 -> 1 | D17: =(C17-$G$6)^2 -> 0.68551278 | F17: nivel de significancia (α) | G17: 0.05
A18: 4 | B18: 3 | C18: =B18-A18 -> -1 | D18: =(C18-$G$6)^2 -> 1.3736848 | F18: grados de libertad (DF) | G18: =G4-1 -> 92
A19: 1 | B19: 3 | C19: =B19-A19 -> 2 | D19: =(C19-$G$6)^2 -> 3.3414268
A20: 2 | B20: 1 | C20: =B20-A20 -> -1 | D20: =(C20-$G$6)^2 -> 1.3736848
A21: 5 | B21: 5 | C21: =B21-A21 -> 0 | D21: =(C21-$G$6)^2 -> 0.029598798
A22: 5 | B22: 5 | C22: =B22-A22 -> 0 | D22: =(C22-$G$6)^2 -> 0.029598798 | F22: Valor critico t
A23: 4 | B23: 3 | C23: =B23-A23 -> -1 | D23: =(C23-$G$6)^2 -> 1.3736848 | F23: valor crítico t (Excel) - 2 colas | G23: =_xlfn.T.INV.2T(G17,G18) -> 1.9860863
A24: 2 | B24: 3 | C24: =B24-A24 -> 1 | D24: =(C24-$G$6)^2 -> 0.68551278 | F24: valor crítico t (Excel) - 1 colas | G24: =_xlfn.T.INV(G17,G18) -> -1.6615854
A25: 1 | B25: 4 | C25: =B25-A25 -> 3 | D25: =(C25-$G$6)^2 -> 7.9973407
A26: 5 | B26: 5 | C26: =B26-A26 -> 0 | D26: =(C26-$G$6)^2 -> 0.029598798
A27: 3 | B27: 5 | C27: =B27-A27 -> 2 | D27: =(C27-$G$6)^2 -> 3.3414268 | F27: p valor
A28: 4 | B28: 2 | C28: =B28-A28 -> -2 | D28: =(C28-$G$6)^2 -> 4.7177708 | F28: p valor
A29: 1 | B29: 4 | C29: =B29-A29 -> 3 | D29: =(C29-$G$6)^2 -> 7.9973407 | F29: p valor con (Excel) dos colas | G29: =TTEST(A:A,B:B,2,1) -> 0.34343556
A30: 2 | B30: 4 | C30: =B30-A30 -> 2 | D30: =(C30-$G$6)^2 -> 3.3414268 | F30: p valor con (Excel) una colas | G30: =TTEST(A:A,B:B,1,1) -> 0.17171778
A31: 2 | B31: 4 | C31: =B31-A31 -> 2 | D31: =(C31-$G$6)^2 -> 3.3414268
A32: 4 | B32: 4 | C32: =B32-A32 -> 0 | D32: =(C32-$G$6)^2 -> 0.029598798
A33: 4 | B33: 5 | C33: =B33-A33 -> 1 | D33: =(C33-$G$6)^2 -> 0.68551278 | F33: Hipotesis
A34: 4 | B34: 3 | C34: =B34-A34 -> -1 | D34: =(C34-$G$6)^2 -> 1.3736848
A35: 5 | B35: 5 | C35: =B35-A35 -> 0 | D35: =(C35-$G$6)^2 -> 0.029598798 | F35: hipotesis nula Ho = No hay diferencias significativa
A36: 2 | B36: 2 | C36: =B36-A36 -> 0 | D36: =(C36-$G$6)^2 -> 0.029598798 | F36: hipotesis alternativa H1 = Si hay diferencia significativa
A37: 2 | B37: 4 | C37: =B37-A37 -> 2 | D37: =(C37-$G$6)^2 -> 3.3414268
A38: 1 | B38: 3 | C38: =B38-A38 -> 2 | D38: =(C38-$G$6)^2 -> 3.3414268
A39: 1 | B39: 2 | C39: =B39-A39 -> 1 | D39: =(C39-$G$6)^2 -> 0.68551278
A40: 3 | B40: 3 | C40: =B40-A40 -> 0 | D40: =(C40-$G$6)^2 -> 0.029598798 | F40: Si t calculado > t critico (Tabla)
...

Sheet Calificación
A1: (Sin Innovacion Didactica) Pre-test Calificación a) 81 - 100 = 5 b) 61 - 80 = 4 c) 41 - 60 = 3 d) 21 - 40 = 2 e) 0 - 20 = 1 | B1: (Sin Innovacion Didactica) Post-test Calificación a) 81 - 100 = 5 b) 61 - 80 = 4 c) 41 - 60 = 3 d) 21 - 40 = 2 e) 0 - 20 = 1 | C1: Diferencia
A2: 4 | B2: 2 | C2: =B2-A2 -> -2 | D2: =(C2-$G$6)^2 -> 3.5005203
A3: 2 | B3: 2 | C3: =B3-A3 -> 0 | D3: =(C3-$G$6)^2 -> 0.016649324 | F3: Datos
A4: 3 | B4: 2 | C4: =B4-A4 -> -1 | D4: =(C4-$G$6)^2 -> 0.75858481 | F4: numero de datos | G4: =COUNT(A:A) -> 93
A5: 3 | B5: 2 | C5: =B5-A5 -> -1 | D5: =(C5-$G$6)^2 -> 0.75858481 | F5: Sumatoria Diferencias | G5: =SUM(C:C) -> -12
A6: 4 | B6: 4 | C6: =B6-A6 -> 0 | D6: =(C6-$G$6)^2 -> 0.016649324 | F6: Media de las diferencias | G6: =G5/G4 -> -0.12903226
A7: 4 | B7: 5 | C7: =B7-A7 -> 1 | D7: =(C7-$G$6)^2 -> 1.2747138 | F7: Sumatoria de diferencias | G7: =SUM(D:D) -> 284.45161
A8: 5 | B8: 4 | C8: =B8-A8 -> -1 | D8: =(C8-$G$6)^2 -> 0.75858481 | F8: desviación estándar de las diferencias | G8: =SQRT(G7/(G4-1)) -> 1.7583701
A9: 5 | B9: 4 | C9: =B9-A9 -> -1 | D9: =(C9-$G$6)^2 -> 0.75858481
A10: 4 | B10: 3 | C10: =B10-A10 -> -1 | D10: =(C10-$G$6)^2 -> 0.75858481
A11: 4 | B11: 4 | C11: =B11-A11 -> 0 | D11: =(C11-$G$6)^2 -> 0.016649324
A12: 5 | B12: 1 | C12: =B12-A12 -> -4 | D12: =(C12-$G$6)^2 -> 14.984391 | F12: t calculado (estadistico t): | G12: =G6/(G8/SQRT(G4)) -> -0.70766788
A13: 5 | B13: 3 | C13: =B13-A13 -> -2 | D13: =(C13-$G$6)^2 -> 3.5005203
A14: 3 | B14: 2 | C14: =B14-A14 -> -1 | D14: =(C14-$G$6)^2 -> 0.75858481
A15: 4 | B15: 5 | C15: =B15-A15 -> 1 | D15: =(C15-$G$6)^2 -> 1.2747138
A16: 4 | B16: 2 | C16: =B16-A16 -> -2 | D16: =(C16-$G$6)^2 -> 3.5005203
A17: 3 | B17: 2 | C17: =B17-A17 -> -1 | D17: =(C17-$G$6)^2 -> 0.75858481 | F17: nivel de significancia (α) | G17: 0.05
A18: 3 | B18: 3 | C18: =B18-A18 -> 0 | D18: =(C18-$G$6)^2 -> 0.016649324 | F18: grados de libertad (DF) | G18: =G4-1 -> 92
A19: 5 | B19: 3 | C19: =B19-A19 -> -2 | D19: =(C19-$G$6)^2 -> 3.5005203
A20: 2 | B20: 3 | C20: =B20-A20 -> 1 | D20: =(C20-$G$6)^2 -> 1.2747138
A21: 3 | B21: 4 | C21: =B21-A21 -> 1 | D21: =(C21-$G$6)^2 -> 1.2747138
A22: 5 | B22: 3 | C22: =B22-A22 -> -2 | D22: =(C22-$G$6)^2 -> 3.5005203 | F22: Valor critico t
A23: 2 | B23: 4 | C23: =B23-A23 -> 2 | D23: =(C23-$G$6)^2 -> 4.5327784 | F23: valor crítico t (Excel) - 2 colas | G23: =_xlfn.T.INV.2T(G17,G18) -> 1.9860863
A24: 2 | B24: 5 | C24: =B24-A24 -> 3 | D24: =(C24-$G$6)^2 -> 9.7908429 | F24: valor crítico t (Excel) - 1 colas | G24: =_xlfn.T.INV(G17,G18) -> -1.6615854
A25: 5 | B25: 4 | C25: =B25-A25 -> -1 | D25: =(C25-$G$6)^2 -> 0.75858481
A26: 4 | B26: 5 | C26: =B26-A26 -> 1 | D26: =(C26-$G$6)^2 -> 1.2747138
A27: 2 | B27: 5 | C27: =B27-A27 -> 3 | D27: =(C27-$G$6)^2 -> 9.7908429 | F27: p valor
A28: 3 | B28: 5 | C28: =B28-A28 -> 2 | D28: =(C28-$G$6)^2 -> 4.5327784 | F28: p valor
A29: 4 | B29: 1 | C29: =B29-A29 -> -3 | D29: =(C29-$G$6)^2 -> 8.2424558 | F29: p valor con (Excel) dos colas | G29: =TTEST(A:A,B:B,2,1) -> 0.48094044
A30: 4 | B30: 3 | C30: =B30-A30 -> -1 | D30: =(C30-$G$6)^2 -> 0.75858481 | F30: p valor con (Excel) una colas | G30: =TTEST(A:A,B:B,1,1) -> 0.24047022
A31: 4 | B31: 1 | C31: =B31-A31 -> -3 | D31: =(C31-$G$6)^2 -> 8.2424558
A32: 3 | B32: 4 | C32: =B32-A32 -> 1 | D32: =(C32-$G$6)^2 -> 1.2747138
A33: 3 | B33: 4 | C33: =B33-A33 -> 1 | D33: =(C33-$G$6)^2 -> 1.2747138 | F33: Hipotesis
A34: 4 | B34: 3 | C34: =B34-A34 -> -1 | D34: =(C34-$G$6)^2 -> 0.75858481
A35: 3 | B35: 4 | C35: =B35-A35 -> 1 | D35: =(C35-$G$6)^2 -> 1.2747138 | F35: hipotesis nula Ho = No hay diferencias significativa
A36: 3 | B36: 5 | C36: =B36-A36 -> 2 | D36: =(C36-$G$6)^2 -> 4.5327784 | F36: hipotesis alternativa H1 = Si hay diferencia significativa
A37: 5 | B37: 3 | C37: =B37-A37 -> -2 | D37: =(C37-$G$6)^2 -> 3.5005203
A38: 4 | B38: 4 | C38: =B38-A38 -> 0 | D38: =(C38-$G$6)^2 -> 0.016649324
A39: 3 | B39: 3 | C39: =B39-A39 -> 0 | D39: =(C39-$G$6)^2 -> 0.016649324
A40: 2 | B40: 3 | C40: =B40-A40 -> 1 | D40: =(C40-$G$6)^2 -> 1.2747138 | F40: Si t calculado > t critico (Tabla)
...

Sheet Nivel-comprensión
A1: (Sin Innovacion Didactica) Pre-test Nivel-comprensión a) Muy Bueno = 5 b) bueno = 4 c) Regular = 3 d) Malo = 2 e) Muy malo = 1 | B1: (Sin Innovacion Didactica) Pre-test Nivel-comprensión a) Muy Bueno = 5 b) bueno = 4 c) Regular = 3 d) Malo = 2 e) Muy malo = 1 | C1: Diferencia
A2: 4 | B2: 4 | C2: =B2-A2 -> 0 | D2: =(C2-$G$6)^2 -> 0.022661579
A3: 3 | B3: 3 | C3: =B3-A3 -> 0 | D3: =(C3-$G$6)^2 -> 0.022661579 | F3: Datos
A4: 4 | B4: 2 | C4: =B4-A4 -> -2 | D4: =(C4-$G$6)^2 -> 3.420511 | F4: numero de datos | G4: =COUNT(A:A) -> 93
A5: 5 | B5: 2 | C5: =B5-A5 -> -3 | D5: =(C5-$G$6)^2 -> 8.1194358 | F5: Sumatoria Diferencias | G5: =SUM(C:C) -> -14
A6: 3 | B6: 1 | C6: =B6-A6 -> -2 | D6: =(C6-$G$6)^2 -> 3.420511 | F6: Media de las diferencias | G6: =G5/G4 -> -0.15053763
A7: 4 | B7: 2 | C7: =B7-A7 -> -2 | D7: =(C7-$G$6)^2 -> 3.420511 | F7: Sumatoria de diferencias | G7: =SUM(D:D) -> 269.89247
A8: 3 | B8: 4 | C8: =B8-A8 -> 1 | D8: =(C8-$G$6)^2 -> 1.3237368 | F8: desviación estándar de las diferencias | G8: =SQRT(G7/(G4-1)) -> 1.7127796
A9: 5 | B9: 3 | C9: =B9-A9 -> -2 | D9: =(C9-$G$6)^2 -> 3.420511
A10: 3 | B10: 4 | C10: =B10-A10 -> 1 | D10: =(C10-$G$6)^2 -> 1.3237368
A11: 3 | B11: 4 | C11: =B11-A11 -> 1 | D11: =(C11-$G$6)^2 -> 1.3237368
A12: 5 | B12: 2 | C12: =B12-A12 -> -3 | D12: =(C12-$G$6)^2 -> 8.1194358 | F12: t calculado (estadistico t): | G12: =G6/(G8/SQRT(G4)) -> -0.84758856
A13: 4 | B13: 5 | C13: =B13-A13 -> 1 | D13: =(C13-$G$6)^2 -> 1.3237368
A14: 5 | B14: 2 | C14: =B14-A14 -> -3 | D14: =(C14-$G$6)^2 -> 8.1194358
A15: 5 | B15: 3 | C15: =B15-A15 -> -2 | D15: =(C15-$G$6)^2 -> 3.420511
A16: 1 | B16: 3 | C16: =B16-A16 -> 2 | D16: =(C16-$G$6)^2 -> 4.6248121
A17: 4 | B17: 3 | C17: =B17-A17 -> -1 | D17: =(C17-$G$6)^2 -> 0.72158631 | F17: nivel de significancia (α) | G17: 0.05
A18: 2 | B18: 2 | C18: =B18-A18 -> 0 | D18: =(C18-$G$6)^2 -> 0.022661579 | F18: grados de libertad (DF) | G18: =G4-1 -> 92
A19: 4 | B19: 3 | C19: =B19-A19 -> -1 | D19: =(C19-$G$6)^2 -> 0.72158631
A20: 3 | B20: 3 | C20: =B20-A20 -> 0 | D20: =(C20-$G$6)^2 -> 0.022661579
A21: 3 | B21: 5 | C21: =B21-A21 -> 2 | D21: =(C21-$G$6)^2 -> 4.6248121
A22: 3 | B22: 3 | C22: =B22-A22 -> 0 | D22: =(C22-$G$6)^2 -> 0.022661579 | F22: Valor critico t
A23: 3 | B23: 5 | C23: =B23-A23 -> 2 | D23: =(C23-$G$6)^2 -> 4.6248121 | F23: valor crítico t (Excel) - 2 colas | G23: =_xlfn.T.INV.2T(G17,G18) -> 1.9860863
A24: 4 | B24: 3 | C24: =B24-A24 -> -1 | D24: =(C24-$G$6)^2 -> 0.72158631 | F24: valor crítico t (Excel) - 1 colas | G24: =_xlfn.T.INV(G17,G18) -> -1.6615854
A25: 4 | B25: 3 | C25: =B25-A25 -> -1 | D25: =(C25-$G$6)^2 -> 0.72158631
A26: 2 | B26: 3 | C26: =B26-A26 -> 1 | D26: =(C26-$G$6)^2 -> 1.3237368
A27: 2 | B27: 5 | C27: =B27-A27 -> 3 | D27: =(C27-$G$6)^2 -> 9.9258874 | F27: p valor
A28: 1 | B28: 5 | C28: =B28-A28 -> 4 | D28: =(C28-$G$6)^2 -> 17.226963 | F28: p valor
A29: 5 | B29: 3 | C29: =B29-A29 -> -2 | D29: =(C29-$G$6)^2 -> 3.420511 | F29: p valor con (Excel) dos colas | G29: =TTEST(A:A,B:B,2,1) -> 0.39886682
A30: 3 | B30: 5 | C30: =B30-A30 -> 2 | D30: =(C30-$G$6)^2 -> 4.6248121 | F30: p valor con (Excel) una colas | G30: =TTEST(A:A,B:B,1,1) -> 0.19943341
A31: 2 | B31: 5 | C31: =B31-A31 -> 3 | D31: =(C31-$G$6)^2 -> 9.9258874
A32: 5 | B32: 5 | C32: =B32-A32 -> 0 | D32: =(C32-$G$6)^2 -> 0.022661579
A33: 5 | B33: 1 | C33: =B33-A33 -> -4 | D33: =(C33-$G$6)^2 -> 14.818361 | F33: Hipotesis
A34: 3 | B34: 3 | C34: =B34-A34 -> 0 | D34: =(C34-$G$6)^2 -> 0.022661579
A35: 3 | B35: 4 | C35: =B35-A35 -> 1 | D35: =(C35-$G$6)^2 -> 1.3237368 | F35: hipotesis nula Ho = No hay diferencias significativa
A36: 2 | B36: 4 | C36: =B36-A36 -> 2 | D36: =(C36-$G$6)^2 -> 4.6248121 | F36: hipotesis alternativa H1 = Si hay diferencia significativa
A37: 5 | B37: 4 | C37: =B37-A37 -> -1 | D37: =(C37-$G$6)^2 -> 0.72158631
A38: 3 | B38: 3 | C38: =B38-A38 -> 0 | D38: =(C38-$G$6)^2 -> 0.022661579
A39: 4 | B39: 3 | C39: =B39-A39 -> -1 | D39: =(C39-$G$6)^2 -> 0.72158631
A40: 5 | B40: 4 | C40: =B40-A40 -> -1 | D40: =(C40-$G$6)^2 -> 0.72158631 | F40: Si t calculado > t critico (Tabla)
...

Sheet Habilidades-tareas
A1: (Sin Innovacion Didactica) Pre-test Habilidades-tareas a) Siempre = 5 b) Muchas veces = 4 c) A veces = 3 d) Pocas veces = 2 e) Nunca = 1 | B1: (Sin Innovacion Didactica) Post-test Habilidades-tareas a) Siempre = 5 b) Muchas veces = 4 c) A veces = 3 d) Pocas veces = 2 e) Nunca = 1 | C1: Diferencia
A2: 1 | B2: 4 | C2: =B2-A2 -> 3 | D2: =(C2-$G$6)^2 -> 9.8582495
A3: 5 | B3: 5 | C3: =B3-A3 -> 0 | D3: =(C3-$G$6)^2 -> 0.019539831 | F3: Datos
A4: 3 | B4: 3 | C4: =B4-A4 -> 0 | D4: =(C4-$G$6)^2 -> 0.019539831 | F4: numero de datos | G4: =COUNT(A:A) -> 93
A5: 3 | B5: 2 | C5: =B5-A5 -> -1 | D5: =(C5-$G$6)^2 -> 0.73996994 | F5: Sumatoria Diferencias | G5: =SUM(C:C) -> -13
A6: 3 | B6: 4 | C6: =B6-A6 -> 1 | D6: =(C6-$G$6)^2 -> 1.2991097 | F6: Media de las diferencias | G6: =G5/G4 -> -0.13978495
A7: 5 | B7: 3 | C7: =B7-A7 -> -2 | D7: =(C7-$G$6)^2 -> 3.4604 | F7: Sumatoria de diferencias | G7: =SUM(D:D) -> 225.1828
A8: 2 | B8: 2 | C8: =B8-A8 -> 0 | D8: =(C8-$G$6)^2 -> 0.019539831 | F8: desviación estándar de las diferencias | G8: =SQRT(G7/(G4-1)) -> 1.5644932
A9: 2 | B9: 3 | C9: =B9-A9 -> 1 | D9: =(C9-$G$6)^2 -> 1.2991097
A10: 3 | B10: 3 | C10: =B10-A10 -> 0 | D10: =(C10-$G$6)^2 -> 0.019539831
A11: 3 | B11: 3 | C11: =B11-A11 -> 0 | D11: =(C11-$G$6)^2 -> 0.019539831
A12: 2 | B12: 3 | C12: =B12-A12 -> 1 | D12: =(C12-$G$6)^2 -> 1.2991097 | F12: t calculado (estadistico t): | G12: =G6/(G8/SQRT(G4)) -> -0.86164464
A13: 3 | B13: 4 | C13: =B13-A13 -> 1 | D13: =(C13-$G$6)^2 -> 1.2991097
A14: 5 | B14: 3 | C14: =B14-A14 -> -2 | D14: =(C14-$G$6)^2 -> 3.4604
A15: 3 | B15: 3 | C15: =B15-A15 -> 0 | D15: =(C15-$G$6)^2 -> 0.019539831
A16: 3 | B16: 2 | C16: =B16-A16 -> -1 | D16: =(C16-$G$6)^2 -> 0.73996994
A17: 4 | B17: 3 | C17: =B17-A17 -> -1 | D17: =(C17-$G$6)^2 -> 0.73996994 | F17: nivel de significancia (α) | G17: 0.05
A18: 3 | B18: 3 | C18: =B18-A18 -> 0 | D18: =(C18-$G$6)^2 -> 0.019539831 | F18: grados de libertad (DF) | G18: =G4-1 -> 92
A19: 1 | B19: 4 | C19: =B19-A19 -> 3 | D19: =(C19-$G$6)^2 -> 9.8582495
A20: 2 | B20: 3 | C20: =B20-A20 -> 1 | D20: =(C20-$G$6)^2 -> 1.2991097
A21: 4 | B21: 5 | C21: =B21-A21 -> 1 | D21: =(C21-$G$6)^2 -> 1.2991097
A22: 5 | B22: 4 | C22: =B22-A22 -> -1 | D22: =(C22-$G$6)^2 -> 0.73996994 | F22: Valor critico t
A23: 1 | B23: 3 | C23: =B23-A23 -> 2 | D23: =(C23-$G$6)^2 -> 4.5786796 | F23: valor crítico t (Excel) - 2 colas | G23: =_xlfn.T.INV.2T(G17,G18) -> 1.9860863
A24: 2 | B24: 1 | C24: =B24-A24 -> -1 | D24: =(C24-$G$6)^2 -> 0.73996994 | F24: valor crítico t (Excel) - 1 colas | G24: =_xlfn.T.INV(G17,G18) -> -1.6615854
A25: 5 | B25: 5 | C25: =B25-A25 -> 0 | D25: =(C25-$G$6)^2 -> 0.019539831
A26: 2 | B26: 4 | C26: =B26-A26 -> 2 | D26: =(C26-$G$6)^2 -> 4.5786796
A27: 2 | B27: 2 | C27: =B27-A27 -> 0 | D27: =(C27-$G$6)^2 -> 0.019539831 | F27: p valor
A28: 3 | B28: 4 | C28: =B28-A28 -> 1 | D28: =(C28-$G$6)^2 -> 1.2991097 | F28: p valor
A29: 3 | B29: 3 | C29: =B29-A29 -> 0 | D29: =(C29-$G$6)^2 -> 0.019539831 | F29: p valor con (Excel) dos colas | G29: =TTEST(A:A,B:B,2,1) -> 0.39112337
A30: 4 | B30: 3 | C30: =B30-A30 -> -1 | D30: =(C30-$G$6)^2 -> 0.73996994 | F30: p valor con (Excel) una colas | G30: =TTEST(A:A,B:B,1,1) -> 0.19556168
A31: 5 | B31: 3 | C31: =B31-A31 -> -2 | D31: =(C31-$G$6)^2 -> 3.4604
A32: 4 | B32: 4 | C32: =B32-A32 -> 0 | D32: =(C32-$G$6)^2 -> 0.019539831
A33: 2 | B33: 4 | C33: =B33-A33 -> 2 | D33: =(C33-$G$6)^2 -> 4.5786796 | F33: Hipotesis
A34: 5 | B34: 2 | C34: =B34-A34 -> -3 | D34: =(C34-$G$6)^2 -> 8.1808302
A35: 4 | B35: 3 | C35: =B35-A35 -> -1 | D35: =(C35-$G$6)^2 -> 0.73996994 | F35: hipotesis nula Ho = No hay diferencias significativa
A36: 4 | B36: 5 | C36: =B36-A36 -> 1 | D36: =(C36-$G$6)^2 -> 1.2991097 | F36: hipotesis alternativa H1 = Si hay diferencia significativa
A37: 3 | B37: 3 | C37: =B37-A37 -> 0 | D37: =(C37-$G$6)^2 -> 0.019539831
A38: 2 | B38: 5 | C38: =B38-A38 -> 3 | D38: =(C38-$G$6)^2 -> 9.8582495
A39: 4 | B39: 3 | C39: =B39-A39 -> -1 | D39: =(C39-$G$6)^2 -> 0.73996994
A40: 4 | B40: 4 | C40: =B40-A40 -> 0 | D40: =(C40-$G$6)^2 -> 0.019539831 | F40: Si t calculado > t critico (Tabla)
...

Sheet Resolución-problemas
A1: (Sin Innovacion Didactica) Pre-test Resolución-problemas a) Siempre = 5 b) Frecuente = 4 c) A veces = 3 d) Raro = 2 e) Nunca = 1 | B1: (Sin Innovacion Didactica) Post-test Resolución-problemas a) Siempre = 5 b) Frecuente = 4 c) A veces = 3 d) Raro = 2 e) Nunca = 1 | C1: Diferencia
A2: 4 | B2: 3 | C2: =B2-A2 -> -1 | D2: =(C2-$G$6)^2 -> 0.89536363
A3: 5 | B3: 4 | C3: =B3-A3 -> -1 | D3: =(C3-$G$6)^2 -> 0.89536363 | F3: Datos
A4: 4 | B4: 4 | C4: =B4-A4 -> 0 | D4: =(C4-$G$6)^2 -> 0.0028905076 | F4: numero de datos | G4: =COUNT(A:A) -> 93
A5: 3 | B5: 4 | C5: =B5-A5 -> 1 | D5: =(C5-$G$6)^2 -> 1.1104174 | F5: Sumatoria Diferencias | G5: =SUM(C:C) -> -5
A6: 2 | B6: 5 | C6: =B6-A6 -> 3 | D6: =(C6-$G$6)^2 -> 9.3254712 | F6: Media de las diferencias | G6: =G5/G4 -> -0.053763441
A7: 2 | B7: 5 | C7: =B7-A7 -> 3 | D7: =(C7-$G$6)^2 -> 9.3254712 | F7: Sumatoria de diferencias | G7: =SUM(D:D) -> 222.73118
A8: 4 | B8: 2 | C8: =B8-A8 -> -2 | D8: =(C8-$G$6)^2 -> 3.7878367 | F8: desviación estándar de las diferencias | G8: =SQRT(G7/(G4-1)) -> 1.5559534
A9: 3 | B9: 4 | C9: =B9-A9 -> 1 | D9: =(C9-$G$6)^2 -> 1.1104174
A10: 4 | B10: 3 | C10: =B10-A10 -> -1 | D10: =(C10-$G$6)^2 -> 0.89536363
A11: 4 | B11: 4 | C11: =B11-A11 -> 0 | D11: =(C11-$G$6)^2 -> 0.0028905076
A12: 2 | B12: 1 | C12: =B12-A12 -> -1 | D12: =(C12-$G$6)^2 -> 0.89536363 | F12: t calculado (estadistico t): | G12: =G6/(G8/SQRT(G4)) -> -0.33322067
A13: 5 | B13: 4 | C13: =B13-A13 -> -1 | D13: =(C13-$G$6)^2 -> 0.89536363
A14: 5 | B14: 4 | C14: =B14-A14 -> -1 | D14: =(C14-$G$6)^2 -> 0.89536363
A15: 4 | B15: 2 | C15: =B15-A15 -> -2 | D15: =(C15-$G$6)^2 -> 3.7878367
A16: 5 | B16: 2 | C16: =B16-A16 -> -3 | D16: =(C16-$G$6)^2 -> 8.6803099
A17: 4 | B17: 4 | C17: =B17-A17 -> 0 | D17: =(C17-$G$6)^2 -> 0.0028905076 | F17: nivel de significancia (α) | G17: 0.05
A18: 3 | B18: 2 | C18: =B18-A18 -> -1 | D18: =(C18-$G$6)^2 -> 0.89536363 | F18: grados de libertad (DF) | G18: =G4-1 -> 92
A19: 4 | B19: 3 | C19: =B19-A19 -> -1 | D19: =(C19-$G$6)^2 -> 0.89536363
A20: 2 | B20: 3 | C20: =B20-A20 -> 1 | D20: =(C20-$G$6)^2 -> 1.1104174
A21: 2 | B21: 5 | C21: =B21-A21 -> 3 | D21: =(C21-$G$6)^2 -> 9.3254712
A22: 4 | B22: 5 | C22: =B22-A22 -> 1 | D22: =(C22-$G$6)^2 -> 1.1104174 | F22: Valor critico t
A23: 4 | B23: 3 | C23: =B23-A23 -> -1 | D23: =(C23-$G$6)^2 -> 0.89536363 | F23: valor crítico t (Excel) - 2 colas | G23: =_xlfn.T.INV.2T(G17,G18) -> 1.9860863
A24: 4 | B24: 3 | C24: =B24-A24 -> -1 | D24: =(C24-$G$6)^2 -> 0.89536363 | F24: valor crítico t (Excel) - 1 colas | G24: =_xlfn.T.INV(G17,G18) -> -1.6615854
A25: 3 | B25: 3 | C25: =B25-A25 -> 0 | D25: =(C25-$G$6)^2 -> 0.0028905076
A26: 4 | B26: 3 | C26: =B26-A26 -> -1 | D26: =(C26-$G$6)^2 -> 0.89536363
A27: 3 | B27: 3 | C27: =B27-A27 -> 0 | D27: =(C27-$G$6)^2 -> 0.0028905076 | F27: p valor
A28: 4 | B28: 4 | C28: =B28-A28 -> 0 | D28: =(C28-$G$6)^2 -> 0.0028905076 | F28: p valor
A29: 3 | B29: 3 | C29: =B29-A29 -> 0 | D29: =(C29-$G$6)^2 -> 0.0028905076 | F29: p valor con (Excel) dos colas | G29: =TTEST(A:A,B:B,2,1) -> 0.73972593
A30: 3 | B30: 5 | C30: =B30-A30 -> 2 | D30: =(C30-$G$6)^2 -> 4.2179443 | F30: p valor con (Excel) una colas | G30: =TTEST(A:A,B:B,1,1) -> 0.36986296
A31: 4 | B31: 3 | C31: =B31-A31 -> -1 | D31: =(C31-$G$6)^2 -> 0.89536363
A32: 1 | B32: 3 | C32: =B32-A32 -> 2 | D32: =(C32-$G$6)^2 -> 4.2179443
A33: 3 | B33: 1 | C33: =B33-A33 -> -2 | D33: =(C33-$G$6)^2 -> 3.7878367 | F33: Hipotesis
A34: 5 | B34: 5 | C34: =B34-A34 -> 0 | D34: =(C34-$G$6)^2 -> 0.0028905076
A35: 2 | B35: 5 | C35: =B35-A35 -> 3 | D35: =(C35-$G$6)^2 -> 9.3254712 | F35: hipotesis nula Ho = No hay diferencias significativa
A36: 3 | B36: 4 | C36: =B36-A36 -> 1 | D36: =(C36-$G$6)^2 -> 1.1104174 | F36: hipotesis alternativa H1 = Si hay diferencia significativa
A37: 2 | B37: 4 | C37: =B37-A37 -> 2 | D37: =(C37-$G$6)^2 -> 4.2179443
A38: 2 | B38: 4 | C38: =B38-A38 -> 2 | D38: =(C38-$G$6)^2 -> 4.2179443
A39: 4 | B39: 2 | C39: =B39-A39 -> -2 | D39: =(C39-$G$6)^2 -> 3.7878367
A40: 5 | B40: 4 | C40: =B40-A40 -> -1 | D40: =(C40-$G$6)^2 -> 0.89536363 | F40: Si t calculado > t critico (Tabla)
...

Sheet Motivación
A1: (Sin Innovacion Didactica) Pre-test Motivación a) Muy Alta = 5 b) Alta = 4 c) Regular = 3 d) Baja = 2 e) Muy Baja = 1 | B1: (Sin Innovacion Didactica) Post-test Motivación a) Muy Alta = 5 b) Alta = 4 c) Regular = 3 d) Baja = 2 e) Muy Baja = 1 | C1: Diferencia
A2: 3 | B2: 4 | C2: =B2-A2 -> 1 | D2: =(C2-$G$6)^2 -> 0.85512776
A3: 3 | B3: 5 | C3: =B3-A3 -> 2 | D3: =(C3-$G$6)^2 -> 3.7045901 | F3: Datos
A4: 4 | B4: 2 | C4: =B4-A4 -> -2 | D4: =(C4-$G$6)^2 -> 4.3067407 | F4: numero de datos | G4: =COUNT(A:A) -> 93
A5: 4 | B5: 4 | C5: =B5-A5 -> 0 | D5: =(C5-$G$6)^2 -> 0.0056653948 | F5: Sumatoria Diferencias | G5: =SUM(C:C) -> 7
A6: 2 | B6: 4 | C6: =B6-A6 -> 2 | D6: =(C6-$G$6)^2 -> 3.7045901 | F6: Media de las diferencias | G6: =G5/G4 -> 0.075268817
A7: 2 | B7: 5 | C7: =B7-A7 -> 3 | D7: =(C7-$G$6)^2 -> 8.5540525 | F7: Sumatoria de diferencias | G7: =SUM(D:D) -> 270.47312
A8: 3 | B8: 4 | C8: =B8-A8 -> 1 | D8: =(C8-$G$6)^2 -> 0.85512776 | F8: desviación estándar de las diferencias | G8: =SQRT(G7/(G4-1)) -> 1.714621
A9: 4 | B9: 3 | C9: =B9-A9 -> -1 | D9: =(C9-$G$6)^2 -> 1.156203
A10: 3 | B10: 3 | C10: =B10-A10 -> 0 | D10: =(C10-$G$6)^2 -> 0.0056653948
A11: 4 | B11: 4 | C11: =B11-A11 -> 0 | D11: =(C11-$G$6)^2 -> 0.0056653948
A12: 5 | B12: 2 | C12: =B12-A12 -> -3 | D12: =(C12-$G$6)^2 -> 9.4572783 | F12: t calculado (estadistico t): | G12: =G6/(G8/SQRT(G4)) -> 0.42333914
A13: 1 | B13: 2 | C13: =B13-A13 -> 1 | D13: =(C13-$G$6)^2 -> 0.85512776
A14: 5 | B14: 2 | C14: =B14-A14 -> -3 | D14: =(C14-$G$6)^2 -> 9.4572783
A15: 1 | B15: 4 | C15: =B15-A15 -> 3 | D15: =(C15-$G$6)^2 -> 8.5540525
A16: 4 | B16: 4 | C16: =B16-A16 -> 0 | D16: =(C16-$G$6)^2 -> 0.0056653948
A17: 4 | B17: 1 | C17: =B17-A17 -> -3 | D17: =(C17-$G$6)^2 -> 9.4572783 | F17: nivel de significancia (α) | G17: 0.05
A18: 3 | B18: 2 | C18: =B18-A18 -> -1 | D18: =(C18-$G$6)^2 -> 1.156203 | F18: grados de libertad (DF) | G18: =G4-1 -> 92
A19: 2 | B19: 5 | C19: =B19-A19 -> 3 | D19: =(C19-$G$6)^2 -> 8.5540525
A20: 3 | B20: 5 | C20: =B20-A20 -> 2 | D20: =(C20-$G$6)^2 -> 3.7045901
A21: 2 | B21: 4 | C21: =B21-A21 -> 2 | D21: =(C21-$G$6)^2 -> 3.7045901
A22: 3 | B22: 2 | C22: =B22-A22 -> -1 | D22: =(C22-$G$6)^2 -> 1.156203 | F22: Valor critico t
A23: 3 | B23: 3 | C23: =B23-A23 -> 0 | D23: =(C23-$G$6)^2 -> 0.0056653948 | F23: valor crítico t (Excel) - 2 colas | G23: =_xlfn.T.INV.2T(G17,G18) -> 1.9860863
A24: 2 | B24: 3 | C24: =B24-A24 -> 1 | D24: =(C24-$G$6)^2 -> 0.85512776 | F24: valor crítico t (Excel) - 1 colas | G24: =_xlfn.T.INV(G17,G18) -> -1.6615854
A25: 4 | B25: 5 | C25: =B25-A25 -> 1 | D25: =(C25-$G$6)^2 -> 0.85512776
A26: 3 | B26: 3 | C26: =B26-A26 -> 0 | D26: =(C26-$G$6)^2 -> 0.0056653948
A27: 4 | B27: 2 | C27: =B27-A27 -> -2 | D27: =(C27-$G$6)^2 -> 4.3067407 | F27: p valor
A28: 1 | B28: 4 | C28: =B28-A28 -> 3 | D28: =(C28-$G$6)^2 -> 8.5540525 | F28: p valor
A29: 1 | B29: 2 | C29: =B29-A29 -> 1 | D29: =(C29-$G$6)^2 -> 0.85512776 | F29: p valor con (Excel) dos colas | G29: =TTEST(A:A,B:B,2,1) -> 0.67303586
A30: 5 | B30: 1 | C30: =B30-A30 -> -4 | D30: =(C30-$G$6)^2 -> 16.607816 | F30: p valor con (Excel) una colas | G30: =TTEST(A:A,B:B,1,1) -> 0.33651793
A31: 3 | B31: 4 | C31: =B31-A31 -> 1 | D31: =(C31-$G$6)^2 -> 0.85512776
A32: 1 | B32: 3 | C32: =B32-A32 -> 2 | D32: =(C32-$G$6)^2 -> 3.7045901
A33: 4 | B33: 4 | C33: =B33-A33 -> 0 | D33: =(C33-$G$6)^2 -> 0.0056653948 | F33: Hipotesis
A34: 3 | B34: 2 | C34: =B34-A34 -> -1 | D34: =(C34-$G$6)^2 -> 1.156203
A35: 1 | B35: 3 | C35: =B35-A35 -> 2 | D35: =(C35-$G$6)^2 -> 3.7045901 | F35: hipotesis nula Ho = No hay diferencias significativa
A36: 5 | B36: 3 | C36: =B36-A36 -> -2 | D36: =(C36-$G$6)^2 -> 4.3067407 | F36: hipotesis alternativa H1 = Si hay diferencia significativa
A37: 3 | B37: 2 | C37: =B37-A37 -> -1 | D37: =(C37-$G$6)^2 -> 1.156203
A38: 4 | B38: 4 | C38: =B38-A38 -> 0 | D38: =(C38-$G$6)^2 -> 0.0056653948
A39: 1 | B39: 1 | C39: =B39-A39 -> 0 | D39: =(C39-$G$6)^2 -> 0.0056653948
A40: 1 | B40: 3 | C40: =B40-A40 -> 2 | D40: =(C40-$G$6)^2 -> 3.7045901 | F40: Si t calculado > t critico (Tabla)
...
