Workbook

Sheet Objetivo
A1: ✅ Chi-cuadrado (Post-test)
A2: Demuestra que la intervencion si genera cambio
A4: Objetivo:
A5: Evaluar si existe relación significativa entre las variables analizadas en el grupo control y el grupo experimental después de la implementación de la intervencion (post-test), con el fin de determinar el efecto de la intervencion en la mejora de los resultados.
A7: Grupos:
A8: Grupo Control – Post Test
A9: Grupo Experimental – Post Test

Sheet Resumen
A1: Indicador | B1: Chi Cuadrado Observado | C1: Chi Cuadrado Valor Critico | D1: P-Valor | E1: α nivel de significancia
A2: Participación activa | B2: =ROUND('Participas-actividades'!B35, 4) -> 43.8041 | C2: =ROUND('Participas-actividades'!B46, 4) -> 9.4877 | D2: ='Participas-actividades'!B47 -> 7.0458884e-09 | E2: 0.05
A3: Comunicación equipo | B3: =ROUND('Comunicación-equipo'!B35, 4) -> 31.2661 | C3: =ROUND('Comunicación-equipo'!B46, 4) -> 9.4877 | D3: ='Comunicación-equipo'!B47 -> 2.7015985e-06 | E3: 0.05
A4: Cumplimiento tareas | B4: =ROUND('Cumplimiento-tareas'!B35, 4) -> 35.856 | C4: =ROUND('Cumplimiento-tareas'!B46, 4) -> 9.4877 | D4: ='Cumplimiento-tareas'!B47 -> 3.0979481e-07 | E4: 0.05
A5: Contribución grupo | B5: =ROUND('Contribución-grupo'!B35,4) -> 43.1232 | C5: =ROUND('Contribución-grupo'!B46,4) -> 9.4877 | D5: ='Contribución-grupo'!B47 -> 9.7564154e-09 | E5: 0.05
A6: Resolución problemas | B6: =ROUND('Resolución-problemas'!B35,4) -> 20.3782 | C6: =ROUND('Resolución-problemas'!B46,4) -> 9.4877 | D6: ='Resolución-problemas'!B47 -> 0.00042046474 | E6: 0.05
A7: Conocimientos adquiridos | B7: =ROUND('Conocimientos-adquiridos'!B35,4) -> 41.3213 | C7: =ROUND('Conocimientos-adquiridos'!B46,4) -> 9.4877 | D7: ='Conocimientos-adquiridos'!B47 -> 2.3060268e-08 | E7: 0.05
A8: Nota final | B8: =ROUND('Nota-final'!B35,4) -> 66.2867 | C8: =ROUND('Nota-final'!B46,4) -> 9.4877 | D8: ='Nota-final'!B47 -> 1.3782853e-13 | E8: 0.05
A9: Comprensión | B9: =ROUND(Comprensión!B35,4) -> 49.1742 | C9: =ROUND(Comprensión!B46,4) -> 9.4877 | D9: =Comprensión!B47 -> 5.3701423e-10 | E9: 0.05
A10: Habilidades | B10: =ROUND(Habilidades!B35,4) -> 33.6579 | C10: =ROUND(Habilidades!B46,4) -> 9.4877 | D10: =Habilidades!B47 -> 8.7578418e-07 | E10: 0.05
A11: Resolución autónoma | B11: =ROUND('Resolución-autónoma'!B35,4) -> 60.6356 | C11: =ROUND('Resolución-autónoma'!B46,4) -> 9.4877 | D11: ='Resolución-autónoma'!B47 -> 2.1327275e-12 | E11: 0.05
A12: Motivación | B12: =ROUND(Motivación!B35,4) -> 39.0667 | C12: =ROUND(Motivación!B46,4) -> 9.4877 | D12: =Motivación!B47 -> 6.74907e-08 | E12: 0.05

Sheet Participas-actividades
A1: Tabla Valores Observados
A2: Grupo / Categoría | B2: a) Siempre | C2: b) Muchas veces | D2: c) A veces | E2: d) Pocas veces | F2: e) Nunca | G2: Total
A3: Grupo Control - Post Test | B3: 12 | C3: 19 | D3: 33 | E3: 23 | F3: 10 | G3: =SUM(B3:F3) -> 97
A4: Grupo Experimental - Post Test | B4: 42 | C4: 32 | D4: 17 | E4: 4 | F4: 2 | G4: =SUM(B4:F4) -> 97
A5: Total | B5: =SUM(B3:B4) -> 54 | C5: =SUM(C3:C4) -> 51 | D5: =SUM(D3:D4) -> 50 | E5: =SUM(E3:E4) -> 27 | F5: =SUM(F3:F4) -> 12 | G5: =SUM(G3:G4) -> 194
A7: Tabla Valores Esperados
A11: Categoria | B11: =B2 -> a) Siempre | C11: =C2 -> b) Muchas veces | D11: =D2 -> c) A veces | E11: =E2 -> d) Pocas veces | F11: =F2 -> e) Nunca | G11: =G2 -> Total
A12: =A3 -> Grupo Control - Post Test | B12: =(G3*B5)/G5 -> 27 | C12: =(G3*C5)/G5 -> 25.5 | D12: =(G3*D5)/G5 -> 25 | E12: =(G3*E5)/G5 -> 13.5 | F12: =(G3*F5)/G5 -> 6 | G12: =SUM(B12:F12) -> 97
A13: =A4 -> Grupo Experimental - Post Test | B13: =(G4*B5)/G5 -> 27 | C13: =(G4*C5)/G5 -> 25.5 | D13: =(G4*D5)/G5 -> 25 | E13: =(G4*E5)/G5 -> 13.5 | F13: =(G4*F5)/G5 -> 6 | G13: =SUM(B13:F13) -> 97
A16: Tabla completa Valores Observados (O) y Valores Esperados (E)
A18: Grupo | B18: Categoria | C18: Valor Observado (O) | D18: Valor Esperado (E )
A19: =A3 -> Grupo Control - Post Test | B19: =B2 -> a) Siempre | C19: =B3 -> 12 | D19: =B12 -> 27 | E19: =(C19-D19)^2 -> 225 | F19: =E19/D19 -> 8.3333333
A20: =A3 -> Grupo Control - Post Test | B20: =C2 -> b) Muchas veces | C20: =C3 -> 19 | D20: =C12 -> 25.5 | E20: =(C20-D20)^2 -> 42.25 | F20: =E20/D20 -> 1.6568627
A21: =A3 -> Grupo Control - Post Test | B21: =D2 -> c) A veces | C21: =D3 -> 33 | D21: =D12 -> 25 | E21: =(C21-D21)^2 -> 64 | F21: =E21/D21 -> 2.56
A22: =A3 -> Grupo Control - Post Test | B22: =E2 -> d) Pocas veces | C22: =E3 -> 23 | D22: =E12 -> 13.5 | E22: =(C22-D22)^2 -> 90.25 | F22: =E22/D22 -> 6.6851852
A23: =A3 -> Grupo Control - Post Test | B23: =F2 -> e) Nunca | C23: =F3 -> 10 | D23: =F12 -> 6 | E23: =(C23-D23)^2 -> 16 | F23: =E23/D23 -> 2.6666667
A24: =A4 -> Grupo Experimental - Post Test | B24: =B2 -> a) Siempre | C24: =B4 -> 42 | D24: =B13 -> 27 | E24: =(C24-D24)^2 -> 225 | F24: =E24/D24 -> 8.3333333
A25: =A4 -> Grupo Experimental - Post Test | B25: =C2 -> b) Muchas veces | C25: =C4 -> 32 | D25: =C13 -> 25.5 | E25: =(C25-D25)^2 -> 42.25 | F25: =E25/D25 -> 1.6568627
A26: =A4 -> Grupo Experimental - Post Test | B26: =D2 -> c) A veces | C26: =D4 -> 17 | D26: =D13 -> 25 | E26: =(C26-D26)^2 -> 64 | F26: =E26/D26 -> 2.56
A27: =A4 -> Grupo Experimental - Post Test | B27: =E2 -> d) Pocas veces | C27: =E4 -> 4 | D27: =E13 -> 13.5 | E27: =(C27-D27)^2 -> 90.25 | F27: =E27/D27 -> 6.6851852
A28: =A4 -> Grupo Experimental - Post Test | B28: =F2 -> e) Nunca | C28: =F4 -> 2 | D28: =F13 -> 6 | E28: =(C28-D28)^2 -> 16 | F28: =E28/D28 -> 2.6666667
A31: Calculo Chi Cuadrado
A35: Chi Cuadrado | B35: =SUM(F19:F28) -> 43.804096
A37: Calculo Grados Libertad
A39: Filas = 2 (Sin sistema, Con sistema) | C39: 2
A40: Columnas = 5 (las 5 categorías) | C40: 5
A41: Grados de libertad df | C41: =(C39-1)*(C40-1) -> 4
A43: Busqueda de Valor Critico en Tabla Chi Cuadrado
A44: df | B44: =C41 -> 4
A45: α | B45: 0.05 | C45: (el más usado en tesis)
A46: valor critico | B46: =CHIINV(B45,B44) -> 9.487729
A47: p valor | B47: =_xlfn.CHISQ.DIST.RT(B35, B44) -> 7.0458884e-09
A49: Interpretacion
A51: H0 Hipotesis Nula | B51: No existe relación entre los grupos y la variable
A52: H1 Hipotesis Alternativa | B52: Si existe relación entre los grupos y la variable
A54: si p valor < α ---> Se rechaza la hipotesis Nula
A55: α nivel de significancia | B55: =B45 -> 0.05
A56: p valor | B56: =B47 -> 7.0458884e-09
A58: Si chi cuadrado > valor critico ---> Se rechaza la hipotesis nula
A59: Chi Cuadrado | B59: =B35 -> 43.804096
...

Sheet Comunicación-equipo
A1: Tabla Valores Observados
A2: Grupo / Categoría | B2: a) Siempre | C2: b) Frecuente | D2: c) A veces | E2: d) Raro | F2: e) Nunca | G2: Total
A3: Grupo Control - Post Test | B3: 17 | C3: 18 | D3: 34 | E3: 16 | F3: 12 | G3: =SUM(B3:F3) -> 97
A4: Grupo Experimental - Post Test | B4: 42 | C4: 29 | D4: 19 | E4: 6 | F4: 1 | G4: =SUM(B4:F4) -> 97
A5: Total | B5: =SUM(B3:B4) -> 59 | C5: =SUM(C3:C4) -> 47 | D5: =SUM(D3:D4) -> 53 | E5: =SUM(E3:E4) -> 22 | F5: =SUM(F3:F4) -> 13 | G5: =SUM(G3:G4) -> 194
A7: Tabla Valores Esperados
A11: Categoria | B11: =B2 -> a) Siempre | C11: =C2 -> b) Frecuente | D11: =D2 -> c) A veces | E11: =E2 -> d) Raro | F11: =F2 -> e) Nunca | G11: =G2 -> Total
A12: =A3 -> Grupo Control - Post Test | B12: =(G3*B5)/G5 -> 29.5 | C12: =(G3*C5)/G5 -> 23.5 | D12: =(G3*D5)/G5 -> 26.5 | E12: =(G3*E5)/G5 -> 11 | F12: =(G3*F5)/G5 -> 6.5 | G12: =SUM(B12:F12) -> 97
A13: =A4 -> Grupo Experimental - Post Test | B13: =(G4*B5)/G5 -> 29.5 | C13: =(G4*C5)/G5 -> 23.5 | D13: =(G4*D5)/G5 -> 26.5 | E13: =(G4*E5)/G5 -> 11 | F13: =(G4*F5)/G5 -> 6.5 | G13: =SUM(B13:F13) -> 97
A16: Tabla completa Valores Observados (O) y Valores Esperados (E)
A18: Grupo | B18: Categoria | C18: Valor Observado (O) | D18: Valor Esperado (E )
A19: =A3 -> Grupo Control - Post Test | B19: =B2 -> a) Siempre | C19: =B3 -> 17 | D19: =B12 -> 29.5 | E19: =(C19-D19)^2 -> 156.25 | F19: =E19/D19 -> 5.2966102
A20: =A3 -> Grupo Control - Post Test | B20: =C2 -> b) Frecuente | C20: =C3 -> 18 | D20: =C12 -> 23.5 | E20: =(C20-D20)^2 -> 30.25 | F20: =E20/D20 -> 1.287234
A21: =A3 -> Grupo Control - Post Test | B21: =D2 -> c) A veces | C21: =D3 -> 34 | D21: =D12 -> 26.5 | E21: =(C21-D21)^2 -> 56.25 | F21: =E21/D21 -> 2.1226415
A22: =A3 -> Grupo Control - Post Test | B22: =E2 -> d) Raro | C22: =E3 -> 16 | D22: =E12 -> 11 | E22: =(C22-D22)^2 -> 25 | F22: =E22/D22 -> 2.2727273
A23: =A3 -> Grupo Control - Post Test | B23: =F2 -> e) Nunca | C23: =F3 -> 12 | D23: =F12 -> 6.5 | E23: =(C23-D23)^2 -> 30.25 | F23: =E23/D23 -> 4.6538462
A24: =A4 -> Grupo Experimental - Post Test | B24: =B2 -> a) Siempre | C24: =B4 -> 42 | D24: =B13 -> 29.5 | E24: =(C24-D24)^2 -> 156.25 | F24: =E24/D24 -> 5.2966102
A25: =A4 -> Grupo Experimental - Post Test | B25: =C2 -> b) Frecuente | C25: =C4 -> 29 | D25: =C13 -> 23.5 | E25: =(C25-D25)^2 -> 30.25 | F25: =E25/D25 -> 1.287234
A26: =A4 -> Grupo Experimental - Post Test | B26: =D2 -> c) A veces | C26: =D4 -> 19 | D26: =D13 -> 26.5 | E26: =(C26-D26)^2 -> 56.25 | F26: =E26/D26 -> 2.1226415
A27: =A4 -> Grupo Experimental - Post Test | B27: =E2 -> d) Raro | C27: =E4 -> 6 | D27: =E13 -> 11 | E27: =(C27-D27)^2 -> 25 | F27: =E27/D27 -> 2.2727273
A28: =A4 -> Grupo Experimental - Post Test | B28: =F2 -> e) Nunca | C28: =F4 -> 1 | D28: =F13 -> 6.5 | E28: =(C28-D28)^2 -> 30.25 | F28: =E28/D28 -> 4.6538462
A31: Calculo Chi Cuadrado
A35: Chi Cuadrado | B35: =SUM(F19:F28) -> 31.266118
A37: Calculo Grados Libertad
A39: Filas = 2 (Sin sistema, Con sistema) | C39: 2
A40: Columnas = 5 (las 5 categorías) | C40: 5
A41: Grados de libertad df | C41: =(C39-1)*(C40-1) -> 4
A43: Busqueda de Valor Critico en Tabla Chi Cuadrado
A44: df | B44: =C41 -> 4
A45: α | B45: 0.05 | C45: (el más usado en tesis)
A46: valor critico | B46: =CHIINV(B45,B44) -> 9.487729
A47: p valor | B47: =_xlfn.CHISQ.DIST.RT(B35, B44) -> 2.7015985e-06
A49: Interpretacion
A51: H0 Hipotesis Nula | B51: No existe relación entre los grupos y la variable
A52: H1 Hipotesis Alternativa | B52: Si existe relación entre los grupos y la variable
A54: si p valor < α ---> Se rechaza la hipotesis Nula
A55: α nivel de significancia | B55: =B45 -> 0.05
A56: p valor | B56: =B47 -> 2.7015985e-06
A58: Si chi cuadrado > valor critico ---> Se rechaza la hipotesis nula
A59: Chi Cuadrado | B59: =B35 -> 31.266118
...

Sheet Cumplimiento-tareas
A1: Tabla Valores Observados
A2: Grupo / Categoría | B2: a) Siempre | C2: b) Muchas veces | D2: c) A veces | E2: d) Pocas veces | F2: e) Nunca | G2: Total
A3: Grupo Control - Post Test | B3: 14 | C3: 21 | D3: 35 | E3: 17 | F3: 10 | G3: =SUM(B3:F3) -> 97
A4: Grupo Experimental - Post Test | B4: 41 | C4: 32 | D4: 16 | E4: 8 | F4: 0 | G4: =SUM(B4:F4) -> 97
A5: Total | B5: =SUM(B3:B4) -> 55 | C5: =SUM(C3:C4) -> 53 | D5: =SUM(D3:D4) -> 51 | E5: =SUM(E3:E4) -> 25 | F5: =SUM(F3:F4) -> 10 | G5: =SUM(G3:G4) -> 194
A7: Tabla Valores Esperados
A11: Categoria | B11: =B2 -> a) Siempre | C11: =C2 -> b) Muchas veces | D11: =D2 -> c) A veces | E11: =E2 -> d) Pocas veces | F11: =F2 -> e) Nunca | G11: =G2 -> Total
A12: =A3 -> Grupo Control - Post Test | B12: =(G3*B5)/G5 -> 27.5 | C12: =(G3*C5)/G5 -> 26.5 | D12: =(G3*D5)/G5 -> 25.5 | E12: =(G3*E5)/G5 -> 12.5 | F12: =(G3*F5)/G5 -> 5 | G12: =SUM(B12:F12) -> 97
A13: =A4 -> Grupo Experimental - Post Test | B13: =(G4*B5)/G5 -> 27.5 | C13: =(G4*C5)/G5 -> 26.5 | D13: =(G4*D5)/G5 -> 25.5 | E13: =(G4*E5)/G5 -> 12.5 | F13: =(G4*F5)/G5 -> 5 | G13: =SUM(B13:F13) -> 97
A16: Tabla completa Valores Observados (O) y Valores Esperados (E)
A18: Grupo | B18: Categoria | C18: Valor Observado (O) | D18: Valor Esperado (E )
A19: =A3 -> Grupo Control - Post Test | B19: =B2 -> a) Siempre | C19: =B3 -> 14 | D19: =B12 -> 27.5 | E19: =(C19-D19)^2 -> 182.25 | F19: =E19/D19 -> 6.6272727
A20: =A3 -> Grupo Control - Post Test | B20: =C2 -> b) Muchas veces | C20: =C3 -> 21 | D20: =C12 -> 26.5 | E20: =(C20-D20)^2 -> 30.25 | F20: =E20/D20 -> 1.1415094
A21: =A3 -> Grupo Control - Post Test | B21: =D2 -> c) A veces | C21: =D3 -> 35 | D21: =D12 -> 25.5 | E21: =(C21-D21)^2 -> 90.25 | F21: =E21/D21 -> 3.5392157
A22: =A3 -> Grupo Control - Post Test | B22: =E2 -> d) Pocas veces | C22: =E3 -> 17 | D22: =E12 -> 12.5 | E22: =(C22-D22)^2 -> 20.25 | F22: =E22/D22 -> 1.62
A23: =A3 -> Grupo Control - Post Test | B23: =F2 -> e) Nunca | C23: =F3 -> 10 | D23: =F12 -> 5 | E23: =(C23-D23)^2 -> 25 | F23: =E23/D23 -> 5
A24: =A4 -> Grupo Experimental - Post Test | B24: =B2 -> a) Siempre | C24: =B4 -> 41 | D24: =B13 -> 27.5 | E24: =(C24-D24)^2 -> 182.25 | F24: =E24/D24 -> 6.6272727
A25: =A4 -> Grupo Experimental - Post Test | B25: =C2 -> b) Muchas veces | C25: =C4 -> 32 | D25: =C13 -> 26.5 | E25: =(C25-D25)^2 -> 30.25 | F25: =E25/D25 -> 1.1415094
A26: =A4 -> Grupo Experimental - Post Test | B26: =D2 -> c) A veces | C26: =D4 -> 16 | D26: =D13 -> 25.5 | E26: =(C26-D26)^2 -> 90.25 | F26: =E26/D26 -> 3.5392157
A27: =A4 -> Grupo Experimental - Post Test | B27: =E2 -> d) Pocas veces | C27: =E4 -> 8 | D27: =E13 -> 12.5 | E27: =(C27-D27)^2 -> 20.25 | F27: =E27/D27 -> 1.62
A28: =A4 -> Grupo Experimental - Post Test | B28: =F2 -> e) Nunca | C28: =F4 -> 0 | D28: =F13 -> 5 | E28: =(C28-D28)^2 -> 25 | F28: =E28/D28 -> 5
A31: Calculo Chi Cuadrado
A35: Chi Cuadrado | B35: =SUM(F19:F28) -> 35.855996
A37: Calculo Grados Libertad
A39: Filas = 2 (Sin sistema, Con sistema) | C39: 2
A40: Columnas = 5 (las 5 categorías) | C40: 5
A41: Grados de libertad df | C41: =(C39-1)*(C40-1) -> 4
A43: Busqueda de Valor Critico en Tabla Chi Cuadrado
A44: df | B44: =C41 -> 4
A45: α | B45: 0.05 | C45: (el más usado en tesis)
A46: valor critico | B46: =CHIINV(B45,B44) -> 9.487729
A47: p valor | B47: =_xlfn.CHISQ.DIST.RT(B35, B44) -> 3.0979481e-07
A49: Interpretacion
A51: H0 Hipotesis Nula | B51: No existe relación entre los grupos y la variable
A52: H1 Hipotesis Alternativa | B52: Si existe relación entre los grupos y la variable
A54: si p valor < α ---> Se rechaza la hipotesis Nula
A55: α nivel de significancia | B55: =B45 -> 0.05
A56: p valor | B56: =B47 -> 3.0979481e-07
A58: Si chi cuadrado > valor critico ---> Se rechaza la hipotesis nula
A59: Chi Cuadrado | B59: =B35 -> 35.855996
...

Sheet Contribución-grupo
A1: Tabla Valores Observados
A2: Grupo / Categoría | B2: a) Siempre | C2: b) Frecuente | D2: c) A veces | E2: d) Raro | F2: e) Nunca | G2: Total
A3: Grupo Control - Post Test | B3: 13 | C3: 22 | D3: 38 | E3: 19 | F3: 5 | G3: =SUM(B3:F3) -> 97
A4: Grupo Experimental - Post Test | B4: 48 | C4: 28 | D4: 17 | E4: 3 | F4: 1 | G4: =SUM(B4:F4) -> 97
A5: Total | B5: =SUM(B3:B4) -> 61 | C5: =SUM(C3:C4) -> 50 | D5: =SUM(D3:D4) -> 55 | E5: =SUM(E3:E4) -> 22 | F5: =SUM(F3:F4) -> 6 | G5: =SUM(G3:G4) -> 194
A7: Tabla Valores Esperados
A11: Categoria | B11: =B2 -> a) Siempre | C11: =C2 -> b) Frecuente | D11: =D2 -> c) A veces | E11: =E2 -> d) Raro | F11: =F2 -> e) Nunca | G11: =G2 -> Total
A12: =A3 -> Grupo Control - Post Test | B12: =(G3*B5)/G5 -> 30.5 | C12: =(G3*C5)/G5 -> 25 | D12: =(G3*D5)/G5 -> 27.5 | E12: =(G3*E5)/G5 -> 11 | F12: =(G3*F5)/G5 -> 3 | G12: =SUM(B12:F12) -> 97
A13: =A4 -> Grupo Experimental - Post Test | B13: =(G4*B5)/G5 -> 30.5 | C13: =(G4*C5)/G5 -> 25 | D13: =(G4*D5)/G5 -> 27.5 | E13: =(G4*E5)/G5 -> 11 | F13: =(G4*F5)/G5 -> 3 | G13: =SUM(B13:F13) -> 97
A16: Tabla completa Valores Observados (O) y Valores Esperados (E)
A18: Grupo | B18: Categoria | C18: Valor Observado (O) | D18: Valor Esperado (E )
A19: =A3 -> Grupo Control - Post Test | B19: =B2 -> a) Siempre | C19: =B3 -> 13 | D19: =B12 -> 30.5 | E19: =(C19-D19)^2 -> 306.25 | F19: =E19/D19 -> 10.040984
A20: =A3 -> Grupo Control - Post Test | B20: =C2 -> b) Frecuente | C20: =C3 -> 22 | D20: =C12 -> 25 | E20: =(C20-D20)^2 -> 9 | F20: =E20/D20 -> 0.36
A21: =A3 -> Grupo Control - Post Test | B21: =D2 -> c) A veces | C21: =D3 -> 38 | D21: =D12 -> 27.5 | E21: =(C21-D21)^2 -> 110.25 | F21: =E21/D21 -> 4.0090909
A22: =A3 -> Grupo Control - Post Test | B22: =E2 -> d) Raro | C22: =E3 -> 19 | D22: =E12 -> 11 | E22: =(C22-D22)^2 -> 64 | F22: =E22/D22 -> 5.8181818
A23: =A3 -> Grupo Control - Post Test | B23: =F2 -> e) Nunca | C23: =F3 -> 5 | D23: =F12 -> 3 | E23: =(C23-D23)^2 -> 4 | F23: =E23/D23 -> 1.3333333
A24: =A4 -> Grupo Experimental - Post Test | B24: =B2 -> a) Siempre | C24: =B4 -> 48 | D24: =B13 -> 30.5 | E24: =(C24-D24)^2 -> 306.25 | F24: =E24/D24 -> 10.040984
A25: =A4 -> Grupo Experimental - Post Test | B25: =C2 -> b) Frecuente | C25: =C4 -> 28 | D25: =C13 -> 25 | E25: =(C25-D25)^2 -> 9 | F25: =E25/D25 -> 0.36
A26: =A4 -> Grupo Experimental - Post Test | B26: =D2 -> c) A veces | C26: =D4 -> 17 | D26: =D13 -> 27.5 | E26: =(C26-D26)^2 -> 110.25 | F26: =E26/D26 -> 4.0090909
A27: =A4 -> Grupo Experimental - Post Test | B27: =E2 -> d) Raro | C27: =E4 -> 3 | D27: =E13 -> 11 | E27: =(C27-D27)^2 -> 64 | F27: =E27/D27 -> 5.8181818
A28: =A4 -> Grupo Experimental - Post Test | B28: =F2 -> e) Nunca | C28: =F4 -> 1 | D28: =F13 -> 3 | E28: =(C28-D28)^2 -> 4 | F28: =E28/D28 -> 1.3333333
A31: Calculo Chi Cuadrado
A35: Chi Cuadrado | B35: =SUM(F19:F28) -> 43.123179
A37: Calculo Grados Libertad
A39: Filas = 2 (Sin sistema, Con sistema) | C39: 2
A40: Columnas = 5 (las 5 categorías) | C40: 5
A41: Grados de libertad df | C41: =(C39-1)*(C40-1) -> 4
A43: Busqueda de Valor Critico en Tabla Chi Cuadrado
A44: df | B44: =C41 -> 4
A45: α | B45: 0.05 | C45: (el más usado en tesis)
A46: valor critico | B46: =CHIINV(B45,B44) -> 9.487729
A47: p valor | B47: =_xlfn.CHISQ.DIST.RT(B35, B44) -> 9.7564154e-09
A49: Interpretacion
A51: H0 Hipotesis Nula | B51: No existe relación entre los grupos y la variable
A52: H1 Hipotesis Alternativa | B52: Si existe relación entre los grupos y la variable
A54: si p valor < α ---> Se rechaza la hipotesis Nula
A55: α nivel de significancia | B55: =B45 -> 0.05
A56: p valor | B56: =B47 -> 9.7564154e-09
A58: Si chi cuadrado > valor critico ---> Se rechaza la hipotesis nula
A59: Chi Cuadrado | B59: =B35 -> 43.123179
...

Sheet Resolución-problemas
A1: Tabla Valores Observados
A2: Grupo / Categoría | B2: a) Siempre | C2: b) Muchas veces | D2: c) A veces | E2: d) Pocas veces | F2: e) Nunca | G2: Total
A3: Grupo Control - Post Test | B3: 14 | C3: 30 | D3: 32 | E3: 12 | F3: 9 | G3: =SUM(B3:F3) -> 97
A4: Grupo Experimental - Post Test | B4: 34 | C4: 38 | D4: 16 | E4: 7 | F4: 2 | G4: =SUM(B4:F4) -> 97
A5: Total | B5: =SUM(B3:B4) -> 48 | C5: =SUM(C3:C4) -> 68 | D5: =SUM(D3:D4) -> 48 | E5: =SUM(E3:E4) -> 19 | F5: =SUM(F3:F4) -> 11 | G5: =SUM(G3:G4) -> 194
A7: Tabla Valores Esperados
A11: Categoria | B11: =B2 -> a) Siempre | C11: =C2 -> b) Muchas veces | D11: =D2 -> c) A veces | E11: =E2 -> d) Pocas veces | F11: =F2 -> e) Nunca | G11: =G2 -> Total
A12: =A3 -> Grupo Control - Post Test | B12: =(G3*B5)/G5 -> 24 | C12: =(G3*C5)/G5 -> 34 | D12: =(G3*D5)/G5 -> 24 | E12: =(G3*E5)/G5 -> 9.5 | F12: =(G3*F5)/G5 -> 5.5 | G12: =SUM(B12:F12) -> 97
A13: =A4 -> Grupo Experimental - Post Test | B13: =(G4*B5)/G5 -> 24 | C13: =(G4*C5)/G5 -> 34 | D13: =(G4*D5)/G5 -> 24 | E13: =(G4*E5)/G5 -> 9.5 | F13: =(G4*F5)/G5 -> 5.5 | G13: =SUM(B13:F13) -> 97
A16: Tabla completa Valores Observados (O) y Valores Esperados (E)
A18: Grupo | B18: Categoria | C18: Valor Observado (O) | D18: Valor Esperado (E )
A19: =A3 -> Grupo Control - Post Test | B19: =B2 -> a) Siempre | C19: =B3 -> 14 | D19: =B12 -> 24 | E19: =(C19-D19)^2 -> 100 | F19: =E19/D19 -> 4.1666667
A20: =A3 -> Grupo Control - Post Test | B20: =C2 -> b) Muchas veces | C20: =C3 -> 30 | D20: =C12 -> 34 | E20: =(C20-D20)^2 -> 16 | F20: =E20/D20 -> 0.47058824
A21: =A3 -> Grupo Control - Post Test | B21: =D2 -> c) A veces | C21: =D3 -> 32 | D21: =D12 -> 24 | E21: =(C21-D21)^2 -> 64 | F21: =E21/D21 -> 2.6666667
A22: =A3 -> Grupo Control - Post Test | B22: =E2 -> d) Pocas veces | C22: =E3 -> 12 | D22: =E12 -> 9.5 | E22: =(C22-D22)^2 -> 6.25 | F22: =E22/D22 -> 0.65789474
A23: =A3 -> Grupo Control - Post Test | B23: =F2 -> e) Nunca | C23: =F3 -> 9 | D23: =F12 -> 5.5 | E23: =(C23-D23)^2 -> 12.25 | F23: =E23/D23 -> 2.2272727
A24: =A4 -> Grupo Experimental - Post Test | B24: =B2 -> a) Siempre | C24: =B4 -> 34 | D24: =B13 -> 24 | E24: =(C24-D24)^2 -> 100 | F24: =E24/D24 -> 4.1666667
A25: =A4 -> Grupo Experimental - Post Test | B25: =C2 -> b) Muchas veces | C25: =C4 -> 38 | D25: =C13 -> 34 | E25: =(C25-D25)^2 -> 16 | F25: =E25/D25 -> 0.47058824
A26: =A4 -> Grupo Experimental - Post Test | B26: =D2 -> c) A veces | C26: =D4 -> 16 | D26: =D13 -> 24 | E26: =(C26-D26)^2 -> 64 | F26: =E26/D26 -> 2.6666667
A27: =A4 -> Grupo Experimental - Post Test | B27: =E2 -> d) Pocas veces | C27: =E4 -> 7 | D27: =E13 -> 9.5 | E27: =(C27-D27)^2 -> 6.25 | F27: =E27/D27 -> 0.65789474
A28: =A4 -> Grupo Experimental - Post Test | B28: =F2 -> e) Nunca | C28: =F4 -> 2 | D28: =F13 -> 5.5 | E28: =(C28-D28)^2 -> 12.25 | F28: =E28/D28 -> 2.2272727
A31: Calculo Chi Cuadrado
A35: Chi Cuadrado | B35: =SUM(F19:F28) -> 20.378178
A37: Calculo Grados Libertad
A39: Filas = 2 (Sin sistema, Con sistema) | C39: 2
A40: Columnas = 5 (las 5 categorías) | C40: 5
A41: Grados de libertad df | C41: =(C39-1)*(C40-1) -> 4
A43: Busqueda de Valor Critico en Tabla Chi Cuadrado
A44: df | B44: =C41 -> 4
A45: α | B45: 0.05 | C45: (el más usado en tesis)
A46: valor critico | B46: =CHIINV(B45,B44) -> 9.487729
A47: p valor | B47: =_xlfn.CHISQ.DIST.RT(B35, B44) -> 0.00042046474
A49: Interpretacion
A51: H0 Hipotesis Nula | B51: No existe relación entre los grupos y la variable
A52: H1 Hipotesis Alternativa | B52: Si existe relación entre los grupos y la variable
A54: si p valor < α ---> Se rechaza la hipotesis Nula
A55: α nivel de significancia | B55: =B45 -> 0.05
A56: p valor | B56: =B47 -> 0.00042046474
A58: Si chi cuadrado > valor critico ---> Se rechaza la hipotesis nula
A59: Chi Cuadrado | B59: =B35 -> 20.378178
...

Sheet Conocimientos-adquiridos
A1: Tabla Valores Observados
A2: Grupo / Categoría | B2: a) Siempre | C2: b) Frecuente | D2: c) A veces | E2: d) Raro | F2: e) Nunca | G2: Total
A3: Grupo Control - Post Test | B3: 16 | C3: 23 | D3: 25 | E3: 24 | F3: 9 | G3: =SUM(B3:F3) -> 97
A4: Grupo Experimental - Post Test | B4: 43 | C4: 38 | D4: 10 | E4: 5 | F4: 1 | G4: =SUM(B4:F4) -> 97
A5: Total | B5: =SUM(B3:B4) -> 59 | C5: =SUM(C3:C4) -> 61 | D5: =SUM(D3:D4) -> 35 | E5: =SUM(E3:E4) -> 29 | F5: =SUM(F3:F4) -> 10 | G5: =SUM(G3:G4) -> 194
A7: Tabla Valores Esperados
A11: Categoria | B11: =B2 -> a) Siempre | C11: =C2 -> b) Frecuente | D11: =D2 -> c) A veces | E11: =E2 -> d) Raro | F11: =F2 -> e) Nunca | G11: =G2 -> Total
A12: =A3 -> Grupo Control - Post Test | B12: =(G3*B5)/G5 -> 29.5 | C12: =(G3*C5)/G5 -> 30.5 | D12: =(G3*D5)/G5 -> 17.5 | E12: =(G3*E5)/G5 -> 14.5 | F12: =(G3*F5)/G5 -> 5 | G12: =SUM(B12:F12) -> 97
A13: =A4 -> Grupo Experimental - Post Test | B13: =(G4*B5)/G5 -> 29.5 | C13: =(G4*C5)/G5 -> 30.5 | D13: =(G4*D5)/G5 -> 17.5 | E13: =(G4*E5)/G5 -> 14.5 | F13: =(G4*F5)/G5 -> 5 | G13: =SUM(B13:F13) -> 97
A16: Tabla completa Valores Observados (O) y Valores Esperados (E)
A18: Grupo | B18: Categoria | C18: Valor Observado (O) | D18: Valor Esperado (E )
A19: =A3 -> Grupo Control - Post Test | B19: =B2 -> a) Siempre | C19: =B3 -> 16 | D19: =B12 -> 29.5 | E19: =(C19-D19)^2 -> 182.25 | F19: =E19/D19 -> 6.1779661
A20: =A3 -> Grupo Control - Post Test | B20: =C2 -> b) Frecuente | C20: =C3 -> 23 | D20: =C12 -> 30.5 | E20: =(C20-D20)^2 -> 56.25 | F20: =E20/D20 -> 1.8442623
A21: =A3 -> Grupo Control - Post Test | B21: =D2 -> c) A veces | C21: =D3 -> 25 | D21: =D12 -> 17.5 | E21: =(C21-D21)^2 -> 56.25 | F21: =E21/D21 -> 3.2142857
A22: =A3 -> Grupo Control - Post Test | B22: =E2 -> d) Raro | C22: =E3 -> 24 | D22: =E12 -> 14.5 | E22: =(C22-D22)^2 -> 90.25 | F22: =E22/D22 -> 6.2241379
A23: =A3 -> Grupo Control - Post Test | B23: =F2 -> e) Nunca | C23: =F3 -> 9 | D23: =F12 -> 5 | E23: =(C23-D23)^2 -> 16 | F23: =E23/D23 -> 3.2
A24: =A4 -> Grupo Experimental - Post Test | B24: =B2 -> a) Siempre | C24: =B4 -> 43 | D24: =B13 -> 29.5 | E24: =(C24-D24)^2 -> 182.25 | F24: =E24/D24 -> 6.1779661
A25: =A4 -> Grupo Experimental - Post Test | B25: =C2 -> b) Frecuente | C25: =C4 -> 38 | D25: =C13 -> 30.5 | E25: =(C25-D25)^2 -> 56.25 | F25: =E25/D25 -> 1.8442623
A26: =A4 -> Grupo Experimental - Post Test | B26: =D2 -> c) A veces | C26: =D4 -> 10 | D26: =D13 -> 17.5 | E26: =(C26-D26)^2 -> 56.25 | F26: =E26/D26 -> 3.2142857
A27: =A4 -> Grupo Experimental - Post Test | B27: =E2 -> d) Raro | C27: =E4 -> 5 | D27: =E13 -> 14.5 | E27: =(C27-D27)^2 -> 90.25 | F27: =E27/D27 -> 6.2241379
A28: =A4 -> Grupo Experimental - Post Test | B28: =F2 -> e) Nunca | C28: =F4 -> 1 | D28: =F13 -> 5 | E28: =(C28-D28)^2 -> 16 | F28: =E28/D28 -> 3.2
A31: Calculo Chi Cuadrado
A35: Chi Cuadrado | B35: =SUM(F19:F28) -> 41.321304
A37: Calculo Grados Libertad
A39: Filas = 2 (Sin sistema, Con sistema) | C39: 2
A40: Columnas = 5 (las 5 categorías) | C40: 5
A41: Grados de libertad df | C41: =(C39-1)*(C40-1) -> 4
A43: Busqueda de Valor Critico en Tabla Chi Cuadrado
A44: df | B44: =C41 -> 4
A45: α | B45: 0.05 | C45: (el más usado en tesis)
A46: valor critico | B46: =CHIINV(B45,B44) -> 9.487729
A47: p valor | B47: =_xlfn.CHISQ.DIST.RT(B35, B44) -> 2.3060268e-08
A49: Interpretacion
A51: H0 Hipotesis Nula | B51: No existe relación entre los grupos y la variable
A52: H1 Hipotesis Alternativa | B52: Si existe relación entre los grupos y la variable
A54: si p valor < α ---> Se rechaza la hipotesis Nula
A55: α nivel de significancia | B55: =B45 -> 0.05
A56: p valor | B56: =B47 -> 2.3060268e-08
A58: Si chi cuadrado > valor critico ---> Se rechaza la hipotesis nula
A59: Chi Cuadrado | B59: =B35 -> 41.321304
...

Sheet Nota-final
A1: Tabla Valores Observados
A2: Grupo / Categoría | B2: a) 81 - 100 | C2: b) 61 – 80 | D2: c) 41 - 60 | E2: d) 21 - 40 | F2: e) 0 - 20 | G2: Total
A3: Grupo Control - Post Test | B3: 8 | C3: 15 | D3: 39 | E3: 17 | F3: 18 | G3: =SUM(B3:F3) -> 97
A4: Grupo Experimental - Post Test | B4: 42 | C4: 35 | D4: 13 | E4: 7 | F4: 0 | G4: =SUM(B4:F4) -> 97
A5: Total | B5: =SUM(B3:B4) -> 50 | C5: =SUM(C3:C4) -> 50 | D5: =SUM(D3:D4) -> 52 | E5: =SUM(E3:E4) -> 24 | F5: =SUM(F3:F4) -> 18 | G5: =SUM(G3:G4) -> 194
A7: Tabla Valores Esperados
A11: Categoria | B11: =B2 -> a) 81 - 100 | C11: =C2 -> b) 61 – 80 | D11: =D2 -> c) 41 - 60 | E11: =E2 -> d) 21 - 40 | F11: =F2 -> e) 0 - 20 | G11: =G2 -> Total
A12: =A3 -> Grupo Control - Post Test | B12: =(G3*B5)/G5 -> 25 | C12: =(G3*C5)/G5 -> 25 | D12: =(G3*D5)/G5 -> 26 | E12: =(G3*E5)/G5 -> 12 | F12: =(G3*F5)/G5 -> 9 | G12: =SUM(B12:F12) -> 97
A13: =A4 -> Grupo Experimental - Post Test | B13: =(G4*B5)/G5 -> 25 | C13: =(G4*C5)/G5 -> 25 | D13: =(G4*D5)/G5 -> 26 | E13: =(G4*E5)/G5 -> 12 | F13: =(G4*F5)/G5 -> 9 | G13: =SUM(B13:F13) -> 97
A16: Tabla completa Valores Observados (O) y Valores Esperados (E)
A18: Grupo | B18: Categoria | C18: Valor Observado (O) | D18: Valor Esperado (E )
A19: =A3 -> Grupo Control - Post Test | B19: =B2 -> a) 81 - 100 | C19: =B3 -> 8 | D19: =B12 -> 25 | E19: =(C19-D19)^2 -> 289 | F19: =E19/D19 -> 11.56
A20: =A3 -> Grupo Control - Post Test | B20: =C2 -> b) 61 – 80 | C20: =C3 -> 15 | D20: =C12 -> 25 | E20: =(C20-D20)^2 -> 100 | F20: =E20/D20 -> 4
A21: =A3 -> Grupo Control - Post Test | B21: =D2 -> c) 41 - 60 | C21: =D3 -> 39 | D21: =D12 -> 26 | E21: =(C21-D21)^2 -> 169 | F21: =E21/D21 -> 6.5
A22: =A3 -> Grupo Control - Post Test | B22: =E2 -> d) 21 - 40 | C22: =E3 -> 17 | D22: =E12 -> 12 | E22: =(C22-D22)^2 -> 25 | F22: =E22/D22 -> 2.0833333
A23: =A3 -> Grupo Control - Post Test | B23: =F2 -> e) 0 - 20 | C23: =F3 -> 18 | D23: =F12 -> 9 | E23: =(C23-D23)^2 -> 81 | F23: =E23/D23 -> 9
A24: =A4 -> Grupo Experimental - Post Test | B24: =B2 -> a) 81 - 100 | C24: =B4 -> 42 | D24: =B13 -> 25 | E24: =(C24-D24)^2 -> 289 | F24: =E24/D24 -> 11.56
A25: =A4 -> Grupo Experimental - Post Test | B25: =C2 -> b) 61 – 80 | C25: =C4 -> 35 | D25: =C13 -> 25 | E25: =(C25-D25)^2 -> 100 | F25: =E25/D25 -> 4
A26: =A4 -> Grupo Experimental - Post Test | B26: =D2 -> c) 41 - 60 | C26: =D4 -> 13 | D26: =D13 -> 26 | E26: =(C26-D26)^2 -> 169 | F26: =E26/D26 -> 6.5
A27: =A4 -> Grupo Experimental - Post Test | B27: =E2 -> d) 21 - 40 | C27: =E4 -> 7 | D27: =E13 -> 12 | E27: =(C27-D27)^2 -> 25 | F27: =E27/D27 -> 2.0833333
A28: =A4 -> Grupo Experimental - Post Test | B28: =F2 -> e) 0 - 20 | C28: =F4 -> 0 | D28: =F13 -> 9 | E28: =(C28-D28)^2 -> 81 | F28: =E28/D28 -> 9
A31: Calculo Chi Cuadrado
A35: Chi Cuadrado | B35: =SUM(F19:F28) -> 66.286667
A37: Calculo Grados Libertad
A39: Filas = 2 (Sin sistema, Con sistema) | C39: 2
A40: Columnas = 5 (las 5 categorías) | C40: 5
A41: Grados de libertad df | C41: =(C39-1)*(C40-1) -> 4
A43: Busqueda de Valor Critico en Tabla Chi Cuadrado
A44: df | B44: =C41 -> 4
A45: α | B45: 0.05 | C45: (el más usado en tesis)
A46: valor critico | B46: =CHIINV(B45,B44) -> 9.487729
A47: p valor | B47: =_xlfn.CHISQ.DIST.RT(B35, B44) -> 1.3782853e-13
A49: Interpretacion
A51: H0 Hipotesis Nula | B51: No existe relación entre los grupos y la variable
A52: H1 Hipotesis Alternativa | B52: Si existe relación entre los grupos y la variable
A54: si p valor < α ---> Se rechaza la hipotesis Nula
A55: α nivel de significancia | B55: =B45 -> 0.05
A56: p valor | B56: =B47 -> 1.3782853e-13
A58: Si chi cuadrado > valor critico ---> Se rechaza la hipotesis nula
A59: Chi Cuadrado | B59: =B35 -> 66.286667
...

Sheet Comprensión
A1: Tabla Valores Observados
A2: Grupo / Categoría | B2: a) Muy Bueno | C2: b) bueno | D2: c) Regular | E2: d) Malo | F2: e) Muy malo | G2: Total
A3: Grupo Control - Post Test | B3: 18 | C3: 11 | D3: 36 | E3: 23 | F3: 9 | G3: =SUM(B3:F3) -> 97
A4: Grupo Experimental - Post Test | B4: 40 | C4: 36 | D4: 16 | E4: 3 | F4: 2 | G4: =SUM(B4:F4) -> 97
A5: Total | B5: =SUM(B3:B4) -> 58 | C5: =SUM(C3:C4) -> 47 | D5: =SUM(D3:D4) -> 52 | E5: =SUM(E3:E4) -> 26 | F5: =SUM(F3:F4) -> 11 | G5: =SUM(G3:G4) -> 194
A7: Tabla Valores Esperados
A11: Categoria | B11: =B2 -> a) Muy Bueno | C11: =C2 -> b) bueno | D11: =D2 -> c) Regular | E11: =E2 -> d) Malo | F11: =F2 -> e) Muy malo | G11: =G2 -> Total
A12: =A3 -> Grupo Control - Post Test | B12: =(G3*B5)/G5 -> 29 | C12: =(G3*C5)/G5 -> 23.5 | D12: =(G3*D5)/G5 -> 26 | E12: =(G3*E5)/G5 -> 13 | F12: =(G3*F5)/G5 -> 5.5 | G12: =SUM(B12:F12) -> 97
A13: =A4 -> Grupo Experimental - Post Test | B13: =(G4*B5)/G5 -> 29 | C13: =(G4*C5)/G5 -> 23.5 | D13: =(G4*D5)/G5 -> 26 | E13: =(G4*E5)/G5 -> 13 | F13: =(G4*F5)/G5 -> 5.5 | G13: =SUM(B13:F13) -> 97
A16: Tabla completa Valores Observados (O) y Valores Esperados (E)
A18: Grupo | B18: Categoria | C18: Valor Observado (O) | D18: Valor Esperado (E )
A19: =A3 -> Grupo Control - Post Test | B19: =B2 -> a) Muy Bueno | C19: =B3 -> 18 | D19: =B12 -> 29 | E19: =(C19-D19)^2 -> 121 | F19: =E19/D19 -> 4.1724138
A20: =A3 -> Grupo Control - Post Test | B20: =C2 -> b) bueno | C20: =C3 -> 11 | D20: =C12 -> 23.5 | E20: =(C20-D20)^2 -> 156.25 | F20: =E20/D20 -> 6.6489362
A21: =A3 -> Grupo Control - Post Test | B21: =D2 -> c) Regular | C21: =D3 -> 36 | D21: =D12 -> 26 | E21: =(C21-D21)^2 -> 100 | F21: =E21/D21 -> 3.8461538
A22: =A3 -> Grupo Control - Post Test | B22: =E2 -> d) Malo | C22: =E3 -> 23 | D22: =E12 -> 13 | E22: =(C22-D22)^2 -> 100 | F22: =E22/D22 -> 7.6923077
A23: =A3 -> Grupo Control - Post Test | B23: =F2 -> e) Muy malo | C23: =F3 -> 9 | D23: =F12 -> 5.5 | E23: =(C23-D23)^2 -> 12.25 | F23: =E23/D23 -> 2.2272727
A24: =A4 -> Grupo Experimental - Post Test | B24: =B2 -> a) Muy Bueno | C24: =B4 -> 40 | D24: =B13 -> 29 | E24: =(C24-D24)^2 -> 121 | F24: =E24/D24 -> 4.1724138
A25: =A4 -> Grupo Experimental - Post Test | B25: =C2 -> b) bueno | C25: =C4 -> 36 | D25: =C13 -> 23.5 | E25: =(C25-D25)^2 -> 156.25 | F25: =E25/D25 -> 6.6489362
A26: =A4 -> Grupo Experimental - Post Test | B26: =D2 -> c) Regular | C26: =D4 -> 16 | D26: =D13 -> 26 | E26: =(C26-D26)^2 -> 100 | F26: =E26/D26 -> 3.8461538
A27: =A4 -> Grupo Experimental - Post Test | B27: =E2 -> d) Malo | C27: =E4 -> 3 | D27: =E13 -> 13 | E27: =(C27-D27)^2 -> 100 | F27: =E27/D27 -> 7.6923077
A28: =A4 -> Grupo Experimental - Post Test | B28: =F2 -> e) Muy malo | C28: =F4 -> 2 | D28: =F13 -> 5.5 | E28: =(C28-D28)^2 -> 12.25 | F28: =E28/D28 -> 2.2272727
A31: Calculo Chi Cuadrado
A35: Chi Cuadrado | B35: =SUM(F19:F28) -> 49.174168
A37: Calculo Grados Libertad
A39: Filas = 2 (Sin sistema, Con sistema) | C39: 2
A40: Columnas = 5 (las 5 categorías) | C40: 5
A41: Grados de libertad df | C41: =(C39-1)*(C40-1) -> 4
A43: Busqueda de Valor Critico en Tabla Chi Cuadrado
A44: df | B44: =C41 -> 4
A45: α | B45: 0.05 | C45: (el más usado en tesis)
A46: valor critico | B46: =CHIINV(B45,B44) -> 9.487729
A47: p valor | B47: =_xlfn.CHISQ.DIST.RT(B35, B44) -> 5.3701423e-10
A49: Interpretacion
A51: H0 Hipotesis Nula | B51: No existe relación entre los grupos y la variable
A52: H1 Hipotesis Alternativa | B52: Si existe relación entre los grupos y la variable
A54: si p valor < α ---> Se rechaza la hipotesis Nula
A55: α nivel de significancia | B55: =B45 -> 0.05
A56: p valor | B56: =B47 -> 5.3701423e-10
A58: Si chi cuadrado > valor critico ---> Se rechaza la hipotesis nula
A59: Chi Cuadrado | B59: =B35 -> 49.174168
...

Sheet Habilidades
A1: Tabla Valores Observados
A2: Grupo / Categoría | B2: a) Siempre | C2: b) Muchas veces | D2: c) A veces | E2: d) Pocas veces | F2: e) Nunca | G2: Total
A3: Grupo Control - Post Test | B3: 13 | C3: 24 | D3: 27 | E3: 25 | F3: 8 | G3: =SUM(B3:F3) -> 97
A4: Grupo Experimental - Post Test | B4: 45 | C4: 27 | D4: 15 | E4: 7 | F4: 3 | G4: =SUM(B4:F4) -> 97
A5: Total | B5: =SUM(B3:B4) -> 58 | C5: =SUM(C3:C4) -> 51 | D5: =SUM(D3:D4) -> 42 | E5: =SUM(E3:E4) -> 32 | F5: =SUM(F3:F4) -> 11 | G5: =SUM(G3:G4) -> 194
A7: Tabla Valores Esperados
A11: Categoria | B11: =B2 -> a) Siempre | C11: =C2 -> b) Muchas veces | D11: =D2 -> c) A veces | E11: =E2 -> d) Pocas veces | F11: =F2 -> e) Nunca | G11: =G2 -> Total
A12: =A3 -> Grupo Control - Post Test | B12: =(G3*B5)/G5 -> 29 | C12: =(G3*C5)/G5 -> 25.5 | D12: =(G3*D5)/G5 -> 21 | E12: =(G3*E5)/G5 -> 16 | F12: =(G3*F5)/G5 -> 5.5 | G12: =SUM(B12:F12) -> 97
A13: =A4 -> Grupo Experimental - Post Test | B13: =(G4*B5)/G5 -> 29 | C13: =(G4*C5)/G5 -> 25.5 | D13: =(G4*D5)/G5 -> 21 | E13: =(G4*E5)/G5 -> 16 | F13: =(G4*F5)/G5 -> 5.5 | G13: =SUM(B13:F13) -> 97
A16: Tabla completa Valores Observados (O) y Valores Esperados (E)
A18: Grupo | B18: Categoria | C18: Valor Observado (O) | D18: Valor Esperado (E )
A19: =A3 -> Grupo Control - Post Test | B19: =B2 -> a) Siempre | C19: =B3 -> 13 | D19: =B12 -> 29 | E19: =(C19-D19)^2 -> 256 | F19: =E19/D19 -> 8.8275862
A20: =A3 -> Grupo Control - Post Test | B20: =C2 -> b) Muchas veces | C20: =C3 -> 24 | D20: =C12 -> 25.5 | E20: =(C20-D20)^2 -> 2.25 | F20: =E20/D20 -> 0.088235294
A21: =A3 -> Grupo Control - Post Test | B21: =D2 -> c) A veces | C21: =D3 -> 27 | D21: =D12 -> 21 | E21: =(C21-D21)^2 -> 36 | F21: =E21/D21 -> 1.7142857
A22: =A3 -> Grupo Control - Post Test | B22: =E2 -> d) Pocas veces | C22: =E3 -> 25 | D22: =E12 -> 16 | E22: =(C22-D22)^2 -> 81 | F22: =E22/D22 -> 5.0625
A23: =A3 -> Grupo Control - Post Test | B23: =F2 -> e) Nunca | C23: =F3 -> 8 | D23: =F12 -> 5.5 | E23: =(C23-D23)^2 -> 6.25 | F23: =E23/D23 -> 1.1363636
A24: =A4 -> Grupo Experimental - Post Test | B24: =B2 -> a) Siempre | C24: =B4 -> 45 | D24: =B13 -> 29 | E24: =(C24-D24)^2 -> 256 | F24: =E24/D24 -> 8.8275862
A25: =A4 -> Grupo Experimental - Post Test | B25: =C2 -> b) Muchas veces | C25: =C4 -> 27 | D25: =C13 -> 25.5 | E25: =(C25-D25)^2 -> 2.25 | F25: =E25/D25 -> 0.088235294
A26: =A4 -> Grupo Experimental - Post Test | B26: =D2 -> c) A veces | C26: =D4 -> 15 | D26: =D13 -> 21 | E26: =(C26-D26)^2 -> 36 | F26: =E26/D26 -> 1.7142857
A27: =A4 -> Grupo Experimental - Post Test | B27: =E2 -> d) Pocas veces | C27: =E4 -> 7 | D27: =E13 -> 16 | E27: =(C27-D27)^2 -> 81 | F27: =E27/D27 -> 5.0625
A28: =A4 -> Grupo Experimental - Post Test | B28: =F2 -> e) Nunca | C28: =F4 -> 3 | D28: =F13 -> 5.5 | E28: =(C28-D28)^2 -> 6.25 | F28: =E28/D28 -> 1.1363636
A31: Calculo Chi Cuadrado
A35: Chi Cuadrado | B35: =SUM(F19:F28) -> 33.657942
A37: Calculo Grados Libertad
A39: Filas = 2 (Sin sistema, Con sistema) | C39: 2
A40: Columnas = 5 (las 5 categorías) | C40: 5
A41: Grados de libertad df | C41: =(C39-1)*(C40-1) -> 4
A43: Busqueda de Valor Critico en Tabla Chi Cuadrado
A44: df | B44: =C41 -> 4
A45: α | B45: 0.05 | C45: (el más usado en tesis)
A46: valor critico | B46: =CHIINV(B45,B44) -> 9.487729
A47: p valor | B47: =_xlfn.CHISQ.DIST.RT(B35, B44) -> 8.7578418e-07
A49: Interpretacion
A51: H0 Hipotesis Nula | B51: No existe relación entre los grupos y la variable
A52: H1 Hipotesis Alternativa | B52: Si existe relación entre los grupos y la variable
A54: si p valor < α ---> Se rechaza la hipotesis Nula
A55: α nivel de significancia | B55: =B45 -> 0.05
A56: p valor | B56: =B47 -> 8.7578418e-07
A58: Si chi cuadrado > valor critico ---> Se rechaza la hipotesis nula
A59: Chi Cuadrado | B59: =B35 -> 33.657942
...

Sheet Resolución-autónoma
A1: Tabla Valores Observados
A2: Grupo / Categoría | B2: a) Siempre | C2: b) Frecuente | D2: c) A veces | E2: d) Raro | F2: e) Nunca | G2: Total
A3: Grupo Control - Post Test | B3: 9 | C3: 19 | D3: 37 | E3: 23 | F3: 9 | G3: =SUM(B3:F3) -> 97
A4: Grupo Experimental - Post Test | B4: 49 | C4: 30 | D4: 12 | E4: 4 | F4: 2 | G4: =SUM(B4:F4) -> 97
A5: Total | B5: =SUM(B3:B4) -> 58 | C5: =SUM(C3:C4) -> 49 | D5: =SUM(D3:D4) -> 49 | E5: =SUM(E3:E4) -> 27 | F5: =SUM(F3:F4) -> 11 | G5: =SUM(G3:G4) -> 194
A7: Tabla Valores Esperados
A11: Categoria | B11: =B2 -> a) Siempre | C11: =C2 -> b) Frecuente | D11: =D2 -> c) A veces | E11: =E2 -> d) Raro | F11: =F2 -> e) Nunca | G11: =G2 -> Total
A12: =A3 -> Grupo Control - Post Test | B12: =(G3*B5)/G5 -> 29 | C12: =(G3*C5)/G5 -> 24.5 | D12: =(G3*D5)/G5 -> 24.5 | E12: =(G3*E5)/G5 -> 13.5 | F12: =(G3*F5)/G5 -> 5.5 | G12: =SUM(B12:F12) -> 97
A13: =A4 -> Grupo Experimental - Post Test | B13: =(G4*B5)/G5 -> 29 | C13: =(G4*C5)/G5 -> 24.5 | D13: =(G4*D5)/G5 -> 24.5 | E13: =(G4*E5)/G5 -> 13.5 | F13: =(G4*F5)/G5 -> 5.5 | G13: =SUM(B13:F13) -> 97
A16: Tabla completa Valores Observados (O) y Valores Esperados (E)
A18: Grupo | B18: Categoria | C18: Valor Observado (O) | D18: Valor Esperado (E )
A19: =A3 -> Grupo Control - Post Test | B19: =B2 -> a) Siempre | C19: =B3 -> 9 | D19: =B12 -> 29 | E19: =(C19-D19)^2 -> 400 | F19: =E19/D19 -> 13.793103
A20: =A3 -> Grupo Control - Post Test | B20: =C2 -> b) Frecuente | C20: =C3 -> 19 | D20: =C12 -> 24.5 | E20: =(C20-D20)^2 -> 30.25 | F20: =E20/D20 -> 1.2346939
A21: =A3 -> Grupo Control - Post Test | B21: =D2 -> c) A veces | C21: =D3 -> 37 | D21: =D12 -> 24.5 | E21: =(C21-D21)^2 -> 156.25 | F21: =E21/D21 -> 6.377551
A22: =A3 -> Grupo Control - Post Test | B22: =E2 -> d) Raro | C22: =E3 -> 23 | D22: =E12 -> 13.5 | E22: =(C22-D22)^2 -> 90.25 | F22: =E22/D22 -> 6.6851852
A23: =A3 -> Grupo Control - Post Test | B23: =F2 -> e) Nunca | C23: =F3 -> 9 | D23: =F12 -> 5.5 | E23: =(C23-D23)^2 -> 12.25 | F23: =E23/D23 -> 2.2272727
A24: =A4 -> Grupo Experimental - Post Test | B24: =B2 -> a) Siempre | C24: =B4 -> 49 | D24: =B13 -> 29 | E24: =(C24-D24)^2 -> 400 | F24: =E24/D24 -> 13.793103
A25: =A4 -> Grupo Experimental - Post Test | B25: =C2 -> b) Frecuente | C25: =C4 -> 30 | D25: =C13 -> 24.5 | E25: =(C25-D25)^2 -> 30.25 | F25: =E25/D25 -> 1.2346939
A26: =A4 -> Grupo Experimental - Post Test | B26: =D2 -> c) A veces | C26: =D4 -> 12 | D26: =D13 -> 24.5 | E26: =(C26-D26)^2 -> 156.25 | F26: =E26/D26 -> 6.377551
A27: =A4 -> Grupo Experimental - Post Test | B27: =E2 -> d) Raro | C27: =E4 -> 4 | D27: =E13 -> 13.5 | E27: =(C27-D27)^2 -> 90.25 | F27: =E27/D27 -> 6.6851852
A28: =A4 -> Grupo Experimental - Post Test | B28: =F2 -> e) Nunca | C28: =F4 -> 2 | D28: =F13 -> 5.5 | E28: =(C28-D28)^2 -> 12.25 | F28: =E28/D28 -> 2.2272727
A31: Calculo Chi Cuadrado
A35: Chi Cuadrado | B35: =SUM(F19:F28) -> 60.635613
A37: Calculo Grados Libertad
A39: Filas = 2 (Sin sistema, Con sistema) | C39: 2
A40: Columnas = 5 (las 5 categorías) | C40: 5
A41: Grados de libertad df | C41: =(C39-1)*(C40-1) -> 4
A43: Busqueda de Valor Critico en Tabla Chi Cuadrado
A44: df | B44: =C41 -> 4
A45: α | B45: 0.05 | C45: (el más usado en tesis)
A46: valor critico | B46: =CHIINV(B45,B44) -> 9.487729
A47: p valor | B47: =_xlfn.CHISQ.DIST.RT(B35, B44) -> 2.1327275e-12
A49: Interpretacion
A51: H0 Hipotesis Nula | B51: No existe relación entre los grupos y la variable
A52: H1 Hipotesis Alternativa | B52: Si existe relación entre los grupos y la variable
A54: si p valor < α ---> Se rechaza la hipotesis Nula
A55: α nivel de significancia | B55: =B45 -> 0.05
A56: p valor | B56: =B47 -> 2.1327275e-12
A58: Si chi cuadrado > valor critico ---> Se rechaza la hipotesis nula
A59: Chi Cuadrado | B59: =B35 -> 60.635613
...

Sheet Motivación
A1: Tabla Valores Observados
A2: Grupo / Categoría | B2: a) Muy alta | C2: b) Alta | D2: c) Regular | E2: d) Baja | F2: e) Muy baja | G2: Total
A3: Grupo Control - Post Test | B3: 12 | C3: 13 | D3: 42 | E3: 16 | F3: 14 | G3: =SUM(B3:F3) -> 97
A4: Grupo Experimental - Post Test | B4: 39 | C4: 29 | D4: 18 | E4: 7 | F4: 4 | G4: =SUM(B4:F4) -> 97
A5: Total | B5: =SUM(B3:B4) -> 51 | C5: =SUM(C3:C4) -> 42 | D5: =SUM(D3:D4) -> 60 | E5: =SUM(E3:E4) -> 23 | F5: =SUM(F3:F4) -> 18 | G5: =SUM(G3:G4) -> 194
A7: Tabla Valores Esperados
A11: Categoria | B11: =B2 -> a) Muy alta | C11: =C2 -> b) Alta | D11: =D2 -> c) Regular | E11: =E2 -> d) Baja | F11: =F2 -> e) Muy baja | G11: =G2 -> Total
A12: =A3 -> Grupo Control - Post Test | B12: =(G3*B5)/G5 -> 25.5 | C12: =(G3*C5)/G5 -> 21 | D12: =(G3*D5)/G5 -> 30 | E12: =(G3*E5)/G5 -> 11.5 | F12: =(G3*F5)/G5 -> 9 | G12: =SUM(B12:F12) -> 97
A13: =A4 -> Grupo Experimental - Post Test | B13: =(G4*B5)/G5 -> 25.5 | C13: =(G4*C5)/G5 -> 21 | D13: =(G4*D5)/G5 -> 30 | E13: =(G4*E5)/G5 -> 11.5 | F13: =(G4*F5)/G5 -> 9 | G13: =SUM(B13:F13) -> 97
A16: Tabla completa Valores Observados (O) y Valores Esperados (E)
A18: Grupo | B18: Categoria | C18: Valor Observado (O) | D18: Valor Esperado (E )
A19: =A3 -> Grupo Control - Post Test | B19: =B2 -> a) Muy alta | C19: =B3 -> 12 | D19: =B12 -> 25.5 | E19: =(C19-D19)^2 -> 182.25 | F19: =E19/D19 -> 7.1470588
A20: =A3 -> Grupo Control - Post Test | B20: =C2 -> b) Alta | C20: =C3 -> 13 | D20: =C12 -> 21 | E20: =(C20-D20)^2 -> 64 | F20: =E20/D20 -> 3.047619
A21: =A3 -> Grupo Control - Post Test | B21: =D2 -> c) Regular | C21: =D3 -> 42 | D21: =D12 -> 30 | E21: =(C21-D21)^2 -> 144 | F21: =E21/D21 -> 4.8
A22: =A3 -> Grupo Control - Post Test | B22: =E2 -> d) Baja | C22: =E3 -> 16 | D22: =E12 -> 11.5 | E22: =(C22-D22)^2 -> 20.25 | F22: =E22/D22 -> 1.7608696
A23: =A3 -> Grupo Control - Post Test | B23: =F2 -> e) Muy baja | C23: =F3 -> 14 | D23: =F12 -> 9 | E23: =(C23-D23)^2 -> 25 | F23: =E23/D23 -> 2.7777778
A24: =A4 -> Grupo Experimental - Post Test | B24: =B2 -> a) Muy alta | C24: =B4 -> 39 | D24: =B13 -> 25.5 | E24: =(C24-D24)^2 -> 182.25 | F24: =E24/D24 -> 7.1470588
A25: =A4 -> Grupo Experimental - Post Test | B25: =C2 -> b) Alta | C25: =C4 -> 29 | D25: =C13 -> 21 | E25: =(C25-D25)^2 -> 64 | F25: =E25/D25 -> 3.047619
A26: =A4 -> Grupo Experimental - Post Test | B26: =D2 -> c) Regular | C26: =D4 -> 18 | D26: =D13 -> 30 | E26: =(C26-D26)^2 -> 144 | F26: =E26/D26 -> 4.8
A27: =A4 -> Grupo Experimental - Post Test | B27: =E2 -> d) Baja | C27: =E4 -> 7 | D27: =E13 -> 11.5 | E27: =(C27-D27)^2 -> 20.25 | F27: =E27/D27 -> 1.7608696
A28: =A4 -> Grupo Experimental - Post Test | B28: =F2 -> e) Muy baja | C28: =F4 -> 4 | D28: =F13 -> 9 | E28: =(C28-D28)^2 -> 25 | F28: =E28/D28 -> 2.7777778
A31: Calculo Chi Cuadrado
A35: Chi Cuadrado | B35: =SUM(F19:F28) -> 39.06665
A37: Calculo Grados Libertad
A39: Filas = 2 (Sin sistema, Con sistema) | C39: 2
A40: Columnas = 5 (las 5 categorías) | C40: 5
A41: Grados de libertad df | C41: =(C39-1)*(C40-1) -> 4
A43: Busqueda de Valor Critico en Tabla Chi Cuadrado
A44: df | B44: =C41 -> 4
A45: α | B45: 0.05 | C45: (el más usado en tesis)
A46: valor critico | B46: =CHIINV(B45,B44) -> 9.487729
A47: p valor | B47: =_xlfn.CHISQ.DIST.RT(B35, B44) -> 6.74907e-08
A49: Interpretacion
A51: H0 Hipotesis Nula | B51: No existe relación entre los grupos y la variable
A52: H1 Hipotesis Alternativa | B52: Si existe relación entre los grupos y la variable
A54: si p valor < α ---> Se rechaza la hipotesis Nula
A55: α nivel de significancia | B55: =B45 -> 0.05
A56: p valor | B56: =B47 -> 6.74907e-08
A58: Si chi cuadrado > valor critico ---> Se rechaza la hipotesis nula
A59: Chi Cuadrado | B59: =B35 -> 39.06665
...
