Workbook

Sheet Resumen
A1: Indicador | B1: T Calculado | C1: T Critico 2 Colas | D1: T Critico 1 Cola | E1: P valor 2 Colas | F1: P valor 1 Cola
A2: Participación activa | B2: =ROUND('Participación-activa'!E29, 4) -> 0.4266 | C2: =ROUND('Participación-activa'!E52, 4) -> 1.9725 | D2: =ROUND('Participación-activa'!E53, 4) -> -1.6529 | E2: =ROUND('Participación-activa'!E55, 4) -> 0.6701 | F2: =ROUND('Participación-activa'!E56, 4) -> 0.3351
A3: Comunicación equipo | B3: =ROUND('Comunicación-equipo'!E29, 4) -> -0.6835 | C3: =ROUND('Comunicación-equipo'!E52, 4) -> 1.9725 | D3: =ROUND('Comunicación-equipo'!E53, 4) -> -1.6529 | E3: =ROUND('Comunicación-equipo'!E55, 4) -> 0.4951 | F3: =ROUND('Comunicación-equipo'!E56, 4) -> 0.2476
A4: Cumplimiento tareas | B4: =ROUND('Cumplimiento-tareas'!E29, 4) -> 0.6922 | C4: =ROUND('Cumplimiento-tareas'!E52, 4) -> 1.9726 | D4: =ROUND('Cumplimiento-tareas'!E53, 4) -> -1.653 | E4: =ROUND('Cumplimiento-tareas'!E55, 4) -> 0.4897 | F4: =ROUND('Cumplimiento-tareas'!E56, 4) -> 0.2448
A5: Contribución grupo | B5: =ROUND('Contribución-grupo'!E29, 4) -> 0.5956 | C5: =ROUND('Contribución-grupo'!E52, 4) -> 1.9729 | D5: =ROUND('Contribución-grupo'!E53, 4) -> -1.6532 | E5: =ROUND('Contribución-grupo'!E55, 4) -> 0.5521 | F5: =ROUND('Contribución-grupo'!E56, 4) -> 0.2761
A6: Resolución problemas | B6: =ROUND('Resolución-problemas'!E29, 4) -> -0.6062 | C6: =ROUND('Resolución-problemas'!E52, 4) -> 1.9726 | D6: =ROUND('Resolución-problemas'!E53, 4) -> -1.653 | E6: =ROUND('Resolución-problemas'!E55, 4) -> 0.5451 | F6: =ROUND('Resolución-problemas'!E56, 4) -> 0.2725
A7: Conocimientos adquiridos | B7: =ROUND('Conocimientos-adquiridos'!E29, 4) -> 1.1087 | C7: =ROUND('Conocimientos-adquiridos'!E52, 4) -> 1.9725 | D7: =ROUND('Conocimientos-adquiridos'!E53, 4) -> -1.6529 | E7: =ROUND('Conocimientos-adquiridos'!E55, 4) -> 0.2689 | F7: =ROUND('Conocimientos-adquiridos'!E56, 4) -> 0.1345
A8: Nota final | B8: =ROUND('Nota-final'!E29, 4) -> 0.2691 | C8: =ROUND('Nota-final'!E52, 4) -> 1.9725 | D8: =ROUND('Nota-final'!E53, 4) -> -1.6529 | E8: =ROUND('Nota-final'!E55, 4) -> 0.7881 | F8: =ROUND('Nota-final'!E56, 4) -> 0.3941
A9: Comprensión | B9: =ROUND(Comprensión!E29, 4) -> 0.0613 | C9: =ROUND(Comprensión!E52, 4) -> 1.9725 | D9: =ROUND(Comprensión!E53, 4) -> -1.6529 | E9: =ROUND(Comprensión!E55, 4) -> 0.9512 | F9: =ROUND(Comprensión!E56, 4) -> 0.4756
A10: Habilidades | B10: =ROUND(Habilidades!E29, 4) -> 1.2188 | C10: =ROUND(Habilidades!E52, 4) -> 1.9725 | D10: =ROUND(Habilidades!E53, 4) -> -1.6529 | E10: =ROUND(Habilidades!E55, 4) -> 0.2244 | F10: =ROUND(Habilidades!E56, 4) -> 0.1122
A11: Resolución autónoma | B11: =ROUND('Resolución-autónoma'!E29, 4) -> -0.2696 | C11: =ROUND('Resolución-autónoma'!E52, 4) -> 1.9725 | D11: =ROUND('Resolución-autónoma'!E53, 4) -> -1.6529 | E11: =ROUND('Resolución-autónoma'!E55, 4) -> 0.7878 | F11: =ROUND('Resolución-autónoma'!E56, 4) -> 0.3939
A12: Motivación | B12: =ROUND(Motivación!E29, 4) -> 0.5471 | C12: =ROUND(Motivación!E52, 4) -> 1.9725 | D12: =ROUND(Motivación!E53, 4) -> -1.6529 | E12: =ROUND(Motivación!E55, 4) -> 0.585 | F12: =ROUND(Motivación!E56, 4) -> 0.2925

Sheet Participación-activa
A1: (Sin Aprendizaje Colaborativo) Grupo Control - Pre-test Participación-activa | B1: (Sin Aprendizaje Colaborativo) Grupo Experimental - Pre-test Participación-activa
A2: 2 | B2: 4 | D2: Media (X1) Grupo Control | E2: =AVERAGE(A:A) -> 3.185567
A3: 4 | B3: 1 | D3: Mediana (Me1) | E3: =MEDIAN(A:A) -> 3
A4: 2 | B4: 3 | D4: Moda (Mo1) | E4: =MODE(A:A) -> 3
A5: 3 | B5: 2 | D5: Desviacion Tipica o Estandar (S1) | E5: =STDEV(A:A) -> 1.2018206
A6: 2 | B6: 3 | D6: n1 | E6: =COUNT(A:A) -> 97
A7: 1 | B7: 5
A8: 5 | B8: 3 | D8: Media (X2) Grupo Experimental | E8: =AVERAGE(B:B) -> 3.1134021
A9: 3 | B9: 5 | D9: Mediana (Me2) | E9: =MEDIAN(B:B) -> 3
A10: 3 | B10: 3 | D10: Moda (Mo2) | E10: =MODE(B:B) -> 3
A11: 5 | B11: 2 | D11: Desviacion Tipica o Estandar (S2) | E11: =STDEV(B:B) -> 1.153584
A12: 2 | B12: 4 | D12: n2 | E12: =COUNT(B:B) -> 97
A13: 4 | B13: 2
A14: 5 | B14: 3
A15: 5 | B15: 3
A16: 1 | B16: 4
A17: 3 | B17: 2 | D17: t de student
A18: 5 | B18: 2
A19: 4 | B19: 1
A20: 2 | B20: 5
A21: 4 | B21: 4
A22: 2 | B22: 3
A23: 3 | B23: 2
A24: 2 | B24: 1
A25: 1 | B25: 4
A26: 5 | B26: 3
A27: 5 | B27: 4
A28: 3 | B28: 5
A29: 3 | B29: 2 | D29: Valor de t | E29: =(E2-E8)/SQRT(((E5^2)/E6)+((E11^2)/E12)) -> 0.42664887
A30: 4 | B30: 5
A31: 5 | B31: 3 | D31: df grados de libertad
A32: 4 | B32: 5
A33: 5 | B33: 3
A34: 2 | B34: 4
A35: 3 | B35: 2
A36: 3 | B36: 2
A37: 3 | B37: 2
A38: 3 | B38: 3
A39: 5 | B39: 3
A40: 5 | B40: 1
...

Sheet Comunicación-equipo
A1: (Sin Aprendizaje Colaborativo) Grupo Control - Pre-test Comunicación-equipo | B1: (Sin Aprendizaje Colaborativo) Grupo Experimental - Pre-test Comprensión-contenidos
A2: 3 | B2: 2 | D2: Media (X1) Grupo Control | E2: =AVERAGE(A:A) -> 2.9278351
A3: 4 | B3: 5 | D3: Mediana (Me1) | E3: =MEDIAN(A:A) -> 3
A4: 2 | B4: 1 | D4: Moda (Mo1) | E4: =MODE(A:A) -> 3
A5: 5 | B5: 4 | D5: Desviacion Tipica o Estandar (S1) | E5: =STDEV(A:A) -> 1.1295964
A6: 3 | B6: 2 | D6: n1 | E6: =COUNT(A:A) -> 97
A7: 2 | B7: 2
A8: 3 | B8: 3 | D8: Media (X2) Grupo Experimental | E8: =AVERAGE(B:B) -> 3.0412371
A9: 3 | B9: 3 | D9: Mediana (Me2) | E9: =MEDIAN(B:B) -> 3
A10: 5 | B10: 4 | D10: Moda (Mo2) | E10: =MODE(B:B) -> 3
A11: 1 | B11: 4 | D11: Desviacion Tipica o Estandar (S2) | E11: =STDEV(B:B) -> 1.1807265
A12: 3 | B12: 3 | D12: n2 | E12: =COUNT(B:B) -> 97
A13: 2 | B13: 2
A14: 3 | B14: 3
A15: 4 | B15: 3
A16: 3 | B16: 3
A17: 4 | B17: 1 | D17: t de student
A18: 1 | B18: 3
A19: 3 | B19: 5
A20: 3 | B20: 3
A21: 2 | B21: 3
A22: 3 | B22: 4
A23: 2 | B23: 2
A24: 4 | B24: 2
A25: 1 | B25: 3
A26: 3 | B26: 2
A27: 3 | B27: 1
A28: 5 | B28: 3
A29: 4 | B29: 2 | D29: Valor de t | E29: =(E2-E8)/SQRT(((E5^2)/E6)+((E11^2)/E12)) -> -0.68350674
A30: 5 | B30: 5
A31: 3 | B31: 3 | D31: df grados de libertad
A32: 1 | B32: 5
A33: 2 | B33: 5
A34: 3 | B34: 2
A35: 4 | B35: 5
A36: 5 | B36: 2
A37: 4 | B37: 4
A38: 3 | B38: 2
A39: 3 | B39: 3
A40: 3 | B40: 3
...

Sheet Cumplimiento-tareas
A1: (Sin Aprendizaje Colaborativo) Grupo Control - Pre-test Cumplimiento-tareas | B1: (Sin Aprendizaje Colaborativo) Grupo Experimental - Pre-test Cumplimiento-tareas
A2: 3 | B2: 5 | D2: Media (X1) Grupo Control | E2: =AVERAGE(A:A) -> 3.2886598
A3: 3 | B3: 3 | D3: Mediana (Me1) | E3: =MEDIAN(A:A) -> 3
A4: 5 | B4: 5 | D4: Moda (Mo1) | E4: =MODE(A:A) -> 3
A5: 4 | B5: 3 | D5: Desviacion Tipica o Estandar (S1) | E5: =STDEV(A:A) -> 1.207259
A6: 4 | B6: 2 | D6: n1 | E6: =COUNT(A:A) -> 97
A7: 2 | B7: 4
A8: 3 | B8: 5 | D8: Media (X2) Grupo Experimental | E8: =AVERAGE(B:B) -> 3.1752577
A9: 5 | B9: 3 | D9: Mediana (Me2) | E9: =MEDIAN(B:B) -> 3
A10: 2 | B10: 3 | D10: Moda (Mo2) | E10: =MODE(B:B) -> 3
A11: 4 | B11: 4 | D11: Desviacion Tipica o Estandar (S2) | E11: =STDEV(B:B) -> 1.0705364
A12: 1 | B12: 4 | D12: n2 | E12: =COUNT(B:B) -> 97
A13: 3 | B13: 2
A14: 4 | B14: 2
A15: 5 | B15: 4
A16: 3 | B16: 3
A17: 2 | B17: 3 | D17: t de student
A18: 3 | B18: 3
A19: 5 | B19: 5
A20: 4 | B20: 4
A21: 5 | B21: 4
A22: 3 | B22: 2
A23: 2 | B23: 4
A24: 2 | B24: 4
A25: 2 | B25: 3
A26: 2 | B26: 3
A27: 4 | B27: 2
A28: 3 | B28: 4
A29: 1 | B29: 4 | D29: Valor de t | E29: =(E2-E8)/SQRT(((E5^2)/E6)+((E11^2)/E12)) -> 0.69219134
A30: 4 | B30: 3
A31: 4 | B31: 5 | D31: df grados de libertad
A32: 5 | B32: 4
A33: 4 | B33: 2
A34: 2 | B34: 4
A35: 2 | B35: 3
A36: 3 | B36: 1
A37: 2 | B37: 3
A38: 4 | B38: 1
A39: 5 | B39: 3
A40: 5 | B40: 2
...

Sheet Contribución-grupo
A1: (Sin Aprendizaje Colaborativo) Grupo control - Pre-test Contribución-grupo | B1: (Sin Aprendizaje Colaborativo) Grupo Experimental - Pre-test Contribución-grupo
A2: 4 | B2: 3 | D2: Media (X1) Grupo Control | E2: =AVERAGE(A:A) -> 3.1030928
A3: 2 | B3: 3 | D3: Mediana (Me1) | E3: =MEDIAN(A:A) -> 3
A4: 5 | B4: 3 | D4: Moda (Mo1) | E4: =MODE(A:A) -> 3
A5: 3 | B5: 3 | D5: Desviacion Tipica o Estandar (S1) | E5: =STDEV(A:A) -> 0.97344466
A6: 3 | B6: 4 | D6: n1 | E6: =COUNT(A:A) -> 97
A7: 1 | B7: 3
A8: 3 | B8: 3 | D8: Media (X2) Grupo Experimental | E8: =AVERAGE(B:B) -> 3.0103093
A9: 3 | B9: 4 | D9: Mediana (Me2) | E9: =MEDIAN(B:B) -> 3
A10: 3 | B10: 1 | D10: Moda (Mo2) | E10: =MODE(B:B) -> 3
A11: 4 | B11: 3 | D11: Desviacion Tipica o Estandar (S2) | E11: =STDEV(B:B) -> 1.1858088
A12: 4 | B12: 3 | D12: n2 | E12: =COUNT(B:B) -> 97
A13: 4 | B13: 2
A14: 2 | B14: 4
A15: 3 | B15: 4
A16: 4 | B16: 2
A17: 3 | B17: 1 | D17: t de student
A18: 4 | B18: 3
A19: 2 | B19: 2
A20: 3 | B20: 2
A21: 5 | B21: 4
A22: 3 | B22: 3
A23: 5 | B23: 3
A24: 3 | B24: 3
A25: 4 | B25: 4
A26: 3 | B26: 2
A27: 3 | B27: 3
A28: 3 | B28: 5
A29: 3 | B29: 3 | D29: Valor de t | E29: =(E2-E8)/SQRT(((E5^2)/E6)+((E11^2)/E12)) -> 0.59563151
A30: 3 | B30: 3
A31: 3 | B31: 3 | D31: df grados de libertad
A32: 3 | B32: 4
A33: 3 | B33: 3
A34: 5 | B34: 3
A35: 4 | B35: 1
A36: 3 | B36: 3
A37: 2 | B37: 2
A38: 5 | B38: 1
A39: 3 | B39: 1
A40: 4 | B40: 5
...

Sheet Resolución-problemas
A1: (Sin Aprendizaje Colaborativo) Grupo Control - Pre-test Resolución-problemas | B1: (Sin Aprendizaje Colaborativo) Grupo Experimental - Pre-test Resolución-problemas
A2: 2 | B2: 5 | D2: Media (X1) Grupo Control | E2: =AVERAGE(A:A) -> 2.9793814
A3: 3 | B3: 4 | D3: Mediana (Me1) | E3: =MEDIAN(A:A) -> 3
A4: 4 | B4: 3 | D4: Moda (Mo1) | E4: =MODE(A:A) -> 3
A5: 1 | B5: 2 | D5: Desviacion Tipica o Estandar (S1) | E5: =STDEV(A:A) -> 1.1178419
A6: 3 | B6: 2 | D6: n1 | E6: =COUNT(A:A) -> 97
A7: 4 | B7: 2
A8: 5 | B8: 5 | D8: Media (X2) Grupo Experimental | E8: =AVERAGE(B:B) -> 3.0824742
A9: 2 | B9: 2 | D9: Mediana (Me2) | E9: =MEDIAN(B:B) -> 3
A10: 3 | B10: 3 | D10: Moda (Mo2) | E10: =MODE(B:B) -> 3
A11: 3 | B11: 2 | D11: Desviacion Tipica o Estandar (S2) | E11: =STDEV(B:B) -> 1.2472478
A12: 3 | B12: 1 | D12: n2 | E12: =COUNT(B:B) -> 97
A13: 5 | B13: 2
A14: 2 | B14: 2
A15: 3 | B15: 4
A16: 1 | B16: 2
A17: 3 | B17: 5 | D17: t de student
A18: 3 | B18: 3
A19: 4 | B19: 3
A20: 3 | B20: 3
A21: 3 | B21: 2
A22: 2 | B22: 2
A23: 2 | B23: 3
A24: 2 | B24: 4
A25: 3 | B25: 2
A26: 5 | B26: 3
A27: 1 | B27: 1
A28: 3 | B28: 3
A29: 3 | B29: 4 | D29: Valor de t | E29: =(E2-E8)/SQRT(((E5^2)/E6)+((E11^2)/E12)) -> -0.60622299
A30: 2 | B30: 5
A31: 4 | B31: 3 | D31: df grados de libertad
A32: 5 | B32: 3
A33: 2 | B33: 2
A34: 5 | B34: 4
A35: 5 | B35: 2
A36: 2 | B36: 4
A37: 3 | B37: 5
A38: 5 | B38: 4
A39: 1 | B39: 1
A40: 3 | B40: 5
...

Sheet Conocimientos-adquiridos
A1: (Sin Aprendizaje Colaborativo) Grupo Control - Pre-test Conocimientos-adquiridos | B1: (Sin Aprendizaje Colaborativo) Grupo Experimental - Pre-test Conocimientos-adquiridos
A2: 2 | B2: 3 | D2: Media (X1) Grupo Control | E2: =AVERAGE(A:A) -> 3.2268041
A3: 2 | B3: 3 | D3: Mediana (Me1) | E3: =MEDIAN(A:A) -> 3
A4: 5 | B4: 3 | D4: Moda (Mo1) | E4: =MODE(A:A) -> 3
A5: 4 | B5: 5 | D5: Desviacion Tipica o Estandar (S1) | E5: =STDEV(A:A) -> 1.1227306
A6: 5 | B6: 4 | D6: n1 | E6: =COUNT(A:A) -> 97
A7: 5 | B7: 3
A8: 5 | B8: 4 | D8: Media (X2) Grupo Experimental | E8: =AVERAGE(B:B) -> 3.0412371
A9: 2 | B9: 3 | D9: Mediana (Me2) | E9: =MEDIAN(B:B) -> 3
A10: 4 | B10: 4 | D10: Moda (Mo2) | E10: =MODE(B:B) -> 3
A11: 3 | B11: 2 | D11: Desviacion Tipica o Estandar (S2) | E11: =STDEV(B:B) -> 1.2069031
A12: 3 | B12: 1 | D12: n2 | E12: =COUNT(B:B) -> 97
A13: 4 | B13: 3
A14: 3 | B14: 5
A15: 4 | B15: 5
A16: 3 | B16: 2
A17: 3 | B17: 3 | D17: t de student
A18: 4 | B18: 3
A19: 3 | B19: 4
A20: 3 | B20: 2
A21: 3 | B21: 5
A22: 4 | B22: 1
A23: 4 | B23: 4
A24: 1 | B24: 5
A25: 5 | B25: 3
A26: 5 | B26: 3
A27: 4 | B27: 3
A28: 4 | B28: 3
A29: 3 | B29: 5 | D29: Valor de t | E29: =(E2-E8)/SQRT(((E5^2)/E6)+((E11^2)/E12)) -> 1.1087425
A30: 2 | B30: 5
A31: 5 | B31: 2 | D31: df grados de libertad
A32: 4 | B32: 1
A33: 3 | B33: 3
A34: 4 | B34: 3
A35: 1 | B35: 2
A36: 3 | B36: 3
A37: 3 | B37: 2
A38: 5 | B38: 3
A39: 3 | B39: 3
A40: 3 | B40: 3
...

Sheet Nota-final
A1: (Sin Aprendizaje Colaborativo) Grupo Control - Pre-test Nota-final | B1: (Sin Aprendizaje Colaborativo) Grupo Experimental - Pre-test Nota-final
A2: 3 | B2: 3 | D2: Media (X1) Grupo Control | E2: =AVERAGE(A:A) -> 2.9381443
A3: 4 | B3: 3 | D3: Mediana (Me1) | E3: =MEDIAN(A:A) -> 3
A4: 3 | B4: 3 | D4: Moda (Mo1) | E4: =MODE(A:A) -> 3
A5: 3 | B5: 2 | D5: Desviacion Tipica o Estandar (S1) | E5: =STDEV(A:A) -> 1.0974823
A6: 2 | B6: 3 | D6: n1 | E6: =COUNT(A:A) -> 97
A7: 2 | B7: 3
A8: 3 | B8: 3 | D8: Media (X2) Grupo Experimental | E8: =AVERAGE(B:B) -> 2.8969072
A9: 1 | B9: 3 | D9: Mediana (Me2) | E9: =MEDIAN(B:B) -> 3
A10: 4 | B10: 1 | D10: Moda (Mo2) | E10: =MODE(B:B) -> 3
A11: 5 | B11: 4 | D11: Desviacion Tipica o Estandar (S2) | E11: =STDEV(B:B) -> 1.0356614
A12: 1 | B12: 1 | D12: n2 | E12: =COUNT(B:B) -> 97
A13: 3 | B13: 4
A14: 5 | B14: 2
A15: 3 | B15: 1
A16: 3 | B16: 3
A17: 3 | B17: 2 | D17: t de student
A18: 2 | B18: 4
A19: 3 | B19: 3
A20: 3 | B20: 3
A21: 4 | B21: 4
A22: 3 | B22: 3
A23: 4 | B23: 2
A24: 3 | B24: 5
A25: 3 | B25: 1
A26: 4 | B26: 5
A27: 2 | B27: 2
A28: 2 | B28: 5
A29: 2 | B29: 1 | D29: Valor de t | E29: =(E2-E8)/SQRT(((E5^2)/E6)+((E11^2)/E12)) -> 0.26914524
A30: 1 | B30: 4
A31: 3 | B31: 2 | D31: df grados de libertad
A32: 4 | B32: 5
A33: 3 | B33: 2
A34: 4 | B34: 4
A35: 2 | B35: 3
A36: 1 | B36: 3
A37: 5 | B37: 2
A38: 2 | B38: 4
A39: 3 | B39: 1
A40: 3 | B40: 2
...

Sheet Comprensión
A1: (Sin Aprendizaje Colaborativo) Grupo Control - Pre-test Comprensión | B1: (Sin Aprendizaje Colaborativo) Grupo Experimental - Pre-test Comprensión
A2: 3 | B2: 5 | D2: Media (X1) Grupo Control | E2: =AVERAGE(A:A) -> 3.1340206
A3: 3 | B3: 3 | D3: Mediana (Me1) | E3: =MEDIAN(A:A) -> 3
A4: 1 | B4: 4 | D4: Moda (Mo1) | E4: =MODE(A:A) -> 3
A5: 3 | B5: 3 | D5: Desviacion Tipica o Estandar (S1) | E5: =STDEV(A:A) -> 1.2300819
A6: 3 | B6: 4 | D6: n1 | E6: =COUNT(A:A) -> 97
A7: 3 | B7: 2
A8: 3 | B8: 3 | D8: Media (X2) Grupo Experimental | E8: =AVERAGE(B:B) -> 3.1237113
A9: 4 | B9: 4 | D9: Mediana (Me2) | E9: =MEDIAN(B:B) -> 3
A10: 3 | B10: 4 | D10: Moda (Mo2) | E10: =MODE(B:B) -> 3
A11: 5 | B11: 4 | D11: Desviacion Tipica o Estandar (S2) | E11: =STDEV(B:B) -> 1.1110968
A12: 1 | B12: 3 | D12: n2 | E12: =COUNT(B:B) -> 97
A13: 2 | B13: 2
A14: 5 | B14: 3
A15: 2 | B15: 3
A16: 3 | B16: 1
A17: 4 | B17: 3 | D17: t de student
A18: 4 | B18: 5
A19: 3 | B19: 4
A20: 2 | B20: 2
A21: 4 | B21: 2
A22: 3 | B22: 4
A23: 4 | B23: 4
A24: 5 | B24: 4
A25: 4 | B25: 5
A26: 4 | B26: 3
A27: 5 | B27: 5
A28: 3 | B28: 2
A29: 3 | B29: 4 | D29: Valor de t | E29: =(E2-E8)/SQRT(((E5^2)/E6)+((E11^2)/E12)) -> 0.061253995
A30: 2 | B30: 2
A31: 2 | B31: 3 | D31: df grados de libertad
A32: 5 | B32: 3
A33: 3 | B33: 3
A34: 4 | B34: 4
A35: 4 | B35: 5
A36: 4 | B36: 3
A37: 2 | B37: 2
A38: 3 | B38: 5
A39: 2 | B39: 5
A40: 3 | B40: 2
...

Sheet Habilidades
A1: (Sin Aprendizaje Colaborativo) Grupo Control - Pre-test Habilidades | B1: (Sin Aprendizaje Colaborativo) Grupo Experimental - Pre-test Habilidades
A2: 4 | B2: 3 | D2: Media (X1) Grupo Control | E2: =AVERAGE(A:A) -> 3.1546392
A3: 4 | B3: 3 | D3: Mediana (Me1) | E3: =MEDIAN(A:A) -> 3
A4: 3 | B4: 5 | D4: Moda (Mo1) | E4: =MODE(A:A) -> 3
A5: 3 | B5: 3 | D5: Desviacion Tipica o Estandar (S1) | E5: =STDEV(A:A) -> 1.1118697
A6: 5 | B6: 4 | D6: n1 | E6: =COUNT(A:A) -> 97
A7: 3 | B7: 2
A8: 4 | B8: 4 | D8: Media (X2) Grupo Experimental | E8: =AVERAGE(B:B) -> 2.9587629
A9: 3 | B9: 3 | D9: Mediana (Me2) | E9: =MEDIAN(B:B) -> 3
A10: 5 | B10: 2 | D10: Moda (Mo2) | E10: =MODE(B:B) -> 3
A11: 4 | B11: 4 | D11: Desviacion Tipica o Estandar (S2) | E11: =STDEV(B:B) -> 1.1265501
A12: 3 | B12: 2 | D12: n2 | E12: =COUNT(B:B) -> 97
A13: 3 | B13: 2
A14: 3 | B14: 5
A15: 1 | B15: 5
A16: 3 | B16: 5
A17: 1 | B17: 5 | D17: t de student
A18: 5 | B18: 3
A19: 1 | B19: 1
A20: 4 | B20: 3
A21: 4 | B21: 1
A22: 2 | B22: 5
A23: 2 | B23: 4
A24: 4 | B24: 3
A25: 3 | B25: 2
A26: 4 | B26: 1
A27: 4 | B27: 3
A28: 2 | B28: 3
A29: 2 | B29: 2 | D29: Valor de t | E29: =(E2-E8)/SQRT(((E5^2)/E6)+((E11^2)/E12)) -> 1.2187983
A30: 3 | B30: 5
A31: 3 | B31: 1 | D31: df grados de libertad
A32: 5 | B32: 3
A33: 3 | B33: 3
A34: 4 | B34: 5
A35: 3 | B35: 3
A36: 3 | B36: 4
A37: 4 | B37: 3
A38: 2 | B38: 4
A39: 2 | B39: 2
A40: 5 | B40: 4
...

Sheet Resolución-autónoma
A1: (Sin Aprendizaje Colaborativo) Grupo Control - Pre-test Resolución-autónoma | B1: (Sin Aprendizaje Colaborativo) Grupo Experimental - Pre-test Resolución-autónoma
A2: 3 | B2: 1 | D2: Media (X1) Grupo Control | E2: =AVERAGE(A:A) -> 2.9793814
A3: 4 | B3: 1 | D3: Mediana (Me1) | E3: =MEDIAN(A:A) -> 3
A4: 3 | B4: 3 | D4: Moda (Mo1) | E4: =MODE(A:A) -> 3
A5: 3 | B5: 3 | D5: Desviacion Tipica o Estandar (S1) | E5: =STDEV(A:A) -> 1.0505889
A6: 3 | B6: 1 | D6: n1 | E6: =COUNT(A:A) -> 97
A7: 3 | B7: 3
A8: 3 | B8: 4 | D8: Media (X2) Grupo Experimental | E8: =AVERAGE(B:B) -> 3.0206186
A9: 3 | B9: 1 | D9: Mediana (Me2) | E9: =MEDIAN(B:B) -> 3
A10: 4 | B10: 4 | D10: Moda (Mo2) | E10: =MODE(B:B) -> 3
A11: 3 | B11: 4 | D11: Desviacion Tipica o Estandar (S2) | E11: =STDEV(B:B) -> 1.0799246
A12: 5 | B12: 3 | D12: n2 | E12: =COUNT(B:B) -> 97
A13: 3 | B13: 2
A14: 1 | B14: 3
A15: 2 | B15: 1
A16: 2 | B16: 3
A17: 3 | B17: 5 | D17: t de student
A18: 2 | B18: 3
A19: 3 | B19: 3
A20: 4 | B20: 3
A21: 5 | B21: 5
A22: 2 | B22: 3
A23: 3 | B23: 5
A24: 3 | B24: 3
A25: 4 | B25: 4
A26: 5 | B26: 3
A27: 2 | B27: 3
A28: 2 | B28: 3
A29: 2 | B29: 4 | D29: Valor de t | E29: =(E2-E8)/SQRT(((E5^2)/E6)+((E11^2)/E12)) -> -0.2695651
A30: 2 | B30: 3
A31: 4 | B31: 3 | D31: df grados de libertad
A32: 3 | B32: 4
A33: 4 | B33: 3
A34: 3 | B34: 2
A35: 3 | B35: 3
A36: 2 | B36: 3
A37: 1 | B37: 2
A38: 3 | B38: 5
A39: 3 | B39: 3
A40: 2 | B40: 2
...

Sheet Motivación
A1: (Sin Aprendizaje Colaborativo) Grupo Control - Pre-test Motivación | B1: (Sin Aprendizaje Colaborativo) Grupo Experimental - Pre-test Motivación
A2: 4 | B2: 3 | D2: Media (X1) Grupo Control | E2: =AVERAGE(A:A) -> 3.0309278
A3: 4 | B3: 4 | D3: Mediana (Me1) | E3: =MEDIAN(A:A) -> 3
A4: 2 | B4: 2 | D4: Moda (Mo1) | E4: =MODE(A:A) -> 3
A5: 3 | B5: 1 | D5: Desviacion Tipica o Estandar (S1) | E5: =STDEV(A:A) -> 1.0552805
A6: 3 | B6: 3 | D6: n1 | E6: =COUNT(A:A) -> 97
A7: 2 | B7: 3
A8: 4 | B8: 3 | D8: Media (X2) Grupo Experimental | E8: =AVERAGE(B:B) -> 2.9484536
A9: 3 | B9: 2 | D9: Mediana (Me2) | E9: =MEDIAN(B:B) -> 3
A10: 3 | B10: 3 | D10: Moda (Mo2) | E10: =MODE(B:B) -> 3
A11: 1 | B11: 3 | D11: Desviacion Tipica o Estandar (S2) | E11: =STDEV(B:B) -> 1.0445407
A12: 1 | B12: 2 | D12: n2 | E12: =COUNT(B:B) -> 97
A13: 4 | B13: 4
A14: 4 | B14: 3
A15: 5 | B15: 5
A16: 5 | B16: 3
A17: 2 | B17: 3 | D17: t de student
A18: 3 | B18: 3
A19: 3 | B19: 3
A20: 4 | B20: 4
A21: 3 | B21: 2
A22: 2 | B22: 2
A23: 3 | B23: 3
A24: 1 | B24: 4
A25: 3 | B25: 2
A26: 3 | B26: 4
A27: 4 | B27: 4
A28: 3 | B28: 1
A29: 3 | B29: 3 | D29: Valor de t | E29: =(E2-E8)/SQRT(((E5^2)/E6)+((E11^2)/E12)) -> 0.54705517
A30: 3 | B30: 1
A31: 3 | B31: 3 | D31: df grados de libertad
A32: 5 | B32: 3
A33: 3 | B33: 5
A34: 1 | B34: 3
A35: 5 | B35: 1
A36: 1 | B36: 5
A37: 3 | B37: 3
A38: 2 | B38: 3
A39: 2 | B39: 4
A40: 3 | B40: 4
...
