Workbook

Sheet Resumen
A1: Indicador | B1: T Calculado | C1: T Critico 2 Colas | D1: T Critico 1 Cola | E1: P valor 2 Colas | F1: P valor 1 Cola
A2: Participación activa | B2: =ROUND('Participación-activa'!G12, 4) -> -1.0689 | C2: =ROUND('Participación-activa'!G23, 4) -> 1.985 | D2: =ROUND('Participación-activa'!G24, 4) -> -1.6609 | E2: =ROUND('Participación-activa'!G29, 4) -> 0.2878 | F2: =ROUND('Participación-activa'!G30, 4) -> 0.1439
A3: Comunicación equipo | B3: =ROUND('Comunicación-equipo'!G12, 4) -> 1.0645 | C3: =ROUND('Comunicación-equipo'!G23, 4) -> 1.985 | D3: =ROUND('Comunicación-equipo'!G24, 4) -> -1.6609 | E3: =ROUND('Comunicación-equipo'!G29, 4) -> 0.2898 | F3: =ROUND('Comunicación-equipo'!G30, 4) -> 0.1449
A4: Cumplimiento tareas | B4: =ROUND('Cumplimiento-tareas'!G12, 4) -> -0.9262 | C4: =ROUND('Cumplimiento-tareas'!G23, 4) -> 1.985 | D4: =ROUND('Cumplimiento-tareas'!G24, 4) -> -1.6609 | E4: =ROUND('Cumplimiento-tareas'!G29, 4) -> 0.3567 | F4: =ROUND('Cumplimiento-tareas'!G30, 4) -> 0.1783
A5: Contribución grupo | B5: =ROUND('Contribución-grupo'!G12, 4) -> 0.6425 | C5: =ROUND('Contribución-grupo'!G23, 4) -> 1.985 | D5: =ROUND('Contribución-grupo'!G24, 4) -> -1.6609 | E5: =ROUND('Contribución-grupo'!G29, 4) -> 0.522 | F5: =ROUND('Contribución-grupo'!G30, 4) -> 0.261
A6: Resolución problemas | B6: =ROUND('Resolución-problemas'!G12, 4) -> 1.9157 | C6: =ROUND('Resolución-problemas'!G23, 4) -> 1.985 | D6: =ROUND('Resolución-problemas'!G24, 4) -> -1.6609 | E6: =ROUND('Resolución-problemas'!G29, 4) -> 0.0584 | F6: =ROUND('Resolución-problemas'!G30, 4) -> 0.0292
A7: Conocimientos adquiridos | B7: =ROUND('Conocimientos-adquiridos'!G12, 4) -> -0.5151 | C7: =ROUND('Conocimientos-adquiridos'!G23, 4) -> 1.985 | D7: =ROUND('Conocimientos-adquiridos'!G24, 4) -> -1.6609 | E7: =ROUND('Conocimientos-adquiridos'!G29, 4) -> 0.6077 | F7: =ROUND('Conocimientos-adquiridos'!G30, 4) -> 0.3038
A8: Nota final | B8: =ROUND('Nota-final'!G12, 4) -> -0.9961 | C8: =ROUND('Nota-final'!G23, 4) -> 1.985 | D8: =ROUND('Nota-final'!G24, 4) -> -1.6609 | E8: =ROUND('Nota-final'!G29, 4) -> 0.3217 | F8: =ROUND('Nota-final'!G30, 4) -> 0.1609
A9: Comprensión | B9: =ROUND('Comprensión'!G12, 4) -> -0.3978 | C9: =ROUND('Comprensión'!G23, 4) -> 1.985 | D9: =ROUND('Comprensión'!G24, 4) -> -1.6609 | E9: =ROUND('Comprensión'!G29, 4) -> 0.6917 | F9: =ROUND('Comprensión'!G30, 4) -> 0.3458
A10: Habilidades | B10: =ROUND(Habilidades!G12, 4) -> -0.3719 | C10: =ROUND(Habilidades!G23, 4) -> 1.985 | D10: =ROUND(Habilidades!G24, 4) -> -1.6609 | E10: =ROUND(Habilidades!G29, 4) -> 0.7108 | F10: =ROUND(Habilidades!G30, 4) -> 0.3554
A11: Resolución autónoma | B11: =ROUND('Resolución-autónoma'!G12, 4) -> -0.1386 | C11: =ROUND('Resolución-autónoma'!G23, 4) -> 1.985 | D11: =ROUND('Resolución-autónoma'!G24, 4) -> -1.6609 | E11: =ROUND('Resolución-autónoma'!G29, 4) -> 0.89 | F11: =ROUND('Resolución-autónoma'!G30, 4) -> 0.445
A12: Motivación | B12: =ROUND('Motivación'!G12, 4) -> -0.6435 | C12: =ROUND('Motivación'!G23, 4) -> 1.985 | D12: =ROUND('Motivación'!G24, 4) -> -1.6609 | E12: =ROUND('Motivación'!G29, 4) -> 0.5214 | F12: =ROUND('Motivación'!G30, 4) -> 0.2607

Sheet Participación-activa
A1: (Sin Aprendizaje Colaborativo) Pre-test Participación-activa | B1: (Sin Aprendizaje Colaborativo) Post-test Participación-activa | C1: Diferencia
A2: 2 | B2: 2 | C2: =B2-A2 -> 0 | D2: =(C2-$G$6)^2 -> 0.034435115
A3: 4 | B3: 2 | C3: =B3-A3 -> -2 | D3: =(C3-$G$6)^2 -> 3.2921671 | F3: Datos
A4: 2 | B4: 2 | C4: =B4-A4 -> 0 | D4: =(C4-$G$6)^2 -> 0.034435115 | F4: numero de datos | G4: =COUNT(A:A) -> 97
A5: 3 | B5: 3 | C5: =B5-A5 -> 0 | D5: =(C5-$G$6)^2 -> 0.034435115 | F5: Sumatoria Diferencias | G5: =SUM(C:C) -> -18
A6: 2 | B6: 4 | C6: =B6-A6 -> 2 | D6: =(C6-$G$6)^2 -> 4.7767032 | F6: Media de las diferencias | G6: =G5/G4 -> -0.18556701
A7: 1 | B7: 5 | C7: =B7-A7 -> 4 | D7: =(C7-$G$6)^2 -> 17.518971 | F7: Sumatoria de diferencias | G7: =SUM(D:D) -> 280.65979
A8: 5 | B8: 1 | C8: =B8-A8 -> -4 | D8: =(C8-$G$6)^2 -> 14.549899 | F8: desviación estándar de las diferencias | G8: =SQRT(G7/(G4-1)) -> 1.7098361
A9: 3 | B9: 2 | C9: =B9-A9 -> -1 | D9: =(C9-$G$6)^2 -> 0.66330109
A10: 3 | B10: 3 | C10: =B10-A10 -> 0 | D10: =(C10-$G$6)^2 -> 0.034435115
A11: 5 | B11: 3 | C11: =B11-A11 -> -2 | D11: =(C11-$G$6)^2 -> 3.2921671
A12: 2 | B12: 3 | C12: =B12-A12 -> 1 | D12: =(C12-$G$6)^2 -> 1.4055691 | F12: t calculado (estadistico t): | G12: =G6/(G8/SQRT(G4)) -> -1.0688879
A13: 4 | B13: 5 | C13: =B13-A13 -> 1 | D13: =(C13-$G$6)^2 -> 1.4055691
A14: 5 | B14: 4 | C14: =B14-A14 -> -1 | D14: =(C14-$G$6)^2 -> 0.66330109
A15: 5 | B15: 5 | C15: =B15-A15 -> 0 | D15: =(C15-$G$6)^2 -> 0.034435115
A16: 1 | B16: 2 | C16: =B16-A16 -> 1 | D16: =(C16-$G$6)^2 -> 1.4055691
A17: 3 | B17: 4 | C17: =B17-A17 -> 1 | D17: =(C17-$G$6)^2 -> 1.4055691 | F17: nivel de significancia (α) | G17: 0.05
A18: 5 | B18: 3 | C18: =B18-A18 -> -2 | D18: =(C18-$G$6)^2 -> 3.2921671 | F18: grados de libertad (DF) | G18: =G4-1 -> 96
A19: 4 | B19: 5 | C19: =B19-A19 -> 1 | D19: =(C19-$G$6)^2 -> 1.4055691
A20: 2 | B20: 4 | C20: =B20-A20 -> 2 | D20: =(C20-$G$6)^2 -> 4.7767032
A21: 4 | B21: 3 | C21: =B21-A21 -> -1 | D21: =(C21-$G$6)^2 -> 0.66330109
A22: 2 | B22: 2 | C22: =B22-A22 -> 0 | D22: =(C22-$G$6)^2 -> 0.034435115 | F22: Valor critico t
A23: 3 | B23: 2 | C23: =B23-A23 -> -1 | D23: =(C23-$G$6)^2 -> 0.66330109 | F23: valor crítico t (Excel) - 2 colas | G23: =_xlfn.T.INV.2T(G17,G18) -> 1.9849843
A24: 2 | B24: 1 | C24: =B24-A24 -> -1 | D24: =(C24-$G$6)^2 -> 0.66330109 | F24: valor crítico t (Excel) - 1 colas | G24: =_xlfn.T.INV(G17,G18) -> -1.6608814
A25: 1 | B25: 2 | C25: =B25-A25 -> 1 | D25: =(C25-$G$6)^2 -> 1.4055691
A26: 5 | B26: 2 | C26: =B26-A26 -> -3 | D26: =(C26-$G$6)^2 -> 7.9210331
A27: 5 | B27: 2 | C27: =B27-A27 -> -3 | D27: =(C27-$G$6)^2 -> 7.9210331 | F27: p valor
A28: 3 | B28: 5 | C28: =B28-A28 -> 2 | D28: =(C28-$G$6)^2 -> 4.7767032 | F28: p valor
A29: 3 | B29: 4 | C29: =B29-A29 -> 1 | D29: =(C29-$G$6)^2 -> 1.4055691 | F29: p valor con (Excel) dos colas | G29: =TTEST(A:A,B:B,2,1) -> 0.28780054
A30: 4 | B30: 4 | C30: =B30-A30 -> 0 | D30: =(C30-$G$6)^2 -> 0.034435115 | F30: p valor con (Excel) una colas | G30: =TTEST(A:A,B:B,1,1) -> 0.14390027
A31: 5 | B31: 3 | C31: =B31-A31 -> -2 | D31: =(C31-$G$6)^2 -> 3.2921671
A32: 4 | B32: 3 | C32: =B32-A32 -> -1 | D32: =(C32-$G$6)^2 -> 0.66330109
A33: 5 | B33: 4 | C33: =B33-A33 -> -1 | D33: =(C33-$G$6)^2 -> 0.66330109 | F33: Hipotesis
A34: 2 | B34: 4 | C34: =B34-A34 -> 2 | D34: =(C34-$G$6)^2 -> 4.7767032
A35: 3 | B35: 5 | C35: =B35-A35 -> 2 | D35: =(C35-$G$6)^2 -> 4.7767032 | F35: hipotesis nula Ho = No hay diferencias significativa
A36: 3 | B36: 2 | C36: =B36-A36 -> -1 | D36: =(C36-$G$6)^2 -> 0.66330109 | F36: hipotesis alternativa H1 = Si hay diferencia significativa
A37: 3 | B37: 4 | C37: =B37-A37 -> 1 | D37: =(C37-$G$6)^2 -> 1.4055691
A38: 3 | B38: 2 | C38: =B38-A38 -> -1 | D38: =(C38-$G$6)^2 -> 0.66330109
A39: 5 | B39: 1 | C39: =B39-A39 -> -4 | D39: =(C39-$G$6)^2 -> 14.549899
A40: 5 | B40: 3 | C40: =B40-A40 -> -2 | D40: =(C40-$G$6)^2 -> 3.2921671 | F40: Si t calculado > t critico (Tabla)
...

Sheet Comunicación-equipo
A1: (Sin Aprendizaje Colaborativo) Pre-test Comunicación-equipo | B1: (Sin Aprendizaje Colaborativo) Post-test Comunicación-equipo | C1: Diferencia
A2: 3 | B2: 3 | C2: =B2-A2 -> 0 | D2: =(C2-$G$6)^2 -> 0.03836752
A3: 4 | B3: 3 | C3: =B3-A3 -> -1 | D3: =(C3-$G$6)^2 -> 1.4301201 | F3: Datos
A4: 2 | B4: 3 | C4: =B4-A4 -> 1 | D4: =(C4-$G$6)^2 -> 0.64661494 | F4: numero de datos | G4: =COUNT(A:A) -> 97
A5: 5 | B5: 2 | C5: =B5-A5 -> -3 | D5: =(C5-$G$6)^2 -> 10.213625 | F5: Sumatoria Diferencias | G5: =SUM(C:C) -> 19
A6: 3 | B6: 1 | C6: =B6-A6 -> -2 | D6: =(C6-$G$6)^2 -> 4.8218727 | F6: Media de las diferencias | G6: =G5/G4 -> 0.19587629
A7: 2 | B7: 3 | C7: =B7-A7 -> 1 | D7: =(C7-$G$6)^2 -> 0.64661494 | F7: Sumatoria de diferencias | G7: =SUM(D:D) -> 315.27835
A8: 3 | B8: 3 | C8: =B8-A8 -> 0 | D8: =(C8-$G$6)^2 -> 0.03836752 | F8: desviación estándar de las diferencias | G8: =SQRT(G7/(G4-1)) -> 1.8122223
A9: 3 | B9: 4 | C9: =B9-A9 -> 1 | D9: =(C9-$G$6)^2 -> 0.64661494
A10: 5 | B10: 1 | C10: =B10-A10 -> -4 | D10: =(C10-$G$6)^2 -> 17.605378
A11: 1 | B11: 4 | C11: =B11-A11 -> 3 | D11: =(C11-$G$6)^2 -> 7.8631098
A12: 3 | B12: 2 | C12: =B12-A12 -> -1 | D12: =(C12-$G$6)^2 -> 1.4301201 | F12: t calculado (estadistico t): | G12: =G6/(G8/SQRT(G4)) -> 1.064526
A13: 2 | B13: 3 | C13: =B13-A13 -> 1 | D13: =(C13-$G$6)^2 -> 0.64661494
A14: 3 | B14: 2 | C14: =B14-A14 -> -1 | D14: =(C14-$G$6)^2 -> 1.4301201
A15: 4 | B15: 2 | C15: =B15-A15 -> -2 | D15: =(C15-$G$6)^2 -> 4.8218727
A16: 3 | B16: 5 | C16: =B16-A16 -> 2 | D16: =(C16-$G$6)^2 -> 3.2548624
A17: 4 | B17: 1 | C17: =B17-A17 -> -3 | D17: =(C17-$G$6)^2 -> 10.213625 | F17: nivel de significancia (α) | G17: 0.05
A18: 1 | B18: 5 | C18: =B18-A18 -> 4 | D18: =(C18-$G$6)^2 -> 14.471357 | F18: grados de libertad (DF) | G18: =G4-1 -> 96
A19: 3 | B19: 4 | C19: =B19-A19 -> 1 | D19: =(C19-$G$6)^2 -> 0.64661494
A20: 3 | B20: 3 | C20: =B20-A20 -> 0 | D20: =(C20-$G$6)^2 -> 0.03836752
A21: 2 | B21: 3 | C21: =B21-A21 -> 1 | D21: =(C21-$G$6)^2 -> 0.64661494
A22: 3 | B22: 3 | C22: =B22-A22 -> 0 | D22: =(C22-$G$6)^2 -> 0.03836752 | F22: Valor critico t
A23: 2 | B23: 4 | C23: =B23-A23 -> 2 | D23: =(C23-$G$6)^2 -> 3.2548624 | F23: valor crítico t (Excel) - 2 colas | G23: =_xlfn.T.INV.2T(G17,G18) -> 1.9849843
A24: 4 | B24: 1 | C24: =B24-A24 -> -3 | D24: =(C24-$G$6)^2 -> 10.213625 | F24: valor crítico t (Excel) - 1 colas | G24: =_xlfn.T.INV(G17,G18) -> -1.6608814
A25: 1 | B25: 4 | C25: =B25-A25 -> 3 | D25: =(C25-$G$6)^2 -> 7.8631098
A26: 3 | B26: 4 | C26: =B26-A26 -> 1 | D26: =(C26-$G$6)^2 -> 0.64661494
A27: 3 | B27: 4 | C27: =B27-A27 -> 1 | D27: =(C27-$G$6)^2 -> 0.64661494 | F27: p valor
A28: 5 | B28: 5 | C28: =B28-A28 -> 0 | D28: =(C28-$G$6)^2 -> 0.03836752 | F28: p valor
A29: 4 | B29: 3 | C29: =B29-A29 -> -1 | D29: =(C29-$G$6)^2 -> 1.4301201 | F29: p valor con (Excel) dos colas | G29: =TTEST(A:A,B:B,2,1) -> 0.2897607
A30: 5 | B30: 1 | C30: =B30-A30 -> -4 | D30: =(C30-$G$6)^2 -> 17.605378 | F30: p valor con (Excel) una colas | G30: =TTEST(A:A,B:B,1,1) -> 0.14488035
A31: 3 | B31: 5 | C31: =B31-A31 -> 2 | D31: =(C31-$G$6)^2 -> 3.2548624
A32: 1 | B32: 1 | C32: =B32-A32 -> 0 | D32: =(C32-$G$6)^2 -> 0.03836752
A33: 2 | B33: 4 | C33: =B33-A33 -> 2 | D33: =(C33-$G$6)^2 -> 3.2548624 | F33: Hipotesis
A34: 3 | B34: 1 | C34: =B34-A34 -> -2 | D34: =(C34-$G$6)^2 -> 4.8218727
A35: 4 | B35: 2 | C35: =B35-A35 -> -2 | D35: =(C35-$G$6)^2 -> 4.8218727 | F35: hipotesis nula Ho = No hay diferencias significativa
A36: 5 | B36: 5 | C36: =B36-A36 -> 0 | D36: =(C36-$G$6)^2 -> 0.03836752 | F36: hipotesis alternativa H1 = Si hay diferencia significativa
A37: 4 | B37: 3 | C37: =B37-A37 -> -1 | D37: =(C37-$G$6)^2 -> 1.4301201
A38: 3 | B38: 4 | C38: =B38-A38 -> 1 | D38: =(C38-$G$6)^2 -> 0.64661494
A39: 3 | B39: 4 | C39: =B39-A39 -> 1 | D39: =(C39-$G$6)^2 -> 0.64661494
A40: 3 | B40: 5 | C40: =B40-A40 -> 2 | D40: =(C40-$G$6)^2 -> 3.2548624 | F40: Si t calculado > t critico (Tabla)
...

Sheet Cumplimiento-tareas
A1: (Sin Aprendizaje Colaborativo) Pre-test Cumplimiento-tareas | B1: (Sin Aprendizaje Colaborativo) Post-test Cumplimiento-tareas | C1: Diferencia
A2: 3 | B2: 4 | C2: =B2-A2 -> 1 | D2: =(C2-$G$6)^2 -> 1.3571049
A3: 3 | B3: 3 | C3: =B3-A3 -> 0 | D3: =(C3-$G$6)^2 -> 0.027207992 | F3: Datos
A4: 5 | B4: 4 | C4: =B4-A4 -> -1 | D4: =(C4-$G$6)^2 -> 0.69731109 | F4: numero de datos | G4: =COUNT(A:A) -> 97
A5: 4 | B5: 3 | C5: =B5-A5 -> -1 | D5: =(C5-$G$6)^2 -> 0.69731109 | F5: Sumatoria Diferencias | G5: =SUM(C:C) -> -16
A6: 4 | B6: 3 | C6: =B6-A6 -> -1 | D6: =(C6-$G$6)^2 -> 0.69731109 | F6: Media de las diferencias | G6: =G5/G4 -> -0.16494845
A7: 2 | B7: 4 | C7: =B7-A7 -> 2 | D7: =(C7-$G$6)^2 -> 4.6870018 | F7: Sumatoria de diferencias | G7: =SUM(D:D) -> 295.36082
A8: 3 | B8: 3 | C8: =B8-A8 -> 0 | D8: =(C8-$G$6)^2 -> 0.027207992 | F8: desviación estándar de las diferencias | G8: =SQRT(G7/(G4-1)) -> 1.7540454
A9: 5 | B9: 3 | C9: =B9-A9 -> -2 | D9: =(C9-$G$6)^2 -> 3.3674142
A10: 2 | B10: 5 | C10: =B10-A10 -> 3 | D10: =(C10-$G$6)^2 -> 10.016899
A11: 4 | B11: 3 | C11: =B11-A11 -> -1 | D11: =(C11-$G$6)^2 -> 0.69731109
A12: 1 | B12: 4 | C12: =B12-A12 -> 3 | D12: =(C12-$G$6)^2 -> 10.016899 | F12: t calculado (estadistico t): | G12: =G6/(G8/SQRT(G4)) -> -0.92617549
A13: 3 | B13: 5 | C13: =B13-A13 -> 2 | D13: =(C13-$G$6)^2 -> 4.6870018
A14: 4 | B14: 2 | C14: =B14-A14 -> -2 | D14: =(C14-$G$6)^2 -> 3.3674142
A15: 5 | B15: 3 | C15: =B15-A15 -> -2 | D15: =(C15-$G$6)^2 -> 3.3674142
A16: 3 | B16: 4 | C16: =B16-A16 -> 1 | D16: =(C16-$G$6)^2 -> 1.3571049
A17: 2 | B17: 4 | C17: =B17-A17 -> 2 | D17: =(C17-$G$6)^2 -> 4.6870018 | F17: nivel de significancia (α) | G17: 0.05
A18: 3 | B18: 4 | C18: =B18-A18 -> 1 | D18: =(C18-$G$6)^2 -> 1.3571049 | F18: grados de libertad (DF) | G18: =G4-1 -> 96
A19: 5 | B19: 5 | C19: =B19-A19 -> 0 | D19: =(C19-$G$6)^2 -> 0.027207992
A20: 4 | B20: 3 | C20: =B20-A20 -> -1 | D20: =(C20-$G$6)^2 -> 0.69731109
A21: 5 | B21: 3 | C21: =B21-A21 -> -2 | D21: =(C21-$G$6)^2 -> 3.3674142
A22: 3 | B22: 4 | C22: =B22-A22 -> 1 | D22: =(C22-$G$6)^2 -> 1.3571049 | F22: Valor critico t
A23: 2 | B23: 2 | C23: =B23-A23 -> 0 | D23: =(C23-$G$6)^2 -> 0.027207992 | F23: valor crítico t (Excel) - 2 colas | G23: =_xlfn.T.INV.2T(G17,G18) -> 1.9849843
A24: 2 | B24: 4 | C24: =B24-A24 -> 2 | D24: =(C24-$G$6)^2 -> 4.6870018 | F24: valor crítico t (Excel) - 1 colas | G24: =_xlfn.T.INV(G17,G18) -> -1.6608814
A25: 2 | B25: 2 | C25: =B25-A25 -> 0 | D25: =(C25-$G$6)^2 -> 0.027207992
A26: 2 | B26: 5 | C26: =B26-A26 -> 3 | D26: =(C26-$G$6)^2 -> 10.016899
A27: 4 | B27: 3 | C27: =B27-A27 -> -1 | D27: =(C27-$G$6)^2 -> 0.69731109 | F27: p valor
A28: 3 | B28: 1 | C28: =B28-A28 -> -2 | D28: =(C28-$G$6)^2 -> 3.3674142 | F28: p valor
A29: 1 | B29: 3 | C29: =B29-A29 -> 2 | D29: =(C29-$G$6)^2 -> 4.6870018 | F29: p valor con (Excel) dos colas | G29: =TTEST(A:A,B:B,2,1) -> 0.3566773
A30: 4 | B30: 3 | C30: =B30-A30 -> -1 | D30: =(C30-$G$6)^2 -> 0.69731109 | F30: p valor con (Excel) una colas | G30: =TTEST(A:A,B:B,1,1) -> 0.17833865
A31: 4 | B31: 1 | C31: =B31-A31 -> -3 | D31: =(C31-$G$6)^2 -> 8.0375173
A32: 5 | B32: 5 | C32: =B32-A32 -> 0 | D32: =(C32-$G$6)^2 -> 0.027207992
A33: 4 | B33: 4 | C33: =B33-A33 -> 0 | D33: =(C33-$G$6)^2 -> 0.027207992 | F33: Hipotesis
A34: 2 | B34: 5 | C34: =B34-A34 -> 3 | D34: =(C34-$G$6)^2 -> 10.016899
A35: 2 | B35: 3 | C35: =B35-A35 -> 1 | D35: =(C35-$G$6)^2 -> 1.3571049 | F35: hipotesis nula Ho = No hay diferencias significativa
A36: 3 | B36: 1 | C36: =B36-A36 -> -2 | D36: =(C36-$G$6)^2 -> 3.3674142 | F36: hipotesis alternativa H1 = Si hay diferencia significativa
A37: 2 | B37: 2 | C37: =B37-A37 -> 0 | D37: =(C37-$G$6)^2 -> 0.027207992
A38: 4 | B38: 4 | C38: =B38-A38 -> 0 | D38: =(C38-$G$6)^2 -> 0.027207992
A39: 5 | B39: 4 | C39: =B39-A39 -> -1 | D39: =(C39-$G$6)^2 -> 0.69731109
A40: 5 | B40: 4 | C40: =B40-A40 -> -1 | D40: =(C40-$G$6)^2 -> 0.69731109 | F40: Si t calculado > t critico (Tabla)
...

Sheet Contribución-grupo
A1: (Sin Aprendizaje Colaborativo) Pre-test Contribución-grupo | B1: (Sin Aprendizaje Colaborativo) Post-test Contribución-grupo | C1: Diferencia
A2: 4 | B2: 3 | C2: =B2-A2 -> -1 | D2: =(C2-$G$6)^2 -> 1.1941758
A3: 2 | B3: 3 | C3: =B3-A3 -> 1 | D3: =(C3-$G$6)^2 -> 0.82304177 | F3: Datos
A4: 5 | B4: 4 | C4: =B4-A4 -> -1 | D4: =(C4-$G$6)^2 -> 1.1941758 | F4: numero de datos | G4: =COUNT(A:A) -> 97
A5: 3 | B5: 3 | C5: =B5-A5 -> 0 | D5: =(C5-$G$6)^2 -> 0.0086087788 | F5: Sumatoria Diferencias | G5: =SUM(C:C) -> 9
A6: 3 | B6: 4 | C6: =B6-A6 -> 1 | D6: =(C6-$G$6)^2 -> 0.82304177 | F6: Media de las diferencias | G6: =G5/G4 -> 0.092783505
A7: 1 | B7: 3 | C7: =B7-A7 -> 2 | D7: =(C7-$G$6)^2 -> 3.6374748 | F7: Sumatoria de diferencias | G7: =SUM(D:D) -> 194.16495
A8: 3 | B8: 4 | C8: =B8-A8 -> 1 | D8: =(C8-$G$6)^2 -> 0.82304177 | F8: desviación estándar de las diferencias | G8: =SQRT(G7/(G4-1)) -> 1.4221644
A9: 3 | B9: 2 | C9: =B9-A9 -> -1 | D9: =(C9-$G$6)^2 -> 1.1941758
A10: 3 | B10: 3 | C10: =B10-A10 -> 0 | D10: =(C10-$G$6)^2 -> 0.0086087788
A11: 4 | B11: 3 | C11: =B11-A11 -> -1 | D11: =(C11-$G$6)^2 -> 1.1941758
A12: 4 | B12: 5 | C12: =B12-A12 -> 1 | D12: =(C12-$G$6)^2 -> 0.82304177 | F12: t calculado (estadistico t): | G12: =G6/(G8/SQRT(G4)) -> 0.64254987
A13: 4 | B13: 4 | C13: =B13-A13 -> 0 | D13: =(C13-$G$6)^2 -> 0.0086087788
A14: 2 | B14: 5 | C14: =B14-A14 -> 3 | D14: =(C14-$G$6)^2 -> 8.4519077
A15: 3 | B15: 5 | C15: =B15-A15 -> 2 | D15: =(C15-$G$6)^2 -> 3.6374748
A16: 4 | B16: 4 | C16: =B16-A16 -> 0 | D16: =(C16-$G$6)^2 -> 0.0086087788
A17: 3 | B17: 5 | C17: =B17-A17 -> 2 | D17: =(C17-$G$6)^2 -> 3.6374748 | F17: nivel de significancia (α) | G17: 0.05
A18: 4 | B18: 3 | C18: =B18-A18 -> -1 | D18: =(C18-$G$6)^2 -> 1.1941758 | F18: grados de libertad (DF) | G18: =G4-1 -> 96
A19: 2 | B19: 2 | C19: =B19-A19 -> 0 | D19: =(C19-$G$6)^2 -> 0.0086087788
A20: 3 | B20: 3 | C20: =B20-A20 -> 0 | D20: =(C20-$G$6)^2 -> 0.0086087788
A21: 5 | B21: 1 | C21: =B21-A21 -> -4 | D21: =(C21-$G$6)^2 -> 16.750877
A22: 3 | B22: 4 | C22: =B22-A22 -> 1 | D22: =(C22-$G$6)^2 -> 0.82304177 | F22: Valor critico t
A23: 5 | B23: 3 | C23: =B23-A23 -> -2 | D23: =(C23-$G$6)^2 -> 4.3797428 | F23: valor crítico t (Excel) - 2 colas | G23: =_xlfn.T.INV.2T(G17,G18) -> 1.9849843
A24: 3 | B24: 4 | C24: =B24-A24 -> 1 | D24: =(C24-$G$6)^2 -> 0.82304177 | F24: valor crítico t (Excel) - 1 colas | G24: =_xlfn.T.INV(G17,G18) -> -1.6608814
A25: 4 | B25: 1 | C25: =B25-A25 -> -3 | D25: =(C25-$G$6)^2 -> 9.5653098
A26: 3 | B26: 3 | C26: =B26-A26 -> 0 | D26: =(C26-$G$6)^2 -> 0.0086087788
A27: 3 | B27: 2 | C27: =B27-A27 -> -1 | D27: =(C27-$G$6)^2 -> 1.1941758 | F27: p valor
A28: 3 | B28: 3 | C28: =B28-A28 -> 0 | D28: =(C28-$G$6)^2 -> 0.0086087788 | F28: p valor
A29: 3 | B29: 5 | C29: =B29-A29 -> 2 | D29: =(C29-$G$6)^2 -> 3.6374748 | F29: p valor con (Excel) dos colas | G29: =TTEST(A:A,B:B,2,1) -> 0.52204784
A30: 3 | B30: 4 | C30: =B30-A30 -> 1 | D30: =(C30-$G$6)^2 -> 0.82304177 | F30: p valor con (Excel) una colas | G30: =TTEST(A:A,B:B,1,1) -> 0.26102392
A31: 3 | B31: 3 | C31: =B31-A31 -> 0 | D31: =(C31-$G$6)^2 -> 0.0086087788
A32: 3 | B32: 2 | C32: =B32-A32 -> -1 | D32: =(C32-$G$6)^2 -> 1.1941758
A33: 3 | B33: 3 | C33: =B33-A33 -> 0 | D33: =(C33-$G$6)^2 -> 0.0086087788 | F33: Hipotesis
A34: 5 | B34: 2 | C34: =B34-A34 -> -3 | D34: =(C34-$G$6)^2 -> 9.5653098
A35: 4 | B35: 5 | C35: =B35-A35 -> 1 | D35: =(C35-$G$6)^2 -> 0.82304177 | F35: hipotesis nula Ho = No hay diferencias significativa
A36: 3 | B36: 3 | C36: =B36-A36 -> 0 | D36: =(C36-$G$6)^2 -> 0.0086087788 | F36: hipotesis alternativa H1 = Si hay diferencia significativa
A37: 2 | B37: 3 | C37: =B37-A37 -> 1 | D37: =(C37-$G$6)^2 -> 0.82304177
A38: 5 | B38: 3 | C38: =B38-A38 -> -2 | D38: =(C38-$G$6)^2 -> 4.3797428
A39: 3 | B39: 2 | C39: =B39-A39 -> -1 | D39: =(C39-$G$6)^2 -> 1.1941758
A40: 4 | B40: 4 | C40: =B40-A40 -> 0 | D40: =(C40-$G$6)^2 -> 0.0086087788 | F40: Si t calculado > t critico (Tabla)
...

Sheet Resolución-problemas
A1: (Sin Aprendizaje Colaborativo) Pre-test Resolución-problemas | B1: (Sin Aprendizaje Colaborativo) Post-test Resolución-problemas | C1: Diferencia
A2: 2 | B2: 4 | C2: =B2-A2 -> 2 | D2: =(C2-$G$6)^2 -> 2.8585397
A3: 3 | B3: 3 | C3: =B3-A3 -> 0 | D3: =(C3-$G$6)^2 -> 0.095653098 | F3: Datos
A4: 4 | B4: 1 | C4: =B4-A4 -> -3 | D4: =(C4-$G$6)^2 -> 10.951323 | F4: numero de datos | G4: =COUNT(A:A) -> 97
A5: 1 | B5: 3 | C5: =B5-A5 -> 2 | D5: =(C5-$G$6)^2 -> 2.8585397 | F5: Sumatoria Diferencias | G5: =SUM(C:C) -> 30
A6: 3 | B6: 3 | C6: =B6-A6 -> 0 | D6: =(C6-$G$6)^2 -> 0.095653098 | F6: Media de las diferencias | G6: =G5/G4 -> 0.30927835
A7: 4 | B7: 5 | C7: =B7-A7 -> 1 | D7: =(C7-$G$6)^2 -> 0.4770964 | F7: Sumatoria de diferencias | G7: =SUM(D:D) -> 242.72165
A8: 5 | B8: 3 | C8: =B8-A8 -> -2 | D8: =(C8-$G$6)^2 -> 5.3327665 | F8: desviación estándar de las diferencias | G8: =SQRT(G7/(G4-1)) -> 1.5900788
A9: 2 | B9: 3 | C9: =B9-A9 -> 1 | D9: =(C9-$G$6)^2 -> 0.4770964
A10: 3 | B10: 4 | C10: =B10-A10 -> 1 | D10: =(C10-$G$6)^2 -> 0.4770964
A11: 3 | B11: 4 | C11: =B11-A11 -> 1 | D11: =(C11-$G$6)^2 -> 0.4770964
A12: 3 | B12: 3 | C12: =B12-A12 -> 0 | D12: =(C12-$G$6)^2 -> 0.095653098 | F12: t calculado (estadistico t): | G12: =G6/(G8/SQRT(G4)) -> 1.9156526
A13: 5 | B13: 3 | C13: =B13-A13 -> -2 | D13: =(C13-$G$6)^2 -> 5.3327665
A14: 2 | B14: 4 | C14: =B14-A14 -> 2 | D14: =(C14-$G$6)^2 -> 2.8585397
A15: 3 | B15: 4 | C15: =B15-A15 -> 1 | D15: =(C15-$G$6)^2 -> 0.4770964
A16: 1 | B16: 3 | C16: =B16-A16 -> 2 | D16: =(C16-$G$6)^2 -> 2.8585397
A17: 3 | B17: 2 | C17: =B17-A17 -> -1 | D17: =(C17-$G$6)^2 -> 1.7142098 | F17: nivel de significancia (α) | G17: 0.05
A18: 3 | B18: 5 | C18: =B18-A18 -> 2 | D18: =(C18-$G$6)^2 -> 2.8585397 | F18: grados de libertad (DF) | G18: =G4-1 -> 96
A19: 4 | B19: 2 | C19: =B19-A19 -> -2 | D19: =(C19-$G$6)^2 -> 5.3327665
A20: 3 | B20: 4 | C20: =B20-A20 -> 1 | D20: =(C20-$G$6)^2 -> 0.4770964
A21: 3 | B21: 3 | C21: =B21-A21 -> 0 | D21: =(C21-$G$6)^2 -> 0.095653098
A22: 2 | B22: 4 | C22: =B22-A22 -> 2 | D22: =(C22-$G$6)^2 -> 2.8585397 | F22: Valor critico t
A23: 2 | B23: 3 | C23: =B23-A23 -> 1 | D23: =(C23-$G$6)^2 -> 0.4770964 | F23: valor crítico t (Excel) - 2 colas | G23: =_xlfn.T.INV.2T(G17,G18) -> 1.9849843
A24: 2 | B24: 3 | C24: =B24-A24 -> 1 | D24: =(C24-$G$6)^2 -> 0.4770964 | F24: valor crítico t (Excel) - 1 colas | G24: =_xlfn.T.INV(G17,G18) -> -1.6608814
A25: 3 | B25: 4 | C25: =B25-A25 -> 1 | D25: =(C25-$G$6)^2 -> 0.4770964
A26: 5 | B26: 2 | C26: =B26-A26 -> -3 | D26: =(C26-$G$6)^2 -> 10.951323
A27: 1 | B27: 5 | C27: =B27-A27 -> 4 | D27: =(C27-$G$6)^2 -> 13.621426 | F27: p valor
A28: 3 | B28: 2 | C28: =B28-A28 -> -1 | D28: =(C28-$G$6)^2 -> 1.7142098 | F28: p valor
A29: 3 | B29: 1 | C29: =B29-A29 -> -2 | D29: =(C29-$G$6)^2 -> 5.3327665 | F29: p valor con (Excel) dos colas | G29: =TTEST(A:A,B:B,2,1) -> 0.058385121
A30: 2 | B30: 4 | C30: =B30-A30 -> 2 | D30: =(C30-$G$6)^2 -> 2.8585397 | F30: p valor con (Excel) una colas | G30: =TTEST(A:A,B:B,1,1) -> 0.029192561
A31: 4 | B31: 3 | C31: =B31-A31 -> -1 | D31: =(C31-$G$6)^2 -> 1.7142098
A32: 5 | B32: 3 | C32: =B32-A32 -> -2 | D32: =(C32-$G$6)^2 -> 5.3327665
A33: 2 | B33: 1 | C33: =B33-A33 -> -1 | D33: =(C33-$G$6)^2 -> 1.7142098 | F33: Hipotesis
A34: 5 | B34: 3 | C34: =B34-A34 -> -2 | D34: =(C34-$G$6)^2 -> 5.3327665
A35: 5 | B35: 3 | C35: =B35-A35 -> -2 | D35: =(C35-$G$6)^2 -> 5.3327665 | F35: hipotesis nula Ho = No hay diferencias significativa
A36: 2 | B36: 5 | C36: =B36-A36 -> 3 | D36: =(C36-$G$6)^2 -> 7.239983 | F36: hipotesis alternativa H1 = Si hay diferencia significativa
A37: 3 | B37: 1 | C37: =B37-A37 -> -2 | D37: =(C37-$G$6)^2 -> 5.3327665
A38: 5 | B38: 4 | C38: =B38-A38 -> -1 | D38: =(C38-$G$6)^2 -> 1.7142098
A39: 1 | B39: 4 | C39: =B39-A39 -> 3 | D39: =(C39-$G$6)^2 -> 7.239983
A40: 3 | B40: 3 | C40: =B40-A40 -> 0 | D40: =(C40-$G$6)^2 -> 0.095653098 | F40: Si t calculado > t critico (Tabla)
...

Sheet Conocimientos-adquiridos
A1: (Sin Aprendizaje Colaborativo) Pre-test Conocimientos-adquiridos | B1: (Sin Aprendizaje Colaborativo) Post-test Conocimientos-adquiridos | C1: Diferencia
A2: 2 | B2: 3 | C2: =B2-A2 -> 1 | D2: =(C2-$G$6)^2 -> 1.1941758
A3: 2 | B3: 4 | C3: =B3-A3 -> 2 | D3: =(C3-$G$6)^2 -> 4.3797428 | F3: Datos
A4: 5 | B4: 2 | C4: =B4-A4 -> -3 | D4: =(C4-$G$6)^2 -> 8.4519077 | F4: numero de datos | G4: =COUNT(A:A) -> 97
A5: 4 | B5: 2 | C5: =B5-A5 -> -2 | D5: =(C5-$G$6)^2 -> 3.6374748 | F5: Sumatoria Diferencias | G5: =SUM(C:C) -> -9
A6: 5 | B6: 2 | C6: =B6-A6 -> -3 | D6: =(C6-$G$6)^2 -> 8.4519077 | F6: Media de las diferencias | G6: =G5/G4 -> -0.092783505
A7: 5 | B7: 3 | C7: =B7-A7 -> -2 | D7: =(C7-$G$6)^2 -> 3.6374748 | F7: Sumatoria de diferencias | G7: =SUM(D:D) -> 302.16495
A8: 5 | B8: 3 | C8: =B8-A8 -> -2 | D8: =(C8-$G$6)^2 -> 3.6374748 | F8: desviación estándar de las diferencias | G8: =SQRT(G7/(G4-1)) -> 1.774134
A9: 2 | B9: 4 | C9: =B9-A9 -> 2 | D9: =(C9-$G$6)^2 -> 4.3797428
A10: 4 | B10: 2 | C10: =B10-A10 -> -2 | D10: =(C10-$G$6)^2 -> 3.6374748
A11: 3 | B11: 2 | C11: =B11-A11 -> -1 | D11: =(C11-$G$6)^2 -> 0.82304177
A12: 3 | B12: 5 | C12: =B12-A12 -> 2 | D12: =(C12-$G$6)^2 -> 4.3797428 | F12: t calculado (estadistico t): | G12: =G6/(G8/SQRT(G4)) -> -0.5150747
A13: 4 | B13: 5 | C13: =B13-A13 -> 1 | D13: =(C13-$G$6)^2 -> 1.1941758
A14: 3 | B14: 1 | C14: =B14-A14 -> -2 | D14: =(C14-$G$6)^2 -> 3.6374748
A15: 4 | B15: 5 | C15: =B15-A15 -> 1 | D15: =(C15-$G$6)^2 -> 1.1941758
A16: 3 | B16: 3 | C16: =B16-A16 -> 0 | D16: =(C16-$G$6)^2 -> 0.0086087788
A17: 3 | B17: 5 | C17: =B17-A17 -> 2 | D17: =(C17-$G$6)^2 -> 4.3797428 | F17: nivel de significancia (α) | G17: 0.05
A18: 4 | B18: 1 | C18: =B18-A18 -> -3 | D18: =(C18-$G$6)^2 -> 8.4519077 | F18: grados de libertad (DF) | G18: =G4-1 -> 96
A19: 3 | B19: 2 | C19: =B19-A19 -> -1 | D19: =(C19-$G$6)^2 -> 0.82304177
A20: 3 | B20: 3 | C20: =B20-A20 -> 0 | D20: =(C20-$G$6)^2 -> 0.0086087788
A21: 3 | B21: 3 | C21: =B21-A21 -> 0 | D21: =(C21-$G$6)^2 -> 0.0086087788
A22: 4 | B22: 4 | C22: =B22-A22 -> 0 | D22: =(C22-$G$6)^2 -> 0.0086087788 | F22: Valor critico t
A23: 4 | B23: 4 | C23: =B23-A23 -> 0 | D23: =(C23-$G$6)^2 -> 0.0086087788 | F23: valor crítico t (Excel) - 2 colas | G23: =_xlfn.T.INV.2T(G17,G18) -> 1.9849843
A24: 1 | B24: 4 | C24: =B24-A24 -> 3 | D24: =(C24-$G$6)^2 -> 9.5653098 | F24: valor crítico t (Excel) - 1 colas | G24: =_xlfn.T.INV(G17,G18) -> -1.6608814
A25: 5 | B25: 2 | C25: =B25-A25 -> -3 | D25: =(C25-$G$6)^2 -> 8.4519077
A26: 5 | B26: 3 | C26: =B26-A26 -> -2 | D26: =(C26-$G$6)^2 -> 3.6374748
A27: 4 | B27: 3 | C27: =B27-A27 -> -1 | D27: =(C27-$G$6)^2 -> 0.82304177 | F27: p valor
A28: 4 | B28: 1 | C28: =B28-A28 -> -3 | D28: =(C28-$G$6)^2 -> 8.4519077 | F28: p valor
A29: 3 | B29: 3 | C29: =B29-A29 -> 0 | D29: =(C29-$G$6)^2 -> 0.0086087788 | F29: p valor con (Excel) dos colas | G29: =TTEST(A:A,B:B,2,1) -> 0.60768481
A30: 2 | B30: 5 | C30: =B30-A30 -> 3 | D30: =(C30-$G$6)^2 -> 9.5653098 | F30: p valor con (Excel) una colas | G30: =TTEST(A:A,B:B,1,1) -> 0.30384241
A31: 5 | B31: 1 | C31: =B31-A31 -> -4 | D31: =(C31-$G$6)^2 -> 15.266341
A32: 4 | B32: 5 | C32: =B32-A32 -> 1 | D32: =(C32-$G$6)^2 -> 1.1941758
A33: 3 | B33: 3 | C33: =B33-A33 -> 0 | D33: =(C33-$G$6)^2 -> 0.0086087788 | F33: Hipotesis
A34: 4 | B34: 4 | C34: =B34-A34 -> 0 | D34: =(C34-$G$6)^2 -> 0.0086087788
A35: 1 | B35: 5 | C35: =B35-A35 -> 4 | D35: =(C35-$G$6)^2 -> 16.750877 | F35: hipotesis nula Ho = No hay diferencias significativa
A36: 3 | B36: 4 | C36: =B36-A36 -> 1 | D36: =(C36-$G$6)^2 -> 1.1941758 | F36: hipotesis alternativa H1 = Si hay diferencia significativa
A37: 3 | B37: 2 | C37: =B37-A37 -> -1 | D37: =(C37-$G$6)^2 -> 0.82304177
A38: 5 | B38: 3 | C38: =B38-A38 -> -2 | D38: =(C38-$G$6)^2 -> 3.6374748
A39: 3 | B39: 2 | C39: =B39-A39 -> -1 | D39: =(C39-$G$6)^2 -> 0.82304177
A40: 3 | B40: 4 | C40: =B40-A40 -> 1 | D40: =(C40-$G$6)^2 -> 1.1941758 | F40: Si t calculado > t critico (Tabla)
...

Sheet Nota-final
A1: (Sin Aprendizaje Colaborativo) Pre-test Nota-final | B1: (Sin Aprendizaje Colaborativo) Post-test Nota-final | C1: Diferencia
A2: 3 | B2: 3 | C2: =B2-A2 -> 0 | D2: =(C2-$G$6)^2 -> 0.027207992
A3: 4 | B3: 2 | C3: =B3-A3 -> -2 | D3: =(C3-$G$6)^2 -> 3.3674142 | F3: Datos
A4: 3 | B4: 1 | C4: =B4-A4 -> -2 | D4: =(C4-$G$6)^2 -> 3.3674142 | F4: numero de datos | G4: =COUNT(A:A) -> 97
A5: 3 | B5: 2 | C5: =B5-A5 -> -1 | D5: =(C5-$G$6)^2 -> 0.69731109 | F5: Sumatoria Diferencias | G5: =SUM(C:C) -> -16
A6: 2 | B6: 5 | C6: =B6-A6 -> 3 | D6: =(C6-$G$6)^2 -> 10.016899 | F6: Media de las diferencias | G6: =G5/G4 -> -0.16494845
A7: 2 | B7: 2 | C7: =B7-A7 -> 0 | D7: =(C7-$G$6)^2 -> 0.027207992 | F7: Sumatoria de diferencias | G7: =SUM(D:D) -> 255.36082
A8: 3 | B8: 4 | C8: =B8-A8 -> 1 | D8: =(C8-$G$6)^2 -> 1.3571049 | F8: desviación estándar de las diferencias | G8: =SQRT(G7/(G4-1)) -> 1.6309533
A9: 1 | B9: 4 | C9: =B9-A9 -> 3 | D9: =(C9-$G$6)^2 -> 10.016899
A10: 4 | B10: 2 | C10: =B10-A10 -> -2 | D10: =(C10-$G$6)^2 -> 3.3674142
A11: 5 | B11: 2 | C11: =B11-A11 -> -3 | D11: =(C11-$G$6)^2 -> 8.0375173
A12: 1 | B12: 3 | C12: =B12-A12 -> 2 | D12: =(C12-$G$6)^2 -> 4.6870018 | F12: t calculado (estadistico t): | G12: =G6/(G8/SQRT(G4)) -> -0.99607627
A13: 3 | B13: 5 | C13: =B13-A13 -> 2 | D13: =(C13-$G$6)^2 -> 4.6870018
A14: 5 | B14: 3 | C14: =B14-A14 -> -2 | D14: =(C14-$G$6)^2 -> 3.3674142
A15: 3 | B15: 1 | C15: =B15-A15 -> -2 | D15: =(C15-$G$6)^2 -> 3.3674142
A16: 3 | B16: 1 | C16: =B16-A16 -> -2 | D16: =(C16-$G$6)^2 -> 3.3674142
A17: 3 | B17: 3 | C17: =B17-A17 -> 0 | D17: =(C17-$G$6)^2 -> 0.027207992 | F17: nivel de significancia (α) | G17: 0.05
A18: 2 | B18: 3 | C18: =B18-A18 -> 1 | D18: =(C18-$G$6)^2 -> 1.3571049 | F18: grados de libertad (DF) | G18: =G4-1 -> 96
A19: 3 | B19: 2 | C19: =B19-A19 -> -1 | D19: =(C19-$G$6)^2 -> 0.69731109
A20: 3 | B20: 4 | C20: =B20-A20 -> 1 | D20: =(C20-$G$6)^2 -> 1.3571049
A21: 4 | B21: 2 | C21: =B21-A21 -> -2 | D21: =(C21-$G$6)^2 -> 3.3674142
A22: 3 | B22: 3 | C22: =B22-A22 -> 0 | D22: =(C22-$G$6)^2 -> 0.027207992 | F22: Valor critico t
A23: 4 | B23: 1 | C23: =B23-A23 -> -3 | D23: =(C23-$G$6)^2 -> 8.0375173 | F23: valor crítico t (Excel) - 2 colas | G23: =_xlfn.T.INV.2T(G17,G18) -> 1.9849843
A24: 3 | B24: 4 | C24: =B24-A24 -> 1 | D24: =(C24-$G$6)^2 -> 1.3571049 | F24: valor crítico t (Excel) - 1 colas | G24: =_xlfn.T.INV(G17,G18) -> -1.6608814
A25: 3 | B25: 3 | C25: =B25-A25 -> 0 | D25: =(C25-$G$6)^2 -> 0.027207992
A26: 4 | B26: 3 | C26: =B26-A26 -> -1 | D26: =(C26-$G$6)^2 -> 0.69731109
A27: 2 | B27: 3 | C27: =B27-A27 -> 1 | D27: =(C27-$G$6)^2 -> 1.3571049 | F27: p valor
A28: 2 | B28: 1 | C28: =B28-A28 -> -1 | D28: =(C28-$G$6)^2 -> 0.69731109 | F28: p valor
A29: 2 | B29: 2 | C29: =B29-A29 -> 0 | D29: =(C29-$G$6)^2 -> 0.027207992 | F29: p valor con (Excel) dos colas | G29: =TTEST(A:A,B:B,2,1) -> 0.32171717
A30: 1 | B30: 3 | C30: =B30-A30 -> 2 | D30: =(C30-$G$6)^2 -> 4.6870018 | F30: p valor con (Excel) una colas | G30: =TTEST(A:A,B:B,1,1) -> 0.16085859
A31: 3 | B31: 1 | C31: =B31-A31 -> -2 | D31: =(C31-$G$6)^2 -> 3.3674142
A32: 4 | B32: 1 | C32: =B32-A32 -> -3 | D32: =(C32-$G$6)^2 -> 8.0375173
A33: 3 | B33: 3 | C33: =B33-A33 -> 0 | D33: =(C33-$G$6)^2 -> 0.027207992 | F33: Hipotesis
A34: 4 | B34: 5 | C34: =B34-A34 -> 1 | D34: =(C34-$G$6)^2 -> 1.3571049
A35: 2 | B35: 5 | C35: =B35-A35 -> 3 | D35: =(C35-$G$6)^2 -> 10.016899 | F35: hipotesis nula Ho = No hay diferencias significativa
A36: 1 | B36: 1 | C36: =B36-A36 -> 0 | D36: =(C36-$G$6)^2 -> 0.027207992 | F36: hipotesis alternativa H1 = Si hay diferencia significativa
A37: 5 | B37: 3 | C37: =B37-A37 -> -2 | D37: =(C37-$G$6)^2 -> 3.3674142
A38: 2 | B38: 2 | C38: =B38-A38 -> 0 | D38: =(C38-$G$6)^2 -> 0.027207992
A39: 3 | B39: 2 | C39: =B39-A39 -> -1 | D39: =(C39-$G$6)^2 -> 0.69731109
A40: 3 | B40: 1 | C40: =B40-A40 -> -2 | D40: =(C40-$G$6)^2 -> 3.3674142 | F40: Si t calculado > t critico (Tabla)
...

Sheet Comprensión
A1: (Sin Aprendizaje Colaborativo) Pre-test Comprensión | B1: (Sin Aprendizaje Colaborativo) Pre-test Comprensión | C1: Diferencia
A2: 3 | B2: 3 | C2: =B2-A2 -> 0 | D2: =(C2-$G$6)^2 -> 0.0052077798
A3: 3 | B3: 5 | C3: =B3-A3 -> 2 | D3: =(C3-$G$6)^2 -> 4.2938676 | F3: Datos
A4: 1 | B4: 2 | C4: =B4-A4 -> 1 | D4: =(C4-$G$6)^2 -> 1.1495377 | F4: numero de datos | G4: =COUNT(A:A) -> 97
A5: 3 | B5: 3 | C5: =B5-A5 -> 0 | D5: =(C5-$G$6)^2 -> 0.0052077798 | F5: Sumatoria Diferencias | G5: =SUM(C:C) -> -7
A6: 3 | B6: 3 | C6: =B6-A6 -> 0 | D6: =(C6-$G$6)^2 -> 0.0052077798 | F6: Media de las diferencias | G6: =G5/G4 -> -0.072164948
A7: 3 | B7: 3 | C7: =B7-A7 -> 0 | D7: =(C7-$G$6)^2 -> 0.0052077798 | F7: Sumatoria de diferencias | G7: =SUM(D:D) -> 306.49485
A8: 3 | B8: 2 | C8: =B8-A8 -> -1 | D8: =(C8-$G$6)^2 -> 0.86087788 | F8: desviación estándar de las diferencias | G8: =SQRT(G7/(G4-1)) -> 1.7868001
A9: 4 | B9: 1 | C9: =B9-A9 -> -3 | D9: =(C9-$G$6)^2 -> 8.5722181
A10: 3 | B10: 3 | C10: =B10-A10 -> 0 | D10: =(C10-$G$6)^2 -> 0.0052077798
A11: 5 | B11: 3 | C11: =B11-A11 -> -2 | D11: =(C11-$G$6)^2 -> 3.716548
A12: 1 | B12: 3 | C12: =B12-A12 -> 2 | D12: =(C12-$G$6)^2 -> 4.2938676 | F12: t calculado (estadistico t): | G12: =G6/(G8/SQRT(G4)) -> -0.39777383
A13: 2 | B13: 2 | C13: =B13-A13 -> 0 | D13: =(C13-$G$6)^2 -> 0.0052077798
A14: 5 | B14: 2 | C14: =B14-A14 -> -3 | D14: =(C14-$G$6)^2 -> 8.5722181
A15: 2 | B15: 5 | C15: =B15-A15 -> 3 | D15: =(C15-$G$6)^2 -> 9.4381975
A16: 3 | B16: 4 | C16: =B16-A16 -> 1 | D16: =(C16-$G$6)^2 -> 1.1495377
A17: 4 | B17: 3 | C17: =B17-A17 -> -1 | D17: =(C17-$G$6)^2 -> 0.86087788 | F17: nivel de significancia (α) | G17: 0.05
A18: 4 | B18: 3 | C18: =B18-A18 -> -1 | D18: =(C18-$G$6)^2 -> 0.86087788 | F18: grados de libertad (DF) | G18: =G4-1 -> 96
A19: 3 | B19: 5 | C19: =B19-A19 -> 2 | D19: =(C19-$G$6)^2 -> 4.2938676
A20: 2 | B20: 4 | C20: =B20-A20 -> 2 | D20: =(C20-$G$6)^2 -> 4.2938676
A21: 4 | B21: 3 | C21: =B21-A21 -> -1 | D21: =(C21-$G$6)^2 -> 0.86087788
A22: 3 | B22: 1 | C22: =B22-A22 -> -2 | D22: =(C22-$G$6)^2 -> 3.716548 | F22: Valor critico t
A23: 4 | B23: 2 | C23: =B23-A23 -> -2 | D23: =(C23-$G$6)^2 -> 3.716548 | F23: valor crítico t (Excel) - 2 colas | G23: =_xlfn.T.INV.2T(G17,G18) -> 1.9849843
A24: 5 | B24: 5 | C24: =B24-A24 -> 0 | D24: =(C24-$G$6)^2 -> 0.0052077798 | F24: valor crítico t (Excel) - 1 colas | G24: =_xlfn.T.INV(G17,G18) -> -1.6608814
A25: 4 | B25: 3 | C25: =B25-A25 -> -1 | D25: =(C25-$G$6)^2 -> 0.86087788
A26: 4 | B26: 3 | C26: =B26-A26 -> -1 | D26: =(C26-$G$6)^2 -> 0.86087788
A27: 5 | B27: 3 | C27: =B27-A27 -> -2 | D27: =(C27-$G$6)^2 -> 3.716548 | F27: p valor
A28: 3 | B28: 1 | C28: =B28-A28 -> -2 | D28: =(C28-$G$6)^2 -> 3.716548 | F28: p valor
A29: 3 | B29: 3 | C29: =B29-A29 -> 0 | D29: =(C29-$G$6)^2 -> 0.0052077798 | F29: p valor con (Excel) dos colas | G29: =TTEST(A:A,B:B,2,1) -> 0.69168005
A30: 2 | B30: 2 | C30: =B30-A30 -> 0 | D30: =(C30-$G$6)^2 -> 0.0052077798 | F30: p valor con (Excel) una colas | G30: =TTEST(A:A,B:B,1,1) -> 0.34584003
A31: 2 | B31: 2 | C31: =B31-A31 -> 0 | D31: =(C31-$G$6)^2 -> 0.0052077798
A32: 5 | B32: 5 | C32: =B32-A32 -> 0 | D32: =(C32-$G$6)^2 -> 0.0052077798
A33: 3 | B33: 4 | C33: =B33-A33 -> 1 | D33: =(C33-$G$6)^2 -> 1.1495377 | F33: Hipotesis
A34: 4 | B34: 4 | C34: =B34-A34 -> 0 | D34: =(C34-$G$6)^2 -> 0.0052077798
A35: 4 | B35: 5 | C35: =B35-A35 -> 1 | D35: =(C35-$G$6)^2 -> 1.1495377 | F35: hipotesis nula Ho = No hay diferencias significativa
A36: 4 | B36: 3 | C36: =B36-A36 -> -1 | D36: =(C36-$G$6)^2 -> 0.86087788 | F36: hipotesis alternativa H1 = Si hay diferencia significativa
A37: 2 | B37: 5 | C37: =B37-A37 -> 3 | D37: =(C37-$G$6)^2 -> 9.4381975
A38: 3 | B38: 1 | C38: =B38-A38 -> -2 | D38: =(C38-$G$6)^2 -> 3.716548
A39: 2 | B39: 4 | C39: =B39-A39 -> 2 | D39: =(C39-$G$6)^2 -> 4.2938676
A40: 3 | B40: 1 | C40: =B40-A40 -> -2 | D40: =(C40-$G$6)^2 -> 3.716548 | F40: Si t calculado > t critico (Tabla)
...

Sheet Habilidades
A1: (Sin Aprendizaje Colaborativo) Pre-test Habilidades | B1: (Sin Aprendizaje Colaborativo) Post-test Habilidades | C1: Diferencia
A2: 4 | B2: 4 | C2: =B2-A2 -> 0 | D2: =(C2-$G$6)^2 -> 0.0038261239
A3: 4 | B3: 4 | C3: =B3-A3 -> 0 | D3: =(C3-$G$6)^2 -> 0.0038261239 | F3: Datos
A4: 3 | B4: 4 | C4: =B4-A4 -> 1 | D4: =(C4-$G$6)^2 -> 1.1275375 | F4: numero de datos | G4: =COUNT(A:A) -> 97
A5: 3 | B5: 2 | C5: =B5-A5 -> -1 | D5: =(C5-$G$6)^2 -> 0.88011478 | F5: Sumatoria Diferencias | G5: =SUM(C:C) -> -6
A6: 5 | B6: 1 | C6: =B6-A6 -> -4 | D6: =(C6-$G$6)^2 -> 15.508981 | F6: Media de las diferencias | G6: =G5/G4 -> -0.06185567
A7: 3 | B7: 5 | C7: =B7-A7 -> 2 | D7: =(C7-$G$6)^2 -> 4.2512488 | F7: Sumatoria de diferencias | G7: =SUM(D:D) -> 257.62887
A8: 4 | B8: 4 | C8: =B8-A8 -> 0 | D8: =(C8-$G$6)^2 -> 0.0038261239 | F8: desviación estándar de las diferencias | G8: =SQRT(G7/(G4-1)) -> 1.6381801
A9: 3 | B9: 2 | C9: =B9-A9 -> -1 | D9: =(C9-$G$6)^2 -> 0.88011478
A10: 5 | B10: 1 | C10: =B10-A10 -> -4 | D10: =(C10-$G$6)^2 -> 15.508981
A11: 4 | B11: 4 | C11: =B11-A11 -> 0 | D11: =(C11-$G$6)^2 -> 0.0038261239
A12: 3 | B12: 2 | C12: =B12-A12 -> -1 | D12: =(C12-$G$6)^2 -> 0.88011478 | F12: t calculado (estadistico t): | G12: =G6/(G8/SQRT(G4)) -> -0.37188078
A13: 3 | B13: 3 | C13: =B13-A13 -> 0 | D13: =(C13-$G$6)^2 -> 0.0038261239
A14: 3 | B14: 5 | C14: =B14-A14 -> 2 | D14: =(C14-$G$6)^2 -> 4.2512488
A15: 1 | B15: 2 | C15: =B15-A15 -> 1 | D15: =(C15-$G$6)^2 -> 1.1275375
A16: 3 | B16: 3 | C16: =B16-A16 -> 0 | D16: =(C16-$G$6)^2 -> 0.0038261239
A17: 1 | B17: 4 | C17: =B17-A17 -> 3 | D17: =(C17-$G$6)^2 -> 9.3749601 | F17: nivel de significancia (α) | G17: 0.05
A18: 5 | B18: 4 | C18: =B18-A18 -> -1 | D18: =(C18-$G$6)^2 -> 0.88011478 | F18: grados de libertad (DF) | G18: =G4-1 -> 96
A19: 1 | B19: 3 | C19: =B19-A19 -> 2 | D19: =(C19-$G$6)^2 -> 4.2512488
A20: 4 | B20: 3 | C20: =B20-A20 -> -1 | D20: =(C20-$G$6)^2 -> 0.88011478
A21: 4 | B21: 3 | C21: =B21-A21 -> -1 | D21: =(C21-$G$6)^2 -> 0.88011478
A22: 2 | B22: 2 | C22: =B22-A22 -> 0 | D22: =(C22-$G$6)^2 -> 0.0038261239 | F22: Valor critico t
A23: 2 | B23: 5 | C23: =B23-A23 -> 3 | D23: =(C23-$G$6)^2 -> 9.3749601 | F23: valor crítico t (Excel) - 2 colas | G23: =_xlfn.T.INV.2T(G17,G18) -> 1.9849843
A24: 4 | B24: 3 | C24: =B24-A24 -> -1 | D24: =(C24-$G$6)^2 -> 0.88011478 | F24: valor crítico t (Excel) - 1 colas | G24: =_xlfn.T.INV(G17,G18) -> -1.6608814
A25: 3 | B25: 3 | C25: =B25-A25 -> 0 | D25: =(C25-$G$6)^2 -> 0.0038261239
A26: 4 | B26: 4 | C26: =B26-A26 -> 0 | D26: =(C26-$G$6)^2 -> 0.0038261239
A27: 4 | B27: 1 | C27: =B27-A27 -> -3 | D27: =(C27-$G$6)^2 -> 8.6326921 | F27: p valor
A28: 2 | B28: 5 | C28: =B28-A28 -> 3 | D28: =(C28-$G$6)^2 -> 9.3749601 | F28: p valor
A29: 2 | B29: 5 | C29: =B29-A29 -> 3 | D29: =(C29-$G$6)^2 -> 9.3749601 | F29: p valor con (Excel) dos colas | G29: =TTEST(A:A,B:B,2,1) -> 0.7108012
A30: 3 | B30: 1 | C30: =B30-A30 -> -2 | D30: =(C30-$G$6)^2 -> 3.7564034 | F30: p valor con (Excel) una colas | G30: =TTEST(A:A,B:B,1,1) -> 0.3554006
A31: 3 | B31: 2 | C31: =B31-A31 -> -1 | D31: =(C31-$G$6)^2 -> 0.88011478
A32: 5 | B32: 3 | C32: =B32-A32 -> -2 | D32: =(C32-$G$6)^2 -> 3.7564034
A33: 3 | B33: 3 | C33: =B33-A33 -> 0 | D33: =(C33-$G$6)^2 -> 0.0038261239 | F33: Hipotesis
A34: 4 | B34: 2 | C34: =B34-A34 -> -2 | D34: =(C34-$G$6)^2 -> 3.7564034
A35: 3 | B35: 4 | C35: =B35-A35 -> 1 | D35: =(C35-$G$6)^2 -> 1.1275375 | F35: hipotesis nula Ho = No hay diferencias significativa
A36: 3 | B36: 4 | C36: =B36-A36 -> 1 | D36: =(C36-$G$6)^2 -> 1.1275375 | F36: hipotesis alternativa H1 = Si hay diferencia significativa
A37: 4 | B37: 4 | C37: =B37-A37 -> 0 | D37: =(C37-$G$6)^2 -> 0.0038261239
A38: 2 | B38: 4 | C38: =B38-A38 -> 2 | D38: =(C38-$G$6)^2 -> 4.2512488
A39: 2 | B39: 2 | C39: =B39-A39 -> 0 | D39: =(C39-$G$6)^2 -> 0.0038261239
A40: 5 | B40: 5 | C40: =B40-A40 -> 0 | D40: =(C40-$G$6)^2 -> 0.0038261239 | F40: Si t calculado > t critico (Tabla)
...

Sheet Resolución-autónoma
A1: (Sin Aprendizaje Colaborativo) Pre-test Resolución-autónoma | B1: (Sin Aprendizaje Colaborativo) Post-test Resolución-autónoma | C1: Diferencia
A2: 3 | B2: 3 | C2: =B2-A2 -> 0 | D2: =(C2-$G$6)^2 -> 0.00042512488
A3: 4 | B3: 2 | C3: =B3-A3 -> -2 | D3: =(C3-$G$6)^2 -> 3.9179509 | F3: Datos
A4: 3 | B4: 5 | C4: =B4-A4 -> 2 | D4: =(C4-$G$6)^2 -> 4.0828994 | F4: numero de datos | G4: =COUNT(A:A) -> 97
A5: 3 | B5: 5 | C5: =B5-A5 -> 2 | D5: =(C5-$G$6)^2 -> 4.0828994 | F5: Sumatoria Diferencias | G5: =SUM(C:C) -> -2
A6: 3 | B6: 4 | C6: =B6-A6 -> 1 | D6: =(C6-$G$6)^2 -> 1.0416622 | F6: Media de las diferencias | G6: =G5/G4 -> -0.020618557
A7: 3 | B7: 2 | C7: =B7-A7 -> -1 | D7: =(C7-$G$6)^2 -> 0.95918801 | F7: Sumatoria de diferencias | G7: =SUM(D:D) -> 205.95876
A8: 3 | B8: 4 | C8: =B8-A8 -> 1 | D8: =(C8-$G$6)^2 -> 1.0416622 | F8: desviación estándar de las diferencias | G8: =SQRT(G7/(G4-1)) -> 1.4647197
A9: 3 | B9: 3 | C9: =B9-A9 -> 0 | D9: =(C9-$G$6)^2 -> 0.00042512488
A10: 4 | B10: 3 | C10: =B10-A10 -> -1 | D10: =(C10-$G$6)^2 -> 0.95918801
A11: 3 | B11: 3 | C11: =B11-A11 -> 0 | D11: =(C11-$G$6)^2 -> 0.00042512488
A12: 5 | B12: 5 | C12: =B12-A12 -> 0 | D12: =(C12-$G$6)^2 -> 0.00042512488 | F12: t calculado (estadistico t): | G12: =G6/(G8/SQRT(G4)) -> -0.13864034
A13: 3 | B13: 5 | C13: =B13-A13 -> 2 | D13: =(C13-$G$6)^2 -> 4.0828994
A14: 1 | B14: 4 | C14: =B14-A14 -> 3 | D14: =(C14-$G$6)^2 -> 9.1241365
A15: 2 | B15: 3 | C15: =B15-A15 -> 1 | D15: =(C15-$G$6)^2 -> 1.0416622
A16: 2 | B16: 3 | C16: =B16-A16 -> 1 | D16: =(C16-$G$6)^2 -> 1.0416622
A17: 3 | B17: 3 | C17: =B17-A17 -> 0 | D17: =(C17-$G$6)^2 -> 0.00042512488 | F17: nivel de significancia (α) | G17: 0.05
A18: 2 | B18: 3 | C18: =B18-A18 -> 1 | D18: =(C18-$G$6)^2 -> 1.0416622 | F18: grados de libertad (DF) | G18: =G4-1 -> 96
A19: 3 | B19: 4 | C19: =B19-A19 -> 1 | D19: =(C19-$G$6)^2 -> 1.0416622
A20: 4 | B20: 3 | C20: =B20-A20 -> -1 | D20: =(C20-$G$6)^2 -> 0.95918801
A21: 5 | B21: 4 | C21: =B21-A21 -> -1 | D21: =(C21-$G$6)^2 -> 0.95918801
A22: 2 | B22: 2 | C22: =B22-A22 -> 0 | D22: =(C22-$G$6)^2 -> 0.00042512488 | F22: Valor critico t
A23: 3 | B23: 5 | C23: =B23-A23 -> 2 | D23: =(C23-$G$6)^2 -> 4.0828994 | F23: valor crítico t (Excel) - 2 colas | G23: =_xlfn.T.INV.2T(G17,G18) -> 1.9849843
A24: 3 | B24: 4 | C24: =B24-A24 -> 1 | D24: =(C24-$G$6)^2 -> 1.0416622 | F24: valor crítico t (Excel) - 1 colas | G24: =_xlfn.T.INV(G17,G18) -> -1.6608814
A25: 4 | B25: 2 | C25: =B25-A25 -> -2 | D25: =(C25-$G$6)^2 -> 3.9179509
A26: 5 | B26: 4 | C26: =B26-A26 -> -1 | D26: =(C26-$G$6)^2 -> 0.95918801
A27: 2 | B27: 3 | C27: =B27-A27 -> 1 | D27: =(C27-$G$6)^2 -> 1.0416622 | F27: p valor
A28: 2 | B28: 3 | C28: =B28-A28 -> 1 | D28: =(C28-$G$6)^2 -> 1.0416622 | F28: p valor
A29: 2 | B29: 3 | C29: =B29-A29 -> 1 | D29: =(C29-$G$6)^2 -> 1.0416622 | F29: p valor con (Excel) dos colas | G29: =TTEST(A:A,B:B,2,1) -> 0.89002478
A30: 2 | B30: 1 | C30: =B30-A30 -> -1 | D30: =(C30-$G$6)^2 -> 0.95918801 | F30: p valor con (Excel) una colas | G30: =TTEST(A:A,B:B,1,1) -> 0.44501239
A31: 4 | B31: 3 | C31: =B31-A31 -> -1 | D31: =(C31-$G$6)^2 -> 0.95918801
A32: 3 | B32: 1 | C32: =B32-A32 -> -2 | D32: =(C32-$G$6)^2 -> 3.9179509
A33: 4 | B33: 3 | C33: =B33-A33 -> -1 | D33: =(C33-$G$6)^2 -> 0.95918801 | F33: Hipotesis
A34: 3 | B34: 3 | C34: =B34-A34 -> 0 | D34: =(C34-$G$6)^2 -> 0.00042512488
A35: 3 | B35: 3 | C35: =B35-A35 -> 0 | D35: =(C35-$G$6)^2 -> 0.00042512488 | F35: hipotesis nula Ho = No hay diferencias significativa
A36: 2 | B36: 3 | C36: =B36-A36 -> 1 | D36: =(C36-$G$6)^2 -> 1.0416622 | F36: hipotesis alternativa H1 = Si hay diferencia significativa
A37: 1 | B37: 4 | C37: =B37-A37 -> 3 | D37: =(C37-$G$6)^2 -> 9.1241365
A38: 3 | B38: 3 | C38: =B38-A38 -> 0 | D38: =(C38-$G$6)^2 -> 0.00042512488
A39: 3 | B39: 2 | C39: =B39-A39 -> -1 | D39: =(C39-$G$6)^2 -> 0.95918801
A40: 2 | B40: 2 | C40: =B40-A40 -> 0 | D40: =(C40-$G$6)^2 -> 0.00042512488 | F40: Si t calculado > t critico (Tabla)
...

Sheet Motivación
A1: (Sin Aprendizaje Colaborativo) Pre-test Motivación | B1: (Sin Aprendizaje Colaborativo) Post-test Motivación | C1: Diferencia
A2: 4 | B2: 3 | C2: =B2-A2 -> -1 | D2: =(C2-$G$6)^2 -> 0.80444255
A3: 4 | B3: 3 | C3: =B3-A3 -> -1 | D3: =(C3-$G$6)^2 -> 0.80444255 | F3: Datos
A4: 2 | B4: 5 | C4: =B4-A4 -> 3 | D4: =(C4-$G$6)^2 -> 9.6291848 | F4: numero de datos | G4: =COUNT(A:A) -> 97
A5: 3 | B5: 5 | C5: =B5-A5 -> 2 | D5: =(C5-$G$6)^2 -> 4.4229993 | F5: Sumatoria Diferencias | G5: =SUM(C:C) -> -10
A6: 3 | B6: 2 | C6: =B6-A6 -> -1 | D6: =(C6-$G$6)^2 -> 0.80444255 | F6: Media de las diferencias | G6: =G5/G4 -> -0.10309278
A7: 2 | B7: 3 | C7: =B7-A7 -> 1 | D7: =(C7-$G$6)^2 -> 1.2168137 | F7: Sumatoria de diferencias | G7: =SUM(D:D) -> 238.96907
A8: 4 | B8: 3 | C8: =B8-A8 -> -1 | D8: =(C8-$G$6)^2 -> 0.80444255 | F8: desviación estándar de las diferencias | G8: =SQRT(G7/(G4-1)) -> 1.5777393
A9: 3 | B9: 1 | C9: =B9-A9 -> -2 | D9: =(C9-$G$6)^2 -> 3.598257
A10: 3 | B10: 2 | C10: =B10-A10 -> -1 | D10: =(C10-$G$6)^2 -> 0.80444255
A11: 1 | B11: 3 | C11: =B11-A11 -> 2 | D11: =(C11-$G$6)^2 -> 4.4229993
A12: 1 | B12: 3 | C12: =B12-A12 -> 2 | D12: =(C12-$G$6)^2 -> 4.4229993 | F12: t calculado (estadistico t): | G12: =G6/(G8/SQRT(G4)) -> -0.64354497
A13: 4 | B13: 5 | C13: =B13-A13 -> 1 | D13: =(C13-$G$6)^2 -> 1.2168137
A14: 4 | B14: 4 | C14: =B14-A14 -> 0 | D14: =(C14-$G$6)^2 -> 0.010628122
A15: 5 | B15: 3 | C15: =B15-A15 -> -2 | D15: =(C15-$G$6)^2 -> 3.598257
A16: 5 | B16: 4 | C16: =B16-A16 -> -1 | D16: =(C16-$G$6)^2 -> 0.80444255
A17: 2 | B17: 4 | C17: =B17-A17 -> 2 | D17: =(C17-$G$6)^2 -> 4.4229993 | F17: nivel de significancia (α) | G17: 0.05
A18: 3 | B18: 2 | C18: =B18-A18 -> -1 | D18: =(C18-$G$6)^2 -> 0.80444255 | F18: grados de libertad (DF) | G18: =G4-1 -> 96
A19: 3 | B19: 2 | C19: =B19-A19 -> -1 | D19: =(C19-$G$6)^2 -> 0.80444255
A20: 4 | B20: 3 | C20: =B20-A20 -> -1 | D20: =(C20-$G$6)^2 -> 0.80444255
A21: 3 | B21: 5 | C21: =B21-A21 -> 2 | D21: =(C21-$G$6)^2 -> 4.4229993
A22: 2 | B22: 1 | C22: =B22-A22 -> -1 | D22: =(C22-$G$6)^2 -> 0.80444255 | F22: Valor critico t
A23: 3 | B23: 2 | C23: =B23-A23 -> -1 | D23: =(C23-$G$6)^2 -> 0.80444255 | F23: valor crítico t (Excel) - 2 colas | G23: =_xlfn.T.INV.2T(G17,G18) -> 1.9849843
A24: 1 | B24: 3 | C24: =B24-A24 -> 2 | D24: =(C24-$G$6)^2 -> 4.4229993 | F24: valor crítico t (Excel) - 1 colas | G24: =_xlfn.T.INV(G17,G18) -> -1.6608814
A25: 3 | B25: 3 | C25: =B25-A25 -> 0 | D25: =(C25-$G$6)^2 -> 0.010628122
A26: 3 | B26: 4 | C26: =B26-A26 -> 1 | D26: =(C26-$G$6)^2 -> 1.2168137
A27: 4 | B27: 1 | C27: =B27-A27 -> -3 | D27: =(C27-$G$6)^2 -> 8.3920714 | F27: p valor
A28: 3 | B28: 1 | C28: =B28-A28 -> -2 | D28: =(C28-$G$6)^2 -> 3.598257 | F28: p valor
A29: 3 | B29: 4 | C29: =B29-A29 -> 1 | D29: =(C29-$G$6)^2 -> 1.2168137 | F29: p valor con (Excel) dos colas | G29: =TTEST(A:A,B:B,2,1) -> 0.52140494
A30: 3 | B30: 1 | C30: =B30-A30 -> -2 | D30: =(C30-$G$6)^2 -> 3.598257 | F30: p valor con (Excel) una colas | G30: =TTEST(A:A,B:B,1,1) -> 0.26070247
A31: 3 | B31: 1 | C31: =B31-A31 -> -2 | D31: =(C31-$G$6)^2 -> 3.598257
A32: 5 | B32: 4 | C32: =B32-A32 -> -1 | D32: =(C32-$G$6)^2 -> 0.80444255
A33: 3 | B33: 2 | C33: =B33-A33 -> -1 | D33: =(C33-$G$6)^2 -> 0.80444255 | F33: Hipotesis
A34: 1 | B34: 3 | C34: =B34-A34 -> 2 | D34: =(C34-$G$6)^2 -> 4.4229993
A35: 5 | B35: 3 | C35: =B35-A35 -> -2 | D35: =(C35-$G$6)^2 -> 3.598257 | F35: hipotesis nula Ho = No hay diferencias significativa
A36: 1 | B36: 5 | C36: =B36-A36 -> 4 | D36: =(C36-$G$6)^2 -> 16.83537 | F36: hipotesis alternativa H1 = Si hay diferencia significativa
A37: 3 | B37: 2 | C37: =B37-A37 -> -1 | D37: =(C37-$G$6)^2 -> 0.80444255
A38: 2 | B38: 5 | C38: =B38-A38 -> 3 | D38: =(C38-$G$6)^2 -> 9.6291848
A39: 2 | B39: 2 | C39: =B39-A39 -> 0 | D39: =(C39-$G$6)^2 -> 0.010628122
A40: 3 | B40: 5 | C40: =B40-A40 -> 2 | D40: =(C40-$G$6)^2 -> 4.4229993 | F40: Si t calculado > t critico (Tabla)
...
