Workbook

Sheet Resumen
A1: Indicador | B1: T Calculado | C1: T Critico 2 Colas | D1: T Critico 1 Cola | E1: P valor 2 Colas | F1: P valor 1 Cola
A2: Participación activa | B2: =ROUND('Participación-activa'!E29, 4) -> -7.215 | C2: =ROUND('Participación-activa'!E52, 4) -> 1.9728 | D2: =ROUND('Participación-activa'!E53, 4) -> -1.6531 | E2: ='Participación-activa'!E55 -> 1.2164728e-11 | F2: ='Participación-activa'!E56 -> 6.0823638e-12
A3: Comunicación equipo | B3: =ROUND('Comunicación-equipo'!E29, 4) -> -5.9491 | C3: =ROUND('Comunicación-equipo'!E52, 4) -> 1.9731 | D3: =ROUND('Comunicación-equipo'!E53, 4) -> -1.6533 | E3: ='Comunicación-equipo'!E55 -> 1.2551529e-08 | F3: ='Comunicación-equipo'!E56 -> 6.2757646e-09
A4: Cumplimiento tareas | B4: =ROUND('Cumplimiento-tareas'!E29, 4) -> -6.295 | C4: =ROUND('Cumplimiento-tareas'!E52, 4) -> 1.9729 | D4: =ROUND('Cumplimiento-tareas'!E53, 4) -> -1.6532 | E4: ='Cumplimiento-tareas'!E55 -> 2.0418739e-09 | F4: ='Cumplimiento-tareas'!E56 -> 1.0209369e-09
A5: Contribución grupo | B5: =ROUND('Contribución-grupo'!E29, 4) -> -7.2118 | C5: =ROUND('Contribución-grupo'!E52, 4) -> 1.9727 | D5: =ROUND('Contribución-grupo'!E53, 4) -> -1.653 | E5: ='Contribución-grupo'!E55 -> 1.2395623e-11 | F5: ='Contribución-grupo'!E56 -> 6.1978117e-12
A6: Resolución problemas | B6: =ROUND('Resolución-problemas'!E29, 4) -> -4.4748 | C6: =ROUND('Resolución-problemas'!E52, 4) -> 1.9727 | D6: =ROUND('Resolución-problemas'!E53, 4) -> -1.653 | E6: ='Resolución-problemas'!E55 -> 1.3088744e-05 | F6: ='Resolución-problemas'!E56 -> 6.5443722e-06
A7: Conocimientos adquiridos | B7: =ROUND('Conocimientos-adquiridos'!E29, 4) -> -6.9263 | C7: =ROUND('Conocimientos-adquiridos'!E52, 4) -> 1.9736 | D7: =ROUND('Conocimientos-adquiridos'!E53, 4) -> -1.6536 | E7: ='Conocimientos-adquiridos'!E55 -> 6.3390533e-11 | F7: ='Conocimientos-adquiridos'!E56 -> 3.1695267e-11
A8: Nota final | B8: =ROUND('Nota-final'!E29, 4) -> -9.1623 | C8: =ROUND('Nota-final'!E52, 4) -> 1.9732 | D8: =ROUND('Nota-final'!E53, 4) -> -1.6533 | E8: ='Nota-final'!E55 -> 7.7758254e-17 | F8: ='Nota-final'!E56 -> 3.8879127e-17
A9: Comprensión | B9: =ROUND(Comprensión!E29, 4) -> -6.8139 | C9: =ROUND(Comprensión!E52, 4) -> 1.9732 | D9: =ROUND(Comprensión!E53, 4) -> -1.6534 | E9: =Comprensión!E55 -> 1.1930592e-10 | F9: =Comprensión!E56 -> 5.9652961e-11
A10: Habilidades | B10: =ROUND(Habilidades!E29, 4) -> -6.0176 | C10: =ROUND(Habilidades!E52, 4) -> 1.9725 | D10: =ROUND(Habilidades!E53, 4) -> -1.6529 | E10: =Habilidades!E55 -> 8.8064005e-09 | F10: =Habilidades!E56 -> 4.4032003e-09
A11: Resolución autónoma | B11: =ROUND('Resolución-autónoma'!E29, 4) -> -8.65 | C11: =ROUND('Resolución-autónoma'!E52, 4) -> 1.9726 | D11: =ROUND('Resolución-autónoma'!E53, 4) -> -1.653 | E11: ='Resolución-autónoma'!E55 -> 2.0409501e-15 | F11: ='Resolución-autónoma'!E56 -> 1.020475e-15
A12: Motivación | B12: =ROUND(Motivación!E29, 4) -> -6.189 | C12: =ROUND(Motivación!E52, 4) -> 1.9725 | D12: =ROUND(Motivación!E53, 4) -> -1.6529 | E12: =Motivación!E55 -> 3.5865188e-09 | F12: =Motivación!E56 -> 1.7932594e-09

Sheet Participación-activa
A1: (Sin Aprendizaje Colaborativo) Grupo Control - Post-test Participación-activa | B1: (Con Aprendizaje Colaborativo) Grupo Experimental - Post-test Participación-activa
A2: 2 | B2: 4 | D2: Media (X1) Grupo Control | E2: =AVERAGE(A:A) -> 3
A3: 2 | B3: 5 | D3: Mediana (Me1) | E3: =MEDIAN(A:A) -> 3
A4: 2 | B4: 2 | D4: Moda (Mo1) | E4: =MODE(A:A) -> 3
A5: 3 | B5: 3 | D5: Desviacion Tipica o Estandar (S1) | E5: =STDEV(A:A) -> 1.1636867
A6: 4 | B6: 4 | D6: n1 | E6: =COUNT(A:A) -> 97
A7: 5 | B7: 4
A8: 1 | B8: 5 | D8: Media (X2) Grupo Experimental | E8: =AVERAGE(B:B) -> 4.1134021
A9: 2 | B9: 4 | D9: Mediana (Me2) | E9: =MEDIAN(B:B) -> 4
A10: 3 | B10: 5 | D10: Moda (Mo2) | E10: =MODE(B:B) -> 5
A11: 3 | B11: 4 | D11: Desviacion Tipica o Estandar (S2) | E11: =STDEV(B:B) -> 0.97762775
A12: 3 | B12: 5 | D12: n2 | E12: =COUNT(B:B) -> 97
A13: 5 | B13: 5
A14: 4 | B14: 5
A15: 5 | B15: 5
A16: 2 | B16: 4
A17: 4 | B17: 5 | D17: t de student
A18: 3 | B18: 5
A19: 5 | B19: 4
A20: 4 | B20: 3
A21: 3 | B21: 5
A22: 2 | B22: 5
A23: 2 | B23: 1
A24: 1 | B24: 4
A25: 2 | B25: 5
A26: 2 | B26: 4
A27: 2 | B27: 4
A28: 5 | B28: 5
A29: 4 | B29: 4 | D29: Valor de t | E29: =(E2-E8)/SQRT(((E5^2)/E6)+((E11^2)/E12)) -> -7.215047
A30: 4 | B30: 2
A31: 3 | B31: 5 | D31: df grados de libertad
A32: 3 | B32: 5
A33: 4 | B33: 5
A34: 4 | B34: 3
A35: 5 | B35: 3
A36: 2 | B36: 5
A37: 4 | B37: 5
A38: 2 | B38: 5
A39: 1 | B39: 4
A40: 3 | B40: 5
...

Sheet Comunicación-equipo
A1: (Sin Aprendizaje Colaborativo) Grupo Control - Post-test Comunicación-equipo | B1: (Con Aprendizaje Colaborativo) Grupo Experimental - Post-test Comprensión-contenidos
A2: 3 | B2: 5 | D2: Media (X1) Grupo Control | E2: =AVERAGE(A:A) -> 3.1237113
A3: 3 | B3: 5 | D3: Mediana (Me1) | E3: =MEDIAN(A:A) -> 3
A4: 3 | B4: 5 | D4: Moda (Mo1) | E4: =MODE(A:A) -> 3
A5: 2 | B5: 4 | D5: Desviacion Tipica o Estandar (S1) | E5: =STDEV(A:A) -> 1.2437991
A6: 1 | B6: 2 | D6: n1 | E6: =COUNT(A:A) -> 97
A7: 3 | B7: 5
A8: 3 | B8: 3 | D8: Media (X2) Grupo Experimental | E8: =AVERAGE(B:B) -> 4.0824742
A9: 4 | B9: 3 | D9: Mediana (Me2) | E9: =MEDIAN(B:B) -> 4
A10: 1 | B10: 5 | D10: Moda (Mo2) | E10: =MODE(B:B) -> 5
A11: 4 | B11: 1 | D11: Desviacion Tipica o Estandar (S2) | E11: =STDEV(B:B) -> 0.9860496
A12: 2 | B12: 3 | D12: n2 | E12: =COUNT(B:B) -> 97
A13: 3 | B13: 5
A14: 2 | B14: 3
A15: 2 | B15: 4
A16: 5 | B16: 4
A17: 1 | B17: 4 | D17: t de student
A18: 5 | B18: 5
A19: 4 | B19: 3
A20: 3 | B20: 5
A21: 3 | B21: 4
A22: 3 | B22: 5
A23: 4 | B23: 5
A24: 1 | B24: 2
A25: 4 | B25: 5
A26: 4 | B26: 5
A27: 4 | B27: 4
A28: 5 | B28: 4
A29: 3 | B29: 4 | D29: Valor de t | E29: =(E2-E8)/SQRT(((E5^2)/E6)+((E11^2)/E12)) -> -5.9491451
A30: 1 | B30: 5
A31: 5 | B31: 3 | D31: df grados de libertad
A32: 1 | B32: 5
A33: 4 | B33: 5
A34: 1 | B34: 5
A35: 2 | B35: 5
A36: 5 | B36: 3
A37: 3 | B37: 5
A38: 4 | B38: 3
A39: 4 | B39: 4
A40: 5 | B40: 3
...

Sheet Cumplimiento-tareas
A1: (Sin Aprendizaje Colaborativo) Grupo Control - Post-test Cumplimiento-tareas | B1: (Con Aprendizaje Colaborativo) Grupo Experimental - Post-test Cumplimiento-tareas
A2: 4 | B2: 4 | D2: Media (X1) Grupo Control | E2: =AVERAGE(A:A) -> 3.1237113
A3: 3 | B3: 4 | D3: Mediana (Me1) | E3: =MEDIAN(A:A) -> 3
A4: 4 | B4: 2 | D4: Moda (Mo1) | E4: =MODE(A:A) -> 3
A5: 3 | B5: 5 | D5: Desviacion Tipica o Estandar (S1) | E5: =STDEV(A:A) -> 1.1748912
A6: 3 | B6: 4 | D6: n1 | E6: =COUNT(A:A) -> 97
A7: 4 | B7: 5
A8: 3 | B8: 5 | D8: Media (X2) Grupo Experimental | E8: =AVERAGE(B:B) -> 4.0927835
A9: 3 | B9: 5 | D9: Mediana (Me2) | E9: =MEDIAN(B:B) -> 4
A10: 5 | B10: 5 | D10: Moda (Mo2) | E10: =MODE(B:B) -> 5
A11: 3 | B11: 4 | D11: Desviacion Tipica o Estandar (S2) | E11: =STDEV(B:B) -> 0.958324
A12: 4 | B12: 5 | D12: n2 | E12: =COUNT(B:B) -> 97
A13: 5 | B13: 3
A14: 2 | B14: 4
A15: 3 | B15: 3
A16: 4 | B16: 4
A17: 4 | B17: 5 | D17: t de student
A18: 4 | B18: 3
A19: 5 | B19: 4
A20: 3 | B20: 4
A21: 3 | B21: 4
A22: 4 | B22: 4
A23: 2 | B23: 3
A24: 4 | B24: 5
A25: 2 | B25: 5
A26: 5 | B26: 2
A27: 3 | B27: 3
A28: 1 | B28: 3
A29: 3 | B29: 4 | D29: Valor de t | E29: =(E2-E8)/SQRT(((E5^2)/E6)+((E11^2)/E12)) -> -6.2949996
A30: 3 | B30: 5
A31: 1 | B31: 2 | D31: df grados de libertad
A32: 5 | B32: 5
A33: 4 | B33: 5
A34: 5 | B34: 5
A35: 3 | B35: 2
A36: 1 | B36: 4
A37: 2 | B37: 5
A38: 4 | B38: 5
A39: 4 | B39: 5
A40: 4 | B40: 4
...

Sheet Contribución-grupo
A1: (Sin Aprendizaje Colaborativo) Grupo control - Post-test Contribución-grupo | B1: (Con Aprendizaje Colaborativo) Grupo Experimental - Post-test Contribución-grupo
A2: 3 | B2: 5 | D2: Media (X1) Grupo Control | E2: =AVERAGE(A:A) -> 3.1958763
A3: 3 | B3: 5 | D3: Mediana (Me1) | E3: =MEDIAN(A:A) -> 3
A4: 4 | B4: 5 | D4: Moda (Mo1) | E4: =MODE(A:A) -> 3
A5: 3 | B5: 4 | D5: Desviacion Tipica o Estandar (S1) | E5: =STDEV(A:A) -> 1.066919
A6: 4 | B6: 5 | D6: n1 | E6: =COUNT(A:A) -> 97
A7: 3 | B7: 4
A8: 4 | B8: 5 | D8: Media (X2) Grupo Experimental | E8: =AVERAGE(B:B) -> 4.2268041
A9: 2 | B9: 5 | D9: Mediana (Me2) | E9: =MEDIAN(B:B) -> 4
A10: 3 | B10: 5 | D10: Moda (Mo2) | E10: =MODE(B:B) -> 5
A11: 3 | B11: 5 | D11: Desviacion Tipica o Estandar (S2) | E11: =STDEV(B:B) -> 0.91861711
A12: 5 | B12: 3 | D12: n2 | E12: =COUNT(B:B) -> 97
A13: 4 | B13: 5
A14: 5 | B14: 3
A15: 5 | B15: 2
A16: 4 | B16: 4
A17: 5 | B17: 5 | D17: t de student
A18: 3 | B18: 5
A19: 2 | B19: 5
A20: 3 | B20: 5
A21: 1 | B21: 5
A22: 4 | B22: 3
A23: 3 | B23: 5
A24: 4 | B24: 5
A25: 1 | B25: 5
A26: 3 | B26: 5
A27: 2 | B27: 4
A28: 3 | B28: 3
A29: 5 | B29: 4 | D29: Valor de t | E29: =(E2-E8)/SQRT(((E5^2)/E6)+((E11^2)/E12)) -> -7.2117937
A30: 4 | B30: 5
A31: 3 | B31: 5 | D31: df grados de libertad
A32: 2 | B32: 5
A33: 3 | B33: 5
A34: 2 | B34: 4
A35: 5 | B35: 5
A36: 3 | B36: 3
A37: 3 | B37: 4
A38: 3 | B38: 5
A39: 2 | B39: 5
A40: 4 | B40: 5
...

Sheet Resolución-problemas
A1: (Sin Aprendizaje Colaborativo) Grupo Control - Post-test Resolución-problemas | B1: (Con Aprendizaje Colaborativo) Grupo Experimental - Post-test Resolución-problemas
A2: 4 | B2: 2 | D2: Media (X1) Grupo Control | E2: =AVERAGE(A:A) -> 3.2886598
A3: 3 | B3: 3 | D3: Mediana (Me1) | E3: =MEDIAN(A:A) -> 3
A4: 1 | B4: 4 | D4: Moda (Mo1) | E4: =MODE(A:A) -> 3
A5: 3 | B5: 1 | D5: Desviacion Tipica o Estandar (S1) | E5: =STDEV(A:A) -> 1.1452689
A6: 3 | B6: 4 | D6: n1 | E6: =COUNT(A:A) -> 97
A7: 5 | B7: 4
A8: 3 | B8: 4 | D8: Media (X2) Grupo Experimental | E8: =AVERAGE(B:B) -> 3.9793814
A9: 3 | B9: 4 | D9: Mediana (Me2) | E9: =MEDIAN(B:B) -> 4
A10: 4 | B10: 5 | D10: Moda (Mo2) | E10: =MODE(B:B) -> 4
A11: 4 | B11: 4 | D11: Desviacion Tipica o Estandar (S2) | E11: =STDEV(B:B) -> 0.9997852
A12: 3 | B12: 5 | D12: n2 | E12: =COUNT(B:B) -> 97
A13: 3 | B13: 3
A14: 4 | B14: 5
A15: 4 | B15: 3
A16: 3 | B16: 4
A17: 2 | B17: 1 | D17: t de student
A18: 5 | B18: 4
A19: 2 | B19: 3
A20: 4 | B20: 4
A21: 3 | B21: 5
A22: 4 | B22: 5
A23: 3 | B23: 5
A24: 3 | B24: 4
A25: 4 | B25: 4
A26: 2 | B26: 3
A27: 5 | B27: 4
A28: 2 | B28: 3
A29: 1 | B29: 4 | D29: Valor de t | E29: =(E2-E8)/SQRT(((E5^2)/E6)+((E11^2)/E12)) -> -4.4747534
A30: 4 | B30: 5
A31: 3 | B31: 4 | D31: df grados de libertad
A32: 3 | B32: 4
A33: 1 | B33: 3
A34: 3 | B34: 4
A35: 3 | B35: 5
A36: 5 | B36: 4
A37: 1 | B37: 3
A38: 4 | B38: 5
A39: 4 | B39: 5
A40: 3 | B40: 5
...

Sheet Conocimientos-adquiridos
A1: (Sin Aprendizaje Colaborativo) Grupo Control - Post-test Conocimientos-adquiridos | B1: (Con Aprendizaje Colaborativo) Grupo Experimental - Post-test Conocimientos-adquiridos
A2: 3 | B2: 4 | D2: Media (X1) Grupo Control | E2: =AVERAGE(A:A) -> 3.1340206
A3: 4 | B3: 5 | D3: Mediana (Me1) | E3: =MEDIAN(A:A) -> 3
A4: 2 | B4: 5 | D4: Moda (Mo1) | E4: =MODE(A:A) -> 3
A5: 2 | B5: 5 | D5: Desviacion Tipica o Estandar (S1) | E5: =STDEV(A:A) -> 1.2300819
A6: 2 | B6: 3 | D6: n1 | E6: =COUNT(A:A) -> 97
A7: 3 | B7: 3
A8: 3 | B8: 4 | D8: Media (X2) Grupo Experimental | E8: =AVERAGE(B:B) -> 4.2061856
A9: 4 | B9: 5 | D9: Mediana (Me2) | E9: =MEDIAN(B:B) -> 4
A10: 2 | B10: 5 | D10: Moda (Mo2) | E10: =MODE(B:B) -> 5
A11: 2 | B11: 4 | D11: Desviacion Tipica o Estandar (S2) | E11: =STDEV(B:B) -> 0.90067272
A12: 5 | B12: 5 | D12: n2 | E12: =COUNT(B:B) -> 97
A13: 5 | B13: 5
A14: 1 | B14: 4
A15: 5 | B15: 5
A16: 3 | B16: 5
A17: 5 | B17: 4 | D17: t de student
A18: 1 | B18: 5
A19: 2 | B19: 4
A20: 3 | B20: 3
A21: 3 | B21: 4
A22: 4 | B22: 4
A23: 4 | B23: 3
A24: 4 | B24: 4
A25: 2 | B25: 5
A26: 3 | B26: 4
A27: 3 | B27: 4
A28: 1 | B28: 5
A29: 3 | B29: 5 | D29: Valor de t | E29: =(E2-E8)/SQRT(((E5^2)/E6)+((E11^2)/E12)) -> -6.9262824
A30: 5 | B30: 4
A31: 1 | B31: 5 | D31: df grados de libertad
A32: 5 | B32: 4
A33: 3 | B33: 4
A34: 4 | B34: 3
A35: 5 | B35: 5
A36: 4 | B36: 5
A37: 2 | B37: 4
A38: 3 | B38: 4
A39: 2 | B39: 2
A40: 4 | B40: 4
...

Sheet Nota-final
A1: (Sin Aprendizaje Colaborativo) Grupo Control - Post-test Nota-final | B1: (Con Aprendizaje Colaborativo) Grupo Experimental - Post-test Nota-final
A2: 3 | B2: 4 | D2: Media (X1) Grupo Control | E2: =AVERAGE(A:A) -> 2.7731959
A3: 2 | B3: 3 | D3: Mediana (Me1) | E3: =MEDIAN(A:A) -> 3
A4: 1 | B4: 5 | D4: Moda (Mo1) | E4: =MODE(A:A) -> 3
A5: 2 | B5: 3 | D5: Desviacion Tipica o Estandar (S1) | E5: =STDEV(A:A) -> 1.1681998
A6: 5 | B6: 5 | D6: n1 | E6: =COUNT(A:A) -> 97
A7: 2 | B7: 4
A8: 4 | B8: 2 | D8: Media (X2) Grupo Experimental | E8: =AVERAGE(B:B) -> 4.1546392
A9: 4 | B9: 4 | D9: Mediana (Me2) | E9: =MEDIAN(B:B) -> 4
A10: 2 | B10: 5 | D10: Moda (Mo2) | E10: =MODE(B:B) -> 5
A11: 2 | B11: 3 | D11: Desviacion Tipica o Estandar (S2) | E11: =STDEV(B:B) -> 0.91674476
A12: 3 | B12: 4 | D12: n2 | E12: =COUNT(B:B) -> 97
A13: 5 | B13: 5
A14: 3 | B14: 5
A15: 1 | B15: 5
A16: 1 | B16: 2
A17: 3 | B17: 5 | D17: t de student
A18: 3 | B18: 4
A19: 2 | B19: 5
A20: 4 | B20: 5
A21: 2 | B21: 4
A22: 3 | B22: 4
A23: 1 | B23: 5
A24: 4 | B24: 5
A25: 3 | B25: 5
A26: 3 | B26: 4
A27: 3 | B27: 5
A28: 1 | B28: 4
A29: 2 | B29: 3 | D29: Valor de t | E29: =(E2-E8)/SQRT(((E5^2)/E6)+((E11^2)/E12)) -> -9.1622816
A30: 3 | B30: 5
A31: 1 | B31: 4 | D31: df grados de libertad
A32: 1 | B32: 4
A33: 3 | B33: 3
A34: 5 | B34: 5
A35: 5 | B35: 5
A36: 1 | B36: 5
A37: 3 | B37: 4
A38: 2 | B38: 4
A39: 2 | B39: 5
A40: 1 | B40: 4
...

Sheet Comprensión
A1: (Sin Aprendizaje Colaborativo) Grupo Control - Post-test Comprensión | B1: (Con Aprendizaje Colaborativo) Grupo Experimental - Post-test Comprensión
A2: 3 | B2: 4 | D2: Media (X1) Grupo Control | E2: =AVERAGE(A:A) -> 3.0618557
A3: 5 | B3: 5 | D3: Mediana (Me1) | E3: =MEDIAN(A:A) -> 3
A4: 2 | B4: 4 | D4: Moda (Mo1) | E4: =MODE(A:A) -> 3
A5: 3 | B5: 5 | D5: Desviacion Tipica o Estandar (S1) | E5: =STDEV(A:A) -> 1.2146196
A6: 3 | B6: 4 | D6: n1 | E6: =COUNT(A:A) -> 97
A7: 3 | B7: 5
A8: 2 | B8: 3 | D8: Media (X2) Grupo Experimental | E8: =AVERAGE(B:B) -> 4.1237113
A9: 1 | B9: 5 | D9: Mediana (Me2) | E9: =MEDIAN(B:B) -> 4
A10: 3 | B10: 3 | D10: Moda (Mo2) | E10: =MODE(B:B) -> 5
A11: 3 | B11: 5 | D11: Desviacion Tipica o Estandar (S2) | E11: =STDEV(B:B) -> 0.93828003
A12: 3 | B12: 5 | D12: n2 | E12: =COUNT(B:B) -> 97
A13: 2 | B13: 4
A14: 2 | B14: 4
A15: 5 | B15: 4
A16: 4 | B16: 5
A17: 3 | B17: 4 | D17: t de student
A18: 3 | B18: 2
A19: 5 | B19: 5
A20: 4 | B20: 3
A21: 3 | B21: 4
A22: 1 | B22: 4
A23: 2 | B23: 3
A24: 5 | B24: 5
A25: 3 | B25: 5
A26: 3 | B26: 5
A27: 3 | B27: 5
A28: 1 | B28: 5
A29: 3 | B29: 3 | D29: Valor de t | E29: =(E2-E8)/SQRT(((E5^2)/E6)+((E11^2)/E12)) -> -6.8138744
A30: 2 | B30: 4
A31: 2 | B31: 5 | D31: df grados de libertad
A32: 5 | B32: 4
A33: 4 | B33: 4
A34: 4 | B34: 5
A35: 5 | B35: 5
A36: 3 | B36: 5
A37: 5 | B37: 4
A38: 1 | B38: 5
A39: 4 | B39: 1
A40: 1 | B40: 5
...

Sheet Habilidades
A1: (Sin Aprendizaje Colaborativo) Grupo Control - Post-test Habilidades | B1: (Con Aprendizaje Colaborativo) Grupo Experimental - Post-test Habilidades
A2: 4 | B2: 4 | D2: Media (X1) Grupo Control | E2: =AVERAGE(A:A) -> 3.0927835
A3: 4 | B3: 3 | D3: Mediana (Me1) | E3: =MEDIAN(A:A) -> 3
A4: 4 | B4: 3 | D4: Moda (Mo1) | E4: =MODE(A:A) -> 3
A5: 2 | B5: 5 | D5: Desviacion Tipica o Estandar (S1) | E5: =STDEV(A:A) -> 1.1733364
A6: 1 | B6: 3 | D6: n1 | E6: =COUNT(A:A) -> 97
A7: 5 | B7: 5
A8: 4 | B8: 3 | D8: Media (X2) Grupo Experimental | E8: =AVERAGE(B:B) -> 4.0721649
A9: 2 | B9: 4 | D9: Mediana (Me2) | E9: =MEDIAN(B:B) -> 4
A10: 1 | B10: 5 | D10: Moda (Mo2) | E10: =MODE(B:B) -> 5
A11: 4 | B11: 1 | D11: Desviacion Tipica o Estandar (S2) | E11: =STDEV(B:B) -> 1.0920873
A12: 2 | B12: 4 | D12: n2 | E12: =COUNT(B:B) -> 97
A13: 3 | B13: 4
A14: 5 | B14: 5
A15: 2 | B15: 5
A16: 3 | B16: 3
A17: 4 | B17: 4 | D17: t de student
A18: 4 | B18: 5
A19: 3 | B19: 5
A20: 3 | B20: 2
A21: 3 | B21: 4
A22: 2 | B22: 5
A23: 5 | B23: 3
A24: 3 | B24: 4
A25: 3 | B25: 5
A26: 4 | B26: 5
A27: 1 | B27: 4
A28: 5 | B28: 2
A29: 5 | B29: 4 | D29: Valor de t | E29: =(E2-E8)/SQRT(((E5^2)/E6)+((E11^2)/E12)) -> -6.0176119
A30: 1 | B30: 4
A31: 2 | B31: 5 | D31: df grados de libertad
A32: 3 | B32: 5
A33: 3 | B33: 4
A34: 2 | B34: 5
A35: 4 | B35: 5
A36: 4 | B36: 5
A37: 4 | B37: 4
A38: 4 | B38: 4
A39: 2 | B39: 5
A40: 5 | B40: 5
...

Sheet Resolución-autónoma
A1: (Sin Aprendizaje Colaborativo) Grupo Control - Post-test Resolución-autónoma | B1: (Con Aprendizaje Colaborativo) Grupo Experimental - Post-test Resolución-autónoma
A2: 3 | B2: 5 | D2: Media (X1) Grupo Control | E2: =AVERAGE(A:A) -> 2.9587629
A3: 2 | B3: 5 | D3: Mediana (Me1) | E3: =MEDIAN(A:A) -> 3
A4: 5 | B4: 4 | D4: Moda (Mo1) | E4: =MODE(A:A) -> 3
A5: 5 | B5: 2 | D5: Desviacion Tipica o Estandar (S1) | E5: =STDEV(A:A) -> 1.0889361
A6: 4 | B6: 3 | D6: n1 | E6: =COUNT(A:A) -> 97
A7: 2 | B7: 5
A8: 4 | B8: 4 | D8: Media (X2) Grupo Experimental | E8: =AVERAGE(B:B) -> 4.2371134
A9: 3 | B9: 5 | D9: Mediana (Me2) | E9: =MEDIAN(B:B) -> 5
A10: 3 | B10: 4 | D10: Moda (Mo2) | E10: =MODE(B:B) -> 5
A11: 3 | B11: 5 | D11: Desviacion Tipica o Estandar (S2) | E11: =STDEV(B:B) -> 0.96580273
A12: 5 | B12: 5 | D12: n2 | E12: =COUNT(B:B) -> 97
A13: 5 | B13: 5
A14: 4 | B14: 1
A15: 3 | B15: 4
A16: 3 | B16: 4
A17: 3 | B17: 4 | D17: t de student
A18: 3 | B18: 4
A19: 4 | B19: 5
A20: 3 | B20: 5
A21: 4 | B21: 3
A22: 2 | B22: 4
A23: 5 | B23: 5
A24: 4 | B24: 5
A25: 2 | B25: 5
A26: 4 | B26: 5
A27: 3 | B27: 5
A28: 3 | B28: 4
A29: 3 | B29: 3 | D29: Valor de t | E29: =(E2-E8)/SQRT(((E5^2)/E6)+((E11^2)/E12)) -> -8.6499933
A30: 1 | B30: 5
A31: 3 | B31: 5 | D31: df grados de libertad
A32: 1 | B32: 5
A33: 3 | B33: 5
A34: 3 | B34: 4
A35: 3 | B35: 5
A36: 3 | B36: 5
A37: 4 | B37: 3
A38: 3 | B38: 3
A39: 2 | B39: 3
A40: 2 | B40: 3
...

Sheet Motivación
A1: (Sin Aprendizaje Colaborativo) Grupo Control - Post-test Motivación | B1: (Con Aprendizaje Colaborativo) Grupo Experimental - Post-test Motivación
A2: 3 | B2: 5 | D2: Media (X1) Grupo Control | E2: =AVERAGE(A:A) -> 2.9278351
A3: 3 | B3: 4 | D3: Mediana (Me1) | E3: =MEDIAN(A:A) -> 3
A4: 5 | B4: 4 | D4: Moda (Mo1) | E4: =MODE(A:A) -> 3
A5: 5 | B5: 1 | D5: Desviacion Tipica o Estandar (S1) | E5: =STDEV(A:A) -> 1.1747998
A6: 2 | B6: 5 | D6: n1 | E6: =COUNT(A:A) -> 97
A7: 3 | B7: 4
A8: 3 | B8: 3 | D8: Media (X2) Grupo Experimental | E8: =AVERAGE(B:B) -> 3.9484536
A9: 1 | B9: 2 | D9: Mediana (Me2) | E9: =MEDIAN(B:B) -> 4
A10: 2 | B10: 5 | D10: Moda (Mo2) | E10: =MODE(B:B) -> 5
A11: 3 | B11: 5 | D11: Desviacion Tipica o Estandar (S2) | E11: =STDEV(B:B) -> 1.1214865
A12: 3 | B12: 3 | D12: n2 | E12: =COUNT(B:B) -> 97
A13: 5 | B13: 4
A14: 4 | B14: 5
A15: 3 | B15: 2
A16: 4 | B16: 5
A17: 4 | B17: 4 | D17: t de student
A18: 2 | B18: 5
A19: 2 | B19: 5
A20: 3 | B20: 4
A21: 5 | B21: 1
A22: 1 | B22: 4
A23: 2 | B23: 3
A24: 3 | B24: 5
A25: 3 | B25: 4
A26: 4 | B26: 3
A27: 1 | B27: 4
A28: 1 | B28: 5
A29: 4 | B29: 2 | D29: Valor de t | E29: =(E2-E8)/SQRT(((E5^2)/E6)+((E11^2)/E12)) -> -6.1890112
A30: 1 | B30: 3
A31: 1 | B31: 4 | D31: df grados de libertad
A32: 4 | B32: 5
A33: 2 | B33: 3
A34: 3 | B34: 5
A35: 3 | B35: 4
A36: 5 | B36: 5
A37: 2 | B37: 5
A38: 5 | B38: 5
A39: 2 | B39: 4
A40: 5 | B40: 4
...
