Workbook

Sheet Resumen
A1: Indicador | B1: F Calculado | C1: F Critico Critico | D1: P Valor
A2: Participo actividades | B2: =ROUND('Participas-actividades'!F73, 4) -> 2.1007 | C2: =ROUND('Participas-actividades'!F81, 4) -> 3.0285 | D2: =ROUND('Participas-actividades'!F82, 4) -> 0.1243
A3: Comprensión contenidos | B3: =ROUND('Comprensión-contenidos'!F73, 4) -> 1.2258 | C3: =ROUND('Comprensión-contenidos'!F81, 4) -> 3.0285 | D3: =ROUND('Comprensión-contenidos'!F82, 4) -> 0.2951
A4: Herramientas tecnológicas | B4: =ROUND('Herramientas-tecnológicas'!F73, 4) -> 1.4696 | C4: =ROUND('Herramientas-tecnológicas'!F81, 4) -> 3.0285 | D4: =ROUND('Herramientas-tecnológicas'!F82, 4) -> 0.2318
A5: Recursos tecnológicos | B5: =ROUND('Recursos-tecnológicos'!F73, 4) -> 1.1733 | C5: =ROUND('Recursos-tecnológicos'!F81, 4) -> 3.0285 | D5: =ROUND('Recursos-tecnológicos'!F82, 4) -> 0.3109
A6: Percepción evaluaciones | B6: =ROUND('Percepción-evaluaciones'!F73, 4) -> 0.8858 | C6: =ROUND('Percepción-evaluaciones'!F81, 4) -> 3.0285 | D6: =ROUND('Percepción-evaluaciones'!F82, 4) -> 0.4135
A7: Retroalimentación oportuna | B7: =ROUND('Retroalimentación-oportuna'!F73, 4) -> 2.6119 | C7: =ROUND('Retroalimentación-oportuna'!F81, 4) -> 3.0285 | D7: =ROUND('Retroalimentación-oportuna'!F82, 4) -> 0.0752
A8: Calificación | B8: =ROUND(Calificación!F73, 4) -> 1.2692 | C8: =ROUND(Calificación!F81, 4) -> 3.0285 | D8: =ROUND(Calificación!F82, 4) -> 0.2827
A9: Nivel comprensión | B9: =ROUND('Nivel-comprensión'!F73, 4) -> 0.4636 | C9: =ROUND('Nivel-comprensión'!F81, 4) -> 3.0285 | D9: =ROUND('Nivel-comprensión'!F82, 4) -> 0.6295
A10: Habilidades tareas | B10: =ROUND('Habilidades-tareas'!F73, 4) -> 0.8377 | C10: =ROUND('Habilidades-tareas'!F81, 4) -> 3.0285 | D10: =ROUND('Habilidades-tareas'!F82, 4) -> 0.4338
A11: Resolución problemas | B11: =ROUND('Resolución-problemas'!F73, 4) -> 0.075 | C11: =ROUND('Resolución-problemas'!F81, 4) -> 3.0285 | D11: =ROUND('Resolución-problemas'!F82, 4) -> 0.9277
A12: Motivación | B12: =ROUND(Motivación!F73, 4) -> 2.9834 | C12: =ROUND(Motivación!F81, 4) -> 3.0285 | D12: =ROUND(Motivación!F82, 4) -> 0.0523

Sheet Participas-actividades
A1: Grupo Control Pre Test Sin intervención | B1: Grupo Control Post Test Sin intervención | C1: Grupo Experimental Pre Test Sin intervención
A2: 5 | B2: 2 | C2: 3 | E2: Datos Generales
A3: 5 | B3: 1 | C3: 4 | E3: Tamano Grupos | F3: =COUNT(A:A) -> 93
A4: 2 | B4: 4 | C4: 2 | E4: Promedio Grupo A | F4: =AVERAGE(A:A) -> 3.4623656
A5: 3 | B5: 3 | C5: 3 | E5: Promedio Grupo B | F5: =AVERAGE(B:B) -> 3.1397849
A6: 3 | B6: 4 | C6: 1 | E6: Promedio Grupo C | F6: =AVERAGE(C:C) -> 3.2150538
A7: 5 | B7: 1 | C7: 3 | E7: Promedio Total total | F7: =AVERAGE(F4:F6) -> 3.2724014
A8: 1 | B8: 4 | C8: 5
A9: 2 | B9: 1 | C9: 3
A10: 4 | B10: 3 | C10: 4 | E10: Calculo Suma de Cuadrados Entre Grupos
A11: 4 | B11: 3 | C11: 3 | E11: Mide qué tan diferentes son los grupos entre sí
A12: 4 | B12: 3 | C12: 5 | E12: Compara las medias de cada grupo con la media general
A13: 4 | B13: 4 | C13: 4
A14: 3 | B14: 4 | C14: 2
A15: 4 | B15: 4 | C15: 4
A16: 4 | B16: 4 | C16: 2 | E16: SC Entre Grupos | F16: =F3*((F4-F7)^2+(F5-F7)^2+(F6-F7)^2) -> 5.297491
A17: 3 | B17: 3 | C17: 4
A18: 5 | B18: 4 | C18: 3
A19: 4 | B19: 5 | C19: 3 | E19: Calculo gl ENTRE (Grados de libertad entre grupos)
A20: 4 | B20: 1 | C20: 3 | E20: Cantidad de grupos independientes que puedes comparar
A21: 4 | B21: 2 | C21: 4 | E21: k (Numero de grupos) | F21: 3
A22: 3 | B22: 2 | C22: 4
A23: 4 | B23: 1 | C23: 5
A24: 3 | B24: 4 | C24: 4 | E24: gl entre | F24: =F21-1 -> 2
A25: 3 | B25: 4 | C25: 3
A26: 5 | B26: 3 | C26: 1
A27: 3 | B27: 3 | C27: 2 | E27: Calculo MC ENTRE (Media Cuadrática Entre)
A28: 4 | B28: 5 | C28: 2 | E28: Es el promedio de la variación entre grupos
A29: 5 | B29: 2 | C29: 2
A30: 2 | B30: 4 | C30: 3
A31: 1 | B31: 4 | C31: 4
A32: 2 | B32: 3 | C32: 2
A33: 4 | B33: 3 | C33: 3 | E33: MC entre | F33: =F16/F24 -> 2.6487455
A34: 5 | B34: 3 | C34: 3
A35: 3 | B35: 5 | C35: 5
A36: 4 | B36: 2 | C36: 3 | E36: Calculo SC DENTRO DE GRUPOS (Suma de Cuadrados Dentro)
A37: 5 | B37: 4 | C37: 3 | E37: Mide la variabilidad interna de cada grupo
A38: 3 | B38: 5 | C38: 2 | E38: Qué tanto varían los datos dentro del mismo grupo
A39: 5 | B39: 2 | C39: 3
A40: 2 | B40: 1 | C40: 4
...

Sheet Comprensión-contenidos
A1: Grupo Control Pre Test Sin intervención | B1: Grupo Control Post Test Sin intervención | C1: Grupo Experimental Pre Test Sin intervención
A2: 3 | B2: 4 | C2: 4 | E2: Datos Generales
A3: 2 | B3: 3 | C3: 3 | E3: Tamano Grupos | F3: =COUNT(A:A) -> 93
A4: 4 | B4: 1 | C4: 3 | E4: Promedio Grupo A | F4: =AVERAGE(A:A) -> 3.344086
A5: 4 | B5: 5 | C5: 2 | E5: Promedio Grupo B | F5: =AVERAGE(B:B) -> 3.3010753
A6: 3 | B6: 1 | C6: 4 | E6: Promedio Grupo C | F6: =AVERAGE(C:C) -> 3.5483871
A7: 4 | B7: 3 | C7: 3 | E7: Promedio Total total | F7: =AVERAGE(F4:F6) -> 3.3978495
A8: 5 | B8: 5 | C8: 3
A9: 4 | B9: 4 | C9: 3
A10: 5 | B10: 3 | C10: 3 | E10: Calculo Suma de Cuadrados Entre Grupos
A11: 2 | B11: 5 | C11: 4 | E11: Mide qué tan diferentes son los grupos entre sí
A12: 2 | B12: 3 | C12: 3 | E12: Compara las medias de cada grupo con la media general
A13: 3 | B13: 4 | C13: 5
A14: 2 | B14: 3 | C14: 4
A15: 2 | B15: 5 | C15: 3
A16: 4 | B16: 2 | C16: 3 | E16: SC Entre Grupos | F16: =F3*((F4-F7)^2+(F5-F7)^2+(F6-F7)^2) -> 3.2473118
A17: 2 | B17: 1 | C17: 1
A18: 3 | B18: 1 | C18: 3
A19: 2 | B19: 3 | C19: 3 | E19: Calculo gl ENTRE (Grados de libertad entre grupos)
A20: 2 | B20: 5 | C20: 3 | E20: Cantidad de grupos independientes que puedes comparar
A21: 4 | B21: 3 | C21: 3 | E21: k (Numero de grupos) | F21: 3
A22: 5 | B22: 5 | C22: 5
A23: 4 | B23: 5 | C23: 4
A24: 4 | B24: 4 | C24: 4 | E24: gl entre | F24: =F21-1 -> 2
A25: 2 | B25: 3 | C25: 4
A26: 2 | B26: 2 | C26: 5
A27: 5 | B27: 3 | C27: 5 | E27: Calculo MC ENTRE (Media Cuadrática Entre)
A28: 3 | B28: 3 | C28: 4 | E28: Es el promedio de la variación entre grupos
A29: 4 | B29: 4 | C29: 1
A30: 4 | B30: 1 | C30: 4
A31: 5 | B31: 4 | C31: 3
A32: 4 | B32: 3 | C32: 5
A33: 1 | B33: 5 | C33: 3 | E33: MC entre | F33: =F16/F24 -> 1.6236559
A34: 4 | B34: 2 | C34: 4
A35: 3 | B35: 3 | C35: 4
A36: 3 | B36: 4 | C36: 3 | E36: Calculo SC DENTRO DE GRUPOS (Suma de Cuadrados Dentro)
A37: 4 | B37: 5 | C37: 5 | E37: Mide la variabilidad interna de cada grupo
A38: 1 | B38: 3 | C38: 5 | E38: Qué tanto varían los datos dentro del mismo grupo
A39: 1 | B39: 3 | C39: 4
A40: 4 | B40: 4 | C40: 5
...

Sheet Herramientas-tecnológicas
A1: Grupo Control Pre Test Sin intervención | B1: Grupo Control Post Test Sin intervención | C1: Grupo Experimental Pre Test Sin intervención
A2: 5 | B2: 3 | C2: 5 | E2: Datos Generales
A3: 5 | B3: 3 | C3: 3 | E3: Tamano Grupos | F3: =COUNT(A:A) -> 93
A4: 2 | B4: 3 | C4: 5 | E4: Promedio Grupo A | F4: =AVERAGE(A:A) -> 3.2365591
A5: 3 | B5: 3 | C5: 5 | E5: Promedio Grupo B | F5: =AVERAGE(B:B) -> 3.3655914
A6: 5 | B6: 5 | C6: 4 | E6: Promedio Grupo C | F6: =AVERAGE(C:C) -> 3.5268817
A7: 5 | B7: 4 | C7: 4 | E7: Promedio Total total | F7: =AVERAGE(F4:F6) -> 3.3763441
A8: 3 | B8: 3 | C8: 3
A9: 5 | B9: 5 | C9: 3
A10: 5 | B10: 4 | C10: 5 | E10: Calculo Suma de Cuadrados Entre Grupos
A11: 3 | B11: 5 | C11: 5 | E11: Mide qué tan diferentes son los grupos entre sí
A12: 3 | B12: 5 | C12: 3 | E12: Compara las medias de cada grupo con la media general
A13: 3 | B13: 4 | C13: 4
A14: 4 | B14: 5 | C14: 3
A15: 3 | B15: 3 | C15: 3
A16: 4 | B16: 3 | C16: 2 | E16: SC Entre Grupos | F16: =F3*((F4-F7)^2+(F5-F7)^2+(F6-F7)^2) -> 3.9354839
A17: 4 | B17: 2 | C17: 3
A18: 3 | B18: 4 | C18: 4
A19: 3 | B19: 5 | C19: 3 | E19: Calculo gl ENTRE (Grados de libertad entre grupos)
A20: 2 | B20: 5 | C20: 4 | E20: Cantidad de grupos independientes que puedes comparar
A21: 3 | B21: 3 | C21: 4 | E21: k (Numero de grupos) | F21: 3
A22: 3 | B22: 3 | C22: 2
A23: 5 | B23: 5 | C23: 4
A24: 4 | B24: 2 | C24: 2 | E24: gl entre | F24: =F21-1 -> 2
A25: 4 | B25: 5 | C25: 2
A26: 4 | B26: 3 | C26: 2
A27: 1 | B27: 3 | C27: 1 | E27: Calculo MC ENTRE (Media Cuadrática Entre)
A28: 4 | B28: 2 | C28: 4 | E28: Es el promedio de la variación entre grupos
A29: 2 | B29: 3 | C29: 4
A30: 3 | B30: 2 | C30: 3
A31: 2 | B31: 4 | C31: 4
A32: 3 | B32: 2 | C32: 3
A33: 3 | B33: 5 | C33: 3 | E33: MC entre | F33: =F16/F24 -> 1.9677419
A34: 3 | B34: 2 | C34: 3
A35: 4 | B35: 3 | C35: 4
A36: 3 | B36: 2 | C36: 5 | E36: Calculo SC DENTRO DE GRUPOS (Suma de Cuadrados Dentro)
A37: 4 | B37: 3 | C37: 4 | E37: Mide la variabilidad interna de cada grupo
A38: 5 | B38: 3 | C38: 5 | E38: Qué tanto varían los datos dentro del mismo grupo
A39: 3 | B39: 3 | C39: 2
A40: 5 | B40: 3 | C40: 4
...

Sheet Recursos-tecnológicos
A1: Grupo Control Pre Test Sin intervención | B1: Grupo Control Post Test Sin intervención | C1: Grupo Experimental Pre Test Sin intervención
A2: 5 | B2: 3 | C2: 5 | E2: Datos Generales
A3: 5 | B3: 4 | C3: 4 | E3: Tamano Grupos | F3: =COUNT(A:A) -> 93
A4: 3 | B4: 3 | C4: 3 | E4: Promedio Grupo A | F4: =AVERAGE(A:A) -> 3.4193548
A5: 3 | B5: 5 | C5: 3 | E5: Promedio Grupo B | F5: =AVERAGE(B:B) -> 3.311828
A6: 3 | B6: 4 | C6: 4 | E6: Promedio Grupo C | F6: =AVERAGE(C:C) -> 3.1505376
A7: 3 | B7: 1 | C7: 1 | E7: Promedio Total total | F7: =AVERAGE(F4:F6) -> 3.2939068
A8: 1 | B8: 4 | C8: 2
A9: 3 | B9: 3 | C9: 3
A10: 4 | B10: 4 | C10: 3 | E10: Calculo Suma de Cuadrados Entre Grupos
A11: 2 | B11: 2 | C11: 3 | E11: Mide qué tan diferentes son los grupos entre sí
A12: 4 | B12: 5 | C12: 4 | E12: Compara las medias de cada grupo con la media general
A13: 4 | B13: 1 | C13: 4
A14: 5 | B14: 4 | C14: 5
A15: 5 | B15: 4 | C15: 3
A16: 1 | B16: 5 | C16: 3 | E16: SC Entre Grupos | F16: =F3*((F4-F7)^2+(F5-F7)^2+(F6-F7)^2) -> 3.4050179
A17: 2 | B17: 5 | C17: 4
A18: 3 | B18: 3 | C18: 1
A19: 4 | B19: 4 | C19: 2 | E19: Calculo gl ENTRE (Grados de libertad entre grupos)
A20: 4 | B20: 2 | C20: 3 | E20: Cantidad de grupos independientes que puedes comparar
A21: 5 | B21: 4 | C21: 3 | E21: k (Numero de grupos) | F21: 3
A22: 4 | B22: 4 | C22: 2
A23: 3 | B23: 3 | C23: 5
A24: 3 | B24: 3 | C24: 2 | E24: gl entre | F24: =F21-1 -> 2
A25: 3 | B25: 5 | C25: 5
A26: 4 | B26: 5 | C26: 2
A27: 1 | B27: 5 | C27: 4 | E27: Calculo MC ENTRE (Media Cuadrática Entre)
A28: 3 | B28: 3 | C28: 2 | E28: Es el promedio de la variación entre grupos
A29: 3 | B29: 3 | C29: 1
A30: 3 | B30: 3 | C30: 5
A31: 4 | B31: 2 | C31: 4
A32: 4 | B32: 2 | C32: 1
A33: 4 | B33: 3 | C33: 3 | E33: MC entre | F33: =F16/F24 -> 1.702509
A34: 3 | B34: 2 | C34: 2
A35: 5 | B35: 4 | C35: 3
A36: 5 | B36: 5 | C36: 4 | E36: Calculo SC DENTRO DE GRUPOS (Suma de Cuadrados Dentro)
A37: 5 | B37: 4 | C37: 4 | E37: Mide la variabilidad interna de cada grupo
A38: 5 | B38: 5 | C38: 4 | E38: Qué tanto varían los datos dentro del mismo grupo
A39: 2 | B39: 3 | C39: 3
A40: 3 | B40: 1 | C40: 4
...

Sheet Percepción-evaluaciones
A1: Grupo Control Pre Test Sin intervención | B1: Grupo Control Post Test Sin intervención | C1: Grupo Experimental Pre Test Sin intervención
A2: 4 | B2: 3 | C2: 1 | E2: Datos Generales
A3: 2 | B3: 2 | C3: 5 | E3: Tamano Grupos | F3: =COUNT(A:A) -> 93
A4: 2 | B4: 3 | C4: 1 | E4: Promedio Grupo A | F4: =AVERAGE(A:A) -> 3.1827957
A5: 5 | B5: 3 | C5: 3 | E5: Promedio Grupo B | F5: =AVERAGE(B:B) -> 3.3978495
A6: 2 | B6: 4 | C6: 4 | E6: Promedio Grupo C | F6: =AVERAGE(C:C) -> 3.3655914
A7: 3 | B7: 2 | C7: 5 | E7: Promedio Total total | F7: =AVERAGE(F4:F6) -> 3.3154122
A8: 2 | B8: 5 | C8: 3
A9: 4 | B9: 3 | C9: 2
A10: 2 | B10: 5 | C10: 3 | E10: Calculo Suma de Cuadrados Entre Grupos
A11: 4 | B11: 4 | C11: 5 | E11: Mide qué tan diferentes son los grupos entre sí
A12: 5 | B12: 4 | C12: 5 | E12: Compara las medias de cada grupo con la media general
A13: 2 | B13: 4 | C13: 4
A14: 5 | B14: 3 | C14: 4
A15: 4 | B15: 4 | C15: 4
A16: 1 | B16: 4 | C16: 4 | E16: SC Entre Grupos | F16: =F3*((F4-F7)^2+(F5-F7)^2+(F6-F7)^2) -> 2.5017921
A17: 1 | B17: 4 | C17: 2
A18: 3 | B18: 4 | C18: 1
A19: 3 | B19: 4 | C19: 4 | E19: Calculo gl ENTRE (Grados de libertad entre grupos)
A20: 3 | B20: 5 | C20: 2 | E20: Cantidad de grupos independientes que puedes comparar
A21: 4 | B21: 3 | C21: 4 | E21: k (Numero de grupos) | F21: 3
A22: 4 | B22: 3 | C22: 3
A23: 3 | B23: 3 | C23: 4
A24: 2 | B24: 4 | C24: 3 | E24: gl entre | F24: =F21-1 -> 2
A25: 2 | B25: 4 | C25: 1
A26: 2 | B26: 2 | C26: 3
A27: 5 | B27: 3 | C27: 4 | E27: Calculo MC ENTRE (Media Cuadrática Entre)
A28: 3 | B28: 3 | C28: 3 | E28: Es el promedio de la variación entre grupos
A29: 5 | B29: 5 | C29: 5
A30: 3 | B30: 4 | C30: 2
A31: 4 | B31: 4 | C31: 3
A32: 2 | B32: 4 | C32: 3
A33: 4 | B33: 3 | C33: 3 | E33: MC entre | F33: =F16/F24 -> 1.2508961
A34: 5 | B34: 3 | C34: 3
A35: 5 | B35: 3 | C35: 5
A36: 2 | B36: 3 | C36: 3 | E36: Calculo SC DENTRO DE GRUPOS (Suma de Cuadrados Dentro)
A37: 3 | B37: 2 | C37: 4 | E37: Mide la variabilidad interna de cada grupo
A38: 5 | B38: 3 | C38: 3 | E38: Qué tanto varían los datos dentro del mismo grupo
A39: 5 | B39: 1 | C39: 2
A40: 3 | B40: 5 | C40: 2
...

Sheet Retroalimentación-oportuna
A1: Grupo Control Pre Test Sin intervención | B1: Grupo Control Post Test Sin intervención | C1: Grupo Experimental Pre Test Sin intervención
A2: 4 | B2: 2 | C2: 4 | E2: Datos Generales
A3: 3 | B3: 4 | C3: 4 | E3: Tamano Grupos | F3: =COUNT(A:A) -> 93
A4: 5 | B4: 5 | C4: 5 | E4: Promedio Grupo A | F4: =AVERAGE(A:A) -> 3.1505376
A5: 1 | B5: 5 | C5: 3 | E5: Promedio Grupo B | F5: =AVERAGE(B:B) -> 3.3225806
A6: 1 | B6: 3 | C6: 4 | E6: Promedio Grupo C | F6: =AVERAGE(C:C) -> 3.5483871
A7: 3 | B7: 3 | C7: 2 | E7: Promedio Total total | F7: =AVERAGE(F4:F6) -> 3.3405018
A8: 3 | B8: 3 | C8: 2
A9: 4 | B9: 4 | C9: 4
A10: 2 | B10: 4 | C10: 3 | E10: Calculo Suma de Cuadrados Entre Grupos
A11: 3 | B11: 3 | C11: 4 | E11: Mide qué tan diferentes son los grupos entre sí
A12: 5 | B12: 3 | C12: 2 | E12: Compara las medias de cada grupo con la media general
A13: 2 | B13: 1 | C13: 4
A14: 2 | B14: 5 | C14: 3
A15: 1 | B15: 3 | C15: 3
A16: 3 | B16: 4 | C16: 4 | E16: SC Entre Grupos | F16: =F3*((F4-F7)^2+(F5-F7)^2+(F6-F7)^2) -> 7.4050179
A17: 3 | B17: 4 | C17: 5
A18: 4 | B18: 3 | C18: 3
A19: 1 | B19: 3 | C19: 3 | E19: Calculo gl ENTRE (Grados de libertad entre grupos)
A20: 2 | B20: 1 | C20: 4 | E20: Cantidad de grupos independientes que puedes comparar
A21: 5 | B21: 5 | C21: 3 | E21: k (Numero de grupos) | F21: 3
A22: 5 | B22: 5 | C22: 4
A23: 4 | B23: 3 | C23: 3
A24: 2 | B24: 3 | C24: 5 | E24: gl entre | F24: =F21-1 -> 2
A25: 1 | B25: 4 | C25: 2
A26: 5 | B26: 5 | C26: 4
A27: 3 | B27: 5 | C27: 4 | E27: Calculo MC ENTRE (Media Cuadrática Entre)
A28: 4 | B28: 2 | C28: 5 | E28: Es el promedio de la variación entre grupos
A29: 1 | B29: 4 | C29: 5
A30: 2 | B30: 4 | C30: 3
A31: 2 | B31: 4 | C31: 4
A32: 4 | B32: 4 | C32: 2
A33: 4 | B33: 5 | C33: 5 | E33: MC entre | F33: =F16/F24 -> 3.702509
A34: 4 | B34: 3 | C34: 4
A35: 5 | B35: 5 | C35: 4
A36: 2 | B36: 2 | C36: 5 | E36: Calculo SC DENTRO DE GRUPOS (Suma de Cuadrados Dentro)
A37: 2 | B37: 4 | C37: 5 | E37: Mide la variabilidad interna de cada grupo
A38: 1 | B38: 3 | C38: 4 | E38: Qué tanto varían los datos dentro del mismo grupo
A39: 1 | B39: 2 | C39: 3
A40: 3 | B40: 3 | C40: 4
...

Sheet Calificación
A1: Grupo Control Pre Test Sin intervención | B1: Grupo Control Post Test Sin intervención | C1: Grupo Experimental Pre Test Sin intervención
A2: 4 | B2: 2 | C2: 3 | E2: Datos Generales
A3: 2 | B3: 2 | C3: 4 | E3: Tamano Grupos | F3: =COUNT(A:A) -> 93
A4: 3 | B4: 2 | C4: 3 | E4: Promedio Grupo A | F4: =AVERAGE(A:A) -> 3.5483871
A5: 3 | B5: 2 | C5: 4 | E5: Promedio Grupo B | F5: =AVERAGE(B:B) -> 3.4193548
A6: 4 | B6: 4 | C6: 4 | E6: Promedio Grupo C | F6: =AVERAGE(C:C) -> 3.2688172
A7: 4 | B7: 5 | C7: 1 | E7: Promedio Total total | F7: =AVERAGE(F4:F6) -> 3.4121864
A8: 5 | B8: 4 | C8: 4
A9: 5 | B9: 4 | C9: 4
A10: 4 | B10: 3 | C10: 2 | E10: Calculo Suma de Cuadrados Entre Grupos
A11: 4 | B11: 4 | C11: 3 | E11: Mide qué tan diferentes son los grupos entre sí
A12: 5 | B12: 1 | C12: 5 | E12: Compara las medias de cada grupo con la media general
A13: 5 | B13: 3 | C13: 5
A14: 3 | B14: 2 | C14: 5
A15: 4 | B15: 5 | C15: 3
A16: 4 | B16: 2 | C16: 4 | E16: SC Entre Grupos | F16: =F3*((F4-F7)^2+(F5-F7)^2+(F6-F7)^2) -> 3.6415771
A17: 3 | B17: 2 | C17: 5
A18: 3 | B18: 3 | C18: 1
A19: 5 | B19: 3 | C19: 3 | E19: Calculo gl ENTRE (Grados de libertad entre grupos)
A20: 2 | B20: 3 | C20: 4 | E20: Cantidad de grupos independientes que puedes comparar
A21: 3 | B21: 4 | C21: 3 | E21: k (Numero de grupos) | F21: 3
A22: 5 | B22: 3 | C22: 3
A23: 2 | B23: 4 | C23: 5
A24: 2 | B24: 5 | C24: 4 | E24: gl entre | F24: =F21-1 -> 2
A25: 5 | B25: 4 | C25: 2
A26: 4 | B26: 5 | C26: 4
A27: 2 | B27: 5 | C27: 3 | E27: Calculo MC ENTRE (Media Cuadrática Entre)
A28: 3 | B28: 5 | C28: 4 | E28: Es el promedio de la variación entre grupos
A29: 4 | B29: 1 | C29: 5
A30: 4 | B30: 3 | C30: 5
A31: 4 | B31: 1 | C31: 4
A32: 3 | B32: 4 | C32: 4
A33: 3 | B33: 4 | C33: 5 | E33: MC entre | F33: =F16/F24 -> 1.8207885
A34: 4 | B34: 3 | C34: 2
A35: 3 | B35: 4 | C35: 1
A36: 3 | B36: 5 | C36: 2 | E36: Calculo SC DENTRO DE GRUPOS (Suma de Cuadrados Dentro)
A37: 5 | B37: 3 | C37: 2 | E37: Mide la variabilidad interna de cada grupo
A38: 4 | B38: 4 | C38: 4 | E38: Qué tanto varían los datos dentro del mismo grupo
A39: 3 | B39: 3 | C39: 1
A40: 2 | B40: 3 | C40: 4
...

Sheet Nivel-comprensión
A1: Grupo Control Pre Test Sin intervención | B1: Grupo Control Post Test Sin intervención | C1: Grupo Experimental Pre Test Sin intervención
A2: 4 | B2: 4 | C2: 4 | E2: Datos Generales
A3: 3 | B3: 3 | C3: 3 | E3: Tamano Grupos | F3: =COUNT(A:A) -> 93
A4: 4 | B4: 2 | C4: 4 | E4: Promedio Grupo A | F4: =AVERAGE(A:A) -> 3.4301075
A5: 5 | B5: 2 | C5: 3 | E5: Promedio Grupo B | F5: =AVERAGE(B:B) -> 3.2795699
A6: 3 | B6: 1 | C6: 4 | E6: Promedio Grupo C | F6: =AVERAGE(C:C) -> 3.3978495
A7: 4 | B7: 2 | C7: 5 | E7: Promedio Total total | F7: =AVERAGE(F4:F6) -> 3.3691756
A8: 3 | B8: 4 | C8: 1
A9: 5 | B9: 3 | C9: 5
A10: 3 | B10: 4 | C10: 3 | E10: Calculo Suma de Cuadrados Entre Grupos
A11: 3 | B11: 4 | C11: 4 | E11: Mide qué tan diferentes son los grupos entre sí
A12: 5 | B12: 2 | C12: 5 | E12: Compara las medias de cada grupo con la media general
A13: 4 | B13: 5 | C13: 5
A14: 5 | B14: 2 | C14: 5
A15: 5 | B15: 3 | C15: 2
A16: 1 | B16: 3 | C16: 4 | E16: SC Entre Grupos | F16: =F3*((F4-F7)^2+(F5-F7)^2+(F6-F7)^2) -> 1.1684588
A17: 4 | B17: 3 | C17: 1
A18: 2 | B18: 2 | C18: 3
A19: 4 | B19: 3 | C19: 4 | E19: Calculo gl ENTRE (Grados de libertad entre grupos)
A20: 3 | B20: 3 | C20: 3 | E20: Cantidad de grupos independientes que puedes comparar
A21: 3 | B21: 5 | C21: 3 | E21: k (Numero de grupos) | F21: 3
A22: 3 | B22: 3 | C22: 3
A23: 3 | B23: 5 | C23: 4
A24: 4 | B24: 3 | C24: 4 | E24: gl entre | F24: =F21-1 -> 2
A25: 4 | B25: 3 | C25: 2
A26: 2 | B26: 3 | C26: 1
A27: 2 | B27: 5 | C27: 2 | E27: Calculo MC ENTRE (Media Cuadrática Entre)
A28: 1 | B28: 5 | C28: 4 | E28: Es el promedio de la variación entre grupos
A29: 5 | B29: 3 | C29: 3
A30: 3 | B30: 5 | C30: 4
A31: 2 | B31: 5 | C31: 3
A32: 5 | B32: 5 | C32: 4
A33: 5 | B33: 1 | C33: 3 | E33: MC entre | F33: =F16/F24 -> 0.58422939
A34: 3 | B34: 3 | C34: 5
A35: 3 | B35: 4 | C35: 4
A36: 2 | B36: 4 | C36: 2 | E36: Calculo SC DENTRO DE GRUPOS (Suma de Cuadrados Dentro)
A37: 5 | B37: 4 | C37: 4 | E37: Mide la variabilidad interna de cada grupo
A38: 3 | B38: 3 | C38: 5 | E38: Qué tanto varían los datos dentro del mismo grupo
A39: 4 | B39: 3 | C39: 5
A40: 5 | B40: 4 | C40: 1
...

Sheet Habilidades-tareas
A1: Grupo Control Pre Test Sin intervención | B1: Grupo Control Post Test Sin intervención | C1: Grupo Experimental Pre Test Sin intervención
A2: 1 | B2: 4 | C2: 5 | E2: Datos Generales
A3: 5 | B3: 5 | C3: 3 | E3: Tamano Grupos | F3: =COUNT(A:A) -> 93
A4: 3 | B4: 3 | C4: 3 | E4: Promedio Grupo A | F4: =AVERAGE(A:A) -> 3.4301075
A5: 3 | B5: 2 | C5: 4 | E5: Promedio Grupo B | F5: =AVERAGE(B:B) -> 3.2903226
A6: 3 | B6: 4 | C6: 1 | E6: Promedio Grupo C | F6: =AVERAGE(C:C) -> 3.2258065
A7: 5 | B7: 3 | C7: 2 | E7: Promedio Total total | F7: =AVERAGE(F4:F6) -> 3.3154122
A8: 2 | B8: 2 | C8: 3
A9: 2 | B9: 3 | C9: 3
A10: 3 | B10: 3 | C10: 3 | E10: Calculo Suma de Cuadrados Entre Grupos
A11: 3 | B11: 3 | C11: 1 | E11: Mide qué tan diferentes son los grupos entre sí
A12: 2 | B12: 3 | C12: 3 | E12: Compara las medias de cada grupo con la media general
A13: 3 | B13: 4 | C13: 3
A14: 5 | B14: 3 | C14: 2
A15: 3 | B15: 3 | C15: 4
A16: 3 | B16: 2 | C16: 2 | E16: SC Entre Grupos | F16: =F3*((F4-F7)^2+(F5-F7)^2+(F6-F7)^2) -> 2.0286738
A17: 4 | B17: 3 | C17: 4
A18: 3 | B18: 3 | C18: 4
A19: 1 | B19: 4 | C19: 4 | E19: Calculo gl ENTRE (Grados de libertad entre grupos)
A20: 2 | B20: 3 | C20: 1 | E20: Cantidad de grupos independientes que puedes comparar
A21: 4 | B21: 5 | C21: 2 | E21: k (Numero de grupos) | F21: 3
A22: 5 | B22: 4 | C22: 3
A23: 1 | B23: 3 | C23: 3
A24: 2 | B24: 1 | C24: 3 | E24: gl entre | F24: =F21-1 -> 2
A25: 5 | B25: 5 | C25: 1
A26: 2 | B26: 4 | C26: 3
A27: 2 | B27: 2 | C27: 4 | E27: Calculo MC ENTRE (Media Cuadrática Entre)
A28: 3 | B28: 4 | C28: 5 | E28: Es el promedio de la variación entre grupos
A29: 3 | B29: 3 | C29: 2
A30: 4 | B30: 3 | C30: 3
A31: 5 | B31: 3 | C31: 4
A32: 4 | B32: 4 | C32: 5
A33: 2 | B33: 4 | C33: 2 | E33: MC entre | F33: =F16/F24 -> 1.0143369
A34: 5 | B34: 2 | C34: 5
A35: 4 | B35: 3 | C35: 3
A36: 4 | B36: 5 | C36: 1 | E36: Calculo SC DENTRO DE GRUPOS (Suma de Cuadrados Dentro)
A37: 3 | B37: 3 | C37: 4 | E37: Mide la variabilidad interna de cada grupo
A38: 2 | B38: 5 | C38: 4 | E38: Qué tanto varían los datos dentro del mismo grupo
A39: 4 | B39: 3 | C39: 3
A40: 4 | B40: 4 | C40: 2
...

Sheet Resolución-problemas
A1: Grupo Control Pre Test Sin intervención | B1: Grupo Control Post Test Sin intervención | C1: Grupo Experimental Pre Test Sin intervención
A2: 4 | B2: 3 | C2: 4 | E2: Datos Generales
A3: 5 | B3: 4 | C3: 3 | E3: Tamano Grupos | F3: =COUNT(A:A) -> 93
A4: 4 | B4: 4 | C4: 3 | E4: Promedio Grupo A | F4: =AVERAGE(A:A) -> 3.4516129
A5: 3 | B5: 4 | C5: 4 | E5: Promedio Grupo B | F5: =AVERAGE(B:B) -> 3.3978495
A6: 2 | B6: 5 | C6: 4 | E6: Promedio Grupo C | F6: =AVERAGE(C:C) -> 3.3978495
A7: 2 | B7: 5 | C7: 4 | E7: Promedio Total total | F7: =AVERAGE(F4:F6) -> 3.4157706
A8: 4 | B8: 2 | C8: 4
A9: 3 | B9: 4 | C9: 4
A10: 4 | B10: 3 | C10: 3 | E10: Calculo Suma de Cuadrados Entre Grupos
A11: 4 | B11: 4 | C11: 4 | E11: Mide qué tan diferentes son los grupos entre sí
A12: 2 | B12: 1 | C12: 4 | E12: Compara las medias de cada grupo con la media general
A13: 5 | B13: 4 | C13: 3
A14: 5 | B14: 4 | C14: 1
A15: 4 | B15: 2 | C15: 3
A16: 5 | B16: 2 | C16: 5 | E16: SC Entre Grupos | F16: =F3*((F4-F7)^2+(F5-F7)^2+(F6-F7)^2) -> 0.17921147
A17: 4 | B17: 4 | C17: 5
A18: 3 | B18: 2 | C18: 1
A19: 4 | B19: 3 | C19: 4 | E19: Calculo gl ENTRE (Grados de libertad entre grupos)
A20: 2 | B20: 3 | C20: 5 | E20: Cantidad de grupos independientes que puedes comparar
A21: 2 | B21: 5 | C21: 3 | E21: k (Numero de grupos) | F21: 3
A22: 4 | B22: 5 | C22: 3
A23: 4 | B23: 3 | C23: 3
A24: 4 | B24: 3 | C24: 4 | E24: gl entre | F24: =F21-1 -> 2
A25: 3 | B25: 3 | C25: 5
A26: 4 | B26: 3 | C26: 1
A27: 3 | B27: 3 | C27: 4 | E27: Calculo MC ENTRE (Media Cuadrática Entre)
A28: 4 | B28: 4 | C28: 3 | E28: Es el promedio de la variación entre grupos
A29: 3 | B29: 3 | C29: 3
A30: 3 | B30: 5 | C30: 3
A31: 4 | B31: 3 | C31: 4
A32: 1 | B32: 3 | C32: 4
A33: 3 | B33: 1 | C33: 3 | E33: MC entre | F33: =F16/F24 -> 0.089605735
A34: 5 | B34: 5 | C34: 2
A35: 2 | B35: 5 | C35: 2
A36: 3 | B36: 4 | C36: 5 | E36: Calculo SC DENTRO DE GRUPOS (Suma de Cuadrados Dentro)
A37: 2 | B37: 4 | C37: 5 | E37: Mide la variabilidad interna de cada grupo
A38: 2 | B38: 4 | C38: 2 | E38: Qué tanto varían los datos dentro del mismo grupo
A39: 4 | B39: 2 | C39: 3
A40: 5 | B40: 4 | C40: 2
...

Sheet Motivación
A1: Grupo Control Pre Test Sin intervención | B1: Grupo Control Post Test Sin intervención | C1: Grupo Experimental Pre Test Sin intervención
A2: 3 | B2: 4 | C2: 2 | E2: Datos Generales
A3: 3 | B3: 5 | C3: 3 | E3: Tamano Grupos | F3: =COUNT(A:A) -> 93
A4: 4 | B4: 2 | C4: 3 | E4: Promedio Grupo A | F4: =AVERAGE(A:A) -> 3.1612903
A5: 4 | B5: 4 | C5: 4 | E5: Promedio Grupo B | F5: =AVERAGE(B:B) -> 3.2365591
A6: 2 | B6: 4 | C6: 4 | E6: Promedio Grupo C | F6: =AVERAGE(C:C) -> 3.5591398
A7: 2 | B7: 5 | C7: 2 | E7: Promedio Total total | F7: =AVERAGE(F4:F6) -> 3.3189964
A8: 3 | B8: 4 | C8: 3
A9: 4 | B9: 3 | C9: 3
A10: 3 | B10: 3 | C10: 4 | E10: Calculo Suma de Cuadrados Entre Grupos
A11: 4 | B11: 4 | C11: 3 | E11: Mide qué tan diferentes son los grupos entre sí
A12: 5 | B12: 2 | C12: 4 | E12: Compara las medias de cada grupo con la media general
A13: 1 | B13: 2 | C13: 3
A14: 5 | B14: 2 | C14: 4
A15: 1 | B15: 4 | C15: 4
A16: 4 | B16: 4 | C16: 3 | E16: SC Entre Grupos | F16: =F3*((F4-F7)^2+(F5-F7)^2+(F6-F7)^2) -> 8.3082437
A17: 4 | B17: 1 | C17: 2
A18: 3 | B18: 2 | C18: 5
A19: 2 | B19: 5 | C19: 2 | E19: Calculo gl ENTRE (Grados de libertad entre grupos)
A20: 3 | B20: 5 | C20: 4 | E20: Cantidad de grupos independientes que puedes comparar
A21: 2 | B21: 4 | C21: 4 | E21: k (Numero de grupos) | F21: 3
A22: 3 | B22: 2 | C22: 5
A23: 3 | B23: 3 | C23: 4
A24: 2 | B24: 3 | C24: 3 | E24: gl entre | F24: =F21-1 -> 2
A25: 4 | B25: 5 | C25: 5
A26: 3 | B26: 3 | C26: 3
A27: 4 | B27: 2 | C27: 2 | E27: Calculo MC ENTRE (Media Cuadrática Entre)
A28: 1 | B28: 4 | C28: 5 | E28: Es el promedio de la variación entre grupos
A29: 1 | B29: 2 | C29: 3
A30: 5 | B30: 1 | C30: 4
A31: 3 | B31: 4 | C31: 3
A32: 1 | B32: 3 | C32: 4
A33: 4 | B33: 4 | C33: 5 | E33: MC entre | F33: =F16/F24 -> 4.1541219
A34: 3 | B34: 2 | C34: 5
A35: 1 | B35: 3 | C35: 5
A36: 5 | B36: 3 | C36: 5 | E36: Calculo SC DENTRO DE GRUPOS (Suma de Cuadrados Dentro)
A37: 3 | B37: 2 | C37: 3 | E37: Mide la variabilidad interna de cada grupo
A38: 4 | B38: 4 | C38: 2 | E38: Qué tanto varían los datos dentro del mismo grupo
A39: 1 | B39: 1 | C39: 2
A40: 1 | B40: 3 | C40: 3
...
