Workbook

Sheet Objetivo
A1: ✅ Chi-cuadrado (Control: Pre vs Post)
A2: Demuestra que el control no cambia
A4: Objetivo:
A5: Evaluar si existen diferencias significativas en las variables analizadas dentro del grupo control entre el pre-test y el post-test, con el fin de comprobar la estabilidad de las mediciones en ausencia de la implementación de la intervencion
A7: Grupos:
A8: Grupo Control – Pre Test
A9: Grupo Control – Post Test

Sheet Resumen
A1: Indicador | B1: Chi Cuadrado Observado | C1: Chi Cuadrado Valor Critico | D1: P-Valor | E1: α nivel de significancia
A2: Participo actividades | B2: =ROUND('Participas-actividades'!B35, 4) -> 4.006 | C2: =ROUND('Participas-actividades'!B46, 4) -> 9.4877 | D2: =ROUND('Participas-actividades'!B47, 4) -> 0.4052 | E2: 0.05
A3: Comprensión contenidos | B3: =ROUND('Comprensión contenidos'!B35, 4) -> 4.563 | C3: =ROUND('Comprensión contenidos'!B46, 4) -> 9.4877 | D3: =ROUND('Comprensión contenidos'!B47, 4) -> 0.3351 | E3: 0.05
A4: Herramientas tecnológicas | B4: =ROUND('Herramientas-tecnológicas'!B35, 4) -> 1.0541 | C4: =ROUND('Herramientas-tecnológicas'!B46, 4) -> 9.4877 | D4: =ROUND('Herramientas-tecnológicas'!B47, 4) -> 0.9015 | E4: 0.05
A5: Recursos tecnológicos | B5: =ROUND('Recursos-tecnológicos'!B35,4) -> 1.4125 | C5: =ROUND('Recursos-tecnológicos'!B46,4) -> 9.4877 | D5: =ROUND('Recursos-tecnológicos'!B47,4) -> 0.842 | E5: 0.05
A6: Percepción evaluaciones | B6: =ROUND('Percepción-evaluaciones'!B35,4) -> 15.9957 | C6: =ROUND('Percepción-evaluaciones'!B46,4) -> 9.4877 | D6: =ROUND('Percepción-evaluaciones'!B47,4) -> 0.003 | E6: 0.05
A7: Retroalimentación oportuna | B7: =ROUND('Retroalimentación-oportuna'!B35,4) -> 3.0392 | C7: =ROUND('Retroalimentación-oportuna'!B46,4) -> 9.4877 | D7: =ROUND('Retroalimentación-oportuna'!B47,4) -> 0.5513 | E7: 0.05
A8: Calificación | B8: =ROUND(Calificación!B35,4) -> 4.1065 | C8: =ROUND(Calificación!B46,4) -> 9.4877 | D8: =ROUND(Calificación!B47,4) -> 0.3918 | E8: 0.05
A9: Nivel comprensión | B9: =ROUND('Nivel-comprensión'!B35,4) -> 1.3285 | C9: =ROUND('Nivel-comprensión'!B46,4) -> 9.4877 | D9: =ROUND('Nivel-comprensión'!B47,4) -> 0.8565 | E9: 0.05
A10: Habilidades tareas | B10: =ROUND('Habilidades-tareas'!B35,4) -> 3.3211 | C10: =ROUND('Habilidades-tareas'!B46,4) -> 9.4877 | D10: =ROUND('Habilidades-tareas'!B47,4) -> 0.5056 | E10: 0.05
A11: Resolución problemas | B11: =ROUND('Resolución-problemas'!B35,4) -> 3.6571 | C11: =ROUND('Resolución-problemas'!B46,4) -> 9.4877 | D11: =ROUND('Resolución-problemas'!B47,4) -> 0.4544 | E11: 0.05
A12: Motivación | B12: =ROUND(Motivación!B35,4) -> 5.9938 | C12: =ROUND(Motivación!B46,4) -> 9.4877 | D12: =ROUND(Motivación!B47,4) -> 0.1996 | E12: 0.05

Sheet Participas-actividades
A1: Tabla Valores Observados
A2: Grupo / Categoría | B2: a) Siempre | C2: b) Frecuente | D2: c) A veces | E2: d) Raro | F2: e) Nunca | G2: Total
A3: Grupo Control - Pre Test | B3: 18 | C3: 28 | D3: 30 | E3: 13 | F3: 4 | G3: =SUM(B3:F3) -> 93
A4: Grupo Control - Post Test | B4: 12 | C4: 22 | D4: 33 | E4: 19 | F4: 7 | G4: =SUM(B4:F4) -> 93
A5: Total | B5: =SUM(B3:B4) -> 30 | C5: =SUM(C3:C4) -> 50 | D5: =SUM(D3:D4) -> 63 | E5: =SUM(E3:E4) -> 32 | F5: =SUM(F3:F4) -> 11 | G5: =SUM(G3:G4) -> 186
A7: Tabla Valores Esperados
A11: Categoria | B11: =B2 -> a) Siempre | C11: =C2 -> b) Frecuente | D11: =D2 -> c) A veces | E11: =E2 -> d) Raro | F11: =F2 -> e) Nunca | G11: =G2 -> Total
A12: =A3 -> Grupo Control - Pre Test | B12: =(G3*B5)/G5 -> 15 | C12: =(G3*C5)/G5 -> 25 | D12: =(G3*D5)/G5 -> 31.5 | E12: =(G3*E5)/G5 -> 16 | F12: =(G3*F5)/G5 -> 5.5 | G12: =SUM(B12:F12) -> 93
A13: =A4 -> Grupo Control - Post Test | B13: =(G4*B5)/G5 -> 15 | C13: =(G4*C5)/G5 -> 25 | D13: =(G4*D5)/G5 -> 31.5 | E13: =(G4*E5)/G5 -> 16 | F13: =(G4*F5)/G5 -> 5.5 | G13: =SUM(B13:F13) -> 93
A16: Tabla completa Valores Observados (O) y Valores Esperados (E)
A18: Grupo | B18: Categoria | C18: Valor Observado (O) | D18: Valor Esperado (E )
A19: =A3 -> Grupo Control - Pre Test | B19: =B2 -> a) Siempre | C19: =B3 -> 18 | D19: =B12 -> 15 | E19: =(C19-D19)^2 -> 9 | F19: =E19/D19 -> 0.6
A20: =A3 -> Grupo Control - Pre Test | B20: =C2 -> b) Frecuente | C20: =C3 -> 28 | D20: =C12 -> 25 | E20: =(C20-D20)^2 -> 9 | F20: =E20/D20 -> 0.36
A21: =A3 -> Grupo Control - Pre Test | B21: =D2 -> c) A veces | C21: =D3 -> 30 | D21: =D12 -> 31.5 | E21: =(C21-D21)^2 -> 2.25 | F21: =E21/D21 -> 0.071428571
A22: =A3 -> Grupo Control - Pre Test | B22: =E2 -> d) Raro | C22: =E3 -> 13 | D22: =E12 -> 16 | E22: =(C22-D22)^2 -> 9 | F22: =E22/D22 -> 0.5625
A23: =A3 -> Grupo Control - Pre Test | B23: =F2 -> e) Nunca | C23: =F3 -> 4 | D23: =F12 -> 5.5 | E23: =(C23-D23)^2 -> 2.25 | F23: =E23/D23 -> 0.40909091
A24: =A4 -> Grupo Control - Post Test | B24: =B2 -> a) Siempre | C24: =B4 -> 12 | D24: =B13 -> 15 | E24: =(C24-D24)^2 -> 9 | F24: =E24/D24 -> 0.6
A25: =A4 -> Grupo Control - Post Test | B25: =C2 -> b) Frecuente | C25: =C4 -> 22 | D25: =C13 -> 25 | E25: =(C25-D25)^2 -> 9 | F25: =E25/D25 -> 0.36
A26: =A4 -> Grupo Control - Post Test | B26: =D2 -> c) A veces | C26: =D4 -> 33 | D26: =D13 -> 31.5 | E26: =(C26-D26)^2 -> 2.25 | F26: =E26/D26 -> 0.071428571
A27: =A4 -> Grupo Control - Post Test | B27: =E2 -> d) Raro | C27: =E4 -> 19 | D27: =E13 -> 16 | E27: =(C27-D27)^2 -> 9 | F27: =E27/D27 -> 0.5625
A28: =A4 -> Grupo Control - Post Test | B28: =F2 -> e) Nunca | C28: =F4 -> 7 | D28: =F13 -> 5.5 | E28: =(C28-D28)^2 -> 2.25 | F28: =E28/D28 -> 0.40909091
A31: Calculo Chi Cuadrado
A35: Chi Cuadrado | B35: =SUM(F19:F28) -> 4.006039
A37: Calculo Grados Libertad
A39: Filas = 2 (Sin sistema, Con sistema) | C39: 2
A40: Columnas = 5 (las 5 categorías) | C40: 5
A41: Grados de libertad df | C41: =(C39-1)*(C40-1) -> 4
A43: Busqueda de Valor Critico en Tabla Chi Cuadrado
A44: df | B44: =C41 -> 4
A45: α | B45: 0.05 | C45: (el más usado en tesis)
A46: valor critico | B46: =CHIINV(B45,B44) -> 9.487729
A47: p valor | B47: =_xlfn.CHISQ.DIST.RT(B35, B44) -> 0.40518918
A49: Interpretacion
A51: H0 Hipotesis Nula | B51: No existe relación entre los grupos y la variable
A52: H1 Hipotesis Alternativa | B52: Si existe relación entre los grupos y la variable
A54: si p valor < α ---> Se rechaza la hipotesis Nula
A55: α nivel de significancia | B55: =B45 -> 0.05
A56: p valor | B56: =B47 -> 0.40518918
A58: Si chi cuadrado > valor critico ---> Se rechaza la hipotesis nula
A59: Chi Cuadrado | B59: =B35 -> 4.006039
...

Sheet Comprensión contenidos
A1: Tabla Valores Observados
A2: Grupo / Categoría | B2: a) Siempre | C2: b) Muchas veces | D2: c) A veces | E2: d) Pocas veces | F2: e) Nunca | G2: Total
A3: Grupo Control - Pre Test | B3: 14 | C3: 31 | D3: 26 | E3: 17 | F3: 5 | G3: =SUM(B3:F3) -> 93
A4: Grupo Control - Post Test | B4: 20 | C4: 22 | D4: 27 | E4: 14 | F4: 10 | G4: =SUM(B4:F4) -> 93
A5: Total | B5: =SUM(B3:B4) -> 34 | C5: =SUM(C3:C4) -> 53 | D5: =SUM(D3:D4) -> 53 | E5: =SUM(E3:E4) -> 31 | F5: =SUM(F3:F4) -> 15 | G5: =SUM(G3:G4) -> 186
A7: Tabla Valores Esperados
A11: Categoria | B11: =B2 -> a) Siempre | C11: =C2 -> b) Muchas veces | D11: =D2 -> c) A veces | E11: =E2 -> d) Pocas veces | F11: =F2 -> e) Nunca | G11: =G2 -> Total
A12: =A3 -> Grupo Control - Pre Test | B12: =(G3*B5)/G5 -> 17 | C12: =(G3*C5)/G5 -> 26.5 | D12: =(G3*D5)/G5 -> 26.5 | E12: =(G3*E5)/G5 -> 15.5 | F12: =(G3*F5)/G5 -> 7.5 | G12: =SUM(B12:F12) -> 93
A13: =A4 -> Grupo Control - Post Test | B13: =(G4*B5)/G5 -> 17 | C13: =(G4*C5)/G5 -> 26.5 | D13: =(G4*D5)/G5 -> 26.5 | E13: =(G4*E5)/G5 -> 15.5 | F13: =(G4*F5)/G5 -> 7.5 | G13: =SUM(B13:F13) -> 93
A16: Tabla completa Valores Observados (O) y Valores Esperados (E)
A18: Grupo | B18: Categoria | C18: Valor Observado (O) | D18: Valor Esperado (E )
A19: =A3 -> Grupo Control - Pre Test | B19: =B2 -> a) Siempre | C19: =B3 -> 14 | D19: =B12 -> 17 | E19: =(C19-D19)^2 -> 9 | F19: =E19/D19 -> 0.52941176
A20: =A3 -> Grupo Control - Pre Test | B20: =C2 -> b) Muchas veces | C20: =C3 -> 31 | D20: =C12 -> 26.5 | E20: =(C20-D20)^2 -> 20.25 | F20: =E20/D20 -> 0.76415094
A21: =A3 -> Grupo Control - Pre Test | B21: =D2 -> c) A veces | C21: =D3 -> 26 | D21: =D12 -> 26.5 | E21: =(C21-D21)^2 -> 0.25 | F21: =E21/D21 -> 0.0094339623
A22: =A3 -> Grupo Control - Pre Test | B22: =E2 -> d) Pocas veces | C22: =E3 -> 17 | D22: =E12 -> 15.5 | E22: =(C22-D22)^2 -> 2.25 | F22: =E22/D22 -> 0.14516129
A23: =A3 -> Grupo Control - Pre Test | B23: =F2 -> e) Nunca | C23: =F3 -> 5 | D23: =F12 -> 7.5 | E23: =(C23-D23)^2 -> 6.25 | F23: =E23/D23 -> 0.83333333
A24: =A4 -> Grupo Control - Post Test | B24: =B2 -> a) Siempre | C24: =B4 -> 20 | D24: =B13 -> 17 | E24: =(C24-D24)^2 -> 9 | F24: =E24/D24 -> 0.52941176
A25: =A4 -> Grupo Control - Post Test | B25: =C2 -> b) Muchas veces | C25: =C4 -> 22 | D25: =C13 -> 26.5 | E25: =(C25-D25)^2 -> 20.25 | F25: =E25/D25 -> 0.76415094
A26: =A4 -> Grupo Control - Post Test | B26: =D2 -> c) A veces | C26: =D4 -> 27 | D26: =D13 -> 26.5 | E26: =(C26-D26)^2 -> 0.25 | F26: =E26/D26 -> 0.0094339623
A27: =A4 -> Grupo Control - Post Test | B27: =E2 -> d) Pocas veces | C27: =E4 -> 14 | D27: =E13 -> 15.5 | E27: =(C27-D27)^2 -> 2.25 | F27: =E27/D27 -> 0.14516129
A28: =A4 -> Grupo Control - Post Test | B28: =F2 -> e) Nunca | C28: =F4 -> 10 | D28: =F13 -> 7.5 | E28: =(C28-D28)^2 -> 6.25 | F28: =E28/D28 -> 0.83333333
A31: Calculo Chi Cuadrado
A35: Chi Cuadrado | B35: =SUM(F19:F28) -> 4.5629826
A37: Calculo Grados Libertad
A39: Filas = 2 (Sin sistema, Con sistema) | C39: 2
A40: Columnas = 5 (las 5 categorías) | C40: 5
A41: Grados de libertad df | C41: =(C39-1)*(C40-1) -> 4
A43: Busqueda de Valor Critico en Tabla Chi Cuadrado
A44: df | B44: =C41 -> 4
A45: α | B45: 0.05 | C45: (el más usado en tesis)
A46: valor critico | B46: =CHIINV(B45,B44) -> 9.487729
A47: p valor | B47: =_xlfn.CHISQ.DIST.RT(B35, B44) -> 0.33514456
A49: Interpretacion
A51: H0 Hipotesis Nula | B51: No existe relación entre los grupos y la variable
A52: H1 Hipotesis Alternativa | B52: Si existe relación entre los grupos y la variable
A54: si p valor < α ---> Se rechaza la hipotesis Nula
A55: α nivel de significancia | B55: =B45 -> 0.05
A56: p valor | B56: =B47 -> 0.33514456
A58: Si chi cuadrado > valor critico ---> Se rechaza la hipotesis nula
A59: Chi Cuadrado | B59: =B35 -> 4.5629826
...

Sheet Herramientas-tecnológicas
A1: Tabla Valores Observados
A2: Grupo / Categoría | B2: a) Siempre | C2: b) Frecuente | D2: c) A veces | E2: d) Raro | F2: e) Nunca | G2: Total
A3: Grupo Control - Pre Test | B3: 17 | C3: 20 | D3: 32 | E3: 16 | F3: 8 | G3: =SUM(B3:F3) -> 93
A4: Grupo Control - Post Test | B4: 20 | C4: 19 | D4: 34 | E4: 15 | F4: 5 | G4: =SUM(B4:F4) -> 93
A5: Total | B5: =SUM(B3:B4) -> 37 | C5: =SUM(C3:C4) -> 39 | D5: =SUM(D3:D4) -> 66 | E5: =SUM(E3:E4) -> 31 | F5: =SUM(F3:F4) -> 13 | G5: =SUM(G3:G4) -> 186
A7: Tabla Valores Esperados
A11: Categoria | B11: =B2 -> a) Siempre | C11: =C2 -> b) Frecuente | D11: =D2 -> c) A veces | E11: =E2 -> d) Raro | F11: =F2 -> e) Nunca | G11: =G2 -> Total
A12: =A3 -> Grupo Control - Pre Test | B12: =(G3*B5)/G5 -> 18.5 | C12: =(G3*C5)/G5 -> 19.5 | D12: =(G3*D5)/G5 -> 33 | E12: =(G3*E5)/G5 -> 15.5 | F12: =(G3*F5)/G5 -> 6.5 | G12: =SUM(B12:F12) -> 93
A13: =A4 -> Grupo Control - Post Test | B13: =(G4*B5)/G5 -> 18.5 | C13: =(G4*C5)/G5 -> 19.5 | D13: =(G4*D5)/G5 -> 33 | E13: =(G4*E5)/G5 -> 15.5 | F13: =(G4*F5)/G5 -> 6.5 | G13: =SUM(B13:F13) -> 93
A16: Tabla completa Valores Observados (O) y Valores Esperados (E)
A18: Grupo | B18: Categoria | C18: Valor Observado (O) | D18: Valor Esperado (E )
A19: =A3 -> Grupo Control - Pre Test | B19: =B2 -> a) Siempre | C19: =B3 -> 17 | D19: =B12 -> 18.5 | E19: =(C19-D19)^2 -> 2.25 | F19: =E19/D19 -> 0.12162162
A20: =A3 -> Grupo Control - Pre Test | B20: =C2 -> b) Frecuente | C20: =C3 -> 20 | D20: =C12 -> 19.5 | E20: =(C20-D20)^2 -> 0.25 | F20: =E20/D20 -> 0.012820513
A21: =A3 -> Grupo Control - Pre Test | B21: =D2 -> c) A veces | C21: =D3 -> 32 | D21: =D12 -> 33 | E21: =(C21-D21)^2 -> 1 | F21: =E21/D21 -> 0.03030303
A22: =A3 -> Grupo Control - Pre Test | B22: =E2 -> d) Raro | C22: =E3 -> 16 | D22: =E12 -> 15.5 | E22: =(C22-D22)^2 -> 0.25 | F22: =E22/D22 -> 0.016129032
A23: =A3 -> Grupo Control - Pre Test | B23: =F2 -> e) Nunca | C23: =F3 -> 8 | D23: =F12 -> 6.5 | E23: =(C23-D23)^2 -> 2.25 | F23: =E23/D23 -> 0.34615385
A24: =A4 -> Grupo Control - Post Test | B24: =B2 -> a) Siempre | C24: =B4 -> 20 | D24: =B13 -> 18.5 | E24: =(C24-D24)^2 -> 2.25 | F24: =E24/D24 -> 0.12162162
A25: =A4 -> Grupo Control - Post Test | B25: =C2 -> b) Frecuente | C25: =C4 -> 19 | D25: =C13 -> 19.5 | E25: =(C25-D25)^2 -> 0.25 | F25: =E25/D25 -> 0.012820513
A26: =A4 -> Grupo Control - Post Test | B26: =D2 -> c) A veces | C26: =D4 -> 34 | D26: =D13 -> 33 | E26: =(C26-D26)^2 -> 1 | F26: =E26/D26 -> 0.03030303
A27: =A4 -> Grupo Control - Post Test | B27: =E2 -> d) Raro | C27: =E4 -> 15 | D27: =E13 -> 15.5 | E27: =(C27-D27)^2 -> 0.25 | F27: =E27/D27 -> 0.016129032
A28: =A4 -> Grupo Control - Post Test | B28: =F2 -> e) Nunca | C28: =F4 -> 5 | D28: =F13 -> 6.5 | E28: =(C28-D28)^2 -> 2.25 | F28: =E28/D28 -> 0.34615385
A31: Calculo Chi Cuadrado
A35: Chi Cuadrado | B35: =SUM(F19:F28) -> 1.0540561
A37: Calculo Grados Libertad
A39: Filas = 2 (Sin sistema, Con sistema) | C39: 2
A40: Columnas = 5 (las 5 categorías) | C40: 5
A41: Grados de libertad df | C41: =(C39-1)*(C40-1) -> 4
A43: Busqueda de Valor Critico en Tabla Chi Cuadrado
A44: df | B44: =C41 -> 4
A45: α | B45: 0.05 | C45: (el más usado en tesis)
A46: valor critico | B46: =CHIINV(B45,B44) -> 9.487729
A47: p valor | B47: =_xlfn.CHISQ.DIST.RT(B35, B44) -> 0.90149151
A49: Interpretacion
A51: H0 Hipotesis Nula | B51: No existe relación entre los grupos y la variable
A52: H1 Hipotesis Alternativa | B52: Si existe relación entre los grupos y la variable
A54: si p valor < α ---> Se rechaza la hipotesis Nula
A55: α nivel de significancia | B55: =B45 -> 0.05
A56: p valor | B56: =B47 -> 0.90149151
A58: Si chi cuadrado > valor critico ---> Se rechaza la hipotesis nula
A59: Chi Cuadrado | B59: =B35 -> 1.0540561
...

Sheet Recursos-tecnológicos
A1: Tabla Valores Observados
A2: Grupo / Categoría | B2: a) Siempre | C2: b) Muchas veces | D2: c) A veces | E2: d) Pocas veces | F2: e) Nunca | G2: Total
A3: Grupo Control - Pre Test | B3: 20 | C3: 23 | D3: 33 | E3: 10 | F3: 7 | G3: =SUM(B3:F3) -> 93
A4: Grupo Control - Post Test | B4: 21 | C4: 20 | D4: 29 | E4: 13 | F4: 10 | G4: =SUM(B4:F4) -> 93
A5: Total | B5: =SUM(B3:B4) -> 41 | C5: =SUM(C3:C4) -> 43 | D5: =SUM(D3:D4) -> 62 | E5: =SUM(E3:E4) -> 23 | F5: =SUM(F3:F4) -> 17 | G5: =SUM(G3:G4) -> 186
A7: Tabla Valores Esperados
A11: Categoria | B11: =B2 -> a) Siempre | C11: =C2 -> b) Muchas veces | D11: =D2 -> c) A veces | E11: =E2 -> d) Pocas veces | F11: =F2 -> e) Nunca | G11: =G2 -> Total
A12: =A3 -> Grupo Control - Pre Test | B12: =(G3*B5)/G5 -> 20.5 | C12: =(G3*C5)/G5 -> 21.5 | D12: =(G3*D5)/G5 -> 31 | E12: =(G3*E5)/G5 -> 11.5 | F12: =(G3*F5)/G5 -> 8.5 | G12: =SUM(B12:F12) -> 93
A13: =A4 -> Grupo Control - Post Test | B13: =(G4*B5)/G5 -> 20.5 | C13: =(G4*C5)/G5 -> 21.5 | D13: =(G4*D5)/G5 -> 31 | E13: =(G4*E5)/G5 -> 11.5 | F13: =(G4*F5)/G5 -> 8.5 | G13: =SUM(B13:F13) -> 93
A16: Tabla completa Valores Observados (O) y Valores Esperados (E)
A18: Grupo | B18: Categoria | C18: Valor Observado (O) | D18: Valor Esperado (E )
A19: =A3 -> Grupo Control - Pre Test | B19: =B2 -> a) Siempre | C19: =B3 -> 20 | D19: =B12 -> 20.5 | E19: =(C19-D19)^2 -> 0.25 | F19: =E19/D19 -> 0.012195122
A20: =A3 -> Grupo Control - Pre Test | B20: =C2 -> b) Muchas veces | C20: =C3 -> 23 | D20: =C12 -> 21.5 | E20: =(C20-D20)^2 -> 2.25 | F20: =E20/D20 -> 0.10465116
A21: =A3 -> Grupo Control - Pre Test | B21: =D2 -> c) A veces | C21: =D3 -> 33 | D21: =D12 -> 31 | E21: =(C21-D21)^2 -> 4 | F21: =E21/D21 -> 0.12903226
A22: =A3 -> Grupo Control - Pre Test | B22: =E2 -> d) Pocas veces | C22: =E3 -> 10 | D22: =E12 -> 11.5 | E22: =(C22-D22)^2 -> 2.25 | F22: =E22/D22 -> 0.19565217
A23: =A3 -> Grupo Control - Pre Test | B23: =F2 -> e) Nunca | C23: =F3 -> 7 | D23: =F12 -> 8.5 | E23: =(C23-D23)^2 -> 2.25 | F23: =E23/D23 -> 0.26470588
A24: =A4 -> Grupo Control - Post Test | B24: =B2 -> a) Siempre | C24: =B4 -> 21 | D24: =B13 -> 20.5 | E24: =(C24-D24)^2 -> 0.25 | F24: =E24/D24 -> 0.012195122
A25: =A4 -> Grupo Control - Post Test | B25: =C2 -> b) Muchas veces | C25: =C4 -> 20 | D25: =C13 -> 21.5 | E25: =(C25-D25)^2 -> 2.25 | F25: =E25/D25 -> 0.10465116
A26: =A4 -> Grupo Control - Post Test | B26: =D2 -> c) A veces | C26: =D4 -> 29 | D26: =D13 -> 31 | E26: =(C26-D26)^2 -> 4 | F26: =E26/D26 -> 0.12903226
A27: =A4 -> Grupo Control - Post Test | B27: =E2 -> d) Pocas veces | C27: =E4 -> 13 | D27: =E13 -> 11.5 | E27: =(C27-D27)^2 -> 2.25 | F27: =E27/D27 -> 0.19565217
A28: =A4 -> Grupo Control - Post Test | B28: =F2 -> e) Nunca | C28: =F4 -> 10 | D28: =F13 -> 8.5 | E28: =(C28-D28)^2 -> 2.25 | F28: =E28/D28 -> 0.26470588
A31: Calculo Chi Cuadrado
A35: Chi Cuadrado | B35: =SUM(F19:F28) -> 1.4124732
A37: Calculo Grados Libertad
A39: Filas = 2 (Sin sistema, Con sistema) | C39: 2
A40: Columnas = 5 (las 5 categorías) | C40: 5
A41: Grados de libertad df | C41: =(C39-1)*(C40-1) -> 4
A43: Busqueda de Valor Critico en Tabla Chi Cuadrado
A44: df | B44: =C41 -> 4
A45: α | B45: 0.05 | C45: (el más usado en tesis)
A46: valor critico | B46: =CHIINV(B45,B44) -> 9.487729
A47: p valor | B47: =_xlfn.CHISQ.DIST.RT(B35, B44) -> 0.84202424
A49: Interpretacion
A51: H0 Hipotesis Nula | B51: No existe relación entre los grupos y la variable
A52: H1 Hipotesis Alternativa | B52: Si existe relación entre los grupos y la variable
A54: si p valor < α ---> Se rechaza la hipotesis Nula
A55: α nivel de significancia | B55: =B45 -> 0.05
A56: p valor | B56: =B47 -> 0.84202424
A58: Si chi cuadrado > valor critico ---> Se rechaza la hipotesis nula
A59: Chi Cuadrado | B59: =B35 -> 1.4124732
...

Sheet Percepción-evaluaciones
A1: Tabla Valores Observados
A2: Grupo / Categoría | B2: a) Siempre | C2: b) Frecuente | D2: c) A veces | E2: d) Raro | F2: e) Nunca | G2: Total
A3: Grupo Control - Pre Test | B3: 22 | C3: 16 | D3: 23 | E3: 21 | F3: 11 | G3: =SUM(B3:F3) -> 93
A4: Grupo Control - Post Test | B4: 12 | C4: 33 | D4: 31 | E4: 14 | F4: 3 | G4: =SUM(B4:F4) -> 93
A5: Total | B5: =SUM(B3:B4) -> 34 | C5: =SUM(C3:C4) -> 49 | D5: =SUM(D3:D4) -> 54 | E5: =SUM(E3:E4) -> 35 | F5: =SUM(F3:F4) -> 14 | G5: =SUM(G3:G4) -> 186
A7: Tabla Valores Esperados
A11: Categoria | B11: =B2 -> a) Siempre | C11: =C2 -> b) Frecuente | D11: =D2 -> c) A veces | E11: =E2 -> d) Raro | F11: =F2 -> e) Nunca | G11: =G2 -> Total
A12: =A3 -> Grupo Control - Pre Test | B12: =(G3*B5)/G5 -> 17 | C12: =(G3*C5)/G5 -> 24.5 | D12: =(G3*D5)/G5 -> 27 | E12: =(G3*E5)/G5 -> 17.5 | F12: =(G3*F5)/G5 -> 7 | G12: =SUM(B12:F12) -> 93
A13: =A4 -> Grupo Control - Post Test | B13: =(G4*B5)/G5 -> 17 | C13: =(G4*C5)/G5 -> 24.5 | D13: =(G4*D5)/G5 -> 27 | E13: =(G4*E5)/G5 -> 17.5 | F13: =(G4*F5)/G5 -> 7 | G13: =SUM(B13:F13) -> 93
A16: Tabla completa Valores Observados (O) y Valores Esperados (E)
A18: Grupo | B18: Categoria | C18: Valor Observado (O) | D18: Valor Esperado (E )
A19: =A3 -> Grupo Control - Pre Test | B19: =B2 -> a) Siempre | C19: =B3 -> 22 | D19: =B12 -> 17 | E19: =(C19-D19)^2 -> 25 | F19: =E19/D19 -> 1.4705882
A20: =A3 -> Grupo Control - Pre Test | B20: =C2 -> b) Frecuente | C20: =C3 -> 16 | D20: =C12 -> 24.5 | E20: =(C20-D20)^2 -> 72.25 | F20: =E20/D20 -> 2.9489796
A21: =A3 -> Grupo Control - Pre Test | B21: =D2 -> c) A veces | C21: =D3 -> 23 | D21: =D12 -> 27 | E21: =(C21-D21)^2 -> 16 | F21: =E21/D21 -> 0.59259259
A22: =A3 -> Grupo Control - Pre Test | B22: =E2 -> d) Raro | C22: =E3 -> 21 | D22: =E12 -> 17.5 | E22: =(C22-D22)^2 -> 12.25 | F22: =E22/D22 -> 0.7
A23: =A3 -> Grupo Control - Pre Test | B23: =F2 -> e) Nunca | C23: =F3 -> 11 | D23: =F12 -> 7 | E23: =(C23-D23)^2 -> 16 | F23: =E23/D23 -> 2.2857143
A24: =A4 -> Grupo Control - Post Test | B24: =B2 -> a) Siempre | C24: =B4 -> 12 | D24: =B13 -> 17 | E24: =(C24-D24)^2 -> 25 | F24: =E24/D24 -> 1.4705882
A25: =A4 -> Grupo Control - Post Test | B25: =C2 -> b) Frecuente | C25: =C4 -> 33 | D25: =C13 -> 24.5 | E25: =(C25-D25)^2 -> 72.25 | F25: =E25/D25 -> 2.9489796
A26: =A4 -> Grupo Control - Post Test | B26: =D2 -> c) A veces | C26: =D4 -> 31 | D26: =D13 -> 27 | E26: =(C26-D26)^2 -> 16 | F26: =E26/D26 -> 0.59259259
A27: =A4 -> Grupo Control - Post Test | B27: =E2 -> d) Raro | C27: =E4 -> 14 | D27: =E13 -> 17.5 | E27: =(C27-D27)^2 -> 12.25 | F27: =E27/D27 -> 0.7
A28: =A4 -> Grupo Control - Post Test | B28: =F2 -> e) Nunca | C28: =F4 -> 3 | D28: =F13 -> 7 | E28: =(C28-D28)^2 -> 16 | F28: =E28/D28 -> 2.2857143
A31: Calculo Chi Cuadrado
A35: Chi Cuadrado | B35: =SUM(F19:F28) -> 15.995749
A37: Calculo Grados Libertad
A39: Filas = 2 (Sin sistema, Con sistema) | C39: 2
A40: Columnas = 5 (las 5 categorías) | C40: 5
A41: Grados de libertad df | C41: =(C39-1)*(C40-1) -> 4
A43: Busqueda de Valor Critico en Tabla Chi Cuadrado
A44: df | B44: =C41 -> 4
A45: α | B45: 0.05 | C45: (el más usado en tesis)
A46: valor critico | B46: =CHIINV(B45,B44) -> 9.487729
A47: p valor | B47: =_xlfn.CHISQ.DIST.RT(B35, B44) -> 0.0030248726
A49: Interpretacion
A51: H0 Hipotesis Nula | B51: No existe relación entre los grupos y la variable
A52: H1 Hipotesis Alternativa | B52: Si existe relación entre los grupos y la variable
A54: si p valor < α ---> Se rechaza la hipotesis Nula
A55: α nivel de significancia | B55: =B45 -> 0.05
A56: p valor | B56: =B47 -> 0.0030248726
A58: Si chi cuadrado > valor critico ---> Se rechaza la hipotesis nula
A59: Chi Cuadrado | B59: =B35 -> 15.995749
...

Sheet Retroalimentación-oportuna
A1: Tabla Valores Observados
A2: Grupo / Categoría | B2: a) Siempre | C2: b) Muchas veces | D2: c) A veces | E2: d) Pocas veces | F2: e) Nunca | G2: Total
A3: Grupo Control - Pre Test | B3: 15 | C3: 23 | D3: 28 | E3: 15 | F3: 12 | G3: =SUM(B3:F3) -> 93
A4: Grupo Control - Post Test | B4: 17 | C4: 24 | D4: 34 | E4: 8 | F4: 10 | G4: =SUM(B4:F4) -> 93
A5: Total | B5: =SUM(B3:B4) -> 32 | C5: =SUM(C3:C4) -> 47 | D5: =SUM(D3:D4) -> 62 | E5: =SUM(E3:E4) -> 23 | F5: =SUM(F3:F4) -> 22 | G5: =SUM(G3:G4) -> 186
A7: Tabla Valores Esperados
A11: Categoria | B11: =B2 -> a) Siempre | C11: =C2 -> b) Muchas veces | D11: =D2 -> c) A veces | E11: =E2 -> d) Pocas veces | F11: =F2 -> e) Nunca | G11: =G2 -> Total
A12: =A3 -> Grupo Control - Pre Test | B12: =(G3*B5)/G5 -> 16 | C12: =(G3*C5)/G5 -> 23.5 | D12: =(G3*D5)/G5 -> 31 | E12: =(G3*E5)/G5 -> 11.5 | F12: =(G3*F5)/G5 -> 11 | G12: =SUM(B12:F12) -> 93
A13: =A4 -> Grupo Control - Post Test | B13: =(G4*B5)/G5 -> 16 | C13: =(G4*C5)/G5 -> 23.5 | D13: =(G4*D5)/G5 -> 31 | E13: =(G4*E5)/G5 -> 11.5 | F13: =(G4*F5)/G5 -> 11 | G13: =SUM(B13:F13) -> 93
A16: Tabla completa Valores Observados (O) y Valores Esperados (E)
A18: Grupo | B18: Categoria | C18: Valor Observado (O) | D18: Valor Esperado (E )
A19: =A3 -> Grupo Control - Pre Test | B19: =B2 -> a) Siempre | C19: =B3 -> 15 | D19: =B12 -> 16 | E19: =(C19-D19)^2 -> 1 | F19: =E19/D19 -> 0.0625
A20: =A3 -> Grupo Control - Pre Test | B20: =C2 -> b) Muchas veces | C20: =C3 -> 23 | D20: =C12 -> 23.5 | E20: =(C20-D20)^2 -> 0.25 | F20: =E20/D20 -> 0.010638298
A21: =A3 -> Grupo Control - Pre Test | B21: =D2 -> c) A veces | C21: =D3 -> 28 | D21: =D12 -> 31 | E21: =(C21-D21)^2 -> 9 | F21: =E21/D21 -> 0.29032258
A22: =A3 -> Grupo Control - Pre Test | B22: =E2 -> d) Pocas veces | C22: =E3 -> 15 | D22: =E12 -> 11.5 | E22: =(C22-D22)^2 -> 12.25 | F22: =E22/D22 -> 1.0652174
A23: =A3 -> Grupo Control - Pre Test | B23: =F2 -> e) Nunca | C23: =F3 -> 12 | D23: =F12 -> 11 | E23: =(C23-D23)^2 -> 1 | F23: =E23/D23 -> 0.090909091
A24: =A4 -> Grupo Control - Post Test | B24: =B2 -> a) Siempre | C24: =B4 -> 17 | D24: =B13 -> 16 | E24: =(C24-D24)^2 -> 1 | F24: =E24/D24 -> 0.0625
A25: =A4 -> Grupo Control - Post Test | B25: =C2 -> b) Muchas veces | C25: =C4 -> 24 | D25: =C13 -> 23.5 | E25: =(C25-D25)^2 -> 0.25 | F25: =E25/D25 -> 0.010638298
A26: =A4 -> Grupo Control - Post Test | B26: =D2 -> c) A veces | C26: =D4 -> 34 | D26: =D13 -> 31 | E26: =(C26-D26)^2 -> 9 | F26: =E26/D26 -> 0.29032258
A27: =A4 -> Grupo Control - Post Test | B27: =E2 -> d) Pocas veces | C27: =E4 -> 8 | D27: =E13 -> 11.5 | E27: =(C27-D27)^2 -> 12.25 | F27: =E27/D27 -> 1.0652174
A28: =A4 -> Grupo Control - Post Test | B28: =F2 -> e) Nunca | C28: =F4 -> 10 | D28: =F13 -> 11 | E28: =(C28-D28)^2 -> 1 | F28: =E28/D28 -> 0.090909091
A31: Calculo Chi Cuadrado
A35: Chi Cuadrado | B35: =SUM(F19:F28) -> 3.0391747
A37: Calculo Grados Libertad
A39: Filas = 2 (Sin sistema, Con sistema) | C39: 2
A40: Columnas = 5 (las 5 categorías) | C40: 5
A41: Grados de libertad df | C41: =(C39-1)*(C40-1) -> 4
A43: Busqueda de Valor Critico en Tabla Chi Cuadrado
A44: df | B44: =C41 -> 4
A45: α | B45: 0.05 | C45: (el más usado en tesis)
A46: valor critico | B46: =CHIINV(B45,B44) -> 9.487729
A47: p valor | B47: =_xlfn.CHISQ.DIST.RT(B35, B44) -> 0.55129114
A49: Interpretacion
A51: H0 Hipotesis Nula | B51: No existe relación entre los grupos y la variable
A52: H1 Hipotesis Alternativa | B52: Si existe relación entre los grupos y la variable
A54: si p valor < α ---> Se rechaza la hipotesis Nula
A55: α nivel de significancia | B55: =B45 -> 0.05
A56: p valor | B56: =B47 -> 0.55129114
A58: Si chi cuadrado > valor critico ---> Se rechaza la hipotesis nula
A59: Chi Cuadrado | B59: =B35 -> 3.0391747
...

Sheet Calificación
A1: Tabla Valores Observados
A2: Grupo / Categoría | B2: a) 81 - 100 | C2: b) 61 – 80 | D2: c) 41 - 60 | E2: d) 21 - 40 | F2: e) 0 - 20 | G2: Total
A3: Grupo Control - Pre Test | B3: 18 | C3: 33 | D3: 27 | E3: 12 | F3: 3 | G3: =SUM(B3:F3) -> 93
A4: Grupo Control - Post Test | B4: 22 | C4: 25 | D4: 24 | E4: 14 | F4: 8 | G4: =SUM(B4:F4) -> 93
A5: Total | B5: =SUM(B3:B4) -> 40 | C5: =SUM(C3:C4) -> 58 | D5: =SUM(D3:D4) -> 51 | E5: =SUM(E3:E4) -> 26 | F5: =SUM(F3:F4) -> 11 | G5: =SUM(G3:G4) -> 186
A7: Tabla Valores Esperados
A11: Categoria | B11: =B2 -> a) 81 - 100 | C11: =C2 -> b) 61 – 80 | D11: =D2 -> c) 41 - 60 | E11: =E2 -> d) 21 - 40 | F11: =F2 -> e) 0 - 20 | G11: =G2 -> Total
A12: =A3 -> Grupo Control - Pre Test | B12: =(G3*B5)/G5 -> 20 | C12: =(G3*C5)/G5 -> 29 | D12: =(G3*D5)/G5 -> 25.5 | E12: =(G3*E5)/G5 -> 13 | F12: =(G3*F5)/G5 -> 5.5 | G12: =SUM(B12:F12) -> 93
A13: =A4 -> Grupo Control - Post Test | B13: =(G4*B5)/G5 -> 20 | C13: =(G4*C5)/G5 -> 29 | D13: =(G4*D5)/G5 -> 25.5 | E13: =(G4*E5)/G5 -> 13 | F13: =(G4*F5)/G5 -> 5.5 | G13: =SUM(B13:F13) -> 93
A16: Tabla completa Valores Observados (O) y Valores Esperados (E)
A18: Grupo | B18: Categoria | C18: Valor Observado (O) | D18: Valor Esperado (E )
A19: =A3 -> Grupo Control - Pre Test | B19: =B2 -> a) 81 - 100 | C19: =B3 -> 18 | D19: =B12 -> 20 | E19: =(C19-D19)^2 -> 4 | F19: =E19/D19 -> 0.2
A20: =A3 -> Grupo Control - Pre Test | B20: =C2 -> b) 61 – 80 | C20: =C3 -> 33 | D20: =C12 -> 29 | E20: =(C20-D20)^2 -> 16 | F20: =E20/D20 -> 0.55172414
A21: =A3 -> Grupo Control - Pre Test | B21: =D2 -> c) 41 - 60 | C21: =D3 -> 27 | D21: =D12 -> 25.5 | E21: =(C21-D21)^2 -> 2.25 | F21: =E21/D21 -> 0.088235294
A22: =A3 -> Grupo Control - Pre Test | B22: =E2 -> d) 21 - 40 | C22: =E3 -> 12 | D22: =E12 -> 13 | E22: =(C22-D22)^2 -> 1 | F22: =E22/D22 -> 0.076923077
A23: =A3 -> Grupo Control - Pre Test | B23: =F2 -> e) 0 - 20 | C23: =F3 -> 3 | D23: =F12 -> 5.5 | E23: =(C23-D23)^2 -> 6.25 | F23: =E23/D23 -> 1.1363636
A24: =A4 -> Grupo Control - Post Test | B24: =B2 -> a) 81 - 100 | C24: =B4 -> 22 | D24: =B13 -> 20 | E24: =(C24-D24)^2 -> 4 | F24: =E24/D24 -> 0.2
A25: =A4 -> Grupo Control - Post Test | B25: =C2 -> b) 61 – 80 | C25: =C4 -> 25 | D25: =C13 -> 29 | E25: =(C25-D25)^2 -> 16 | F25: =E25/D25 -> 0.55172414
A26: =A4 -> Grupo Control - Post Test | B26: =D2 -> c) 41 - 60 | C26: =D4 -> 24 | D26: =D13 -> 25.5 | E26: =(C26-D26)^2 -> 2.25 | F26: =E26/D26 -> 0.088235294
A27: =A4 -> Grupo Control - Post Test | B27: =E2 -> d) 21 - 40 | C27: =E4 -> 14 | D27: =E13 -> 13 | E27: =(C27-D27)^2 -> 1 | F27: =E27/D27 -> 0.076923077
A28: =A4 -> Grupo Control - Post Test | B28: =F2 -> e) 0 - 20 | C28: =F4 -> 8 | D28: =F13 -> 5.5 | E28: =(C28-D28)^2 -> 6.25 | F28: =E28/D28 -> 1.1363636
A31: Calculo Chi Cuadrado
A35: Chi Cuadrado | B35: =SUM(F19:F28) -> 4.1064923
A37: Calculo Grados Libertad
A39: Filas = 2 (Sin sistema, Con sistema) | C39: 2
A40: Columnas = 5 (las 5 categorías) | C40: 5
A41: Grados de libertad df | C41: =(C39-1)*(C40-1) -> 4
A43: Busqueda de Valor Critico en Tabla Chi Cuadrado
A44: df | B44: =C41 -> 4
A45: α | B45: 0.05 | C45: (el más usado en tesis)
A46: valor critico | B46: =CHIINV(B45,B44) -> 9.487729
A47: p valor | B47: =_xlfn.CHISQ.DIST.RT(B35, B44) -> 0.39178549
A49: Interpretacion
A51: H0 Hipotesis Nula | B51: No existe relación entre los grupos y la variable
A52: H1 Hipotesis Alternativa | B52: Si existe relación entre los grupos y la variable
A54: si p valor < α ---> Se rechaza la hipotesis Nula
A55: α nivel de significancia | B55: =B45 -> 0.05
A56: p valor | B56: =B47 -> 0.39178549
A58: Si chi cuadrado > valor critico ---> Se rechaza la hipotesis nula
A59: Chi Cuadrado | B59: =B35 -> 4.1064923
...

Sheet Nivel-comprensión
A1: Tabla Valores Observados
A2: Grupo / Categoría | B2: a) Muy Bueno | C2: b) bueno | D2: c) Regular | E2: d) Malo | F2: e) Muy malo | G2: Total
A3: Grupo Control - Pre Test | B3: 18 | C3: 24 | D3: 34 | E3: 14 | F3: 3 | G3: =SUM(B3:F3) -> 93
A4: Grupo Control - Post Test | B4: 15 | C4: 23 | D4: 34 | E4: 15 | F4: 6 | G4: =SUM(B4:F4) -> 93
A5: Total | B5: =SUM(B3:B4) -> 33 | C5: =SUM(C3:C4) -> 47 | D5: =SUM(D3:D4) -> 68 | E5: =SUM(E3:E4) -> 29 | F5: =SUM(F3:F4) -> 9 | G5: =SUM(G3:G4) -> 186
A7: Tabla Valores Esperados
A11: Categoria | B11: =B2 -> a) Muy Bueno | C11: =C2 -> b) bueno | D11: =D2 -> c) Regular | E11: =E2 -> d) Malo | F11: =F2 -> e) Muy malo | G11: =G2 -> Total
A12: =A3 -> Grupo Control - Pre Test | B12: =(G3*B5)/G5 -> 16.5 | C12: =(G3*C5)/G5 -> 23.5 | D12: =(G3*D5)/G5 -> 34 | E12: =(G3*E5)/G5 -> 14.5 | F12: =(G3*F5)/G5 -> 4.5 | G12: =SUM(B12:F12) -> 93
A13: =A4 -> Grupo Control - Post Test | B13: =(G4*B5)/G5 -> 16.5 | C13: =(G4*C5)/G5 -> 23.5 | D13: =(G4*D5)/G5 -> 34 | E13: =(G4*E5)/G5 -> 14.5 | F13: =(G4*F5)/G5 -> 4.5 | G13: =SUM(B13:F13) -> 93
A16: Tabla completa Valores Observados (O) y Valores Esperados (E)
A18: Grupo | B18: Categoria | C18: Valor Observado (O) | D18: Valor Esperado (E )
A19: =A3 -> Grupo Control - Pre Test | B19: =B2 -> a) Muy Bueno | C19: =B3 -> 18 | D19: =B12 -> 16.5 | E19: =(C19-D19)^2 -> 2.25 | F19: =E19/D19 -> 0.13636364
A20: =A3 -> Grupo Control - Pre Test | B20: =C2 -> b) bueno | C20: =C3 -> 24 | D20: =C12 -> 23.5 | E20: =(C20-D20)^2 -> 0.25 | F20: =E20/D20 -> 0.010638298
A21: =A3 -> Grupo Control - Pre Test | B21: =D2 -> c) Regular | C21: =D3 -> 34 | D21: =D12 -> 34 | E21: =(C21-D21)^2 -> 0 | F21: =E21/D21 -> 0
A22: =A3 -> Grupo Control - Pre Test | B22: =E2 -> d) Malo | C22: =E3 -> 14 | D22: =E12 -> 14.5 | E22: =(C22-D22)^2 -> 0.25 | F22: =E22/D22 -> 0.017241379
A23: =A3 -> Grupo Control - Pre Test | B23: =F2 -> e) Muy malo | C23: =F3 -> 3 | D23: =F12 -> 4.5 | E23: =(C23-D23)^2 -> 2.25 | F23: =E23/D23 -> 0.5
A24: =A4 -> Grupo Control - Post Test | B24: =B2 -> a) Muy Bueno | C24: =B4 -> 15 | D24: =B13 -> 16.5 | E24: =(C24-D24)^2 -> 2.25 | F24: =E24/D24 -> 0.13636364
A25: =A4 -> Grupo Control - Post Test | B25: =C2 -> b) bueno | C25: =C4 -> 23 | D25: =C13 -> 23.5 | E25: =(C25-D25)^2 -> 0.25 | F25: =E25/D25 -> 0.010638298
A26: =A4 -> Grupo Control - Post Test | B26: =D2 -> c) Regular | C26: =D4 -> 34 | D26: =D13 -> 34 | E26: =(C26-D26)^2 -> 0 | F26: =E26/D26 -> 0
A27: =A4 -> Grupo Control - Post Test | B27: =E2 -> d) Malo | C27: =E4 -> 15 | D27: =E13 -> 14.5 | E27: =(C27-D27)^2 -> 0.25 | F27: =E27/D27 -> 0.017241379
A28: =A4 -> Grupo Control - Post Test | B28: =F2 -> e) Muy malo | C28: =F4 -> 6 | D28: =F13 -> 4.5 | E28: =(C28-D28)^2 -> 2.25 | F28: =E28/D28 -> 0.5
A31: Calculo Chi Cuadrado
A35: Chi Cuadrado | B35: =SUM(F19:F28) -> 1.3284866
A37: Calculo Grados Libertad
A39: Filas = 2 (Sin sistema, Con sistema) | C39: 2
A40: Columnas = 5 (las 5 categorías) | C40: 5
A41: Grados de libertad df | C41: =(C39-1)*(C40-1) -> 4
A43: Busqueda de Valor Critico en Tabla Chi Cuadrado
A44: df | B44: =C41 -> 4
A45: α | B45: 0.05 | C45: (el más usado en tesis)
A46: valor critico | B46: =CHIINV(B45,B44) -> 9.487729
A47: p valor | B47: =_xlfn.CHISQ.DIST.RT(B35, B44) -> 0.85652415
A49: Interpretacion
A51: H0 Hipotesis Nula | B51: No existe relación entre los grupos y la variable
A52: H1 Hipotesis Alternativa | B52: Si existe relación entre los grupos y la variable
A54: si p valor < α ---> Se rechaza la hipotesis Nula
A55: α nivel de significancia | B55: =B45 -> 0.05
A56: p valor | B56: =B47 -> 0.85652415
A58: Si chi cuadrado > valor critico ---> Se rechaza la hipotesis nula
A59: Chi Cuadrado | B59: =B35 -> 1.3284866
...

Sheet Habilidades-tareas
A1: Tabla Valores Observados
A2: Grupo / Categoría | B2: a) Siempre | C2: b) Muchas veces | D2: c) A veces | E2: d) Pocas veces | F2: e) Nunca | G2: Total
A3: Grupo Control - Pre Test | B3: 18 | C3: 28 | D3: 29 | E3: 12 | F3: 6 | G3: =SUM(B3:F3) -> 93
A4: Grupo Control - Post Test | B4: 13 | C4: 23 | D4: 39 | E4: 14 | F4: 4 | G4: =SUM(B4:F4) -> 93
A5: Total | B5: =SUM(B3:B4) -> 31 | C5: =SUM(C3:C4) -> 51 | D5: =SUM(D3:D4) -> 68 | E5: =SUM(E3:E4) -> 26 | F5: =SUM(F3:F4) -> 10 | G5: =SUM(G3:G4) -> 186
A7: Tabla Valores Esperados
A11: Categoria | B11: =B2 -> a) Siempre | C11: =C2 -> b) Muchas veces | D11: =D2 -> c) A veces | E11: =E2 -> d) Pocas veces | F11: =F2 -> e) Nunca | G11: =G2 -> Total
A12: =A3 -> Grupo Control - Pre Test | B12: =(G3*B5)/G5 -> 15.5 | C12: =(G3*C5)/G5 -> 25.5 | D12: =(G3*D5)/G5 -> 34 | E12: =(G3*E5)/G5 -> 13 | F12: =(G3*F5)/G5 -> 5 | G12: =SUM(B12:F12) -> 93
A13: =A4 -> Grupo Control - Post Test | B13: =(G4*B5)/G5 -> 15.5 | C13: =(G4*C5)/G5 -> 25.5 | D13: =(G4*D5)/G5 -> 34 | E13: =(G4*E5)/G5 -> 13 | F13: =(G4*F5)/G5 -> 5 | G13: =SUM(B13:F13) -> 93
A16: Tabla completa Valores Observados (O) y Valores Esperados (E)
A18: Grupo | B18: Categoria | C18: Valor Observado (O) | D18: Valor Esperado (E )
A19: =A3 -> Grupo Control - Pre Test | B19: =B2 -> a) Siempre | C19: =B3 -> 18 | D19: =B12 -> 15.5 | E19: =(C19-D19)^2 -> 6.25 | F19: =E19/D19 -> 0.40322581
A20: =A3 -> Grupo Control - Pre Test | B20: =C2 -> b) Muchas veces | C20: =C3 -> 28 | D20: =C12 -> 25.5 | E20: =(C20-D20)^2 -> 6.25 | F20: =E20/D20 -> 0.24509804
A21: =A3 -> Grupo Control - Pre Test | B21: =D2 -> c) A veces | C21: =D3 -> 29 | D21: =D12 -> 34 | E21: =(C21-D21)^2 -> 25 | F21: =E21/D21 -> 0.73529412
A22: =A3 -> Grupo Control - Pre Test | B22: =E2 -> d) Pocas veces | C22: =E3 -> 12 | D22: =E12 -> 13 | E22: =(C22-D22)^2 -> 1 | F22: =E22/D22 -> 0.076923077
A23: =A3 -> Grupo Control - Pre Test | B23: =F2 -> e) Nunca | C23: =F3 -> 6 | D23: =F12 -> 5 | E23: =(C23-D23)^2 -> 1 | F23: =E23/D23 -> 0.2
A24: =A4 -> Grupo Control - Post Test | B24: =B2 -> a) Siempre | C24: =B4 -> 13 | D24: =B13 -> 15.5 | E24: =(C24-D24)^2 -> 6.25 | F24: =E24/D24 -> 0.40322581
A25: =A4 -> Grupo Control - Post Test | B25: =C2 -> b) Muchas veces | C25: =C4 -> 23 | D25: =C13 -> 25.5 | E25: =(C25-D25)^2 -> 6.25 | F25: =E25/D25 -> 0.24509804
A26: =A4 -> Grupo Control - Post Test | B26: =D2 -> c) A veces | C26: =D4 -> 39 | D26: =D13 -> 34 | E26: =(C26-D26)^2 -> 25 | F26: =E26/D26 -> 0.73529412
A27: =A4 -> Grupo Control - Post Test | B27: =E2 -> d) Pocas veces | C27: =E4 -> 14 | D27: =E13 -> 13 | E27: =(C27-D27)^2 -> 1 | F27: =E27/D27 -> 0.076923077
A28: =A4 -> Grupo Control - Post Test | B28: =F2 -> e) Nunca | C28: =F4 -> 4 | D28: =F13 -> 5 | E28: =(C28-D28)^2 -> 1 | F28: =E28/D28 -> 0.2
A31: Calculo Chi Cuadrado
A35: Chi Cuadrado | B35: =SUM(F19:F28) -> 3.3210821
A37: Calculo Grados Libertad
A39: Filas = 2 (Sin sistema, Con sistema) | C39: 2
A40: Columnas = 5 (las 5 categorías) | C40: 5
A41: Grados de libertad df | C41: =(C39-1)*(C40-1) -> 4
A43: Busqueda de Valor Critico en Tabla Chi Cuadrado
A44: df | B44: =C41 -> 4
A45: α | B45: 0.05 | C45: (el más usado en tesis)
A46: valor critico | B46: =CHIINV(B45,B44) -> 9.487729
A47: p valor | B47: =_xlfn.CHISQ.DIST.RT(B35, B44) -> 0.50559894
A49: Interpretacion
A51: H0 Hipotesis Nula | B51: No existe relación entre los grupos y la variable
A52: H1 Hipotesis Alternativa | B52: Si existe relación entre los grupos y la variable
A54: si p valor < α ---> Se rechaza la hipotesis Nula
A55: α nivel de significancia | B55: =B45 -> 0.05
A56: p valor | B56: =B47 -> 0.50559894
A58: Si chi cuadrado > valor critico ---> Se rechaza la hipotesis nula
A59: Chi Cuadrado | B59: =B35 -> 3.3210821
...

Sheet Resolución-problemas
A1: Tabla Valores Observados
A2: Grupo / Categoría | B2: a) Siempre | C2: b) Frecuente | D2: c) A veces | E2: d) Raro | F2: e) Nunca | G2: Total
A3: Grupo Control - Pre Test | B3: 15 | C3: 32 | D3: 29 | E3: 14 | F3: 3 | G3: =SUM(B3:F3) -> 93
A4: Grupo Control - Post Test | B4: 18 | C4: 25 | D4: 33 | E4: 10 | F4: 7 | G4: =SUM(B4:F4) -> 93
A5: Total | B5: =SUM(B3:B4) -> 33 | C5: =SUM(C3:C4) -> 57 | D5: =SUM(D3:D4) -> 62 | E5: =SUM(E3:E4) -> 24 | F5: =SUM(F3:F4) -> 10 | G5: =SUM(G3:G4) -> 186
A7: Tabla Valores Esperados
A11: Categoria | B11: =B2 -> a) Siempre | C11: =C2 -> b) Frecuente | D11: =D2 -> c) A veces | E11: =E2 -> d) Raro | F11: =F2 -> e) Nunca | G11: =G2 -> Total
A12: =A3 -> Grupo Control - Pre Test | B12: =(G3*B5)/G5 -> 16.5 | C12: =(G3*C5)/G5 -> 28.5 | D12: =(G3*D5)/G5 -> 31 | E12: =(G3*E5)/G5 -> 12 | F12: =(G3*F5)/G5 -> 5 | G12: =SUM(B12:F12) -> 93
A13: =A4 -> Grupo Control - Post Test | B13: =(G4*B5)/G5 -> 16.5 | C13: =(G4*C5)/G5 -> 28.5 | D13: =(G4*D5)/G5 -> 31 | E13: =(G4*E5)/G5 -> 12 | F13: =(G4*F5)/G5 -> 5 | G13: =SUM(B13:F13) -> 93
A16: Tabla completa Valores Observados (O) y Valores Esperados (E)
A18: Grupo | B18: Categoria | C18: Valor Observado (O) | D18: Valor Esperado (E )
A19: =A3 -> Grupo Control - Pre Test | B19: =B2 -> a) Siempre | C19: =B3 -> 15 | D19: =B12 -> 16.5 | E19: =(C19-D19)^2 -> 2.25 | F19: =E19/D19 -> 0.13636364
A20: =A3 -> Grupo Control - Pre Test | B20: =C2 -> b) Frecuente | C20: =C3 -> 32 | D20: =C12 -> 28.5 | E20: =(C20-D20)^2 -> 12.25 | F20: =E20/D20 -> 0.42982456
A21: =A3 -> Grupo Control - Pre Test | B21: =D2 -> c) A veces | C21: =D3 -> 29 | D21: =D12 -> 31 | E21: =(C21-D21)^2 -> 4 | F21: =E21/D21 -> 0.12903226
A22: =A3 -> Grupo Control - Pre Test | B22: =E2 -> d) Raro | C22: =E3 -> 14 | D22: =E12 -> 12 | E22: =(C22-D22)^2 -> 4 | F22: =E22/D22 -> 0.33333333
A23: =A3 -> Grupo Control - Pre Test | B23: =F2 -> e) Nunca | C23: =F3 -> 3 | D23: =F12 -> 5 | E23: =(C23-D23)^2 -> 4 | F23: =E23/D23 -> 0.8
A24: =A4 -> Grupo Control - Post Test | B24: =B2 -> a) Siempre | C24: =B4 -> 18 | D24: =B13 -> 16.5 | E24: =(C24-D24)^2 -> 2.25 | F24: =E24/D24 -> 0.13636364
A25: =A4 -> Grupo Control - Post Test | B25: =C2 -> b) Frecuente | C25: =C4 -> 25 | D25: =C13 -> 28.5 | E25: =(C25-D25)^2 -> 12.25 | F25: =E25/D25 -> 0.42982456
A26: =A4 -> Grupo Control - Post Test | B26: =D2 -> c) A veces | C26: =D4 -> 33 | D26: =D13 -> 31 | E26: =(C26-D26)^2 -> 4 | F26: =E26/D26 -> 0.12903226
A27: =A4 -> Grupo Control - Post Test | B27: =E2 -> d) Raro | C27: =E4 -> 10 | D27: =E13 -> 12 | E27: =(C27-D27)^2 -> 4 | F27: =E27/D27 -> 0.33333333
A28: =A4 -> Grupo Control - Post Test | B28: =F2 -> e) Nunca | C28: =F4 -> 7 | D28: =F13 -> 5 | E28: =(C28-D28)^2 -> 4 | F28: =E28/D28 -> 0.8
A31: Calculo Chi Cuadrado
A35: Chi Cuadrado | B35: =SUM(F19:F28) -> 3.6571076
A37: Calculo Grados Libertad
A39: Filas = 2 (Sin sistema, Con sistema) | C39: 2
A40: Columnas = 5 (las 5 categorías) | C40: 5
A41: Grados de libertad df | C41: =(C39-1)*(C40-1) -> 4
A43: Busqueda de Valor Critico en Tabla Chi Cuadrado
A44: df | B44: =C41 -> 4
A45: α | B45: 0.05 | C45: (el más usado en tesis)
A46: valor critico | B46: =CHIINV(B45,B44) -> 9.487729
A47: p valor | B47: =_xlfn.CHISQ.DIST.RT(B35, B44) -> 0.45439508
A49: Interpretacion
A51: H0 Hipotesis Nula | B51: No existe relación entre los grupos y la variable
A52: H1 Hipotesis Alternativa | B52: Si existe relación entre los grupos y la variable
A54: si p valor < α ---> Se rechaza la hipotesis Nula
A55: α nivel de significancia | B55: =B45 -> 0.05
A56: p valor | B56: =B47 -> 0.45439508
A58: Si chi cuadrado > valor critico ---> Se rechaza la hipotesis nula
A59: Chi Cuadrado | B59: =B35 -> 3.6571076
...

Sheet Motivación
A1: Tabla Valores Observados
A2: Grupo / Categoría | B2: a) Siempre | C2: b) Frecuente | D2: c) A veces | E2: d) Raro | F2: e) Nunca | G2: Total
A3: Grupo Control - Pre Test | B3: 13 | C3: 29 | D3: 24 | E3: 14 | F3: 13 | G3: =SUM(B3:F3) -> 93
A4: Grupo Control - Post Test | B4: 17 | C4: 23 | D4: 24 | E4: 23 | F4: 6 | G4: =SUM(B4:F4) -> 93
A5: Total | B5: =SUM(B3:B4) -> 30 | C5: =SUM(C3:C4) -> 52 | D5: =SUM(D3:D4) -> 48 | E5: =SUM(E3:E4) -> 37 | F5: =SUM(F3:F4) -> 19 | G5: =SUM(G3:G4) -> 186
A7: Tabla Valores Esperados
A11: Categoria | B11: =B2 -> a) Siempre | C11: =C2 -> b) Frecuente | D11: =D2 -> c) A veces | E11: =E2 -> d) Raro | F11: =F2 -> e) Nunca | G11: =G2 -> Total
A12: =A3 -> Grupo Control - Pre Test | B12: =(G3*B5)/G5 -> 15 | C12: =(G3*C5)/G5 -> 26 | D12: =(G3*D5)/G5 -> 24 | E12: =(G3*E5)/G5 -> 18.5 | F12: =(G3*F5)/G5 -> 9.5 | G12: =SUM(B12:F12) -> 93
A13: =A4 -> Grupo Control - Post Test | B13: =(G4*B5)/G5 -> 15 | C13: =(G4*C5)/G5 -> 26 | D13: =(G4*D5)/G5 -> 24 | E13: =(G4*E5)/G5 -> 18.5 | F13: =(G4*F5)/G5 -> 9.5 | G13: =SUM(B13:F13) -> 93
A16: Tabla completa Valores Observados (O) y Valores Esperados (E)
A18: Grupo | B18: Categoria | C18: Valor Observado (O) | D18: Valor Esperado (E )
A19: =A3 -> Grupo Control - Pre Test | B19: =B2 -> a) Siempre | C19: =B3 -> 13 | D19: =B12 -> 15 | E19: =(C19-D19)^2 -> 4 | F19: =E19/D19 -> 0.26666667
A20: =A3 -> Grupo Control - Pre Test | B20: =C2 -> b) Frecuente | C20: =C3 -> 29 | D20: =C12 -> 26 | E20: =(C20-D20)^2 -> 9 | F20: =E20/D20 -> 0.34615385
A21: =A3 -> Grupo Control - Pre Test | B21: =D2 -> c) A veces | C21: =D3 -> 24 | D21: =D12 -> 24 | E21: =(C21-D21)^2 -> 0 | F21: =E21/D21 -> 0
A22: =A3 -> Grupo Control - Pre Test | B22: =E2 -> d) Raro | C22: =E3 -> 14 | D22: =E12 -> 18.5 | E22: =(C22-D22)^2 -> 20.25 | F22: =E22/D22 -> 1.0945946
A23: =A3 -> Grupo Control - Pre Test | B23: =F2 -> e) Nunca | C23: =F3 -> 13 | D23: =F12 -> 9.5 | E23: =(C23-D23)^2 -> 12.25 | F23: =E23/D23 -> 1.2894737
A24: =A4 -> Grupo Control - Post Test | B24: =B2 -> a) Siempre | C24: =B4 -> 17 | D24: =B13 -> 15 | E24: =(C24-D24)^2 -> 4 | F24: =E24/D24 -> 0.26666667
A25: =A4 -> Grupo Control - Post Test | B25: =C2 -> b) Frecuente | C25: =C4 -> 23 | D25: =C13 -> 26 | E25: =(C25-D25)^2 -> 9 | F25: =E25/D25 -> 0.34615385
A26: =A4 -> Grupo Control - Post Test | B26: =D2 -> c) A veces | C26: =D4 -> 24 | D26: =D13 -> 24 | E26: =(C26-D26)^2 -> 0 | F26: =E26/D26 -> 0
A27: =A4 -> Grupo Control - Post Test | B27: =E2 -> d) Raro | C27: =E4 -> 23 | D27: =E13 -> 18.5 | E27: =(C27-D27)^2 -> 20.25 | F27: =E27/D27 -> 1.0945946
A28: =A4 -> Grupo Control - Post Test | B28: =F2 -> e) Nunca | C28: =F4 -> 6 | D28: =F13 -> 9.5 | E28: =(C28-D28)^2 -> 12.25 | F28: =E28/D28 -> 1.2894737
A31: Calculo Chi Cuadrado
A35: Chi Cuadrado | B35: =SUM(F19:F28) -> 5.9937776
A37: Calculo Grados Libertad
A39: Filas = 2 (Sin sistema, Con sistema) | C39: 2
A40: Columnas = 5 (las 5 categorías) | C40: 5
A41: Grados de libertad df | C41: =(C39-1)*(C40-1) -> 4
A43: Busqueda de Valor Critico en Tabla Chi Cuadrado
A44: df | B44: =C41 -> 4
A45: α | B45: 0.05 | C45: (el más usado en tesis)
A46: valor critico | B46: =CHIINV(B45,B44) -> 9.487729
A47: p valor | B47: =_xlfn.CHISQ.DIST.RT(B35, B44) -> 0.19961345
A49: Interpretacion
A51: H0 Hipotesis Nula | B51: No existe relación entre los grupos y la variable
A52: H1 Hipotesis Alternativa | B52: Si existe relación entre los grupos y la variable
A54: si p valor < α ---> Se rechaza la hipotesis Nula
A55: α nivel de significancia | B55: =B45 -> 0.05
A56: p valor | B56: =B47 -> 0.19961345
A58: Si chi cuadrado > valor critico ---> Se rechaza la hipotesis nula
A59: Chi Cuadrado | B59: =B35 -> 5.9937776
...
