Workbook

Sheet Objetivo
A1: ✅ Chi-cuadrado (Post-test)
A2: Demuestra que la intervencion si genera cambio
A4: Objetivo:
A5: Evaluar si existe relación significativa entre las variables analizadas en el grupo control y el grupo experimental después de la implementación de la intervencion (post-test), con el fin de determinar el efecto de la intervencion en la mejora de los resultados.
A7: Grupos:
A8: Grupo Control – Post Test
A9: Grupo Experimental – Post Test

Sheet Resumen
A1: Indicador | B1: Chi Cuadrado Observado | C1: Chi Cuadrado Valor Critico | D1: P-Valor | E1: α nivel de significancia
A2: Participo actividades | B2: =ROUND('Participas-actividades'!B35, 4) -> 30.5651 | C2: =ROUND('Participas-actividades'!B46, 4) -> 9.4877 | D2: ='Participas-actividades'!B47 -> 3.7549036e-06 | E2: 0.05
A3: Comprensión contenidos | B3: =ROUND('Comprensión contenidos'!B35, 4) -> 12.9934 | C3: =ROUND('Comprensión contenidos'!B46, 4) -> 9.4877 | D3: ='Comprensión contenidos'!B47 -> 0.011307939 | E3: 0.05
A4: Herramientas tecnológicas | B4: =ROUND('Herramientas-tecnológicas'!B35, 4) -> 16.9377 | C4: =ROUND('Herramientas-tecnológicas'!B46, 4) -> 9.4877 | D4: ='Herramientas-tecnológicas'!B47 -> 0.0019875863 | E4: 0.05
A5: Recursos tecnológicos | B5: =ROUND('Recursos-tecnológicos'!B35,4) -> 27.665 | C5: =ROUND('Recursos-tecnológicos'!B46,4) -> 9.4877 | D5: ='Recursos-tecnológicos'!B47 -> 1.458286e-05 | E5: 0.05
A6: Percepción evaluaciones | B6: =ROUND('Percepción-evaluaciones'!B35,4) -> 20.9683 | C6: =ROUND('Percepción-evaluaciones'!B46,4) -> 9.4877 | D6: ='Percepción-evaluaciones'!B47 -> 0.00032128373 | E6: 0.05
A7: Retroalimentación oportuna | B7: =ROUND('Retroalimentación-oportuna'!B35,4) -> 28.1803 | C7: =ROUND('Retroalimentación-oportuna'!B46,4) -> 9.4877 | D7: ='Retroalimentación-oportuna'!B47 -> 1.1466039e-05 | E7: 0.05
A8: Calificación | B8: =ROUND(Calificación!B35,4) -> 19.1468 | C8: =ROUND(Calificación!B46,4) -> 9.4877 | D8: =Calificación!B47 -> 0.00073544223 | E8: 0.05
A9: Nivel comprensión | B9: =ROUND('Nivel-comprensión'!B35,4) -> 36.3603 | C9: =ROUND('Nivel-comprensión'!B46,4) -> 9.4877 | D9: ='Nivel-comprensión'!B47 -> 2.4395229e-07 | E9: 0.05
A10: Habilidades tareas | B10: =ROUND('Habilidades-tareas'!B35,4) -> 27.4101 | C10: =ROUND('Habilidades-tareas'!B46,4) -> 9.4877 | D10: ='Habilidades-tareas'!B47 -> 1.6422268e-05 | E10: 0.05
A11: Resolución problemas | B11: =ROUND('Resolución-problemas'!B35,4) -> 29.7357 | C11: =ROUND('Resolución-problemas'!B46,4) -> 9.4877 | D11: ='Resolución-problemas'!B47 -> 5.5398912e-06 | E11: 0.05
A12: Motivación | B12: =ROUND(Motivación!B35,4) -> 25.2868 | C12: =ROUND(Motivación!B46,4) -> 9.4877 | D12: =Motivación!B47 -> 4.4052579e-05 | E12: 0.05

Sheet Participas-actividades
A1: Tabla Valores Observados
A2: Grupo / Categoría | B2: a) Siempre | C2: b) Frecuente | D2: c) A veces | E2: d) Raro | F2: e) Nunca | G2: Total
A3: Grupo Control - Post Test | B3: 12 | C3: 22 | D3: 33 | E3: 19 | F3: 7 | G3: =SUM(B3:F3) -> 93
A4: Grupo Experimental - Post Test | B4: 34 | C4: 35 | D4: 18 | E4: 5 | F4: 1 | G4: =SUM(B4:F4) -> 93
A5: Total | B5: =SUM(B3:B4) -> 46 | C5: =SUM(C3:C4) -> 57 | D5: =SUM(D3:D4) -> 51 | E5: =SUM(E3:E4) -> 24 | F5: =SUM(F3:F4) -> 8 | G5: =SUM(G3:G4) -> 186
A7: Tabla Valores Esperados
A11: Categoria | B11: =B2 -> a) Siempre | C11: =C2 -> b) Frecuente | D11: =D2 -> c) A veces | E11: =E2 -> d) Raro | F11: =F2 -> e) Nunca | G11: =G2 -> Total
A12: =A3 -> Grupo Control - Post Test | B12: =(G3*B5)/G5 -> 23 | C12: =(G3*C5)/G5 -> 28.5 | D12: =(G3*D5)/G5 -> 25.5 | E12: =(G3*E5)/G5 -> 12 | F12: =(G3*F5)/G5 -> 4 | G12: =SUM(B12:F12) -> 93
A13: =A4 -> Grupo Experimental - Post Test | B13: =(G4*B5)/G5 -> 23 | C13: =(G4*C5)/G5 -> 28.5 | D13: =(G4*D5)/G5 -> 25.5 | E13: =(G4*E5)/G5 -> 12 | F13: =(G4*F5)/G5 -> 4 | G13: =SUM(B13:F13) -> 93
A16: Tabla completa Valores Observados (O) y Valores Esperados (E)
A18: Grupo | B18: Categoria | C18: Valor Observado (O) | D18: Valor Esperado (E )
A19: =A3 -> Grupo Control - Post Test | B19: =B2 -> a) Siempre | C19: =B3 -> 12 | D19: =B12 -> 23 | E19: =(C19-D19)^2 -> 121 | F19: =E19/D19 -> 5.2608696
A20: =A3 -> Grupo Control - Post Test | B20: =C2 -> b) Frecuente | C20: =C3 -> 22 | D20: =C12 -> 28.5 | E20: =(C20-D20)^2 -> 42.25 | F20: =E20/D20 -> 1.4824561
A21: =A3 -> Grupo Control - Post Test | B21: =D2 -> c) A veces | C21: =D3 -> 33 | D21: =D12 -> 25.5 | E21: =(C21-D21)^2 -> 56.25 | F21: =E21/D21 -> 2.2058824
A22: =A3 -> Grupo Control - Post Test | B22: =E2 -> d) Raro | C22: =E3 -> 19 | D22: =E12 -> 12 | E22: =(C22-D22)^2 -> 49 | F22: =E22/D22 -> 4.0833333
A23: =A3 -> Grupo Control - Post Test | B23: =F2 -> e) Nunca | C23: =F3 -> 7 | D23: =F12 -> 4 | E23: =(C23-D23)^2 -> 9 | F23: =E23/D23 -> 2.25
A24: =A4 -> Grupo Experimental - Post Test | B24: =B2 -> a) Siempre | C24: =B4 -> 34 | D24: =B13 -> 23 | E24: =(C24-D24)^2 -> 121 | F24: =E24/D24 -> 5.2608696
A25: =A4 -> Grupo Experimental - Post Test | B25: =C2 -> b) Frecuente | C25: =C4 -> 35 | D25: =C13 -> 28.5 | E25: =(C25-D25)^2 -> 42.25 | F25: =E25/D25 -> 1.4824561
A26: =A4 -> Grupo Experimental - Post Test | B26: =D2 -> c) A veces | C26: =D4 -> 18 | D26: =D13 -> 25.5 | E26: =(C26-D26)^2 -> 56.25 | F26: =E26/D26 -> 2.2058824
A27: =A4 -> Grupo Experimental - Post Test | B27: =E2 -> d) Raro | C27: =E4 -> 5 | D27: =E13 -> 12 | E27: =(C27-D27)^2 -> 49 | F27: =E27/D27 -> 4.0833333
A28: =A4 -> Grupo Experimental - Post Test | B28: =F2 -> e) Nunca | C28: =F4 -> 1 | D28: =F13 -> 4 | E28: =(C28-D28)^2 -> 9 | F28: =E28/D28 -> 2.25
A31: Calculo Chi Cuadrado
A35: Chi Cuadrado | B35: =SUM(F19:F28) -> 30.565083
A37: Calculo Grados Libertad
A39: Filas = 2 (Sin sistema, Con sistema) | C39: 2
A40: Columnas = 5 (las 5 categorías) | C40: 5
A41: Grados de libertad df | C41: =(C39-1)*(C40-1) -> 4
A43: Busqueda de Valor Critico en Tabla Chi Cuadrado
A44: df | B44: =C41 -> 4
A45: α | B45: 0.05 | C45: (el más usado en tesis)
A46: valor critico | B46: =CHIINV(B45,B44) -> 9.487729
A47: p valor | B47: =_xlfn.CHISQ.DIST.RT(B35, B44) -> 3.7549036e-06
A49: Interpretacion
A51: H0 Hipotesis Nula | B51: No existe relación entre los grupos y la variable
A52: H1 Hipotesis Alternativa | B52: Si existe relación entre los grupos y la variable
A54: si p valor < α ---> Se rechaza la hipotesis Nula
A55: α nivel de significancia | B55: =B45 -> 0.05
A56: p valor | B56: =B47 -> 3.7549036e-06
A58: Si chi cuadrado > valor critico ---> Se rechaza la hipotesis nula
A59: Chi Cuadrado | B59: =B35 -> 30.565083
...

Sheet Comprensión contenidos
A1: Tabla Valores Observados
A2: Grupo / Categoría | B2: a) Siempre | C2: b) Muchas veces | D2: c) A veces | E2: d) Pocas veces | F2: e) Nunca | G2: Total
A3: Grupo Control - Post Test | B3: 20 | C3: 22 | D3: 27 | E3: 14 | F3: 10 | G3: =SUM(B3:F3) -> 93
A4: Grupo Experimental - Post Test | B4: 39 | C4: 23 | D4: 21 | E4: 7 | F4: 3 | G4: =SUM(B4:F4) -> 93
A5: Total | B5: =SUM(B3:B4) -> 59 | C5: =SUM(C3:C4) -> 45 | D5: =SUM(D3:D4) -> 48 | E5: =SUM(E3:E4) -> 21 | F5: =SUM(F3:F4) -> 13 | G5: =SUM(G3:G4) -> 186
A7: Tabla Valores Esperados
A11: Categoria | B11: =B2 -> a) Siempre | C11: =C2 -> b) Muchas veces | D11: =D2 -> c) A veces | E11: =E2 -> d) Pocas veces | F11: =F2 -> e) Nunca | G11: =G2 -> Total
A12: =A3 -> Grupo Control - Post Test | B12: =(G3*B5)/G5 -> 29.5 | C12: =(G3*C5)/G5 -> 22.5 | D12: =(G3*D5)/G5 -> 24 | E12: =(G3*E5)/G5 -> 10.5 | F12: =(G3*F5)/G5 -> 6.5 | G12: =SUM(B12:F12) -> 93
A13: =A4 -> Grupo Experimental - Post Test | B13: =(G4*B5)/G5 -> 29.5 | C13: =(G4*C5)/G5 -> 22.5 | D13: =(G4*D5)/G5 -> 24 | E13: =(G4*E5)/G5 -> 10.5 | F13: =(G4*F5)/G5 -> 6.5 | G13: =SUM(B13:F13) -> 93
A16: Tabla completa Valores Observados (O) y Valores Esperados (E)
A18: Grupo | B18: Categoria | C18: Valor Observado (O) | D18: Valor Esperado (E )
A19: =A3 -> Grupo Control - Post Test | B19: =B2 -> a) Siempre | C19: =B3 -> 20 | D19: =B12 -> 29.5 | E19: =(C19-D19)^2 -> 90.25 | F19: =E19/D19 -> 3.059322
A20: =A3 -> Grupo Control - Post Test | B20: =C2 -> b) Muchas veces | C20: =C3 -> 22 | D20: =C12 -> 22.5 | E20: =(C20-D20)^2 -> 0.25 | F20: =E20/D20 -> 0.011111111
A21: =A3 -> Grupo Control - Post Test | B21: =D2 -> c) A veces | C21: =D3 -> 27 | D21: =D12 -> 24 | E21: =(C21-D21)^2 -> 9 | F21: =E21/D21 -> 0.375
A22: =A3 -> Grupo Control - Post Test | B22: =E2 -> d) Pocas veces | C22: =E3 -> 14 | D22: =E12 -> 10.5 | E22: =(C22-D22)^2 -> 12.25 | F22: =E22/D22 -> 1.1666667
A23: =A3 -> Grupo Control - Post Test | B23: =F2 -> e) Nunca | C23: =F3 -> 10 | D23: =F12 -> 6.5 | E23: =(C23-D23)^2 -> 12.25 | F23: =E23/D23 -> 1.8846154
A24: =A4 -> Grupo Experimental - Post Test | B24: =B2 -> a) Siempre | C24: =B4 -> 39 | D24: =B13 -> 29.5 | E24: =(C24-D24)^2 -> 90.25 | F24: =E24/D24 -> 3.059322
A25: =A4 -> Grupo Experimental - Post Test | B25: =C2 -> b) Muchas veces | C25: =C4 -> 23 | D25: =C13 -> 22.5 | E25: =(C25-D25)^2 -> 0.25 | F25: =E25/D25 -> 0.011111111
A26: =A4 -> Grupo Experimental - Post Test | B26: =D2 -> c) A veces | C26: =D4 -> 21 | D26: =D13 -> 24 | E26: =(C26-D26)^2 -> 9 | F26: =E26/D26 -> 0.375
A27: =A4 -> Grupo Experimental - Post Test | B27: =E2 -> d) Pocas veces | C27: =E4 -> 7 | D27: =E13 -> 10.5 | E27: =(C27-D27)^2 -> 12.25 | F27: =E27/D27 -> 1.1666667
A28: =A4 -> Grupo Experimental - Post Test | B28: =F2 -> e) Nunca | C28: =F4 -> 3 | D28: =F13 -> 6.5 | E28: =(C28-D28)^2 -> 12.25 | F28: =E28/D28 -> 1.8846154
A31: Calculo Chi Cuadrado
A35: Chi Cuadrado | B35: =SUM(F19:F28) -> 12.99343
A37: Calculo Grados Libertad
A39: Filas = 2 (Sin sistema, Con sistema) | C39: 2
A40: Columnas = 5 (las 5 categorías) | C40: 5
A41: Grados de libertad df | C41: =(C39-1)*(C40-1) -> 4
A43: Busqueda de Valor Critico en Tabla Chi Cuadrado
A44: df | B44: =C41 -> 4
A45: α | B45: 0.05 | C45: (el más usado en tesis)
A46: valor critico | B46: =CHIINV(B45,B44) -> 9.487729
A47: p valor | B47: =_xlfn.CHISQ.DIST.RT(B35, B44) -> 0.011307939
A49: Interpretacion
A51: H0 Hipotesis Nula | B51: No existe relación entre los grupos y la variable
A52: H1 Hipotesis Alternativa | B52: Si existe relación entre los grupos y la variable
A54: si p valor < α ---> Se rechaza la hipotesis Nula
A55: α nivel de significancia | B55: =B45 -> 0.05
A56: p valor | B56: =B47 -> 0.011307939
A58: Si chi cuadrado > valor critico ---> Se rechaza la hipotesis nula
A59: Chi Cuadrado | B59: =B35 -> 12.99343
...

Sheet Herramientas-tecnológicas
A1: Tabla Valores Observados
A2: Grupo / Categoría | B2: a) Siempre | C2: b) Frecuente | D2: c) A veces | E2: d) Raro | F2: e) Nunca | G2: Total
A3: Grupo Control - Post Test | B3: 20 | C3: 19 | D3: 34 | E3: 15 | F3: 5 | G3: =SUM(B3:F3) -> 93
A4: Grupo Experimental - Post Test | B4: 34 | C4: 31 | D4: 16 | E4: 6 | F4: 6 | G4: =SUM(B4:F4) -> 93
A5: Total | B5: =SUM(B3:B4) -> 54 | C5: =SUM(C3:C4) -> 50 | D5: =SUM(D3:D4) -> 50 | E5: =SUM(E3:E4) -> 21 | F5: =SUM(F3:F4) -> 11 | G5: =SUM(G3:G4) -> 186
A7: Tabla Valores Esperados
A11: Categoria | B11: =B2 -> a) Siempre | C11: =C2 -> b) Frecuente | D11: =D2 -> c) A veces | E11: =E2 -> d) Raro | F11: =F2 -> e) Nunca | G11: =G2 -> Total
A12: =A3 -> Grupo Control - Post Test | B12: =(G3*B5)/G5 -> 27 | C12: =(G3*C5)/G5 -> 25 | D12: =(G3*D5)/G5 -> 25 | E12: =(G3*E5)/G5 -> 10.5 | F12: =(G3*F5)/G5 -> 5.5 | G12: =SUM(B12:F12) -> 93
A13: =A4 -> Grupo Experimental - Post Test | B13: =(G4*B5)/G5 -> 27 | C13: =(G4*C5)/G5 -> 25 | D13: =(G4*D5)/G5 -> 25 | E13: =(G4*E5)/G5 -> 10.5 | F13: =(G4*F5)/G5 -> 5.5 | G13: =SUM(B13:F13) -> 93
A16: Tabla completa Valores Observados (O) y Valores Esperados (E)
A18: Grupo | B18: Categoria | C18: Valor Observado (O) | D18: Valor Esperado (E )
A19: =A3 -> Grupo Control - Post Test | B19: =B2 -> a) Siempre | C19: =B3 -> 20 | D19: =B12 -> 27 | E19: =(C19-D19)^2 -> 49 | F19: =E19/D19 -> 1.8148148
A20: =A3 -> Grupo Control - Post Test | B20: =C2 -> b) Frecuente | C20: =C3 -> 19 | D20: =C12 -> 25 | E20: =(C20-D20)^2 -> 36 | F20: =E20/D20 -> 1.44
A21: =A3 -> Grupo Control - Post Test | B21: =D2 -> c) A veces | C21: =D3 -> 34 | D21: =D12 -> 25 | E21: =(C21-D21)^2 -> 81 | F21: =E21/D21 -> 3.24
A22: =A3 -> Grupo Control - Post Test | B22: =E2 -> d) Raro | C22: =E3 -> 15 | D22: =E12 -> 10.5 | E22: =(C22-D22)^2 -> 20.25 | F22: =E22/D22 -> 1.9285714
A23: =A3 -> Grupo Control - Post Test | B23: =F2 -> e) Nunca | C23: =F3 -> 5 | D23: =F12 -> 5.5 | E23: =(C23-D23)^2 -> 0.25 | F23: =E23/D23 -> 0.045454545
A24: =A4 -> Grupo Experimental - Post Test | B24: =B2 -> a) Siempre | C24: =B4 -> 34 | D24: =B13 -> 27 | E24: =(C24-D24)^2 -> 49 | F24: =E24/D24 -> 1.8148148
A25: =A4 -> Grupo Experimental - Post Test | B25: =C2 -> b) Frecuente | C25: =C4 -> 31 | D25: =C13 -> 25 | E25: =(C25-D25)^2 -> 36 | F25: =E25/D25 -> 1.44
A26: =A4 -> Grupo Experimental - Post Test | B26: =D2 -> c) A veces | C26: =D4 -> 16 | D26: =D13 -> 25 | E26: =(C26-D26)^2 -> 81 | F26: =E26/D26 -> 3.24
A27: =A4 -> Grupo Experimental - Post Test | B27: =E2 -> d) Raro | C27: =E4 -> 6 | D27: =E13 -> 10.5 | E27: =(C27-D27)^2 -> 20.25 | F27: =E27/D27 -> 1.9285714
A28: =A4 -> Grupo Experimental - Post Test | B28: =F2 -> e) Nunca | C28: =F4 -> 6 | D28: =F13 -> 5.5 | E28: =(C28-D28)^2 -> 0.25 | F28: =E28/D28 -> 0.045454545
A31: Calculo Chi Cuadrado
A35: Chi Cuadrado | B35: =SUM(F19:F28) -> 16.937682
A37: Calculo Grados Libertad
A39: Filas = 2 (Sin sistema, Con sistema) | C39: 2
A40: Columnas = 5 (las 5 categorías) | C40: 5
A41: Grados de libertad df | C41: =(C39-1)*(C40-1) -> 4
A43: Busqueda de Valor Critico en Tabla Chi Cuadrado
A44: df | B44: =C41 -> 4
A45: α | B45: 0.05 | C45: (el más usado en tesis)
A46: valor critico | B46: =CHIINV(B45,B44) -> 9.487729
A47: p valor | B47: =_xlfn.CHISQ.DIST.RT(B35, B44) -> 0.0019875863
A49: Interpretacion
A51: H0 Hipotesis Nula | B51: No existe relación entre los grupos y la variable
A52: H1 Hipotesis Alternativa | B52: Si existe relación entre los grupos y la variable
A54: si p valor < α ---> Se rechaza la hipotesis Nula
A55: α nivel de significancia | B55: =B45 -> 0.05
A56: p valor | B56: =B47 -> 0.0019875863
A58: Si chi cuadrado > valor critico ---> Se rechaza la hipotesis nula
A59: Chi Cuadrado | B59: =B35 -> 16.937682
...

Sheet Recursos-tecnológicos
A1: Tabla Valores Observados
A2: Grupo / Categoría | B2: a) Siempre | C2: b) Muchas veces | D2: c) A veces | E2: d) Pocas veces | F2: e) Nunca | G2: Total
A3: Grupo Control - Post Test | B3: 21 | C3: 20 | D3: 29 | E3: 13 | F3: 10 | G3: =SUM(B3:F3) -> 93
A4: Grupo Experimental - Post Test | B4: 45 | C4: 27 | D4: 17 | E4: 4 | F4: 0 | G4: =SUM(B4:F4) -> 93
A5: Total | B5: =SUM(B3:B4) -> 66 | C5: =SUM(C3:C4) -> 47 | D5: =SUM(D3:D4) -> 46 | E5: =SUM(E3:E4) -> 17 | F5: =SUM(F3:F4) -> 10 | G5: =SUM(G3:G4) -> 186
A7: Tabla Valores Esperados
A11: Categoria | B11: =B2 -> a) Siempre | C11: =C2 -> b) Muchas veces | D11: =D2 -> c) A veces | E11: =E2 -> d) Pocas veces | F11: =F2 -> e) Nunca | G11: =G2 -> Total
A12: =A3 -> Grupo Control - Post Test | B12: =(G3*B5)/G5 -> 33 | C12: =(G3*C5)/G5 -> 23.5 | D12: =(G3*D5)/G5 -> 23 | E12: =(G3*E5)/G5 -> 8.5 | F12: =(G3*F5)/G5 -> 5 | G12: =SUM(B12:F12) -> 93
A13: =A4 -> Grupo Experimental - Post Test | B13: =(G4*B5)/G5 -> 33 | C13: =(G4*C5)/G5 -> 23.5 | D13: =(G4*D5)/G5 -> 23 | E13: =(G4*E5)/G5 -> 8.5 | F13: =(G4*F5)/G5 -> 5 | G13: =SUM(B13:F13) -> 93
A16: Tabla completa Valores Observados (O) y Valores Esperados (E)
A18: Grupo | B18: Categoria | C18: Valor Observado (O) | D18: Valor Esperado (E )
A19: =A3 -> Grupo Control - Post Test | B19: =B2 -> a) Siempre | C19: =B3 -> 21 | D19: =B12 -> 33 | E19: =(C19-D19)^2 -> 144 | F19: =E19/D19 -> 4.3636364
A20: =A3 -> Grupo Control - Post Test | B20: =C2 -> b) Muchas veces | C20: =C3 -> 20 | D20: =C12 -> 23.5 | E20: =(C20-D20)^2 -> 12.25 | F20: =E20/D20 -> 0.5212766
A21: =A3 -> Grupo Control - Post Test | B21: =D2 -> c) A veces | C21: =D3 -> 29 | D21: =D12 -> 23 | E21: =(C21-D21)^2 -> 36 | F21: =E21/D21 -> 1.5652174
A22: =A3 -> Grupo Control - Post Test | B22: =E2 -> d) Pocas veces | C22: =E3 -> 13 | D22: =E12 -> 8.5 | E22: =(C22-D22)^2 -> 20.25 | F22: =E22/D22 -> 2.3823529
A23: =A3 -> Grupo Control - Post Test | B23: =F2 -> e) Nunca | C23: =F3 -> 10 | D23: =F12 -> 5 | E23: =(C23-D23)^2 -> 25 | F23: =E23/D23 -> 5
A24: =A4 -> Grupo Experimental - Post Test | B24: =B2 -> a) Siempre | C24: =B4 -> 45 | D24: =B13 -> 33 | E24: =(C24-D24)^2 -> 144 | F24: =E24/D24 -> 4.3636364
A25: =A4 -> Grupo Experimental - Post Test | B25: =C2 -> b) Muchas veces | C25: =C4 -> 27 | D25: =C13 -> 23.5 | E25: =(C25-D25)^2 -> 12.25 | F25: =E25/D25 -> 0.5212766
A26: =A4 -> Grupo Experimental - Post Test | B26: =D2 -> c) A veces | C26: =D4 -> 17 | D26: =D13 -> 23 | E26: =(C26-D26)^2 -> 36 | F26: =E26/D26 -> 1.5652174
A27: =A4 -> Grupo Experimental - Post Test | B27: =E2 -> d) Pocas veces | C27: =E4 -> 4 | D27: =E13 -> 8.5 | E27: =(C27-D27)^2 -> 20.25 | F27: =E27/D27 -> 2.3823529
A28: =A4 -> Grupo Experimental - Post Test | B28: =F2 -> e) Nunca | C28: =F4 -> 0 | D28: =F13 -> 5 | E28: =(C28-D28)^2 -> 25 | F28: =E28/D28 -> 5
A31: Calculo Chi Cuadrado
A35: Chi Cuadrado | B35: =SUM(F19:F28) -> 27.664967
A37: Calculo Grados Libertad
A39: Filas = 2 (Sin sistema, Con sistema) | C39: 2
A40: Columnas = 5 (las 5 categorías) | C40: 5
A41: Grados de libertad df | C41: =(C39-1)*(C40-1) -> 4
A43: Busqueda de Valor Critico en Tabla Chi Cuadrado
A44: df | B44: =C41 -> 4
A45: α | B45: 0.05 | C45: (el más usado en tesis)
A46: valor critico | B46: =CHIINV(B45,B44) -> 9.487729
A47: p valor | B47: =_xlfn.CHISQ.DIST.RT(B35, B44) -> 1.458286e-05
A49: Interpretacion
A51: H0 Hipotesis Nula | B51: No existe relación entre los grupos y la variable
A52: H1 Hipotesis Alternativa | B52: Si existe relación entre los grupos y la variable
A54: si p valor < α ---> Se rechaza la hipotesis Nula
A55: α nivel de significancia | B55: =B45 -> 0.05
A56: p valor | B56: =B47 -> 1.458286e-05
A58: Si chi cuadrado > valor critico ---> Se rechaza la hipotesis nula
A59: Chi Cuadrado | B59: =B35 -> 27.664967
...

Sheet Percepción-evaluaciones
A1: Tabla Valores Observados
A2: Grupo / Categoría | B2: a) Siempre | C2: b) Frecuente | D2: c) A veces | E2: d) Raro | F2: e) Nunca | G2: Total
A3: Grupo Control - Post Test | B3: 12 | C3: 33 | D3: 31 | E3: 14 | F3: 3 | G3: =SUM(B3:F3) -> 93
A4: Grupo Experimental - Post Test | B4: 39 | C4: 27 | D4: 16 | E4: 9 | F4: 2 | G4: =SUM(B4:F4) -> 93
A5: Total | B5: =SUM(B3:B4) -> 51 | C5: =SUM(C3:C4) -> 60 | D5: =SUM(D3:D4) -> 47 | E5: =SUM(E3:E4) -> 23 | F5: =SUM(F3:F4) -> 5 | G5: =SUM(G3:G4) -> 186
A7: Tabla Valores Esperados
A11: Categoria | B11: =B2 -> a) Siempre | C11: =C2 -> b) Frecuente | D11: =D2 -> c) A veces | E11: =E2 -> d) Raro | F11: =F2 -> e) Nunca | G11: =G2 -> Total
A12: =A3 -> Grupo Control - Post Test | B12: =(G3*B5)/G5 -> 25.5 | C12: =(G3*C5)/G5 -> 30 | D12: =(G3*D5)/G5 -> 23.5 | E12: =(G3*E5)/G5 -> 11.5 | F12: =(G3*F5)/G5 -> 2.5 | G12: =SUM(B12:F12) -> 93
A13: =A4 -> Grupo Experimental - Post Test | B13: =(G4*B5)/G5 -> 25.5 | C13: =(G4*C5)/G5 -> 30 | D13: =(G4*D5)/G5 -> 23.5 | E13: =(G4*E5)/G5 -> 11.5 | F13: =(G4*F5)/G5 -> 2.5 | G13: =SUM(B13:F13) -> 93
A16: Tabla completa Valores Observados (O) y Valores Esperados (E)
A18: Grupo | B18: Categoria | C18: Valor Observado (O) | D18: Valor Esperado (E )
A19: =A3 -> Grupo Control - Post Test | B19: =B2 -> a) Siempre | C19: =B3 -> 12 | D19: =B12 -> 25.5 | E19: =(C19-D19)^2 -> 182.25 | F19: =E19/D19 -> 7.1470588
A20: =A3 -> Grupo Control - Post Test | B20: =C2 -> b) Frecuente | C20: =C3 -> 33 | D20: =C12 -> 30 | E20: =(C20-D20)^2 -> 9 | F20: =E20/D20 -> 0.3
A21: =A3 -> Grupo Control - Post Test | B21: =D2 -> c) A veces | C21: =D3 -> 31 | D21: =D12 -> 23.5 | E21: =(C21-D21)^2 -> 56.25 | F21: =E21/D21 -> 2.393617
A22: =A3 -> Grupo Control - Post Test | B22: =E2 -> d) Raro | C22: =E3 -> 14 | D22: =E12 -> 11.5 | E22: =(C22-D22)^2 -> 6.25 | F22: =E22/D22 -> 0.54347826
A23: =A3 -> Grupo Control - Post Test | B23: =F2 -> e) Nunca | C23: =F3 -> 3 | D23: =F12 -> 2.5 | E23: =(C23-D23)^2 -> 0.25 | F23: =E23/D23 -> 0.1
A24: =A4 -> Grupo Experimental - Post Test | B24: =B2 -> a) Siempre | C24: =B4 -> 39 | D24: =B13 -> 25.5 | E24: =(C24-D24)^2 -> 182.25 | F24: =E24/D24 -> 7.1470588
A25: =A4 -> Grupo Experimental - Post Test | B25: =C2 -> b) Frecuente | C25: =C4 -> 27 | D25: =C13 -> 30 | E25: =(C25-D25)^2 -> 9 | F25: =E25/D25 -> 0.3
A26: =A4 -> Grupo Experimental - Post Test | B26: =D2 -> c) A veces | C26: =D4 -> 16 | D26: =D13 -> 23.5 | E26: =(C26-D26)^2 -> 56.25 | F26: =E26/D26 -> 2.393617
A27: =A4 -> Grupo Experimental - Post Test | B27: =E2 -> d) Raro | C27: =E4 -> 9 | D27: =E13 -> 11.5 | E27: =(C27-D27)^2 -> 6.25 | F27: =E27/D27 -> 0.54347826
A28: =A4 -> Grupo Experimental - Post Test | B28: =F2 -> e) Nunca | C28: =F4 -> 2 | D28: =F13 -> 2.5 | E28: =(C28-D28)^2 -> 0.25 | F28: =E28/D28 -> 0.1
A31: Calculo Chi Cuadrado
A35: Chi Cuadrado | B35: =SUM(F19:F28) -> 20.968308
A37: Calculo Grados Libertad
A39: Filas = 2 (Sin sistema, Con sistema) | C39: 2
A40: Columnas = 5 (las 5 categorías) | C40: 5
A41: Grados de libertad df | C41: =(C39-1)*(C40-1) -> 4
A43: Busqueda de Valor Critico en Tabla Chi Cuadrado
A44: df | B44: =C41 -> 4
A45: α | B45: 0.05 | C45: (el más usado en tesis)
A46: valor critico | B46: =CHIINV(B45,B44) -> 9.487729
A47: p valor | B47: =_xlfn.CHISQ.DIST.RT(B35, B44) -> 0.00032128373
A49: Interpretacion
A51: H0 Hipotesis Nula | B51: No existe relación entre los grupos y la variable
A52: H1 Hipotesis Alternativa | B52: Si existe relación entre los grupos y la variable
A54: si p valor < α ---> Se rechaza la hipotesis Nula
A55: α nivel de significancia | B55: =B45 -> 0.05
A56: p valor | B56: =B47 -> 0.00032128373
A58: Si chi cuadrado > valor critico ---> Se rechaza la hipotesis nula
A59: Chi Cuadrado | B59: =B35 -> 20.968308
...

Sheet Retroalimentación-oportuna
A1: Tabla Valores Observados
A2: Grupo / Categoría | B2: a) Siempre | C2: b) Muchas veces | D2: c) A veces | E2: d) Pocas veces | F2: e) Nunca | G2: Total
A3: Grupo Control - Post Test | B3: 17 | C3: 24 | D3: 34 | E3: 8 | F3: 10 | G3: =SUM(B3:F3) -> 93
A4: Grupo Experimental - Post Test | B4: 39 | C4: 34 | D4: 16 | E4: 4 | F4: 0 | G4: =SUM(B4:F4) -> 93
A5: Total | B5: =SUM(B3:B4) -> 56 | C5: =SUM(C3:C4) -> 58 | D5: =SUM(D3:D4) -> 50 | E5: =SUM(E3:E4) -> 12 | F5: =SUM(F3:F4) -> 10 | G5: =SUM(G3:G4) -> 186
A7: Tabla Valores Esperados
A11: Categoria | B11: =B2 -> a) Siempre | C11: =C2 -> b) Muchas veces | D11: =D2 -> c) A veces | E11: =E2 -> d) Pocas veces | F11: =F2 -> e) Nunca | G11: =G2 -> Total
A12: =A3 -> Grupo Control - Post Test | B12: =(G3*B5)/G5 -> 28 | C12: =(G3*C5)/G5 -> 29 | D12: =(G3*D5)/G5 -> 25 | E12: =(G3*E5)/G5 -> 6 | F12: =(G3*F5)/G5 -> 5 | G12: =SUM(B12:F12) -> 93
A13: =A4 -> Grupo Experimental - Post Test | B13: =(G4*B5)/G5 -> 28 | C13: =(G4*C5)/G5 -> 29 | D13: =(G4*D5)/G5 -> 25 | E13: =(G4*E5)/G5 -> 6 | F13: =(G4*F5)/G5 -> 5 | G13: =SUM(B13:F13) -> 93
A16: Tabla completa Valores Observados (O) y Valores Esperados (E)
A18: Grupo | B18: Categoria | C18: Valor Observado (O) | D18: Valor Esperado (E )
A19: =A3 -> Grupo Control - Post Test | B19: =B2 -> a) Siempre | C19: =B3 -> 17 | D19: =B12 -> 28 | E19: =(C19-D19)^2 -> 121 | F19: =E19/D19 -> 4.3214286
A20: =A3 -> Grupo Control - Post Test | B20: =C2 -> b) Muchas veces | C20: =C3 -> 24 | D20: =C12 -> 29 | E20: =(C20-D20)^2 -> 25 | F20: =E20/D20 -> 0.86206897
A21: =A3 -> Grupo Control - Post Test | B21: =D2 -> c) A veces | C21: =D3 -> 34 | D21: =D12 -> 25 | E21: =(C21-D21)^2 -> 81 | F21: =E21/D21 -> 3.24
A22: =A3 -> Grupo Control - Post Test | B22: =E2 -> d) Pocas veces | C22: =E3 -> 8 | D22: =E12 -> 6 | E22: =(C22-D22)^2 -> 4 | F22: =E22/D22 -> 0.66666667
A23: =A3 -> Grupo Control - Post Test | B23: =F2 -> e) Nunca | C23: =F3 -> 10 | D23: =F12 -> 5 | E23: =(C23-D23)^2 -> 25 | F23: =E23/D23 -> 5
A24: =A4 -> Grupo Experimental - Post Test | B24: =B2 -> a) Siempre | C24: =B4 -> 39 | D24: =B13 -> 28 | E24: =(C24-D24)^2 -> 121 | F24: =E24/D24 -> 4.3214286
A25: =A4 -> Grupo Experimental - Post Test | B25: =C2 -> b) Muchas veces | C25: =C4 -> 34 | D25: =C13 -> 29 | E25: =(C25-D25)^2 -> 25 | F25: =E25/D25 -> 0.86206897
A26: =A4 -> Grupo Experimental - Post Test | B26: =D2 -> c) A veces | C26: =D4 -> 16 | D26: =D13 -> 25 | E26: =(C26-D26)^2 -> 81 | F26: =E26/D26 -> 3.24
A27: =A4 -> Grupo Experimental - Post Test | B27: =E2 -> d) Pocas veces | C27: =E4 -> 4 | D27: =E13 -> 6 | E27: =(C27-D27)^2 -> 4 | F27: =E27/D27 -> 0.66666667
A28: =A4 -> Grupo Experimental - Post Test | B28: =F2 -> e) Nunca | C28: =F4 -> 0 | D28: =F13 -> 5 | E28: =(C28-D28)^2 -> 25 | F28: =E28/D28 -> 5
A31: Calculo Chi Cuadrado
A35: Chi Cuadrado | B35: =SUM(F19:F28) -> 28.180328
A37: Calculo Grados Libertad
A39: Filas = 2 (Sin sistema, Con sistema) | C39: 2
A40: Columnas = 5 (las 5 categorías) | C40: 5
A41: Grados de libertad df | C41: =(C39-1)*(C40-1) -> 4
A43: Busqueda de Valor Critico en Tabla Chi Cuadrado
A44: df | B44: =C41 -> 4
A45: α | B45: 0.05 | C45: (el más usado en tesis)
A46: valor critico | B46: =CHIINV(B45,B44) -> 9.487729
A47: p valor | B47: =_xlfn.CHISQ.DIST.RT(B35, B44) -> 1.1466039e-05
A49: Interpretacion
A51: H0 Hipotesis Nula | B51: No existe relación entre los grupos y la variable
A52: H1 Hipotesis Alternativa | B52: Si existe relación entre los grupos y la variable
A54: si p valor < α ---> Se rechaza la hipotesis Nula
A55: α nivel de significancia | B55: =B45 -> 0.05
A56: p valor | B56: =B47 -> 1.1466039e-05
A58: Si chi cuadrado > valor critico ---> Se rechaza la hipotesis nula
A59: Chi Cuadrado | B59: =B35 -> 28.180328
...

Sheet Calificación
A1: Tabla Valores Observados
A2: Grupo / Categoría | B2: a) 81 - 100 | C2: b) 61 – 80 | D2: c) 41 - 60 | E2: d) 21 - 40 | F2: e) 0 - 20 | G2: Total
A3: Grupo Control - Post Test | B3: 22 | C3: 25 | D3: 24 | E3: 14 | F3: 8 | G3: =SUM(B3:F3) -> 93
A4: Grupo Experimental - Post Test | B4: 41 | C4: 29 | D4: 18 | E4: 5 | F4: 0 | G4: =SUM(B4:F4) -> 93
A5: Total | B5: =SUM(B3:B4) -> 63 | C5: =SUM(C3:C4) -> 54 | D5: =SUM(D3:D4) -> 42 | E5: =SUM(E3:E4) -> 19 | F5: =SUM(F3:F4) -> 8 | G5: =SUM(G3:G4) -> 186
A7: Tabla Valores Esperados
A11: Categoria | B11: =B2 -> a) 81 - 100 | C11: =C2 -> b) 61 – 80 | D11: =D2 -> c) 41 - 60 | E11: =E2 -> d) 21 - 40 | F11: =F2 -> e) 0 - 20 | G11: =G2 -> Total
A12: =A3 -> Grupo Control - Post Test | B12: =(G3*B5)/G5 -> 31.5 | C12: =(G3*C5)/G5 -> 27 | D12: =(G3*D5)/G5 -> 21 | E12: =(G3*E5)/G5 -> 9.5 | F12: =(G3*F5)/G5 -> 4 | G12: =SUM(B12:F12) -> 93
A13: =A4 -> Grupo Experimental - Post Test | B13: =(G4*B5)/G5 -> 31.5 | C13: =(G4*C5)/G5 -> 27 | D13: =(G4*D5)/G5 -> 21 | E13: =(G4*E5)/G5 -> 9.5 | F13: =(G4*F5)/G5 -> 4 | G13: =SUM(B13:F13) -> 93
A16: Tabla completa Valores Observados (O) y Valores Esperados (E)
A18: Grupo | B18: Categoria | C18: Valor Observado (O) | D18: Valor Esperado (E )
A19: =A3 -> Grupo Control - Post Test | B19: =B2 -> a) 81 - 100 | C19: =B3 -> 22 | D19: =B12 -> 31.5 | E19: =(C19-D19)^2 -> 90.25 | F19: =E19/D19 -> 2.8650794
A20: =A3 -> Grupo Control - Post Test | B20: =C2 -> b) 61 – 80 | C20: =C3 -> 25 | D20: =C12 -> 27 | E20: =(C20-D20)^2 -> 4 | F20: =E20/D20 -> 0.14814815
A21: =A3 -> Grupo Control - Post Test | B21: =D2 -> c) 41 - 60 | C21: =D3 -> 24 | D21: =D12 -> 21 | E21: =(C21-D21)^2 -> 9 | F21: =E21/D21 -> 0.42857143
A22: =A3 -> Grupo Control - Post Test | B22: =E2 -> d) 21 - 40 | C22: =E3 -> 14 | D22: =E12 -> 9.5 | E22: =(C22-D22)^2 -> 20.25 | F22: =E22/D22 -> 2.1315789
A23: =A3 -> Grupo Control - Post Test | B23: =F2 -> e) 0 - 20 | C23: =F3 -> 8 | D23: =F12 -> 4 | E23: =(C23-D23)^2 -> 16 | F23: =E23/D23 -> 4
A24: =A4 -> Grupo Experimental - Post Test | B24: =B2 -> a) 81 - 100 | C24: =B4 -> 41 | D24: =B13 -> 31.5 | E24: =(C24-D24)^2 -> 90.25 | F24: =E24/D24 -> 2.8650794
A25: =A4 -> Grupo Experimental - Post Test | B25: =C2 -> b) 61 – 80 | C25: =C4 -> 29 | D25: =C13 -> 27 | E25: =(C25-D25)^2 -> 4 | F25: =E25/D25 -> 0.14814815
A26: =A4 -> Grupo Experimental - Post Test | B26: =D2 -> c) 41 - 60 | C26: =D4 -> 18 | D26: =D13 -> 21 | E26: =(C26-D26)^2 -> 9 | F26: =E26/D26 -> 0.42857143
A27: =A4 -> Grupo Experimental - Post Test | B27: =E2 -> d) 21 - 40 | C27: =E4 -> 5 | D27: =E13 -> 9.5 | E27: =(C27-D27)^2 -> 20.25 | F27: =E27/D27 -> 2.1315789
A28: =A4 -> Grupo Experimental - Post Test | B28: =F2 -> e) 0 - 20 | C28: =F4 -> 0 | D28: =F13 -> 4 | E28: =(C28-D28)^2 -> 16 | F28: =E28/D28 -> 4
A31: Calculo Chi Cuadrado
A35: Chi Cuadrado | B35: =SUM(F19:F28) -> 19.146756
A37: Calculo Grados Libertad
A39: Filas = 2 (Sin sistema, Con sistema) | C39: 2
A40: Columnas = 5 (las 5 categorías) | C40: 5
A41: Grados de libertad df | C41: =(C39-1)*(C40-1) -> 4
A43: Busqueda de Valor Critico en Tabla Chi Cuadrado
A44: df | B44: =C41 -> 4
A45: α | B45: 0.05 | C45: (el más usado en tesis)
A46: valor critico | B46: =CHIINV(B45,B44) -> 9.487729
A47: p valor | B47: =_xlfn.CHISQ.DIST.RT(B35, B44) -> 0.00073544223
A49: Interpretacion
A51: H0 Hipotesis Nula | B51: No existe relación entre los grupos y la variable
A52: H1 Hipotesis Alternativa | B52: Si existe relación entre los grupos y la variable
A54: si p valor < α ---> Se rechaza la hipotesis Nula
A55: α nivel de significancia | B55: =B45 -> 0.05
A56: p valor | B56: =B47 -> 0.00073544223
A58: Si chi cuadrado > valor critico ---> Se rechaza la hipotesis nula
A59: Chi Cuadrado | B59: =B35 -> 19.146756
...

Sheet Nivel-comprensión
A1: Tabla Valores Observados
A2: Grupo / Categoría | B2: a) Muy Bueno | C2: b) bueno | D2: c) Regular | E2: d) Malo | F2: e) Muy malo | G2: Total
A3: Grupo Control - Post Test | B3: 15 | C3: 23 | D3: 34 | E3: 15 | F3: 6 | G3: =SUM(B3:F3) -> 93
A4: Grupo Experimental - Post Test | B4: 51 | C4: 22 | D4: 14 | E4: 4 | F4: 2 | G4: =SUM(B4:F4) -> 93
A5: Total | B5: =SUM(B3:B4) -> 66 | C5: =SUM(C3:C4) -> 45 | D5: =SUM(D3:D4) -> 48 | E5: =SUM(E3:E4) -> 19 | F5: =SUM(F3:F4) -> 8 | G5: =SUM(G3:G4) -> 186
A7: Tabla Valores Esperados
A11: Categoria | B11: =B2 -> a) Muy Bueno | C11: =C2 -> b) bueno | D11: =D2 -> c) Regular | E11: =E2 -> d) Malo | F11: =F2 -> e) Muy malo | G11: =G2 -> Total
A12: =A3 -> Grupo Control - Post Test | B12: =(G3*B5)/G5 -> 33 | C12: =(G3*C5)/G5 -> 22.5 | D12: =(G3*D5)/G5 -> 24 | E12: =(G3*E5)/G5 -> 9.5 | F12: =(G3*F5)/G5 -> 4 | G12: =SUM(B12:F12) -> 93
A13: =A4 -> Grupo Experimental - Post Test | B13: =(G4*B5)/G5 -> 33 | C13: =(G4*C5)/G5 -> 22.5 | D13: =(G4*D5)/G5 -> 24 | E13: =(G4*E5)/G5 -> 9.5 | F13: =(G4*F5)/G5 -> 4 | G13: =SUM(B13:F13) -> 93
A16: Tabla completa Valores Observados (O) y Valores Esperados (E)
A18: Grupo | B18: Categoria | C18: Valor Observado (O) | D18: Valor Esperado (E )
A19: =A3 -> Grupo Control - Post Test | B19: =B2 -> a) Muy Bueno | C19: =B3 -> 15 | D19: =B12 -> 33 | E19: =(C19-D19)^2 -> 324 | F19: =E19/D19 -> 9.8181818
A20: =A3 -> Grupo Control - Post Test | B20: =C2 -> b) bueno | C20: =C3 -> 23 | D20: =C12 -> 22.5 | E20: =(C20-D20)^2 -> 0.25 | F20: =E20/D20 -> 0.011111111
A21: =A3 -> Grupo Control - Post Test | B21: =D2 -> c) Regular | C21: =D3 -> 34 | D21: =D12 -> 24 | E21: =(C21-D21)^2 -> 100 | F21: =E21/D21 -> 4.1666667
A22: =A3 -> Grupo Control - Post Test | B22: =E2 -> d) Malo | C22: =E3 -> 15 | D22: =E12 -> 9.5 | E22: =(C22-D22)^2 -> 30.25 | F22: =E22/D22 -> 3.1842105
A23: =A3 -> Grupo Control - Post Test | B23: =F2 -> e) Muy malo | C23: =F3 -> 6 | D23: =F12 -> 4 | E23: =(C23-D23)^2 -> 4 | F23: =E23/D23 -> 1
A24: =A4 -> Grupo Experimental - Post Test | B24: =B2 -> a) Muy Bueno | C24: =B4 -> 51 | D24: =B13 -> 33 | E24: =(C24-D24)^2 -> 324 | F24: =E24/D24 -> 9.8181818
A25: =A4 -> Grupo Experimental - Post Test | B25: =C2 -> b) bueno | C25: =C4 -> 22 | D25: =C13 -> 22.5 | E25: =(C25-D25)^2 -> 0.25 | F25: =E25/D25 -> 0.011111111
A26: =A4 -> Grupo Experimental - Post Test | B26: =D2 -> c) Regular | C26: =D4 -> 14 | D26: =D13 -> 24 | E26: =(C26-D26)^2 -> 100 | F26: =E26/D26 -> 4.1666667
A27: =A4 -> Grupo Experimental - Post Test | B27: =E2 -> d) Malo | C27: =E4 -> 4 | D27: =E13 -> 9.5 | E27: =(C27-D27)^2 -> 30.25 | F27: =E27/D27 -> 3.1842105
A28: =A4 -> Grupo Experimental - Post Test | B28: =F2 -> e) Muy malo | C28: =F4 -> 2 | D28: =F13 -> 4 | E28: =(C28-D28)^2 -> 4 | F28: =E28/D28 -> 1
A31: Calculo Chi Cuadrado
A35: Chi Cuadrado | B35: =SUM(F19:F28) -> 36.36034
A37: Calculo Grados Libertad
A39: Filas = 2 (Sin sistema, Con sistema) | C39: 2
A40: Columnas = 5 (las 5 categorías) | C40: 5
A41: Grados de libertad df | C41: =(C39-1)*(C40-1) -> 4
A43: Busqueda de Valor Critico en Tabla Chi Cuadrado
A44: df | B44: =C41 -> 4
A45: α | B45: 0.05 | C45: (el más usado en tesis)
A46: valor critico | B46: =CHIINV(B45,B44) -> 9.487729
A47: p valor | B47: =_xlfn.CHISQ.DIST.RT(B35, B44) -> 2.4395229e-07
A49: Interpretacion
A51: H0 Hipotesis Nula | B51: No existe relación entre los grupos y la variable
A52: H1 Hipotesis Alternativa | B52: Si existe relación entre los grupos y la variable
A54: si p valor < α ---> Se rechaza la hipotesis Nula
A55: α nivel de significancia | B55: =B45 -> 0.05
A56: p valor | B56: =B47 -> 2.4395229e-07
A58: Si chi cuadrado > valor critico ---> Se rechaza la hipotesis nula
A59: Chi Cuadrado | B59: =B35 -> 36.36034
...

Sheet Habilidades-tareas
A1: Tabla Valores Observados
A2: Grupo / Categoría | B2: a) Siempre | C2: b) Muchas veces | D2: c) A veces | E2: d) Pocas veces | F2: e) Nunca | G2: Total
A3: Grupo Control - Post Test | B3: 13 | C3: 23 | D3: 39 | E3: 14 | F3: 4 | G3: =SUM(B3:F3) -> 93
A4: Grupo Experimental - Post Test | B4: 37 | C4: 30 | D4: 18 | E4: 3 | F4: 5 | G4: =SUM(B4:F4) -> 93
A5: Total | B5: =SUM(B3:B4) -> 50 | C5: =SUM(C3:C4) -> 53 | D5: =SUM(D3:D4) -> 57 | E5: =SUM(E3:E4) -> 17 | F5: =SUM(F3:F4) -> 9 | G5: =SUM(G3:G4) -> 186
A7: Tabla Valores Esperados
A11: Categoria | B11: =B2 -> a) Siempre | C11: =C2 -> b) Muchas veces | D11: =D2 -> c) A veces | E11: =E2 -> d) Pocas veces | F11: =F2 -> e) Nunca | G11: =G2 -> Total
A12: =A3 -> Grupo Control - Post Test | B12: =(G3*B5)/G5 -> 25 | C12: =(G3*C5)/G5 -> 26.5 | D12: =(G3*D5)/G5 -> 28.5 | E12: =(G3*E5)/G5 -> 8.5 | F12: =(G3*F5)/G5 -> 4.5 | G12: =SUM(B12:F12) -> 93
A13: =A4 -> Grupo Experimental - Post Test | B13: =(G4*B5)/G5 -> 25 | C13: =(G4*C5)/G5 -> 26.5 | D13: =(G4*D5)/G5 -> 28.5 | E13: =(G4*E5)/G5 -> 8.5 | F13: =(G4*F5)/G5 -> 4.5 | G13: =SUM(B13:F13) -> 93
A16: Tabla completa Valores Observados (O) y Valores Esperados (E)
A18: Grupo | B18: Categoria | C18: Valor Observado (O) | D18: Valor Esperado (E )
A19: =A3 -> Grupo Control - Post Test | B19: =B2 -> a) Siempre | C19: =B3 -> 13 | D19: =B12 -> 25 | E19: =(C19-D19)^2 -> 144 | F19: =E19/D19 -> 5.76
A20: =A3 -> Grupo Control - Post Test | B20: =C2 -> b) Muchas veces | C20: =C3 -> 23 | D20: =C12 -> 26.5 | E20: =(C20-D20)^2 -> 12.25 | F20: =E20/D20 -> 0.46226415
A21: =A3 -> Grupo Control - Post Test | B21: =D2 -> c) A veces | C21: =D3 -> 39 | D21: =D12 -> 28.5 | E21: =(C21-D21)^2 -> 110.25 | F21: =E21/D21 -> 3.8684211
A22: =A3 -> Grupo Control - Post Test | B22: =E2 -> d) Pocas veces | C22: =E3 -> 14 | D22: =E12 -> 8.5 | E22: =(C22-D22)^2 -> 30.25 | F22: =E22/D22 -> 3.5588235
A23: =A3 -> Grupo Control - Post Test | B23: =F2 -> e) Nunca | C23: =F3 -> 4 | D23: =F12 -> 4.5 | E23: =(C23-D23)^2 -> 0.25 | F23: =E23/D23 -> 0.055555556
A24: =A4 -> Grupo Experimental - Post Test | B24: =B2 -> a) Siempre | C24: =B4 -> 37 | D24: =B13 -> 25 | E24: =(C24-D24)^2 -> 144 | F24: =E24/D24 -> 5.76
A25: =A4 -> Grupo Experimental - Post Test | B25: =C2 -> b) Muchas veces | C25: =C4 -> 30 | D25: =C13 -> 26.5 | E25: =(C25-D25)^2 -> 12.25 | F25: =E25/D25 -> 0.46226415
A26: =A4 -> Grupo Experimental - Post Test | B26: =D2 -> c) A veces | C26: =D4 -> 18 | D26: =D13 -> 28.5 | E26: =(C26-D26)^2 -> 110.25 | F26: =E26/D26 -> 3.8684211
A27: =A4 -> Grupo Experimental - Post Test | B27: =E2 -> d) Pocas veces | C27: =E4 -> 3 | D27: =E13 -> 8.5 | E27: =(C27-D27)^2 -> 30.25 | F27: =E27/D27 -> 3.5588235
A28: =A4 -> Grupo Experimental - Post Test | B28: =F2 -> e) Nunca | C28: =F4 -> 5 | D28: =F13 -> 4.5 | E28: =(C28-D28)^2 -> 0.25 | F28: =E28/D28 -> 0.055555556
A31: Calculo Chi Cuadrado
A35: Chi Cuadrado | B35: =SUM(F19:F28) -> 27.410129
A37: Calculo Grados Libertad
A39: Filas = 2 (Sin sistema, Con sistema) | C39: 2
A40: Columnas = 5 (las 5 categorías) | C40: 5
A41: Grados de libertad df | C41: =(C39-1)*(C40-1) -> 4
A43: Busqueda de Valor Critico en Tabla Chi Cuadrado
A44: df | B44: =C41 -> 4
A45: α | B45: 0.05 | C45: (el más usado en tesis)
A46: valor critico | B46: =CHIINV(B45,B44) -> 9.487729
A47: p valor | B47: =_xlfn.CHISQ.DIST.RT(B35, B44) -> 1.6422268e-05
A49: Interpretacion
A51: H0 Hipotesis Nula | B51: No existe relación entre los grupos y la variable
A52: H1 Hipotesis Alternativa | B52: Si existe relación entre los grupos y la variable
A54: si p valor < α ---> Se rechaza la hipotesis Nula
A55: α nivel de significancia | B55: =B45 -> 0.05
A56: p valor | B56: =B47 -> 1.6422268e-05
A58: Si chi cuadrado > valor critico ---> Se rechaza la hipotesis nula
A59: Chi Cuadrado | B59: =B35 -> 27.410129
...

Sheet Resolución-problemas
A1: Tabla Valores Observados
A2: Grupo / Categoría | B2: a) Siempre | C2: b) Frecuente | D2: c) A veces | E2: d) Raro | F2: e) Nunca | G2: Total
A3: Grupo Control - Post Test | B3: 18 | C3: 25 | D3: 33 | E3: 10 | F3: 7 | G3: =SUM(B3:F3) -> 93
A4: Grupo Experimental - Post Test | B4: 42 | C4: 35 | D4: 10 | E4: 5 | F4: 1 | G4: =SUM(B4:F4) -> 93
A5: Total | B5: =SUM(B3:B4) -> 60 | C5: =SUM(C3:C4) -> 60 | D5: =SUM(D3:D4) -> 43 | E5: =SUM(E3:E4) -> 15 | F5: =SUM(F3:F4) -> 8 | G5: =SUM(G3:G4) -> 186
A7: Tabla Valores Esperados
A11: Categoria | B11: =B2 -> a) Siempre | C11: =C2 -> b) Frecuente | D11: =D2 -> c) A veces | E11: =E2 -> d) Raro | F11: =F2 -> e) Nunca | G11: =G2 -> Total
A12: =A3 -> Grupo Control - Post Test | B12: =(G3*B5)/G5 -> 30 | C12: =(G3*C5)/G5 -> 30 | D12: =(G3*D5)/G5 -> 21.5 | E12: =(G3*E5)/G5 -> 7.5 | F12: =(G3*F5)/G5 -> 4 | G12: =SUM(B12:F12) -> 93
A13: =A4 -> Grupo Experimental - Post Test | B13: =(G4*B5)/G5 -> 30 | C13: =(G4*C5)/G5 -> 30 | D13: =(G4*D5)/G5 -> 21.5 | E13: =(G4*E5)/G5 -> 7.5 | F13: =(G4*F5)/G5 -> 4 | G13: =SUM(B13:F13) -> 93
A16: Tabla completa Valores Observados (O) y Valores Esperados (E)
A18: Grupo | B18: Categoria | C18: Valor Observado (O) | D18: Valor Esperado (E )
A19: =A3 -> Grupo Control - Post Test | B19: =B2 -> a) Siempre | C19: =B3 -> 18 | D19: =B12 -> 30 | E19: =(C19-D19)^2 -> 144 | F19: =E19/D19 -> 4.8
A20: =A3 -> Grupo Control - Post Test | B20: =C2 -> b) Frecuente | C20: =C3 -> 25 | D20: =C12 -> 30 | E20: =(C20-D20)^2 -> 25 | F20: =E20/D20 -> 0.83333333
A21: =A3 -> Grupo Control - Post Test | B21: =D2 -> c) A veces | C21: =D3 -> 33 | D21: =D12 -> 21.5 | E21: =(C21-D21)^2 -> 132.25 | F21: =E21/D21 -> 6.1511628
A22: =A3 -> Grupo Control - Post Test | B22: =E2 -> d) Raro | C22: =E3 -> 10 | D22: =E12 -> 7.5 | E22: =(C22-D22)^2 -> 6.25 | F22: =E22/D22 -> 0.83333333
A23: =A3 -> Grupo Control - Post Test | B23: =F2 -> e) Nunca | C23: =F3 -> 7 | D23: =F12 -> 4 | E23: =(C23-D23)^2 -> 9 | F23: =E23/D23 -> 2.25
A24: =A4 -> Grupo Experimental - Post Test | B24: =B2 -> a) Siempre | C24: =B4 -> 42 | D24: =B13 -> 30 | E24: =(C24-D24)^2 -> 144 | F24: =E24/D24 -> 4.8
A25: =A4 -> Grupo Experimental - Post Test | B25: =C2 -> b) Frecuente | C25: =C4 -> 35 | D25: =C13 -> 30 | E25: =(C25-D25)^2 -> 25 | F25: =E25/D25 -> 0.83333333
A26: =A4 -> Grupo Experimental - Post Test | B26: =D2 -> c) A veces | C26: =D4 -> 10 | D26: =D13 -> 21.5 | E26: =(C26-D26)^2 -> 132.25 | F26: =E26/D26 -> 6.1511628
A27: =A4 -> Grupo Experimental - Post Test | B27: =E2 -> d) Raro | C27: =E4 -> 5 | D27: =E13 -> 7.5 | E27: =(C27-D27)^2 -> 6.25 | F27: =E27/D27 -> 0.83333333
A28: =A4 -> Grupo Experimental - Post Test | B28: =F2 -> e) Nunca | C28: =F4 -> 1 | D28: =F13 -> 4 | E28: =(C28-D28)^2 -> 9 | F28: =E28/D28 -> 2.25
A31: Calculo Chi Cuadrado
A35: Chi Cuadrado | B35: =SUM(F19:F28) -> 29.735659
A37: Calculo Grados Libertad
A39: Filas = 2 (Sin sistema, Con sistema) | C39: 2
A40: Columnas = 5 (las 5 categorías) | C40: 5
A41: Grados de libertad df | C41: =(C39-1)*(C40-1) -> 4
A43: Busqueda de Valor Critico en Tabla Chi Cuadrado
A44: df | B44: =C41 -> 4
A45: α | B45: 0.05 | C45: (el más usado en tesis)
A46: valor critico | B46: =CHIINV(B45,B44) -> 9.487729
A47: p valor | B47: =_xlfn.CHISQ.DIST.RT(B35, B44) -> 5.5398912e-06
A49: Interpretacion
A51: H0 Hipotesis Nula | B51: No existe relación entre los grupos y la variable
A52: H1 Hipotesis Alternativa | B52: Si existe relación entre los grupos y la variable
A54: si p valor < α ---> Se rechaza la hipotesis Nula
A55: α nivel de significancia | B55: =B45 -> 0.05
A56: p valor | B56: =B47 -> 5.5398912e-06
A58: Si chi cuadrado > valor critico ---> Se rechaza la hipotesis nula
A59: Chi Cuadrado | B59: =B35 -> 29.735659
...

Sheet Motivación
A1: Tabla Valores Observados
A2: Grupo / Categoría | B2: a) Siempre | C2: b) Frecuente | D2: c) A veces | E2: d) Raro | F2: e) Nunca | G2: Total
A3: Grupo Control - Post Test | B3: 17 | C3: 23 | D3: 24 | E3: 23 | F3: 6 | G3: =SUM(B3:F3) -> 93
A4: Grupo Experimental - Post Test | B4: 40 | C4: 32 | D4: 12 | E4: 7 | F4: 2 | G4: =SUM(B4:F4) -> 93
A5: Total | B5: =SUM(B3:B4) -> 57 | C5: =SUM(C3:C4) -> 55 | D5: =SUM(D3:D4) -> 36 | E5: =SUM(E3:E4) -> 30 | F5: =SUM(F3:F4) -> 8 | G5: =SUM(G3:G4) -> 186
A7: Tabla Valores Esperados
A11: Categoria | B11: =B2 -> a) Siempre | C11: =C2 -> b) Frecuente | D11: =D2 -> c) A veces | E11: =E2 -> d) Raro | F11: =F2 -> e) Nunca | G11: =G2 -> Total
A12: =A3 -> Grupo Control - Post Test | B12: =(G3*B5)/G5 -> 28.5 | C12: =(G3*C5)/G5 -> 27.5 | D12: =(G3*D5)/G5 -> 18 | E12: =(G3*E5)/G5 -> 15 | F12: =(G3*F5)/G5 -> 4 | G12: =SUM(B12:F12) -> 93
A13: =A4 -> Grupo Experimental - Post Test | B13: =(G4*B5)/G5 -> 28.5 | C13: =(G4*C5)/G5 -> 27.5 | D13: =(G4*D5)/G5 -> 18 | E13: =(G4*E5)/G5 -> 15 | F13: =(G4*F5)/G5 -> 4 | G13: =SUM(B13:F13) -> 93
A16: Tabla completa Valores Observados (O) y Valores Esperados (E)
A18: Grupo | B18: Categoria | C18: Valor Observado (O) | D18: Valor Esperado (E )
A19: =A3 -> Grupo Control - Post Test | B19: =B2 -> a) Siempre | C19: =B3 -> 17 | D19: =B12 -> 28.5 | E19: =(C19-D19)^2 -> 132.25 | F19: =E19/D19 -> 4.6403509
A20: =A3 -> Grupo Control - Post Test | B20: =C2 -> b) Frecuente | C20: =C3 -> 23 | D20: =C12 -> 27.5 | E20: =(C20-D20)^2 -> 20.25 | F20: =E20/D20 -> 0.73636364
A21: =A3 -> Grupo Control - Post Test | B21: =D2 -> c) A veces | C21: =D3 -> 24 | D21: =D12 -> 18 | E21: =(C21-D21)^2 -> 36 | F21: =E21/D21 -> 2
A22: =A3 -> Grupo Control - Post Test | B22: =E2 -> d) Raro | C22: =E3 -> 23 | D22: =E12 -> 15 | E22: =(C22-D22)^2 -> 64 | F22: =E22/D22 -> 4.2666667
A23: =A3 -> Grupo Control - Post Test | B23: =F2 -> e) Nunca | C23: =F3 -> 6 | D23: =F12 -> 4 | E23: =(C23-D23)^2 -> 4 | F23: =E23/D23 -> 1
A24: =A4 -> Grupo Experimental - Post Test | B24: =B2 -> a) Siempre | C24: =B4 -> 40 | D24: =B13 -> 28.5 | E24: =(C24-D24)^2 -> 132.25 | F24: =E24/D24 -> 4.6403509
A25: =A4 -> Grupo Experimental - Post Test | B25: =C2 -> b) Frecuente | C25: =C4 -> 32 | D25: =C13 -> 27.5 | E25: =(C25-D25)^2 -> 20.25 | F25: =E25/D25 -> 0.73636364
A26: =A4 -> Grupo Experimental - Post Test | B26: =D2 -> c) A veces | C26: =D4 -> 12 | D26: =D13 -> 18 | E26: =(C26-D26)^2 -> 36 | F26: =E26/D26 -> 2
A27: =A4 -> Grupo Experimental - Post Test | B27: =E2 -> d) Raro | C27: =E4 -> 7 | D27: =E13 -> 15 | E27: =(C27-D27)^2 -> 64 | F27: =E27/D27 -> 4.2666667
A28: =A4 -> Grupo Experimental - Post Test | B28: =F2 -> e) Nunca | C28: =F4 -> 2 | D28: =F13 -> 4 | E28: =(C28-D28)^2 -> 4 | F28: =E28/D28 -> 1
A31: Calculo Chi Cuadrado
A35: Chi Cuadrado | B35: =SUM(F19:F28) -> 25.286762
A37: Calculo Grados Libertad
A39: Filas = 2 (Sin sistema, Con sistema) | C39: 2
A40: Columnas = 5 (las 5 categorías) | C40: 5
A41: Grados de libertad df | C41: =(C39-1)*(C40-1) -> 4
A43: Busqueda de Valor Critico en Tabla Chi Cuadrado
A44: df | B44: =C41 -> 4
A45: α | B45: 0.05 | C45: (el más usado en tesis)
A46: valor critico | B46: =CHIINV(B45,B44) -> 9.487729
A47: p valor | B47: =_xlfn.CHISQ.DIST.RT(B35, B44) -> 4.4052579e-05
A49: Interpretacion
A51: H0 Hipotesis Nula | B51: No existe relación entre los grupos y la variable
A52: H1 Hipotesis Alternativa | B52: Si existe relación entre los grupos y la variable
A54: si p valor < α ---> Se rechaza la hipotesis Nula
A55: α nivel de significancia | B55: =B45 -> 0.05
A56: p valor | B56: =B47 -> 4.4052579e-05
A58: Si chi cuadrado > valor critico ---> Se rechaza la hipotesis nula
A59: Chi Cuadrado | B59: =B35 -> 25.286762
...
